File: SupLinearAndTan/Tan_Fan_Chart/Specimen_RawData_5.csv
Time,Extension,Load
(s),(mm),(N)
"0.00000","0.00000","0.05261"
"0.10000","0.00870","0.06017"
"0.20000","0.04158","0.09219"
"0.30000","0.07202","0.07667"
"0.40000","0.10218","0.11414"
"0.50000","0.13213","0.11796"
"0.60000","0.16238","0.14500"
"0.70000","0.19233","0.14580"
"0.80000","0.22259","0.17676"
"0.90000","0.25234","0.19648"
"1.00000","0.28240","0.21010"
"1.10000","0.31210","0.22494"
"1.20000","0.34227","0.25447"
"1.30000","0.37218","0.26575"
"1.40000","0.40229","0.26909"
"1.50000","0.43203","0.32853"
"1.60000","0.46222","0.30137"
"1.70000","0.49208","0.31397"
"1.80000","0.52234","0.31661"
"1.90000","0.55226","0.35397"
"2.00000","0.58235","0.34482"
"2.10000","0.61229","0.39269"
"2.20000","0.64230","0.39104"
"2.30000","0.67235","0.39443"
"2.40000","0.70239","0.41996"
"2.50000","0.73230","0.46288"
"2.60000","0.76212","0.47259"
"2.70000","0.79216","0.46950"
"2.80000","0.82196","0.50540"
"2.90000","0.85216","0.53431"
"3.00000","0.88216","0.54188"
"3.10000","0.91239","0.54409"
"3.20000","0.94231","0.58040"
"3.30000","0.97238","0.60354"
"3.40000","1.00222","0.62037"
"3.50000","1.03240","0.63105"
"3.60000","1.06228","0.66991"
"3.70000","1.09236","0.67968"
"3.80000","1.12214","0.70275"
"3.90000","1.15224","0.71949"
"4.00000","1.18196","0.75484"
"4.10000","1.21231","0.77087"
"4.20000","1.24211","0.79509"
"4.30000","1.27221","0.83024"
"4.40000","1.30226","0.84221"
"4.50000","1.33222","0.86007"
"4.60000","1.36226","0.87869"
"4.70000","1.39251","0.91333"
"4.80000","1.42240","0.92009"
"4.90000","1.45241","0.95383"
"5.00000","1.48222","0.98034"
"5.10000","1.51219","1.01650"
"5.20000","1.54214","1.04173"
"5.30000","1.57206","1.09953"
"5.40000","1.60213","1.11923"
"5.50000","1.63204","1.13774"
"5.60000","1.66223","1.17448"
"5.70000","1.69216","1.21787"
"5.80000","1.72235","1.25467"
"5.90000","1.75238","1.27199"
"6.00000","1.78238","1.33026"
"6.10000","1.81226","1.36208"
"6.20000","1.84232","1.39438"
"6.30000","1.87210","1.43962"
"6.40000","1.90239","1.48430"
"6.50000","1.93213","1.51807"
"6.60000","1.96220","1.57567"
"6.70000","1.99208","1.63285"
"6.80000","2.02208","1.68862"
"6.90000","2.05212","1.73289"
"7.00000","2.08234","1.78826"
"7.10000","2.11230","1.86540"
"7.20000","2.14231","1.92068"
"7.30000","2.17231","2.00397"
"7.40000","2.20237","2.07124"
"7.50000","2.23237","2.15758"
"7.60000","2.26236","2.22411"
"7.70000","2.29227","2.32192"
"7.80000","2.32203","2.41711"
"7.90000","2.35204","2.51436"
"8.00000","2.38205","2.60682"
"8.10000","2.41230","2.72889"
"8.20000","2.44225","2.85762"
"8.30000","2.47230","2.98410"
"8.39300","2.50003","3.13464"
"8.39500","2.50063","3.14027"
"8.49500","2.50179","3.15530"
"8.59500","2.47020","2.99683"
"8.69500","2.43950","2.84759"
"8.79500","2.40951","2.72449"
"8.89500","2.37924","2.59661"
"8.99500","2.34956","2.49596"
"9.09500","2.31952","2.38186"
"9.19500","2.28961","2.31312"
"9.29500","2.25940","2.21933"
"9.39500","2.22941","2.14128"
"9.49500","2.19922","2.07080"
"9.59500","2.16940","1.99008"
"9.69500","2.13927","1.91097"
"9.79500","2.10930","1.84810"
"9.89500","2.07919","1.78983"
"9.99500","2.04910","1.72638"
"10.09500","2.01927","1.66674"
"10.19500","1.98942","1.61347"
"10.29500","1.95956","1.56878"
"10.39500","1.92943","1.51616"
"10.49500","1.89944","1.47355"
"10.59500","1.86930","1.43396"
"10.69500","1.83934","1.40252"
"10.79500","1.80938","1.35676"
"10.89500","1.77949","1.33516"
"10.99500","1.74930","1.29365"
"11.09500","1.71925","1.24238"
"11.19500","1.68909","1.21080"
"11.29500","1.65937","1.18796"
"11.39500","1.62929","1.15309"
"11.49500","1.59956","1.10990"
"11.59500","1.56948","1.08127"
"11.69500","1.53945","1.04702"
"11.79500","1.50937","1.01671"
"11.89500","1.47953","0.98678"
"11.99500","1.44936","0.97855"
"12.09500","1.41942","0.93913"
"12.19500","1.38919","0.91122"
"12.29500","1.35919","0.89296"
"12.39500","1.32911","0.87893"
"12.49500","1.29936","0.84133"
"12.59500","1.26934","0.83504"
"12.69500","1.23937","0.80228"
"12.79500","1.20942","0.76607"
"12.89500","1.17934","0.76420"
"12.99500","1.14946","0.73619"
"13.09500","1.11943","0.71672"
"13.19500","1.08949","0.67987"
"13.29500","1.05937","0.66894"
"13.39500","1.02934","0.64508"
"13.49500","0.99921","0.62769"
"13.59500","0.96941","0.60467"
"13.69500","0.93921","0.58900"
"13.79500","0.90935","0.56830"
"13.89500","0.87924","0.54593"
"13.99500","0.84929","0.54872"
"14.09500","0.81927","0.52425"
"14.19500","0.78957","0.49500"
"14.29500","0.75947","0.46985"
"14.39500","0.72950","0.47041"
"14.49500","0.69930","0.43693"
"14.59500","0.66937","0.42203"
"14.69500","0.63921","0.40371"
"14.79500","0.60944","0.38958"
"14.89500","0.57922","0.36209"
"14.99500","0.54930","0.34448"
"15.09500","0.51923","0.33469"
"15.19500","0.48929","0.30336"
"15.29500","0.45937","0.34045"
"15.39500","0.42952","0.29555"
"15.49500","0.39952","0.28267"
"15.59500","0.36940","0.26438"
"15.69500","0.33938","0.26609"
"15.79500","0.30936","0.24286"
"15.89500","0.27954","0.22629"
"15.99500","0.24935","0.20826"
"16.09500","0.21941","0.20425"
"16.19500","0.18924","0.17872"
"16.29500","0.15916","0.14648"
"16.39500","0.12916","0.14340"
"16.49500","0.09945","0.12274"
"16.59500","0.06938","0.09496"
"16.69500","0.03956","0.08676"
"16.79500","0.00930","0.07342"
"16.89500","-0.02041","0.05360"
"16.99500","-0.05054","0.04097"
"17.09500","-0.08042","0.03471"
"17.19500","-0.11074","0.03593"
"17.29500","-0.14072","0.00620"
"17.39500","-0.17082","0.01036"
"17.49500","-0.20075","-0.01356"
"17.59500","-0.23074","-0.03033"
"17.69500","-0.26065","-0.05630"
"17.79500","-0.29055","-0.05321"
"17.89500","-0.32072","-0.07819"
"17.99500","-0.35071","-0.11322"
"18.09500","-0.38058","-0.11853"
"18.19500","-0.41039","-0.13711"
"18.29500","-0.44055","-0.15341"
"18.39500","-0.47052","-0.18483"
"18.49500","-0.50076","-0.18727"
"18.59500","-0.53070","-0.20164"
"18.69500","-0.56074","-0.21524"
"18.79500","-0.59064","-0.23069"
"18.89500","-0.62074","-0.23601"
"18.99500","-0.65064","-0.25374"
"19.09500","-0.68089","-0.25594"
"19.19500","-0.71056","-0.25731"
"19.29500","-0.74041","-0.29856"
"19.39500","-0.77029","-0.31580"
"19.49500","-0.80065","-0.32923"
"19.59500","-0.83061","-0.34160"
"19.69500","-0.86075","-0.38087"
"19.79500","-0.89072","-0.39684"
"19.89500","-0.92065","-0.42320"
"19.99500","-0.95059","-0.44596"
"20.09500","-0.98075","-0.46208"
"20.19500","-1.01081","-0.48373"
"20.29500","-1.04082","-0.49706"
"20.39500","-1.07073","-0.51490"
"20.49500","-1.10056","-0.53843"
"20.59500","-1.13056","-0.54821"
"20.69500","-1.16045","-0.57140"
"20.79500","-1.19070","-0.58931"
"20.89500","-1.22059","-0.61366"
"20.99500","-1.25059","-0.62901"
"21.09500","-1.28053","-0.64546"
"21.19500","-1.31072","-0.67705"
"21.29500","-1.34070","-0.68057"
"21.39500","-1.37086","-0.73055"
"21.49500","-1.40081","-0.76502"
"21.59500","-1.43067","-0.79034"
"21.69500","-1.46051","-0.81431"
"21.79500","-1.49063","-0.84931"
"21.89500","-1.52053","-0.88924"
"21.99500","-1.55065","-0.90383"
"22.09500","-1.58058","-0.94566"
"22.19500","-1.61059","-0.98126"
"22.29500","-1.64059","-1.00319"
"22.39500","-1.67059","-1.02798"
"22.49500","-1.70076","-1.08181"
"22.59500","-1.73073","-1.09989"
"22.69500","-1.76081","-1.13014"
"22.79500","-1.79078","-1.17280"
"22.89500","-1.82068","-1.21883"
"22.99500","-1.85065","-1.25299"
"23.09500","-1.88081","-1.31421"
"23.19500","-1.91046","-1.38264"
"23.29500","-1.94054","-1.42200"
"23.39500","-1.97037","-1.46924"
"23.49500","-2.00066","-1.52587"
"23.59500","-2.03058","-1.58550"
"23.69500","-2.06077","-1.62980"
"23.79500","-2.09068","-1.70414"
"23.89500","-2.12067","-1.75588"
"23.99500","-2.15062","-1.82496"
"24.09500","-2.18073","-1.88570"
"24.19500","-2.21066","-1.97066"
"24.29500","-2.24067","-2.04416"
"24.39500","-2.27055","-2.12661"
"24.49500","-2.30051","-2.22220"
"24.59500","-2.33046","-2.33187"
"24.69500","-2.36057","-2.43928"
"24.79500","-2.39070","-2.54680"
"24.89500","-2.42063","-2.69775"
"24.99500","-2.45060","-2.81200"
"25.09500","-2.48070","-2.96076"
"25.16000","-2.50011","-3.06516"
"25.16200","-2.50073","-3.06702"
"25.26200","-2.50266","-3.07682"
"25.36200","-2.47035","-2.92242"
"25.46200","-2.43999","-2.77919"
"25.56200","-2.40954","-2.64154"
"25.66200","-2.37967","-2.52018"
"25.76200","-2.34937","-2.41267"
"25.86200","-2.31962","-2.29272"
"25.96200","-2.28950","-2.19319"
"26.06200","-2.25970","-2.11315"
"26.16200","-2.22965","-2.02841"
"26.26200","-2.19962","-1.93476"
"26.36200","-2.16967","-1.85731"
"26.46200","-2.13984","-1.79599"
"26.56200","-2.10970","-1.71502"
"26.66200","-2.07979","-1.64881"
"26.76200","-2.04955","-1.60212"
"26.86200","-2.01948","-1.54740"
"26.96200","-1.98959","-1.48098"
"27.06200","-1.95940","-1.44692"
"27.16200","-1.92960","-1.38071"
"27.26200","-1.89960","-1.34608"
"27.36200","-1.86972","-1.30100"
"27.46200","-1.83964","-1.25572"
"27.56200","-1.80985","-1.21179"
"27.66200","-1.77980","-1.16596"
"27.76200","-1.74992","-1.13630"
"27.86200","-1.71960","-1.09030"
"27.96200","-1.68966","-1.06408"
"28.06200","-1.65942","-1.01802"
"28.16200","-1.62971","-0.99625"
"28.26200","-1.59946","-0.95240"
"28.36200","-1.56975","-0.91626"
"28.46200","-1.53955","-0.88990"
"28.56200","-1.50947","-0.87391"
"28.66200","-1.47949","-0.82387"
"28.76200","-1.44969","-0.78907"
"28.86200","-1.41972","-0.79232"
"28.96200","-1.38987","-0.75076"
"29.06200","-1.35968","-0.71566"
"29.16200","-1.32971","-0.70728"
"29.26200","-1.29965","-0.69366"
"29.36200","-1.26957","-0.65875"
"29.46200","-1.23955","-0.64956"
"29.56200","-1.20948","-0.61664"
"29.66200","-1.17947","-0.59870"
"29.76200","-1.14930","-0.57272"
"29.86200","-1.11962","-0.56544"
"29.96200","-1.08965","-0.52612"
"30.06200","-1.05990","-0.49398"
"30.16200","-1.02978","-0.48029"
"30.26200","-0.99982","-0.46491"
"30.36200","-0.96960","-0.44246"
"30.46200","-0.93980","-0.42020"
"30.56200","-0.90942","-0.41237"
"30.66200","-0.87975","-0.38820"
"30.76200","-0.84952","-0.37377"
"30.86200","-0.81956","-0.35264"
"30.96200","-0.78939","-0.35419"
"31.06200","-0.75956","-0.32144"
"31.16200","-0.72958","-0.30478"
"31.26200","-0.69969","-0.30222"
"31.36200","-0.66963","-0.27871"
"31.46200","-0.63980","-0.25096"
"31.56200","-0.60978","-0.23852"
"31.66200","-0.57980","-0.23167"
"31.76200","-0.54971","-0.20691"
"31.86200","-0.51959","-0.19870"
"31.96200","-0.48946","-0.18646"
"32.06200","-0.45933","-0.18051"
"32.16200","-0.42947","-0.13966"
"32.26200","-0.39949","-0.14189"
"32.36200","-0.36966","-0.11286"
"32.46200","-0.33957","-0.09609"
"32.56200","-0.30967","-0.08211"
"32.66200","-0.27961","-0.07763"
"32.76200","-0.24983","-0.05145"
"32.86200","-0.21966","-0.03537"
"32.96200","-0.18986","-0.03170"
"33.06200","-0.15949","-0.01585"
"33.16200","-0.12971","0.00733"
"33.26200","-0.09951","0.02363"
"33.36200","-0.06962","0.03030"
"33.46200","-0.03955","0.04921"
"33.56200","-0.00962","0.06391"
"33.66200","0.02060","0.08406"
"33.76200","0.05050","0.07971"
"33.86200","0.08043","0.10603"
"33.96200","0.11021","0.11772"
"34.06200","0.14015","0.13364"
"34.16200","0.17019","0.15525"
"34.26200","0.20032","0.17361"
"34.36200","0.23042","0.17548"
"34.46200","0.26045","0.18230"
"34.56200","0.29047","0.21478"
"34.66200","0.32036","0.22440"
"34.76200","0.35056","0.23643"
"34.86200","0.38049","0.25810"
"34.96200","0.41052","0.29659"
"35.06200","0.44031","0.32403"
"35.16200","0.47038","0.29614"
"35.26200","0.50019","0.32778"
"35.36200","0.53045","0.34124"
"35.46200","0.56021","0.35144"
"35.56200","0.59027","0.39377"
"35.66200","0.62024","0.39892"
"35.76200","0.65035","0.38482"
"35.86200","0.68030","0.42674"
"35.96200","0.71065","0.43521"
"36.06200","0.74038","0.44843"
"36.16200","0.77059","0.46256"
"36.26200","0.80039","0.48733"
"36.36200","0.83039","0.50659"
"36.46200","0.86026","0.51869"
"36.56200","0.89028","0.55280"
"36.66200","0.92026","0.57689"
"36.76200","0.95021","0.57515"
"36.86200","0.98029","0.61687"
"36.96200","1.01030","0.63789"
"37.06200","1.04053","0.64964"
"37.16200","1.07054","0.66992"
"37.26200","1.10042","0.68525"
"37.36200","1.13037","0.72299"
"37.46200","1.16040","0.73013"
"37.56200","1.19022","0.76118"
"37.66200","1.22062","0.76902"
"37.76200","1.25030","0.79405"
"37.86200","1.28038","0.81207"
"37.96200","1.31014","0.84403"
"38.06200","1.34020","0.87484"
"38.16200","1.37018","0.87768"
"38.26200","1.40049","0.91792"
"38.36200","1.43031","0.94710"
"38.46200","1.46051","0.97457"
"38.56200","1.49038","0.99150"
"38.66200","1.52059","1.03461"
"38.76200","1.55045","1.06673"
"38.86200","1.58062","1.09956"
"38.96200","1.61035","1.12612"
"39.06200","1.64024","1.16966"
"39.16200","1.67016","1.19854"
"39.26200","1.70014","1.23008"
"39.36200","1.73040","1.26056"
"39.46200","1.76043","1.29688"
"39.56200","1.79037","1.32665"
"39.66200","1.82036","1.36126"
"39.76200","1.85038","1.41689"
"39.86200","1.88029","1.43956"
"39.96200","1.91056","1.49400"
"40.06200","1.94045","1.52703"
"40.16200","1.97057","1.60328"
"40.26200","2.00025","1.64294"
"40.36200","2.03033","1.68946"
"40.46200","2.06014","1.76460"
"40.56200","2.09028","1.83171"
"40.66200","2.12018","1.88257"
"40.76200","2.15032","1.95036"
"40.86200","2.18029","2.01726"
"40.96200","2.21051","2.07839"
"41.06200","2.24048","2.16344"
"41.16200","2.27067","2.25767"
"41.26200","2.30056","2.33540"
"41.36200","2.33050","2.39657"
"41.46200","2.36030","2.52438"
"41.56200","2.39036","2.62793"
"41.66200","2.42037","2.74382"
"41.76200","2.45033","2.89131"
"41.86200","2.48025","3.03247"
"41.92800","2.50007","3.11304"
"41.93000","2.50066","3.11372"
"42.03000","2.50183","3.14490"
"42.13000","2.47025","2.98787"
"42.23000","2.43951","2.84381"
"42.33000","2.40951","2.70929"
"42.43000","2.37928","2.59411"
"42.53000","2.34960","2.47786"
"42.63000","2.31955","2.38997"
"42.73000","2.28961","2.29413"
"42.83000","2.25943","2.20469"
"42.93000","2.22946","2.12918"
"43.03000","2.19924","2.07320"
"43.13000","2.16943","1.98021"
"43.23000","2.13925","1.91724"
"43.33000","2.10934","1.85441"
"43.43000","2.07922","1.78698"
"43.53000","2.04914","1.72726"
"43.63000","2.01933","1.67108"
"43.73000","1.98946","1.62381"
"43.83000","1.95962","1.55727"
"43.93000","1.92947","1.51638"
"44.03000","1.89947","1.48182"
"44.13000","1.86932","1.43803"
"44.23000","1.83936","1.39016"
"44.33000","1.80937","1.36240"
"44.43000","1.77952","1.32509"
"44.53000","1.74932","1.28700"
"44.63000","1.71930","1.24332"
"44.73000","1.68911","1.21767"
"44.83000","1.65939","1.18907"
"44.93000","1.62933","1.13552"
"45.03000","1.59960","1.12676"
"45.13000","1.56951","1.08038"
"45.23000","1.53948","1.03475"
"45.33000","1.50942","1.00610"
"45.43000","1.47955","1.00515"
"45.53000","1.44938","0.96460"
"45.63000","1.41944","0.92637"
"45.73000","1.38923","0.90923"
"45.83000","1.35920","0.89482"
"45.93000","1.32915","0.86457"
"46.03000","1.29938","0.83906"
"46.13000","1.26936","0.83016"
"46.23000","1.23941","0.78690"
"46.33000","1.20944","0.77005"
"46.43000","1.17937","0.75297"
"46.53000","1.14945","0.72253"
"46.63000","1.11948","0.70298"
"46.73000","1.08950","0.68614"
"46.83000","1.05941","0.67469"
"46.93000","1.02936","0.64808"
"47.03000","0.99924","0.61393"
"47.13000","0.96943","0.60390"
"47.23000","0.93922","0.59154"
"47.33000","0.90939","0.56505"
"47.43000","0.87924","0.54668"
"47.53000","0.84932","0.54284"
"47.63000","0.81932","0.51744"
"47.73000","0.78959","0.48189"
"47.83000","0.75951","0.47960"
"47.93000","0.72949","0.44861"
"48.03000","0.69933","0.43309"
"48.13000","0.66938","0.41605"
"48.23000","0.63924","0.41643"
"48.33000","0.60947","0.39120"
"48.43000","0.57925","0.36847"
"48.53000","0.54935","0.35132"
"48.63000","0.51923","0.33501"
"48.73000","0.48932","0.32534"
"48.83000","0.45942","0.33625"
"48.93000","0.42954","0.30304"
"49.03000","0.39955","0.28224"
"49.13000","0.36943","0.26853"
"49.23000","0.33942","0.24921"
"49.33000","0.30937","0.23760"
"49.43000","0.27958","0.20340"
"49.53000","0.24938","0.20335"
"49.63000","0.21941","0.20394"
"49.73000","0.18929","0.16854"
"49.83000","0.15921","0.14210"
"49.93000","0.12918","0.13887"
"50.03000","0.09947","0.13661"
"50.13000","0.06940","0.09943"
"50.23000","0.03967","0.09031"
"50.33000","0.00931","0.07667"
"50.43000","-0.02038","0.06291"
"50.53000","-0.05052","0.03288"
"50.63000","-0.08040","0.05170"
"50.73000","-0.11072","0.01996"
"50.83000","-0.14068","0.01111"
"50.93000","-0.17081","0.00815"
"51.03000","-0.20072","-0.00960"
"51.13000","-0.23072","-0.03356"
"51.23000","-0.26058","-0.05948"
"51.33000","-0.29063","-0.06031"
"51.43000","-0.32061","-0.08102"
"51.53000","-0.35069","-0.11240"
"51.63000","-0.38057","-0.11699"
"51.73000","-0.41032","-0.13824"
"51.83000","-0.44053","-0.16607"
"51.93000","-0.47049","-0.16658"
"52.03000","-0.50073","-0.18705"
"52.13000","-0.53069","-0.19076"
"52.23000","-0.56071","-0.21179"
"52.33000","-0.59062","-0.21901"
"52.43000","-0.62071","-0.23889"
"52.53000","-0.65060","-0.24440"
"52.63000","-0.68086","-0.25897"
"52.73000","-0.71051","-0.27466"
"52.83000","-0.74048","-0.29222"
"52.93000","-0.77024","-0.32528"
"53.03000","-0.80045","-0.33048"
"53.13000","-0.83070","-0.35245"
"53.23000","-0.86075","-0.37457"
"53.33000","-0.89071","-0.40389"
"53.43000","-0.92062","-0.40436"
"53.53000","-0.95058","-0.44607"
"53.63000","-0.98069","-0.46200"
"53.73000","-1.01078","-0.47519"
"53.83000","-1.04081","-0.48221"
"53.93000","-1.07069","-0.51984"
"54.03000","-1.10055","-0.52979"
"54.13000","-1.13053","-0.54178"
"54.23000","-1.16039","-0.57526"
"54.33000","-1.19067","-0.58455"
"54.43000","-1.22057","-0.60838"
"54.53000","-1.25048","-0.63739"
"54.63000","-1.28055","-0.66439"
"54.73000","-1.31073","-0.68011"
"54.83000","-1.34066","-0.70132"
"54.93000","-1.37083","-0.73763"
"55.03000","-1.40079","-0.78075"
"55.13000","-1.43062","-0.79091"
"55.23000","-1.46051","-0.82033"
"55.33000","-1.49060","-0.85991"
"55.43000","-1.52050","-0.87792"
"55.53000","-1.55061","-0.90297"
"55.63000","-1.58056","-0.94120"
"55.73000","-1.61057","-0.97537"
"55.83000","-1.64053","-0.98581"
"55.93000","-1.67055","-1.03179"
"56.03000","-1.70065","-1.07076"
"56.13000","-1.73081","-1.10569"
"56.23000","-1.76082","-1.13582"
"56.33000","-1.79075","-1.18509"
"56.43000","-1.82065","-1.21568"
"56.53000","-1.85061","-1.26979"
"56.63000","-1.88078","-1.31842"
"56.73000","-1.91045","-1.38222"
"56.83000","-1.94050","-1.41152"
"56.93000","-1.97034","-1.47110"
"57.03000","-2.00060","-1.53659"
"57.13000","-2.03053","-1.56368"
"57.23000","-2.06075","-1.63598"
"57.33000","-2.09066","-1.69695"
"57.43000","-2.12053","-1.75339"
"57.53000","-2.15061","-1.80817"
"57.63000","-2.18073","-1.88974"
"57.73000","-2.21066","-1.96794"
"57.83000","-2.24074","-2.04347"
"57.93000","-2.27040","-2.13299"
"58.03000","-2.30052","-2.23459"
"58.13000","-2.33046","-2.33130"
"58.23000","-2.36052","-2.44238"
"58.33000","-2.39068","-2.56764"
"58.43000","-2.42061","-2.68278"
"58.53000","-2.45053","-2.82433"
"58.63000","-2.48066","-2.94916"
"58.69500","-2.50011","-3.05346"
"58.69700","-2.50073","-3.05625"
"58.79700","-2.50262","-3.09245"
"58.89700","-2.47031","-2.92123"
"58.99700","-2.43995","-2.78512"
"59.09700","-2.40951","-2.64738"
"59.19700","-2.37964","-2.53176"
"59.29700","-2.34933","-2.41893"
"59.39700","-2.31961","-2.29315"
"59.49700","-2.28943","-2.19761"
"59.59700","-2.25969","-2.11234"
"59.69700","-2.22959","-2.02413"
"59.79700","-2.19957","-1.92886"
"59.89700","-2.16966","-1.86111"
"59.99700","-2.13979","-1.78211"
"60.09700","-2.10967","-1.71237"
"60.19700","-2.07976","-1.64664"
"60.29700","-2.04950","-1.61239"
"60.39700","-2.01944","-1.54371"
"60.49700","-1.98953","-1.48848"
"60.59700","-1.95937","-1.44469"
"60.69700","-1.92958","-1.40042"
"60.79700","-1.89954","-1.33954"
"60.89700","-1.86970","-1.30245"
"60.99700","-1.83962","-1.25980"
"61.09700","-1.80980","-1.20962"
"61.19700","-1.77978","-1.16902"
"61.29700","-1.74987","-1.13435"
"61.39700","-1.71958","-1.10616"
"61.49700","-1.68963","-1.04901"
"61.59700","-1.65940","-1.03535"
"61.69700","-1.62966","-0.98050"
"61.79700","-1.59945","-0.93896"
"61.89700","-1.56972","-0.91196"
"61.99700","-1.53950","-0.89751"
"62.09700","-1.50946","-0.85807"
"62.19700","-1.47947","-0.81998"
"62.29700","-1.44966","-0.81062"
"62.39700","-1.41966","-0.78182"
"62.49700","-1.38984","-0.74375"
"62.59700","-1.35966","-0.72749"
"62.69700","-1.32966","-0.70957"
"62.79700","-1.29964","-0.68114"
"62.89700","-1.26954","-0.66220"
"62.99700","-1.23954","-0.64697"
"63.09700","-1.20947","-0.62280"
"63.19700","-1.17944","-0.59134"
"63.29700","-1.14926","-0.57273"
"63.39700","-1.11956","-0.55585"
"63.49700","-1.08961","-0.52985"
"63.59700","-1.05988","-0.50125"
"63.69700","-1.02978","-0.48662"
"63.79700","-0.99981","-0.47008"
"63.89700","-0.96965","-0.44191"
"63.99700","-0.93962","-0.43235"
"64.09700","-0.90948","-0.41418"
"64.19700","-0.87971","-0.38806"
"64.29700","-0.84951","-0.35813"
"64.39700","-0.81954","-0.36640"
"64.49700","-0.78937","-0.34398"
"64.59700","-0.75952","-0.31626"
"64.69700","-0.72956","-0.30156"
"64.79700","-0.69965","-0.29920"
"64.89700","-0.66960","-0.27193"
"64.99700","-0.63976","-0.24516"
"65.09700","-0.60973","-0.24528"
"65.19700","-0.57973","-0.21664"
"65.29700","-0.54971","-0.20098"
"65.39700","-0.51955","-0.19125"
"65.49700","-0.48944","-0.18987"
"65.59700","-0.45930","-0.16579"
"65.69700","-0.42944","-0.15365"
"65.79700","-0.39948","-0.14687"
"65.89700","-0.36965","-0.12201"
"65.99700","-0.33953","-0.09467"
"66.09700","-0.30962","-0.10126"
"66.19700","-0.27959","-0.08233"
"66.29700","-0.24979","-0.05537"
"66.39700","-0.21964","-0.05128"
"66.49700","-0.18983","-0.02642"
"66.59700","-0.15947","-0.02013"
"66.69700","-0.12973","0.01904"
"66.79700","-0.09942","0.00642"
"66.89700","-0.06959","0.03884"
"66.99700","-0.03953","0.04735"
"67.09700","-0.00959","0.06883"
"67.19700","0.02062","0.08126"
"67.29700","0.05052","0.09072"
"67.39700","0.08048","0.11407"
"67.49700","0.11025","0.12828"
"67.59700","0.14014","0.12827"
"67.69700","0.17023","0.14711"
"67.79700","0.20034","0.17048"
"67.89700","0.23045","0.17194"
"67.99700","0.26047","0.18569"
"68.09700","0.29048","0.19570"
"68.19700","0.32041","0.21818"
"68.29700","0.35058","0.23365"
"68.39700","0.38053","0.26845"
"68.49700","0.41055","0.28613"
"68.59700","0.44034","0.32513"
"68.69700","0.47039","0.30255"
"68.79700","0.50020","0.32808"
"68.89700","0.53049","0.33954"
"68.99700","0.56020","0.35903"
"69.09700","0.59029","0.38716"
"69.19700","0.62025","0.39000"
"69.29700","0.65040","0.40298"
"69.39700","0.68037","0.42152"
"69.49700","0.71066","0.42956"
"69.59700","0.74042","0.44353"
"69.69700","0.77063","0.46478"
"69.79700","0.80040","0.48384"
"69.89700","0.83043","0.50014"
"69.99700","0.86031","0.51872"
"70.09700","0.89030","0.54883"
"70.19700","0.92028","0.57309"
"70.29700","0.95023","0.58371"
"70.39700","0.98032","0.61800"
"70.49700","1.01033","0.63270"
"70.59700","1.04055","0.66161"
"70.69700","1.07053","0.67315"
"70.79700","1.10046","0.69748"
"70.89700","1.13041","0.72105"
"70.99700","1.16042","0.73404"
"71.09700","1.19022","0.74468"
"71.19700","1.22065","0.78469"
"71.29700","1.25030","0.79055"
"71.39700","1.28043","0.80463"
"71.49700","1.31016","0.84385"
"71.59700","1.34023","0.86719"
"71.69700","1.37020","0.87557"
"71.79700","1.40050","0.90226"
"71.89700","1.43035","0.95565"
"71.99700","1.46053","0.96990"
"72.09700","1.49041","0.99530"
"72.19700","1.52061","1.02781"
"72.29700","1.55050","1.07272"
"72.39700","1.58063","1.09726"
"72.49700","1.61038","1.12837"
"72.59700","1.64029","1.16857"
"72.69700","1.67021","1.19880"
"72.79700","1.70018","1.22468"
"72.89700","1.73042","1.26345"
"72.99700","1.76045","1.29092"
"73.09700","1.79044","1.31609"
"73.19700","1.82039","1.34853"
"73.29700","1.85043","1.40389"
"73.39700","1.88030","1.44607"
"73.49700","1.91060","1.46990"
"73.59700","1.94048","1.54021"
"73.69700","1.97059","1.58918"
"73.79700","2.00027","1.64380"
"73.89700","2.03035","1.69721"
"73.99700","2.06016","1.77771"
"74.09700","2.09032","1.83043"
"74.19700","2.12015","1.89311"
"74.29700","2.15041","1.96421"
"74.39700","2.18028","2.02502"
"74.49700","2.21053","2.08590"
"74.59700","2.24043","2.17367"
"74.69700","2.27081","2.24988"
"74.79700","2.30054","2.33440"
"74.89700","2.33053","2.42908"
"74.99700","2.36037","2.52185"
"75.09700","2.39036","2.62395"
"75.19700","2.42040","2.74785"
"75.29700","2.45036","2.89562"
"75.39700","2.48026","3.02740"
"75.46300","2.50008","3.14572"
"75.46500","2.50067","3.14834"
"75.56500","2.50192","3.14982"
"75.66500","2.47031","2.98223"
"75.76500","2.43961","2.86247"
"75.86500","2.40960","2.71782"
"75.96500","2.37933","2.59099"
"76.06500","2.34966","2.49071"
"76.16500","2.31960","2.39056"
"76.26500","2.28968","2.31131"
"76.36500","2.25951","2.22075"
"76.46500","2.22952","2.15120"
"76.56500","2.19928","2.06704"
"76.66500","2.16949","1.98829"
"76.76500","2.13934","1.91902"
"76.86500","2.10939","1.86310"
"76.96500","2.07929","1.78635"
"77.06500","2.04920","1.72241"
"77.16500","2.01939","1.65867"
"77.26500","1.98951","1.61862"
"77.36500","1.95967","1.55793"
"77.46500","1.92953","1.49928"
"77.56500","1.89953","1.48233"
"77.66500","1.86938","1.43127"
"77.76500","1.83948","1.39067"
"77.86500","1.80941","1.35408"
"77.96500","1.77959","1.32803"
"78.06500","1.74940","1.28451"
"78.16500","1.71937","1.26524"
"78.26500","1.68917","1.22193"
"78.36500","1.65947","1.17779"
"78.46500","1.62940","1.14617"
"78.56500","1.59966","1.12396"
"78.66500","1.56957","1.08729"
"78.76500","1.53954","1.03342"
"78.86500","1.50947","1.01624"
"78.96500","1.47959","0.98736"
"79.06500","1.44943","0.96451"
"79.16500","1.41951","0.92282"
"79.26500","1.38927","0.91641"
"79.36500","1.35927","0.89434"
"79.46500","1.32920","0.87282"
"79.56500","1.29945","0.85425"
"79.66500","1.26944","0.83795"
"79.76500","1.23946","0.80226"
"79.86500","1.20951","0.77818"
"79.96500","1.17941","0.76391"
"80.06500","1.14953","0.73996"
"80.16500","1.11955","0.70510"
"80.26500","1.08956","0.68758"
"80.36500","1.05943","0.68145"
"80.46500","1.02940","0.64018"
"80.56500","0.99933","0.61407"
"80.66500","0.96952","0.61378"
"80.76500","0.93926","0.58255"
"80.86500","0.90946","0.55785"
"80.96500","0.87930","0.55608"
"81.06500","0.84937","0.53698"
"81.16500","0.81942","0.50513"
"81.26500","0.78970","0.48873"
"81.36500","0.75956","0.49256"
"81.46500","0.72958","0.46899"
"81.56500","0.69940","0.44193"
"81.66500","0.66944","0.43974"
"81.76500","0.63931","0.41380"
"81.86500","0.60952","0.38946"
"81.96500","0.57930","0.36330"
"82.06500","0.54940","0.35849"
"82.16500","0.51932","0.32599"
"82.26500","0.48935","0.31338"
"82.36500","0.45949","0.34551"
"82.46500","0.42959","0.28780"
"82.56500","0.39961","0.27394"
"82.66500","0.36948","0.25645"
"82.76500","0.33946","0.25883"
"82.86500","0.30943","0.22470"
"82.96500","0.27965","0.20766"
"83.06500","0.24944","0.20158"
"83.16500","0.21948","0.19616"
"83.26500","0.18930","0.17533"
"83.36500","0.15926","0.16351"
"83.46500","0.12926","0.14500"
"83.56500","0.09966","0.12756"
"83.66500","0.06942","0.10849"
"83.76500","0.03971","0.10245"
"83.86500","0.00933","0.08171"
"83.96500","-0.02034","0.05290"
"84.06500","-0.05045","0.04202"
"84.16500","-0.08035","0.04143"
"84.26500","-0.11063","0.02367"
"84.36500","-0.14061","-0.00755"
"84.46500","-0.17076","0.00290"
"84.56500","-0.20063","-0.02985"
"84.66500","-0.23065","-0.03144"
"84.76500","-0.26054","-0.04851"
"84.86500","-0.29055","-0.05408"
"84.96500","-0.32058","-0.08856"
"85.06500","-0.35053","-0.10318"
"85.16500","-0.38048","-0.10895"
"85.26500","-0.41032","-0.13956"
"85.36500","-0.44047","-0.15938"
"85.46500","-0.47042","-0.16708"
"85.56500","-0.50068","-0.17413"
"85.66500","-0.53063","-0.20190"
"85.76500","-0.56064","-0.20826"
"85.86500","-0.59053","-0.22345"
"85.96500","-0.62065","-0.23896"
"86.06500","-0.65054","-0.26434"
"86.16500","-0.68080","-0.26930"
"86.26500","-0.71047","-0.28490"
"86.36500","-0.74042","-0.30618"
"86.46500","-0.77022","-0.32048"
"86.56500","-0.80028","-0.33327"
"86.66500","-0.83044","-0.34832"
"86.76500","-0.86087","-0.38429"
"86.86500","-0.89067","-0.38278"
"86.96500","-0.92055","-0.40797"
"87.06500","-0.95052","-0.44076"
"87.16500","-0.98063","-0.46268"
"87.26500","-1.01071","-0.46359"
"87.36500","-1.04077","-0.49235"
"87.46500","-1.07065","-0.51587"
"87.56500","-1.10048","-0.53433"
"87.66500","-1.13047","-0.55181"
"87.76500","-1.16035","-0.58935"
"87.86500","-1.19061","-0.60394"
"87.96500","-1.22050","-0.62027"
"88.06500","-1.25036","-0.64502"
"88.16500","-1.28049","-0.66240"
"88.26500","-1.31072","-0.67794"
"88.36500","-1.34059","-0.69511"
"88.46500","-1.37080","-0.72753"
"88.56500","-1.40057","-0.74487"
"88.66500","-1.43065","-0.78329"
"88.76500","-1.46042","-0.82399"
"88.86500","-1.49059","-0.84353"
"88.96500","-1.52043","-0.87664"
"89.06500","-1.55057","-0.90383"
"89.16500","-1.58050","-0.94987"
"89.26500","-1.61048","-0.98036"
"89.36500","-1.64048","-1.00353"
"89.46500","-1.67043","-1.03401"
"89.56500","-1.70065","-1.09241"
"89.66500","-1.73075","-1.10877"
"89.76500","-1.76073","-1.14502"
"89.86500","-1.79067","-1.18069"
"89.96500","-1.82060","-1.22567"
"90.06500","-1.85051","-1.25775"
"90.16500","-1.88073","-1.31579"
"90.26500","-1.91036","-1.36514"
"90.36500","-1.94045","-1.39659"
"90.46500","-1.97028","-1.45502"
"90.56500","-2.00054","-1.52260"
"90.66500","-2.03049","-1.56723"
"90.76500","-2.06068","-1.61533"
"90.86500","-2.09060","-1.70727"
"90.96500","-2.12053","-1.75618"
"91.06500","-2.15060","-1.81690"
"91.16500","-2.18066","-1.89621"
"91.26500","-2.21064","-1.98549"
"91.36500","-2.24064","-2.04397"
"91.46500","-2.27023","-2.13674"
"91.56500","-2.30047","-2.23192"
"91.66500","-2.33036","-2.32585"
"91.76500","-2.36047","-2.43758"
"91.86500","-2.39065","-2.54920"
"91.96500","-2.42054","-2.68018"
"92.06500","-2.45048","-2.78950"
"92.16500","-2.48061","-2.95840"
"92.23000","-2.50006","-3.04805"
"92.23200","-2.50068","-3.05024"
"92.33200","-2.50226","-3.08051"
"92.43200","-2.47027","-2.91761"
"92.53200","-2.43988","-2.76638"
"92.63200","-2.40943","-2.63470"
"92.73200","-2.37958","-2.50759"
"92.83200","-2.34926","-2.40480"
"92.93200","-2.31954","-2.28551"
"93.03200","-2.28937","-2.20017"
"93.13200","-2.25964","-2.10909"
"93.23200","-2.22951","-2.02161"
"93.33200","-2.19960","-1.94273"
"93.43200","-2.16959","-1.86755"
"93.53200","-2.13974","-1.79543"
"93.63200","-2.10961","-1.71366"
"93.73200","-2.07969","-1.66801"
"93.83200","-2.04947","-1.61411"
"93.93200","-2.01940","-1.54029"
"94.03200","-1.98943","-1.47912"
"94.13200","-1.95932","-1.44815"
"94.23200","-1.92951","-1.38472"
"94.33200","-1.89945","-1.33176"
"94.43200","-1.86962","-1.29525"
"94.53200","-1.83954","-1.24456"
"94.63200","-1.80974","-1.19406"
"94.73200","-1.77969","-1.15958"
"94.83200","-1.74981","-1.13500"
"94.93200","-1.71954","-1.08508"
"95.03200","-1.68956","-1.05942"
"95.13200","-1.65934","-1.03095"
"95.23200","-1.62962","-0.99165"
"95.33200","-1.59936","-0.95954"
"95.43200","-1.56965","-0.93607"
"95.53200","-1.53942","-0.89417"
"95.63200","-1.50939","-0.87050"
"95.73200","-1.47939","-0.83003"
"95.83200","-1.44958","-0.80598"
"95.93200","-1.41958","-0.78448"
"96.03200","-1.38978","-0.74078"
"96.13200","-1.35961","-0.71677"
"96.23200","-1.32962","-0.70110"
"96.33200","-1.29957","-0.68778"
"96.43200","-1.26946","-0.64294"
"96.53200","-1.23946","-0.64586"
"96.63200","-1.20940","-0.62185"
"96.73200","-1.17936","-0.59953"
"96.83200","-1.14921","-0.58049"
"96.93200","-1.11952","-0.55264"
"97.03200","-1.08953","-0.52443"
"97.13200","-1.05977","-0.50322"
"97.23200","-1.02973","-0.50668"
"97.33200","-0.99973","-0.46488"
"97.43200","-0.96947","-0.44076"
"97.53200","-0.93963","-0.42856"
"97.63200","-0.90943","-0.41644"
"97.73200","-0.87962","-0.38194"
"97.83200","-0.84945","-0.36569"
"97.93200","-0.81948","-0.34365"
"98.03200","-0.78932","-0.34005"
"98.13200","-0.75946","-0.31957"
"98.23200","-0.72950","-0.30545"
"98.33200","-0.69958","-0.29000"
"98.43200","-0.66953","-0.26348"
"98.53200","-0.63971","-0.25606"
"98.63200","-0.60964","-0.24852"
"98.73200","-0.57974","-0.23570"
"98.83200","-0.54973","-0.20078"
"98.93200","-0.51946","-0.20640"
"99.03200","-0.48936","-0.19599"
"99.13200","-0.45910","-0.16996"
"99.23200","-0.42937","-0.15088"
"99.33200","-0.39939","-0.14312"
"99.43200","-0.36959","-0.12197"
"99.53200","-0.33948","-0.09365"
"99.63200","-0.30956","-0.09782"
"99.73200","-0.27951","-0.06664"
"99.83200","-0.24973","-0.05083"
"99.93200","-0.21956","-0.03127"
"100.03200","-0.18975","-0.02838"
"100.13200","-0.15941","-0.00521"
"100.23200","-0.12962","0.00611"
"100.33200","-0.09939","0.02104"
"100.43200","-0.06952","0.02225"
"100.53200","-0.03946","0.04671"
"100.63200","-0.00951","0.05744"
"100.73200","0.02069","0.06233"
"100.83200","0.05058","0.08691"
"100.93200","0.08055","0.10283"
"101.03200","0.11034","0.12215"
"101.13200","0.14024","0.12483"
"101.23200","0.17029","0.16758"
"101.33200","0.20039","0.16702"
"101.43200","0.23053","0.17462"
"101.53200","0.26054","0.19099"
"101.63200","0.29053","0.21507"
"101.73200","0.32051","0.21882"
"101.83200","0.35065","0.23631"
"101.93200","0.38059","0.27141"
"102.03200","0.41061","0.28679"
"102.13200","0.44041","0.32073"
"102.23200","0.47048","0.29230"
"102.33200","0.50027","0.32929"
"102.43200","0.53054","0.32676"
"102.53200","0.56028","0.36085"
"102.63200","0.59036","0.38008"
"102.73200","0.62032","0.38555"
"102.83200","0.65047","0.38972"
"102.93200","0.68042","0.43596"
"103.03200","0.71072","0.42843"
"103.13200","0.74050","0.45780"
"103.23200","0.77072","0.46883"
"103.33200","0.80047","0.49383"
"103.43200","0.83047","0.52057"
"103.53200","0.86039","0.52552"
"103.63200","0.89038","0.55915"
"103.73200","0.92035","0.56674"
"103.83200","0.95027","0.59643"
"103.93200","0.98039","0.61029"
"104.03200","1.01040","0.64048"
"104.13200","1.04062","0.64832"
"104.23200","1.07060","0.66399"
"104.33200","1.10054","0.69157"
"104.43200","1.13046","0.71801"
"104.53200","1.16047","0.72573"
"104.63200","1.19031","0.75373"
"104.73200","1.22075","0.78783"
"104.83200","1.25038","0.80290"
"104.93200","1.28056","0.82517"
"105.03200","1.31017","0.85323"
"105.13200","1.34030","0.88268"
"105.23200","1.37026","0.88507"
"105.33200","1.40058","0.92436"
"105.43200","1.43039","0.94845"
"105.53200","1.46059","0.97239"
"105.63200","1.49045","1.00121"
"105.73200","1.52068","1.04199"
"105.83200","1.55058","1.05113"
"105.93200","1.58069","1.08823"
"106.03200","1.61048","1.11874"
"106.13200","1.64037","1.15404"
"106.23200","1.67025","1.19169"
"106.33200","1.70026","1.21693"
"106.43200","1.73048","1.26055"
"106.53200","1.76052","1.29068"
"106.63200","1.79048","1.33413"
"106.73200","1.82045","1.37199"
"106.83200","1.85048","1.42560"
"106.93200","1.88040","1.45217"
"107.03200","1.91066","1.49663"
"107.13200","1.94055","1.55489"
"107.23200","1.97067","1.59842"
"107.33200","2.00034","1.63313"
"107.43200","2.03043","1.69927"
"107.53200","2.06024","1.76952"
"107.63200","2.09045","1.81186"
"107.73200","2.12015","1.87123"
"107.83200","2.15047","1.94298"
"107.93200","2.18034","2.01572"
"108.03200","2.21059","2.07412"
"108.13200","2.24058","2.17518"
"108.23200","2.27082","2.24446"
"108.33200","2.30062","2.33013"
"108.43200","2.33063","2.42479"
"108.53200","2.36043","2.54090"
"108.63200","2.39044","2.64435"
"108.73200","2.42049","2.75835"
"108.83200","2.45042","2.90021"
"108.93200","2.48031","3.04898"
"108.99800","2.50018","3.15012"
"109.00000","2.50078","3.15390"
"109.10000","2.50197","3.17459"
"109.20000","2.47037","2.99927"
"109.30000","2.43967","2.87246"
"109.40000","2.40966","2.72995"
"109.50000","2.37940","2.59655"
"109.60000","2.34973","2.49581"
"109.70000","2.31968","2.38619"
"109.80000","2.28974","2.29107"
"109.90000","2.25956","2.21342"
"110.00000","2.22959","2.13920"
"110.10000","2.19935","2.05734"
"110.20000","2.16952","1.97877"
"110.30000","2.13942","1.91184"
"110.40000","2.10944","1.86756"
"110.50000","2.07936","1.79106"
"110.60000","2.04926","1.74160"
"110.70000","2.01944","1.67683"
"110.80000","1.98956","1.64093"
"110.90000","1.95974","1.57299"
"111.00000","1.92959","1.52657"
"111.10000","1.89960","1.48432"
"111.20000","1.86946","1.43227"
"111.30000","1.83948","1.39334"
"111.40000","1.80945","1.35530"
"111.50000","1.77963","1.31410"
"111.60000","1.74943","1.26433"
"111.70000","1.71943","1.24564"
"111.80000","1.68923","1.21571"
"111.90000","1.65951","1.17322"
"112.00000","1.62947","1.13570"
"112.10000","1.59971","1.13273"
"112.20000","1.56962","1.08359"
"112.30000","1.53960","1.04482"
"112.40000","1.50953","1.03422"
"112.50000","1.47967","1.00723"
"112.60000","1.44950","0.96879"
"112.70000","1.41956","0.94491"
"112.80000","1.38935","0.92967"
"112.90000","1.35932","0.88449"
"113.00000","1.32927","0.86748"
"113.10000","1.29950","0.84253"
"113.20000","1.26952","0.82682"
"113.30000","1.23951","0.77842"
"113.40000","1.20958","0.76839"
"113.50000","1.17948","0.75159"
"113.60000","1.14959","0.72537"
"113.70000","1.11960","0.70573"
"113.80000","1.08964","0.69005"
"113.90000","1.05949","0.67122"
"114.00000","1.02946","0.65274"
"114.10000","0.99939","0.63918"
"114.20000","0.96956","0.61716"
"114.30000","0.93934","0.59663"
"114.40000","0.90954","0.56488"
"114.50000","0.87935","0.56521"
"114.60000","0.84943","0.53036"
"114.70000","0.81947","0.49967"
"114.80000","0.78976","0.48508"
"114.90000","0.75961","0.47384"
"115.00000","0.72965","0.45295"
"115.10000","0.69945","0.42854"
"115.20000","0.66952","0.41249"
"115.30000","0.63937","0.40656"
"115.40000","0.60961","0.38711"
"115.50000","0.57938","0.37207"
"115.60000","0.54947","0.36958"
"115.70000","0.51941","0.33946"
"115.80000","0.48940","0.32897"
"115.90000","0.45952","0.35408"
"116.00000","0.42963","0.31077"
"116.10000","0.39967","0.28007"
"116.20000","0.36956","0.27462"
"116.30000","0.33952","0.25788"
"116.40000","0.30949","0.22313"
"116.50000","0.27970","0.21701"
"116.60000","0.24948","0.20124"
"116.70000","0.21957","0.19214"
"116.80000","0.18935","0.16157"
"116.90000","0.15931","0.15588"
"117.00000","0.12930","0.14536"
"117.10000","0.09961","0.11319"
"117.20000","0.06961","0.10755"
"117.30000","0.03969","0.10252"
"117.40000","0.00943","0.08094"
"117.50000","-0.02029","0.06916"
"117.60000","-0.05039","0.05819"
"117.70000","-0.08028","0.06118"
"117.80000","-0.11058","0.03568"
"117.90000","-0.14056","0.01555"
"118.00000","-0.17067","0.00489"
"118.10000","-0.20060","-0.01706"
"118.20000","-0.23060","-0.03531"
"118.30000","-0.26048","-0.05565"
"118.40000","-0.29050","-0.06270"
"118.50000","-0.32051","-0.10415"
"118.60000","-0.35050","-0.10825"
"118.70000","-0.38036","-0.11712"
"118.80000","-0.41036","-0.13406"
"118.90000","-0.44041","-0.16396"
"119.00000","-0.47033","-0.15363"
"119.10000","-0.50063","-0.16334"
"119.20000","-0.53059","-0.19271"
"119.30000","-0.56057","-0.20503"
"119.40000","-0.59048","-0.20796"
"119.50000","-0.62062","-0.23419"
"119.60000","-0.65046","-0.26560"
"119.70000","-0.68073","-0.25735"
"119.80000","-0.71040","-0.28283"
"119.90000","-0.74034","-0.33012"
"120.00000","-0.77018","-0.31576"
"120.10000","-0.80022","-0.34261"
"120.20000","-0.83045","-0.36035"
"120.30000","-0.86058","-0.37397"
"120.40000","-0.89070","-0.39673"
"120.50000","-0.92052","-0.40503"
"120.60000","-0.95045","-0.43452"
"120.70000","-0.98057","-0.44975"
"120.80000","-1.01065","-0.45384"
"120.90000","-1.04068","-0.49333"
"121.00000","-1.07061","-0.49492"
"121.10000","-1.10039","-0.52603"
"121.20000","-1.13041","-0.54716"
"121.30000","-1.16030","-0.58855"
"121.40000","-1.19052","-0.59188"
"121.50000","-1.22037","-0.62193"
"121.60000","-1.25036","-0.64157"
"121.70000","-1.28054","-0.66961"
"121.80000","-1.31058","-0.68509"
"121.90000","-1.34056","-0.69651"
"122.00000","-1.37072","-0.75255"
"122.10000","-1.40065","-0.75886"
"122.20000","-1.43050","-0.78223"
"122.30000","-1.46035","-0.81386"
"122.40000","-1.49047","-0.83996"
"122.50000","-1.52038","-0.86190"
"122.60000","-1.55051","-0.90601"
"122.70000","-1.58042","-0.93372"
"122.80000","-1.61040","-0.96439"
"122.90000","-1.64045","-0.98434"
"123.00000","-1.67031","-1.03856"
"123.10000","-1.70068","-1.07437"
"123.20000","-1.73065","-1.09825"
"123.30000","-1.76064","-1.14740"
"123.40000","-1.79063","-1.18591"
"123.50000","-1.82055","-1.22334"
"123.60000","-1.85042","-1.27009"
"123.70000","-1.88069","-1.32539"
"123.80000","-1.91033","-1.36281"
"123.90000","-1.94038","-1.40669"
"124.00000","-1.97022","-1.45899"
"124.10000","-2.00049","-1.51778"
"124.20000","-2.03041","-1.56367"
"124.30000","-2.06062","-1.62278"
"124.40000","-2.09046","-1.68752"
"124.50000","-2.12048","-1.75403"
"124.60000","-2.15054","-1.80829"
"124.70000","-2.18057","-1.90073"
"124.80000","-2.21053","-1.98735"
"124.90000","-2.24060","-2.05331"
"125.00000","-2.27032","-2.14337"
"125.10000","-2.30031","-2.23826"
"125.20000","-2.33038","-2.34317"
"125.30000","-2.36042","-2.44451"
"125.40000","-2.39054","-2.56017"
"125.50000","-2.42047","-2.69050"
"125.60000","-2.45041","-2.81562"
"125.70000","-2.48053","-2.95144"
"125.76600","-2.50029","-3.05777"
"125.76800","-2.50091","-3.06069"
"125.86800","-2.50251","-3.08829"
"125.96800","-2.47052","-2.92374"
"126.06800","-2.44013","-2.77621"
"126.16800","-2.40969","-2.62984"
"126.26800","-2.37983","-2.51315"
"126.36800","-2.34953","-2.40416"
"126.46800","-2.31982","-2.28582"
"126.56800","-2.28966","-2.18964"
"126.66800","-2.25989","-2.10449"
"126.76800","-2.22979","-2.00108"
"126.86800","-2.19981","-1.92982"
"126.96800","-2.16983","-1.86819"
"127.06800","-2.14001","-1.79214"
"127.16800","-2.10987","-1.71691"
"127.26800","-2.07993","-1.67186"
"127.36800","-2.04969","-1.61634"
"127.46800","-2.01966","-1.54409"
"127.56800","-1.98968","-1.48897"
"127.66800","-1.95959","-1.46373"
"127.76800","-1.92974","-1.38568"
"127.86800","-1.89976","-1.34270"
"127.96800","-1.86988","-1.29482"
"128.06800","-1.83981","-1.25303"
"128.16800","-1.81000","-1.19083"
"128.26800","-1.77997","-1.16508"
"128.36800","-1.75005","-1.11895"
"128.46800","-1.71980","-1.08629"
"128.56800","-1.68983","-1.04590"
"128.66800","-1.65959","-1.02768"
"128.76800","-1.62987","-0.99395"
"128.86800","-1.59961","-0.94342"
"128.96800","-1.56990","-0.93690"
"129.06800","-1.53971","-0.90022"
"129.16800","-1.50968","-0.86176"
"129.26800","-1.47965","-0.82523"
"129.36800","-1.44991","-0.82378"
"129.46800","-1.41982","-0.78030"
"129.56800","-1.39004","-0.73639"
"129.66800","-1.35987","-0.72075"
"129.76800","-1.32986","-0.70543"
"129.86800","-1.29982","-0.66542"
"129.96800","-1.26974","-0.64487"
"130.06800","-1.23970","-0.63412"
"130.16800","-1.20966","-0.60603"
"130.26800","-1.17963","-0.58744"
"130.36800","-1.14950","-0.56722"
"130.46800","-1.11977","-0.55175"
"130.56800","-1.08979","-0.51790"
"130.66800","-1.06006","-0.51228"
"130.76800","-1.02999","-0.49523"
"130.86800","-0.99990","-0.47746"
"130.96800","-0.96975","-0.43772"
"131.06800","-0.93991","-0.43586"
"131.16800","-0.90964","-0.42274"
"131.26800","-0.87989","-0.38990"
"131.36800","-0.84971","-0.36662"
"131.46800","-0.81974","-0.34797"
"131.56800","-0.78954","-0.33835"
"131.66800","-0.75971","-0.30019"
"131.76800","-0.72975","-0.29932"
"131.86800","-0.69984","-0.28075"
"131.96800","-0.66980","-0.25878"
"132.06800","-0.63996","-0.24228"
"132.16800","-0.60992","-0.24025"
"132.26800","-0.57994","-0.21219"
"132.36800","-0.54987","-0.19867"
"132.46800","-0.51974","-0.19604"
"132.56800","-0.48965","-0.18768"
"132.66800","-0.45951","-0.16736"
"132.76800","-0.42964","-0.15847"
"132.86800","-0.39967","-0.15052"
"132.96800","-0.36987","-0.12053"
"133.06800","-0.33973","-0.11117"
"133.16800","-0.30984","-0.09879"
"133.26800","-0.27978","-0.08002"
"133.36800","-0.25000","-0.04406"
"133.46800","-0.21982","-0.04075"
"133.56800","-0.19003","-0.02263"
"133.66800","-0.15967","-0.00948"
"133.76800","-0.12986","0.01895"
"133.86800","-0.09968","0.02600"
"133.96800","-0.06977","0.03930"
"134.06800","-0.03972","0.05989"
"134.16800","-0.00979","0.05822"
"134.20200","0.00017","0.04982"