File: SupLinearAndTan/Tan_Fan_Chart/Specimen_RawData_1.csv
Time,Extension,Load
(s),(mm),(N)
"0.00000","0.00000","0.04549"
"0.10000","0.00850","0.02508"
"0.20000","0.04149","0.07537"
"0.30000","0.07190","0.05616"
"0.40000","0.10213","0.03251"
"0.50000","0.13203","0.03756"
"0.60000","0.16227","0.03203"
"0.70000","0.19225","0.03696"
"0.80000","0.22245","0.03864"
"0.90000","0.25227","0.03974"
"1.00000","0.28227","0.04371"
"1.10000","0.31204","0.05916"
"1.20000","0.34218","0.05561"
"1.30000","0.37209","0.05421"
"1.40000","0.40216","0.05536"
"1.50000","0.43194","0.09882"
"1.60000","0.46214","0.04736"
"1.70000","0.49198","0.03615"
"1.80000","0.52221","0.03174"
"1.90000","0.55217","0.03883"
"2.00000","0.58225","0.04919"
"2.10000","0.61218","0.05199"
"2.20000","0.64219","0.02271"
"2.30000","0.67224","0.03063"
"2.40000","0.70229","0.04541"
"2.50000","0.73222","0.05373"
"2.60000","0.76208","0.02499"
"2.70000","0.79197","0.03792"
"2.80000","0.82185","0.05314"
"2.90000","0.85208","0.04395"
"3.00000","0.88205","0.05690"
"3.10000","0.91229","0.05985"
"3.20000","0.94221","0.03990"
"3.30000","0.97228","0.05148"
"3.40000","1.00211","0.06801"
"3.50000","1.03231","0.04468"
"3.60000","1.06222","0.04551"
"3.70000","1.09225","0.03656"
"3.80000","1.12202","0.06108"
"3.90000","1.15213","0.03526"
"4.00000","1.18194","0.04299"
"4.10000","1.21222","0.04682"
"4.20000","1.24199","0.05462"
"4.30000","1.27208","0.06141"
"4.40000","1.30201","0.06150"
"4.50000","1.33205","0.07176"
"4.60000","1.36216","0.05458"
"4.70000","1.39247","0.05973"
"4.80000","1.42230","0.06623"
"4.90000","1.45229","0.06824"
"5.00000","1.48217","0.05488"
"5.10000","1.51206","0.06225"
"5.20000","1.54202","0.06828"
"5.30000","1.57192","0.08553"
"5.40000","1.60205","0.04042"
"5.50000","1.63197","0.05539"
"5.60000","1.66212","0.03992"
"5.70000","1.69205","0.04050"
"5.80000","1.72228","0.04444"
"5.90000","1.75225","0.04355"
"6.00000","1.78217","0.02967"
"6.10000","1.81224","0.03731"
"6.20000","1.84221","0.06841"
"6.30000","1.87197","0.05245"
"6.40000","1.90229","0.05893"
"6.50000","1.93207","0.05762"
"6.60000","1.96212","0.07338"
"6.70000","1.99192","0.06021"
"6.80000","2.02194","0.07096"
"6.90000","2.05206","0.06624"
"7.00000","2.08225","0.05507"
"7.10000","2.11218","0.05885"
"7.20000","2.14231","0.04921"
"7.30000","2.17213","0.06215"
"7.40000","2.20216","0.03905"
"7.50000","2.23223","0.05236"
"7.60000","2.26231","0.05249"
"7.70000","2.29212","0.04907"
"7.80000","2.32211","0.04547"
"7.90000","2.35199","0.05348"
"8.00000","2.38194","0.06012"
"8.10000","2.41221","0.06016"
"8.20000","2.44214","0.06102"
"8.30000","2.47219","0.06756"
"8.39400","2.50029","0.05496"
"8.39600","2.50089","0.05489"
"8.49600","2.50180","0.05136"
"8.59600","2.47020","0.07545"
"8.69600","2.43952","0.07939"
"8.79600","2.40956","0.08452"
"8.89600","2.37929","0.06932"
"8.99600","2.34962","0.06791"
"9.09600","2.31953","0.06644"
"9.19600","2.28960","0.05445"
"9.29600","2.25942","0.05852"
"9.39600","2.22943","0.07511"
"9.49600","2.19925","0.06566"
"9.59600","2.16940","0.05159"
"9.69600","2.13931","0.07389"
"9.79600","2.10931","0.07084"
"9.89600","2.07923","0.06404"
"9.99600","2.04913","0.07536"
"10.09600","2.01931","0.07681"
"10.19600","1.98944","0.07505"
"10.29600","1.95960","0.08049"
"10.39600","1.92949","0.08510"
"10.49600","1.89945","0.08432"
"10.59600","1.86926","0.05884"
"10.69600","1.83940","0.07721"
"10.79600","1.80938","0.06624"
"10.89600","1.77952","0.05948"
"10.99600","1.74934","0.05387"
"11.09600","1.71927","0.05404"
"11.19600","1.68913","0.05882"
"11.29600","1.65938","0.04882"
"11.39600","1.62934","0.05850"
"11.49600","1.59955","0.06490"
"11.59600","1.56950","0.06766"
"11.69600","1.53949","0.06077"
"11.79600","1.50942","0.07643"
"11.89600","1.47956","0.06636"
"11.99600","1.44938","0.07060"
"12.09600","1.41943","0.08139"
"12.19600","1.38923","0.08527"
"12.29600","1.35921","0.07872"
"12.39600","1.32915","0.08298"
"12.49600","1.29938","0.10050"
"12.59600","1.26936","0.08230"
"12.69600","1.23940","0.06071"
"12.79600","1.20944","0.05544"
"12.89600","1.17937","0.07007"
"12.99600","1.14946","0.04452"
"13.09600","1.11948","0.05754"
"13.19600","1.08951","0.05467"
"13.29600","1.05941","0.06175"
"13.39600","1.02933","0.05515"
"13.49600","0.99925","0.06944"
"13.59600","0.96944","0.07545"
"13.69600","0.93919","0.07401"
"13.79600","0.90940","0.07513"
"13.89600","0.87924","0.08042"
"13.99600","0.84930","0.07120"
"14.09600","0.81931","0.06609"
"14.19600","0.78960","0.07010"
"14.29600","0.75951","0.05291"
"14.39600","0.72950","0.05451"
"14.49600","0.69932","0.05333"
"14.59600","0.66939","0.06412"
"14.69600","0.63927","0.05724"
"14.79600","0.60949","0.04370"
"14.89600","0.57926","0.05080"
"14.99600","0.54931","0.06484"
"15.09600","0.51924","0.03562"
"15.19600","0.48927","0.04066"
"15.29600","0.45941","0.11568"
"15.39600","0.42953","0.07118"
"15.49600","0.39954","0.06594"
"15.59600","0.36944","0.06793"
"15.69600","0.33935","0.08099"
"15.79600","0.30941","0.06234"
"15.89600","0.27958","0.08927"
"15.99600","0.24933","0.07707"
"16.09600","0.21944","0.06509"
"16.19600","0.18921","0.05759"
"16.29600","0.15923","0.06459"
"16.39600","0.12918","0.05830"
"16.49600","0.09949","0.04212"
"16.59600","0.06936","0.04496"
"16.69600","0.03960","0.05156"
"16.79600","0.00935","0.04884"
"16.89600","-0.02032","0.04675"
"16.99600","-0.05050","0.05520"
"17.09600","-0.08040","0.06889"
"17.19600","-0.11070","0.06896"
"17.29600","-0.14068","0.05808"
"17.39600","-0.17080","0.08159"
"17.49600","-0.20073","0.06960"
"17.59600","-0.23071","0.07842"
"17.69600","-0.26059","0.06296"
"17.79600","-0.29062","0.07648"
"17.89600","-0.32071","0.05972"
"17.99600","-0.35064","0.05721"
"18.09600","-0.38056","0.07730"
"18.19600","-0.41038","0.05401"
"18.29600","-0.44054","0.06191"
"18.39600","-0.47047","0.04829"
"18.49600","-0.50076","0.06824"
"18.59600","-0.53068","0.05527"
"18.69600","-0.56067","0.05402"
"18.79600","-0.59060","0.05905"
"18.89600","-0.62075","0.05229"
"18.99600","-0.65061","0.04690"
"19.09600","-0.68087","0.06938"
"19.19600","-0.71051","0.09036"
"19.29600","-0.74048","0.07095"
"19.39600","-0.77031","0.08069"
"19.49600","-0.80053","0.10083"
"19.59600","-0.83059","0.10145"
"19.69600","-0.86072","0.08393"
"19.79600","-0.89067","0.08504"
"19.89600","-0.92061","0.07837"
"19.99600","-0.95062","0.06155"
"20.09600","-0.98072","0.07572"
"20.19600","-1.01076","0.07440"
"20.29600","-1.04084","0.07027"
"20.39600","-1.07072","0.07427"
"20.49600","-1.10052","0.07551"
"20.59600","-1.13051","0.08432"
"20.69600","-1.16044","0.07180"
"20.79600","-1.19067","0.08424"
"20.89600","-1.22057","0.08160"
"20.99600","-1.25058","0.08737"
"21.09600","-1.28051","0.08664"
"21.19600","-1.31070","0.08018"
"21.29600","-1.34071","0.09939"
"21.39600","-1.37084","0.07791"
"21.49600","-1.40076","0.07891"
"21.59600","-1.43063","0.08696"
"21.69600","-1.46048","0.07780"
"21.79600","-1.49058","0.07059"
"21.89600","-1.52052","0.07398"
"21.99600","-1.55064","0.08164"
"22.09600","-1.58050","0.05923"
"22.19600","-1.61061","0.06889"
"22.29600","-1.64055","0.08094"
"22.39600","-1.67058","0.07111"
"22.49600","-1.70076","0.06615"
"22.59600","-1.73069","0.09182"
"22.69600","-1.76077","0.11296"
"22.79600","-1.79074","0.10724"
"22.89600","-1.82072","0.11318"
"22.99600","-1.85061","0.11360"
"23.09600","-1.88077","0.11090"
"23.19600","-1.91047","0.09769"
"23.29600","-1.94048","0.10593"
"23.39600","-1.97035","0.09695"
"23.49600","-2.00059","0.09301"
"23.59600","-2.03044","0.07554"
"23.69600","-2.06082","0.09037"
"23.79600","-2.09066","0.08041"
"23.89600","-2.12062","0.08333"
"23.99600","-2.15061","0.08141"
"24.09600","-2.18068","0.09699"
"24.19600","-2.21068","0.09355"
"24.29600","-2.24072","0.08200"
"24.39600","-2.27048","0.08937"
"24.49600","-2.30044","0.08660"
"24.59600","-2.33044","0.07631"
"24.69600","-2.36055","0.08069"
"24.79600","-2.39068","0.09818"
"24.89600","-2.42061","0.07182"
"24.99600","-2.45050","0.07578"
"25.09600","-2.48070","0.08505"
"25.16100","-2.50014","0.08010"
"25.16300","-2.50075","0.08323"
"25.26300","-2.50228","0.09314"
"25.36300","-2.47019","0.07166"
"25.46300","-2.43980","0.06729"
"25.56300","-2.40937","0.08602"
"25.66300","-2.37948","0.06999"
"25.76300","-2.34919","0.06858"
"25.86300","-2.31948","0.07956"
"25.96300","-2.28932","0.07969"
"26.06300","-2.25954","0.07228"
"26.16300","-2.22943","0.08210"
"26.26300","-2.19950","0.08218"
"26.36300","-2.16950","0.08831"
"26.46300","-2.13970","0.07594"
"26.56300","-2.10953","0.08906"
"26.66300","-2.07959","0.07401"
"26.76300","-2.04940","0.07797"
"26.86300","-2.01930","0.08481"
"26.96300","-1.98937","0.09738"
"27.06300","-1.95926","0.08831"
"27.16300","-1.92947","0.09401"
"27.26300","-1.89941","0.10905"
"27.36300","-1.86954","0.09298"
"27.46300","-1.83948","0.10558"
"27.56300","-1.80968","0.09357"
"27.66300","-1.77963","0.10928"
"27.76300","-1.74973","0.09790"
"27.86300","-1.71945","0.05927"
"27.96300","-1.68952","0.05566"
"28.06300","-1.65928","0.06961"
"28.16300","-1.62953","0.06955"
"28.26300","-1.59930","0.06073"
"28.36300","-1.56953","0.07871"
"28.46300","-1.53936","0.07905"
"28.56300","-1.50933","0.06764"
"28.66300","-1.47930","0.07326"
"28.76300","-1.44949","0.07824"
"28.86300","-1.41956","0.06477"
"28.96300","-1.38973","0.08292"
"29.06300","-1.35955","0.08298"
"29.16300","-1.32955","0.06926"
"29.26300","-1.29950","0.05833"
"29.36300","-1.26939","0.07086"
"29.46300","-1.23940","0.07116"
"29.56300","-1.20931","0.05620"
"29.66300","-1.17930","0.06453"
"29.76300","-1.14917","0.07315"
"29.86300","-1.11938","0.05836"
"29.96300","-1.08945","0.05790"
"30.06300","-1.05971","0.07390"
"30.16300","-1.02958","0.05810"
"30.26300","-0.99957","0.06750"
"30.36300","-0.96948","0.05975"
"30.46300","-0.93961","0.07137"
"30.56300","-0.90936","0.05789"
"30.66300","-0.87962","0.06814"
"30.76300","-0.84939","0.07981"
"30.86300","-0.81938","0.08039"
"30.96300","-0.78921","0.06790"
"31.06300","-0.75937","0.05602"
"31.16300","-0.72942","0.06289"
"31.26300","-0.69951","0.03348"
"31.36300","-0.66945","0.03539"
"31.46300","-0.63956","0.03528"
"31.56300","-0.60956","0.04898"
"31.66300","-0.57963","0.03066"
"31.76300","-0.54954","0.05066"
"31.86300","-0.51942","0.05037"
"31.96300","-0.48934","0.03918"
"32.06300","-0.45919","0.02947"
"32.16300","-0.42930","0.04716"
"32.26300","-0.39931","0.04984"
"32.36300","-0.36952","0.03409"
"32.46300","-0.33939","0.05283"
"32.56300","-0.30949","0.04523"
"32.66300","-0.27942","0.04857"
"32.76300","-0.24968","0.04065"
"32.86300","-0.21950","0.05492"
"32.96300","-0.18968","0.04926"
"33.06300","-0.15933","0.04154"
"33.16300","-0.12951","0.04704"
"33.26300","-0.09936","0.04972"
"33.36300","-0.06946","0.04125"
"33.46300","-0.03938","0.02851"
"33.56300","-0.00946","0.04326"
"33.66300","0.02072","0.03364"
"33.76300","0.05066","0.02670"
"33.86300","0.08062","0.02494"
"33.96300","0.11037","0.05153"
"34.06300","0.14029","0.05206"
"34.16300","0.17037","0.04786"
"34.26300","0.20049","0.04454"
"34.36300","0.23057","0.05942"
"34.46300","0.26061","0.04503"
"34.56300","0.29063","0.05684"
"34.66300","0.32058","0.05196"
"34.76300","0.35070","0.03636"
"34.86300","0.38066","0.04462"
"34.96300","0.41069","0.06113"
"35.06300","0.44047","0.09449"
"35.16300","0.47056","0.01049"
"35.26300","0.50036","0.02586"
"35.36300","0.53060","0.03900"
"35.46300","0.56036","0.04327"
"35.56300","0.59045","0.04070"
"35.66300","0.62040","0.04651"
"35.76300","0.65052","0.03909"
"35.86300","0.68048","0.04219"
"35.96300","0.71079","0.03844"
"36.06300","0.74061","0.05243"
"36.16300","0.77075","0.03729"
"36.26300","0.80053","0.03289"
"36.36300","0.83053","0.05789"
"36.46300","0.86041","0.04473"
"36.56300","0.89043","0.05893"
"36.66300","0.92043","0.04969"
"36.76300","0.95038","0.05692"
"36.86300","0.98047","0.04062"
"36.96300","1.01048","0.03332"
"37.06300","1.04069","0.03873"
"37.16300","1.07070","0.02282"
"37.26300","1.10059","0.03400"
"37.36300","1.13052","0.03797"
"37.46300","1.16066","0.04211"
"37.56300","1.19044","0.04534"
"37.66300","1.22078","0.04029"
"37.76300","1.25043","0.05921"
"37.86300","1.28049","0.08087"
"37.96300","1.31023","0.06489"
"38.06300","1.34036","0.06734"
"38.16300","1.37040","0.06878"
"38.26300","1.40063","0.05491"
"38.36300","1.43045","0.04479"
"38.46300","1.46071","0.06006"
"38.56300","1.49051","0.04654"
"38.66300","1.52074","0.03859"
"38.76300","1.55061","0.05089"
"38.86300","1.58079","0.05718"
"38.96300","1.61057","0.03176"
"39.06300","1.64043","0.03339"
"39.16300","1.67036","0.05507"
"39.26300","1.70034","0.04674"
"39.36300","1.73052","0.04487"
"39.46300","1.76056","0.04700"
"39.56300","1.79061","0.06077"
"39.66300","1.82056","0.04963"
"39.76300","1.85053","0.06556"
"39.86300","1.88040","0.06513"
"39.96300","1.91074","0.05895"
"40.06300","1.94069","0.04865"
"40.16300","1.97079","0.05234"
"40.26300","2.00035","0.06365"
"40.36300","2.03053","0.04123"
"40.46300","2.06035","0.04969"
"40.56300","2.09046","0.05238"
"40.66300","2.12031","0.06764"
"40.76300","2.15048","0.04056"
"40.86300","2.18032","0.05908"
"40.96300","2.21064","0.05989"
"41.06300","2.24068","0.06211"
"41.16300","2.27087","0.06032"
"41.26300","2.30077","0.06622"
"41.36300","2.33071","0.05036"
"41.46300","2.36053","0.04277"
"41.56300","2.39052","0.06911"
"41.66300","2.42053","0.06316"
"41.76300","2.45045","0.07555"
"41.86300","2.48043","0.05863"
"41.92900","2.50025","0.04877"
"41.93100","2.50085","0.04992"
"42.03100","2.50189","0.07130"
"42.13100","2.47024","0.08056"
"42.23100","2.43959","0.07805"
"42.33100","2.40963","0.06634"
"42.43100","2.37934","0.07631"
"42.53100","2.34966","0.06067"
"42.63100","2.31957","0.05255"
"42.73100","2.28967","0.06162"
"42.83100","2.25950","0.05877"
"42.93100","2.22950","0.06270"
"43.03100","2.19932","0.06526"
"43.13100","2.16947","0.06968"
"43.23100","2.13937","0.06470"
"43.33100","2.10938","0.06886"
"43.43100","2.07926","0.06890"
"43.53100","2.04921","0.08322"
"43.63100","2.01934","0.05570"
"43.73100","1.98948","0.06477"
"43.83100","1.95969","0.07808"
"43.93100","1.92952","0.06691"
"44.03100","1.89956","0.07024"
"44.13100","1.86931","0.06240"
"44.23100","1.83943","0.07096"
"44.33100","1.80944","0.04707"
"44.43100","1.77957","0.05428"
"44.53100","1.74938","0.06752"
"44.63100","1.71933","0.06440"
"44.73100","1.68920","0.05653"
"44.83100","1.65945","0.06650"
"44.93100","1.62939","0.06568"
"45.03100","1.59962","0.07722"
"45.13100","1.56955","0.07597"
"45.23100","1.53953","0.07031"
"45.33100","1.50948","0.06432"
"45.43100","1.47961","0.07685"
"45.53100","1.44944","0.08161"
"45.63100","1.41949","0.08703"
"45.73100","1.38930","0.07887"
"45.83100","1.35926","0.07468"
"45.93100","1.32923","0.09919"
"46.03100","1.29945","0.08767"
"46.13100","1.26941","0.07946"
"46.23100","1.23946","0.08178"
"46.33100","1.20949","0.07687"
"46.43100","1.17944","0.05707"
"46.53100","1.14952","0.06413"
"46.63100","1.11951","0.08314"
"46.73100","1.08958","0.07673"
"46.83100","1.05945","0.06829"
"46.93100","1.02937","0.06719"
"47.03100","0.99931","0.08031"
"47.13100","0.96950","0.06772"
"47.23100","0.93930","0.08669"
"47.33100","0.90946","0.07435"
"47.43100","0.87931","0.08127"
"47.53100","0.84936","0.07145"
"47.63100","0.81937","0.07502"
"47.73100","0.78970","0.08085"
"47.83100","0.75958","0.06132"
"47.93100","0.72957","0.05931"
"48.03100","0.69938","0.07755"
"48.13100","0.66944","0.06588"
"48.23100","0.63932","0.05678"
"48.33100","0.60955","0.06541"
"48.43100","0.57932","0.06053"
"48.53100","0.54937","0.05725"
"48.63100","0.51931","0.04072"
"48.73100","0.48933","0.05959"
"48.83100","0.45949","0.10095"
"48.93100","0.42959","0.05779"
"49.03100","0.39963","0.07157"
"49.13100","0.36948","0.06883"
"49.23100","0.33949","0.06967"
"49.33100","0.30947","0.06475"
"49.43100","0.27964","0.08453"
"49.53100","0.24938","0.06581"
"49.63100","0.21948","0.06931"
"49.73100","0.18929","0.06830"
"49.83100","0.15928","0.07059"
"49.93100","0.12926","0.05668"
"50.03100","0.09954","0.05829"
"50.13100","0.06944","0.05558"
"50.23100","0.03967","0.06419"
"50.33100","0.00937","0.05040"
"50.43100","-0.02031","0.05707"
"50.53100","-0.05046","0.06085"
"50.63100","-0.08034","0.05859"
"50.73100","-0.11065","0.06603"
"50.83100","-0.14061","0.06806"
"50.93100","-0.17076","0.07422"
"51.03100","-0.20066","0.03506"
"51.13100","-0.23066","0.07329"
"51.23100","-0.26052","0.06634"
"51.33100","-0.29052","0.05900"
"51.43100","-0.32064","0.06494"
"51.53100","-0.35059","0.06885"
"51.63100","-0.38057","0.06709"
"51.73100","-0.41032","0.06252"
"51.83100","-0.44047","0.08341"
"51.93100","-0.47039","0.06238"
"52.03100","-0.50070","0.06301"
"52.13100","-0.53062","0.06062"
"52.23100","-0.56062","0.07657"
"52.33100","-0.59054","0.05908"
"52.43100","-0.62067","0.05882"
"52.53100","-0.65054","0.05889"
"52.63100","-0.68081","0.06528"
"52.73100","-0.71045","0.07491"
"52.83100","-0.74038","0.07192"
"52.93100","-0.77026","0.08404"
"53.03100","-0.80047","0.08779"
"53.13100","-0.83052","0.07962"
"53.23100","-0.86066","0.08910"
"53.33100","-0.89062","0.10050"
"53.43100","-0.92057","0.07989"
"53.53100","-0.95055","0.08080"
"53.63100","-0.98064","0.08369"
"53.73100","-1.01072","0.08436"
"53.83100","-1.04074","0.08025"
"53.93100","-1.07065","0.09006"
"54.03100","-1.10045","0.08090"
"54.13100","-1.13047","0.07165"
"54.23100","-1.16039","0.06948"
"54.33100","-1.19062","0.09078"
"54.43100","-1.22049","0.07464"
"54.53100","-1.25053","0.06304"
"54.63100","-1.28044","0.09160"
"54.73100","-1.31062","0.07188"
"54.83100","-1.34062","0.08883"
"54.93100","-1.37080","0.08344"
"55.03100","-1.40073","0.10599"
"55.13100","-1.43060","0.09001"
"55.23100","-1.46044","0.08920"
"55.33100","-1.49053","0.09359"
"55.43100","-1.52044","0.09289"
"55.53100","-1.55056","0.08487"
"55.63100","-1.58050","0.09058"
"55.73100","-1.61041","0.09129"
"55.83100","-1.64056","0.08927"
"55.93100","-1.67053","0.08442"
"56.03100","-1.70070","0.08245"
"56.13100","-1.73067","0.09295"
"56.23100","-1.76067","0.11090"
"56.33100","-1.79071","0.11495"
"56.43100","-1.82066","0.11813"
"56.53100","-1.85052","0.11306"
"56.63100","-1.88070","0.09227"
"56.73100","-1.91040","0.10512"
"56.83100","-1.94046","0.11838"
"56.93100","-1.97027","0.10459"
"57.03100","-2.00054","0.09923"
"57.13100","-2.03037","0.09175"
"57.23100","-2.06075","0.09185"
"57.33100","-2.09059","0.09408"
"57.43100","-2.12055","0.10941"
"57.53100","-2.15055","0.10313"
"57.63100","-2.18064","0.09106"
"57.73100","-2.21061","0.08576"
"57.83100","-2.24068","0.11903"
"57.93100","-2.27043","0.08873"
"58.03100","-2.30038","0.08199"
"58.13100","-2.33035","0.09740"
"58.23100","-2.36050","0.08251"
"58.33100","-2.39063","0.08671"
"58.43100","-2.42054","0.08429"
"58.53100","-2.45049","0.09818"
"58.63100","-2.48053","0.08382"
"58.69600","-2.50009","0.08786"
"58.69800","-2.50071","0.08745"
"58.79800","-2.50233","0.06808"
"58.89800","-2.47016","0.07164"
"58.99800","-2.43980","0.08056"
"59.09800","-2.40938","0.07805"
"59.19800","-2.37948","0.07592"
"59.29800","-2.34919","0.08917"
"59.39800","-2.31947","0.09058"
"59.49800","-2.28934","0.08771"
"59.59800","-2.25954","0.09270"
"59.69800","-2.22945","0.09831"
"59.79800","-2.19947","0.08491"
"59.89800","-2.16952","0.09648"
"59.99800","-2.13968","0.09282"
"60.09800","-2.10951","0.09171"
"60.19800","-2.07959","0.07102"
"60.29800","-2.04941","0.08827"
"60.39800","-2.01928","0.08913"
"60.49800","-1.98938","0.08964"
"60.59800","-1.95925","0.08458"
"60.69800","-1.92947","0.09745"
"60.79800","-1.89937","0.11189"
"60.89800","-1.86953","0.09440"
"60.99800","-1.83949","0.10734"
"61.09800","-1.80966","0.09636"
"61.19800","-1.77965","0.10855"
"61.29800","-1.74972","0.11602"
"61.39800","-1.71948","0.08005"
"61.49800","-1.68951","0.07186"
"61.59800","-1.65927","0.07141"
"61.69800","-1.62953","0.07346"
"61.79800","-1.59931","0.06965"
"61.89800","-1.56952","0.07264"
"61.99800","-1.53935","0.06319"
"62.09800","-1.50934","0.07801"
"62.19800","-1.47933","0.07583"
"62.29800","-1.44950","0.07319"
"62.39800","-1.41955","0.07502"
"62.49800","-1.38975","0.09052"
"62.59800","-1.35953","0.06395"
"62.69800","-1.32959","0.07186"
"62.79800","-1.29946","0.07379"
"62.89800","-1.26937","0.08009"
"62.99800","-1.23939","0.06522"
"63.09800","-1.20933","0.07109"
"63.19800","-1.17930","0.08044"
"63.29800","-1.14916","0.05994"
"63.39800","-1.11941","0.06329"
"63.49800","-1.08948","0.06387"
"63.59800","-1.05971","0.05370"
"63.69800","-1.02958","0.04199"
"63.79800","-0.99961","0.05849"
"63.89800","-0.96946","0.05544"
"63.99800","-0.93962","0.05702"
"64.09800","-0.90935","0.05755"
"64.19800","-0.87963","0.07789"
"64.29800","-0.84936","0.07232"
"64.39800","-0.81934","0.06873"
"64.49800","-0.78920","0.07852"
"64.59800","-0.75937","0.06251"
"64.69800","-0.72942","0.07102"
"64.79800","-0.69949","0.04335"
"64.89800","-0.66946","0.05921"
"64.99800","-0.63958","0.03850"
"65.09800","-0.60957","0.03932"
"65.19800","-0.57962","0.04083"
"65.29800","-0.54955","0.05434"
"65.39800","-0.51942","0.04017"
"65.49800","-0.48932","0.03105"
"65.59800","-0.45921","0.04699"
"65.69800","-0.42932","0.04315"
"65.79800","-0.39929","0.03852"
"65.89800","-0.36950","0.04080"
"65.99800","-0.33942","0.05529"
"66.09800","-0.30945","0.02783"
"66.19800","-0.27943","0.04329"
"66.29800","-0.24968","0.05876"
"66.39800","-0.21952","0.05526"
"66.49800","-0.18970","0.03611"
"66.59800","-0.15933","0.05622"
"66.69800","-0.12953","0.05334"
"66.79800","-0.09936","0.05226"
"66.89800","-0.06947","0.04349"
"66.99800","-0.03939","0.04047"
"67.09800","-0.00946","0.03394"
"67.19800","0.02075","0.02563"
"67.29800","0.05065","0.03291"
"67.39800","0.08063","0.03446"
"67.49800","0.11039","0.04075"
"67.59800","0.14029","0.02771"
"67.69800","0.17036","0.04805"
"67.79800","0.20048","0.05135"
"67.89800","0.23057","0.05693"
"67.99800","0.26060","0.05543"
"68.09800","0.29065","0.06388"
"68.19800","0.32059","0.05057"
"68.29800","0.35071","0.04179"
"68.39800","0.38063","0.06427"
"68.49800","0.41068","0.05594"
"68.59800","0.44045","0.08163"
"68.69800","0.47058","0.02675"
"68.79800","0.50033","0.03896"
"68.89800","0.53059","0.02143"
"68.99800","0.56038","0.03093"
"69.09800","0.59044","0.05770"
"69.19800","0.62041","0.04196"
"69.29800","0.65052","0.03320"
"69.39800","0.68045","0.04817"
"69.49800","0.71079","0.04878"
"69.59800","0.74060","0.05123"
"69.69800","0.77076","0.04226"
"69.79800","0.80051","0.04844"
"69.89800","0.83057","0.05417"
"69.99800","0.86041","0.04972"
"70.09800","0.89048","0.06809"
"70.19800","0.92041","0.06215"
"70.29800","0.95037","0.06332"
"70.39800","0.98044","0.05599"
"70.49800","1.01050","0.05087"
"70.59800","1.04069","0.04488"
"70.69800","1.07069","0.03641"
"70.79800","1.10060","0.04264"
"70.89800","1.13054","0.05030"
"70.99800","1.16065","0.03465"
"71.09800","1.19043","0.04915"
"71.19800","1.22081","0.06564"
"71.29800","1.25044","0.06765"
"71.39800","1.28044","0.06526"
"71.49800","1.31026","0.06767"
"71.59800","1.34037","0.08650"
"71.69800","1.37041","0.05832"
"71.79800","1.40063","0.06944"
"71.89800","1.43046","0.06796"
"71.99800","1.46070","0.07182"
"72.09800","1.49053","0.06373"
"72.19800","1.52075","0.06261"
"72.29800","1.55061","0.07727"
"72.39800","1.58080","0.07503"
"72.49800","1.61058","0.05341"
"72.59800","1.64042","0.05936"
"72.69800","1.67038","0.06203"
"72.79800","1.70030","0.04875"
"72.89800","1.73053","0.06136"
"72.99800","1.76048","0.06059"
"73.09800","1.79065","0.05548"
"73.19800","1.82055","0.05099"
"73.29800","1.85055","0.07214"
"73.39800","1.88042","0.07405"
"73.49800","1.91078","0.06802"
"73.59800","1.94063","0.07140"
"73.69800","1.97076","0.08472"
"73.79800","2.00037","0.07761"
"73.89800","2.03052","0.06543"
"73.99800","2.06035","0.07050"
"74.09800","2.09048","0.06893"
"74.19800","2.12029","0.06875"
"74.29800","2.15045","0.06155"
"74.39800","2.18028","0.08047"
"74.49800","2.21067","0.05515"
"74.59800","2.24061","0.06388"
"74.69800","2.27090","0.06928"
"74.79800","2.30084","0.05686"
"74.89800","2.33069","0.04684"
"74.99800","2.36051","0.05997"
"75.09800","2.39051","0.08715"
"75.19800","2.42053","0.07526"
"75.29800","2.45047","0.07955"
"75.39800","2.48044","0.08578"
"75.46400","2.50028","0.04890"
"75.46600","2.50088","0.05090"
"75.56600","2.50189","0.07727"
"75.66600","2.47026","0.08636"
"75.76600","2.43958","0.08753"
"75.86600","2.40961","0.08979"
"75.96600","2.37935","0.08357"
"76.06600","2.34967","0.08617"
"76.16600","2.31960","0.07978"
"76.26600","2.28968","0.08920"
"76.36600","2.25951","0.07728"
"76.46600","2.22952","0.06824"
"76.56600","2.19931","0.09099"
"76.66600","2.16951","0.08331"
"76.76600","2.13936","0.07198"
"76.86600","2.10940","0.07825"
"76.96600","2.07929","0.07001"
"77.06600","2.04920","0.07803"
"77.16600","2.01936","0.07102"
"77.26600","1.98951","0.08564"
"77.36600","1.95969","0.07994"
"77.46600","1.92953","0.07661"
"77.56600","1.89958","0.08758"
"77.66600","1.86936","0.08451"
"77.76600","1.83941","0.08703"
"77.86600","1.80947","0.06219"
"77.96600","1.77959","0.09088"
"78.06600","1.74941","0.08637"
"78.16600","1.71933","0.07647"
"78.26600","1.68918","0.07170"
"78.36600","1.65949","0.07243"
"78.46600","1.62940","0.08028"
"78.56600","1.59964","0.09622"
"78.66600","1.56956","0.08275"
"78.76600","1.53952","0.08013"
"78.86600","1.50949","0.06931"
"78.96600","1.47964","0.07469"
"79.06600","1.44943","0.09593"
"79.16600","1.41949","0.07525"
"79.26600","1.38930","0.09317"
"79.36600","1.35928","0.10033"
"79.46600","1.32923","0.10926"
"79.56600","1.29944","0.09590"
"79.66600","1.26943","0.09304"
"79.76600","1.23946","0.08318"
"79.86600","1.20950","0.06599"
"79.96600","1.17944","0.06167"
"80.06600","1.14953","0.07610"
"80.16600","1.11953","0.07643"
"80.26600","1.08959","0.05417"
"80.36600","1.05945","0.07445"
"80.46600","1.02939","0.07225"
"80.56600","0.99935","0.07957"
"80.66600","0.96951","0.07001"
"80.76600","0.93925","0.08913"
"80.86600","0.90947","0.07723"
"80.96600","0.87932","0.08427"
"81.06600","0.84935","0.07766"
"81.16600","0.81939","0.07989"
"81.26600","0.78969","0.07798"
"81.36600","0.75962","0.07341"
"81.46600","0.72955","0.07425"
"81.56600","0.69940","0.07354"
"81.66600","0.66943","0.07130"
"81.76600","0.63933","0.06555"
"81.86600","0.60955","0.08087"
"81.96600","0.57931","0.05959"
"82.06600","0.54939","0.05175"
"82.16600","0.51931","0.05025"
"82.26600","0.48931","0.07496"
"82.36600","0.45949","0.11075"
"82.46600","0.42958","0.07344"
"82.56600","0.39961","0.08429"
"82.66600","0.36949","0.08006"
"82.76600","0.33947","0.08570"
"82.86600","0.30945","0.08684"
"82.96600","0.27965","0.08781"
"83.06600","0.24942","0.06957"
"83.16600","0.21950","0.08494"
"83.26600","0.18928","0.07627"
"83.36600","0.15926","0.06117"
"83.46600","0.12926","0.05822"
"83.56600","0.09956","0.06884"
"83.66600","0.06946","0.05132"
"83.76600","0.03965","0.05462"
"83.86600","0.00940","0.05360"
"83.96600","-0.02029","0.07002"
"84.06600","-0.05047","0.06054"
"84.16600","-0.08034","0.06883"
"84.26600","-0.11062","0.08476"
"84.36600","-0.14062","0.07845"
"84.46600","-0.17077","0.08612"
"84.56600","-0.20066","0.07047"
"84.66600","-0.23065","0.08040"
"84.76600","-0.26053","0.07269"
"84.86600","-0.29050","0.07562"
"84.96600","-0.32060","0.07018"
"85.06600","-0.35057","0.07199"
"85.16600","-0.38050","0.07113"
"85.26600","-0.41032","0.05464"
"85.36600","-0.44047","0.07542"
"85.46600","-0.47040","0.06119"
"85.56600","-0.50066","0.06349"
"85.66600","-0.53062","0.07450"
"85.76600","-0.56060","0.07371"
"85.86600","-0.59052","0.05758"
"85.96600","-0.62068","0.06911"
"86.06600","-0.65055","0.07310"
"86.16600","-0.68079","0.07909"
"86.26600","-0.71043","0.07625"
"86.36600","-0.74037","0.09691"
"86.46600","-0.77025","0.10081"
"86.56600","-0.80044","0.08658"
"86.66600","-0.83053","0.09793"
"86.76600","-0.86061","0.09198"
"86.86600","-0.89065","0.09262"
"86.96600","-0.92055","0.07918"
"87.06600","-0.95057","0.08095"
"87.16600","-0.98063","0.07731"
"87.26600","-1.01071","0.07406"
"87.36600","-1.04070","0.08412"
"87.46600","-1.07066","0.10295"
"87.56600","-1.10044","0.08006"
"87.66600","-1.13048","0.08025"
"87.76600","-1.16037","0.08480"
"87.86600","-1.19062","0.09797"
"87.96600","-1.22051","0.08967"
"88.06600","-1.25048","0.08266"
"88.16600","-1.28041","0.10285"
"88.26600","-1.31066","0.08784"
"88.36600","-1.34062","0.09526"
"88.46600","-1.37079","0.08747"
"88.56600","-1.40071","0.09764"
"88.66600","-1.43055","0.08347"
"88.76600","-1.46044","0.08972"
"88.86600","-1.49052","0.09363"
"88.96600","-1.52045","0.08275"
"89.06600","-1.55057","0.08086"
"89.16600","-1.58049","0.09983"
"89.26600","-1.61044","0.09620"
"89.36600","-1.64054","0.08400"
"89.46600","-1.67052","0.08713"
"89.56600","-1.70067","0.09293"
"89.66600","-1.73065","0.10317"
"89.76600","-1.76067","0.10885"
"89.86600","-1.79071","0.12083"
"89.96600","-1.82065","0.11730"
"90.06600","-1.85051","0.12020"
"90.16600","-1.88070","0.10946"
"90.26600","-1.91040","0.11798"
"90.36600","-1.94047","0.09623"
"90.46600","-1.97026","0.09638"
"90.56600","-2.00056","0.09424"
"90.66600","-2.03047","0.09161"
"90.76600","-2.06057","0.08060"
"90.86600","-2.09067","0.08622"
"90.96600","-2.12058","0.10348"
"91.06600","-2.15049","0.09470"
"91.16600","-2.18066","0.09249"
"91.26600","-2.21059","0.10062"
"91.36600","-2.24065","0.11978"
"91.46600","-2.27042","0.09353"
"91.56600","-2.30036","0.10080"
"91.66600","-2.33035","0.09742"
"91.76600","-2.36049","0.09741"
"91.86600","-2.39063","0.07479"
"91.96600","-2.42054","0.08494"
"92.06600","-2.45048","0.09268"
"92.16600","-2.48053","0.07396"
"92.23200","-2.50031","0.09445"
"92.23400","-2.50093","0.09346"
"92.33400","-2.50273","0.07908"
"92.43400","-2.47050","0.08088"
"92.53400","-2.44016","0.08810"
"92.63400","-2.40975","0.06426"
"92.73400","-2.37986","0.07634"
"92.83400","-2.34955","0.08401"
"92.93400","-2.31982","0.08409"
"93.03400","-2.28969","0.07178"
"93.13400","-2.25991","0.09214"
"93.23400","-2.22982","0.09778"
"93.33400","-2.19986","0.08224"
"93.43400","-2.16986","0.09803"
"93.53400","-2.14003","0.09910"
"93.63400","-2.10987","0.09677"
"93.73400","-2.07994","0.07915"
"93.83400","-2.04976","0.09658"
"93.93400","-2.01964","0.09231"
"94.03400","-1.98971","0.09837"
"94.13400","-1.95960","0.09024"
"94.23400","-1.92984","0.10440"
"94.33400","-1.89976","0.10597"
"94.43400","-1.86991","0.09792"
"94.53400","-1.83987","0.10364"
"94.63400","-1.81006","0.09975"
"94.73400","-1.77999","0.10257"
"94.83400","-1.75008","0.09797"
"94.93400","-1.71978","0.07872"
"95.03400","-1.68985","0.06318"
"95.13400","-1.65961","0.06387"
"95.23400","-1.62989","0.07588"
"95.33400","-1.59964","0.09199"
"95.43400","-1.56991","0.08469"
"95.53400","-1.53971","0.09125"
"95.63400","-1.50971","0.09115"
"95.73400","-1.47967","0.08639"
"95.83400","-1.44989","0.08671"
"95.93400","-1.41990","0.07692"
"96.03400","-1.39009","0.08339"
"96.13400","-1.35990","0.06392"
"96.23400","-1.32993","0.06839"
"96.33400","-1.29980","0.06911"
"96.43400","-1.26973","0.06517"
"96.53400","-1.23974","0.05270"
"96.63400","-1.20967","0.06887"
"96.73400","-1.17966","0.07099"
"96.83400","-1.14952","0.06180"
"96.93400","-1.11978","0.06304"
"97.03400","-1.08984","0.07853"
"97.13400","-1.06011","0.08146"
"97.23400","-1.02992","0.06876"
"97.33400","-0.99995","0.08452"
"97.43400","-0.96982","0.07408"
"97.53400","-0.93998","0.08369"
"97.63400","-0.90973","0.06953"
"97.73400","-0.87994","0.08715"
"97.83400","-0.84972","0.07586"
"97.93400","-0.81970","0.06823"
"98.03400","-0.78956","0.06714"
"98.13400","-0.75975","0.05994"
"98.23400","-0.72977","0.06571"
"98.33400","-0.69987","0.03075"
"98.43400","-0.66984","0.04848"
"98.53400","-0.63995","0.04249"
"98.63400","-0.60993","0.04009"
"98.73400","-0.57996","0.04769"
"98.83400","-0.54990","0.07602"
"98.93400","-0.51977","0.05722"
"99.03400","-0.48969","0.05258"
"99.13400","-0.45955","0.07096"
"99.23400","-0.42966","0.06872"
"99.33400","-0.39966","0.05775"
"99.43400","-0.36989","0.05381"
"99.53400","-0.33976","0.06182"
"99.63400","-0.30984","0.03955"
"99.73400","-0.27982","0.04738"
"99.83400","-0.25002","0.05733"
"99.93400","-0.21982","0.04519"
"100.03400","-0.19005","0.04562"
"100.13400","-0.15968","0.05509"
"100.23400","-0.12986","0.04794"
"100.33400","-0.09971","0.05507"
"100.43400","-0.06981","0.04224"
"100.53400","-0.03975","0.05745"
"100.63400","-0.00981","0.05377"
"100.73400","0.02041","0.04993"
"100.83400","0.05029","0.05177"
"100.93400","0.08025","0.05244"
"101.03400","0.11002","0.05420"
"101.13400","0.13995","0.03830"
"101.23400","0.17001","0.05732"
"101.33400","0.20013","0.05385"
"101.43400","0.23024","0.04918"
"101.53400","0.26026","0.03901"
"101.63400","0.29031","0.06001"
"101.73400","0.32021","0.03579"
"101.83400","0.35035","0.03082"
"101.93400","0.38028","0.05377"
"102.03400","0.41031","0.05698"
"102.13400","0.44010","0.09154"
"102.23400","0.47018","0.03546"
"102.33400","0.50000","0.04654"
"102.43400","0.53021","0.03986"
"102.53400","0.56002","0.05099"
"102.63400","0.59011","0.06621"
"102.73400","0.62005","0.06617"
"102.83400","0.65016","0.04236"
"102.93400","0.68012","0.05191"
"103.03400","0.71045","0.03924"
"103.13400","0.74024","0.04316"
"103.23400","0.77039","0.02924"
"103.33400","0.80017","0.03819"
"103.43400","0.83018","0.04647"
"103.53400","0.86006","0.03836"
"103.63400","0.89012","0.05877"
"103.73400","0.92004","0.06219"
"103.83400","0.95001","0.06236"
"103.93400","0.98008","0.05523"
"104.03400","1.01013","0.06413"
"104.13400","1.04034","0.06372"
"104.23400","1.07032","0.04934"
"104.33400","1.10025","0.05333"
"104.43400","1.13019","0.05661"
"104.53400","1.16030","0.04423"
"104.63400","1.19008","0.04307"
"104.73400","1.22045","0.05451"
"104.83400","1.25008","0.06070"
"104.93400","1.28008","0.05795"
"105.03400","1.30989","0.06106"
"105.13400","1.33999","0.07185"
"105.23400","1.37008","0.06285"
"105.33400","1.40030","0.06434"
"105.43400","1.43013","0.06013"
"105.53400","1.46037","0.07087"
"105.63400","1.49016","0.06042"
"105.73400","1.52040","0.06386"
"105.83400","1.55026","0.07077"
"105.93400","1.58045","0.08981"
"106.03400","1.61018","0.05425"
"106.13400","1.64006","0.06211"
"106.23400","1.66998","0.06558"
"106.33400","1.69995","0.04857"
"106.43400","1.73018","0.04820"
"106.53400","1.76024","0.05596"
"106.63400","1.79021","0.04395"
"106.73400","1.82019","0.04955"
"106.83400","1.85012","0.06111"
"106.93400","1.88013","0.06415"
"107.03400","1.91045","0.06422"
"107.13400","1.94027","0.05369"
"107.23400","1.97039","0.07730"
"107.33400","2.00000","0.06960"
"107.43400","2.03017","0.06777"
"107.53400","2.05997","0.06919"
"107.63400","2.09014","0.07038"
"107.73400","2.11994","0.07299"
"107.83400","2.15011","0.06764"
"107.93400","2.17996","0.08243"
"108.03400","2.21035","0.06066"
"108.13400","2.24025","0.06300"
"108.23400","2.27055","0.06233"
"108.33400","2.30039","0.06460"
"108.43400","2.33031","0.04756"
"108.53400","2.36022","0.05425"
"108.63400","2.39014","0.07909"
"108.73400","2.42017","0.06405"
"108.83400","2.45012","0.08136"
"108.93400","2.48009","0.07408"
"109.00100","2.50022","0.05252"
"109.00300","2.50082","0.05189"
"109.10300","2.50191","0.07175"
"109.20300","2.47024","0.07667"
"109.30300","2.43953","0.06977"
"109.40300","2.40958","0.08454"
"109.50300","2.37929","0.08419"
"109.60300","2.34961","0.07022"
"109.70300","2.31954","0.07003"
"109.80300","2.28962","0.08117"
"109.90300","2.25946","0.07708"
"110.00300","2.22947","0.07545"
"110.10300","2.19926","0.08003"
"110.20300","2.16945","0.08094"
"110.30300","2.13932","0.07164"
"110.40300","2.10935","0.07850"
"110.50300","2.07923","0.06904"
"110.60300","2.04916","0.07256"
"110.70300","2.01932","0.06475"
"110.80300","1.98946","0.09444"
"110.90300","1.95962","0.08050"
"111.00300","1.92949","0.06790"
"111.10300","1.89944","0.08917"
"111.20300","1.86939","0.09043"
"111.30300","1.83936","0.07862"
"111.40300","1.80939","0.06980"
"111.50300","1.77955","0.08268"
"111.60300","1.74935","0.07653"
"111.70300","1.71930","0.07165"
"111.80300","1.68913","0.07178"
"111.90300","1.65942","0.07209"
"112.00300","1.62933","0.06479"
"112.10300","1.59959","0.09675"
"112.20300","1.56953","0.08346"
"112.30300","1.53949","0.08284"
"112.40300","1.50945","0.07181"
"112.50300","1.47957","0.07848"
"112.60300","1.44941","0.09031"
"112.70300","1.41943","0.09199"
"112.80300","1.38925","0.08431"
"112.90300","1.35924","0.08905"
"113.00300","1.32916","0.09277"
"113.10300","1.29939","0.08263"
"113.20300","1.26939","0.09666"
"113.30300","1.23941","0.08475"
"113.40300","1.20948","0.06943"
"113.50300","1.17938","0.05382"
"113.60300","1.14948","0.07737"
"113.70300","1.11949","0.07261"
"113.80300","1.08953","0.05755"
"113.90300","1.05942","0.07291"
"114.00300","1.02935","0.08467"
"114.10300","0.99925","0.08301"
"114.20300","0.96950","0.07623"
"114.30300","0.93925","0.09527"
"114.40300","0.90943","0.08090"
"114.50300","0.87926","0.08104"
"114.60300","0.84931","0.07423"
"114.70300","0.81935","0.07448"
"114.80300","0.78965","0.05425"
"114.90300","0.75955","0.06207"
"115.00300","0.72951","0.06266"
"115.10300","0.69936","0.06090"
"115.20300","0.66939","0.05657"
"115.30300","0.63928","0.05926"
"115.40300","0.60950","0.06385"
"115.50300","0.57927","0.06055"
"115.60300","0.54936","0.05158"
"115.70300","0.51929","0.05836"
"115.80300","0.48926","0.07262"
"115.90300","0.45943","0.11466"
"116.00300","0.42956","0.08427"
"116.10300","0.39956","0.08009"
"116.20300","0.36945","0.08093"
"116.30300","0.33942","0.07317"
"116.40300","0.30942","0.07522"
"116.50300","0.27956","0.08435"
"116.60300","0.24937","0.05624"
"116.70300","0.21945","0.06003"
"116.80300","0.18925","0.07470"
"116.90300","0.15922","0.05779"
"117.00300","0.12922","0.05347"
"117.10300","0.09950","0.07212"
"117.20300","0.06942","0.06300"
"117.30300","0.03959","0.05729"
"117.40300","0.00938","0.06603"
"117.50300","-0.02036","0.07477"
"117.60300","-0.05050","0.06897"
"117.70300","-0.08036","0.07309"
"117.80300","-0.11067","0.08590"
"117.90300","-0.14065","0.07059"
"118.00300","-0.17080","0.07568"
"118.10300","-0.20071","0.05693"
"118.20300","-0.23071","0.07529"
"118.30300","-0.26057","0.04852"
"118.40300","-0.29058","0.06228"
"118.50300","-0.32063","0.05391"
"118.60300","-0.35064","0.05825"
"118.70300","-0.38055","0.06420"
"118.80300","-0.41035","0.05749"
"118.90300","-0.44050","0.07597"
"119.00300","-0.47044","0.07166"
"119.10300","-0.50072","0.07433"
"119.20300","-0.53066","0.07520"
"119.30300","-0.56068","0.09282"
"119.40300","-0.59056","0.06581"
"119.50300","-0.62071","0.06411"
"119.60300","-0.65061","0.07032"
"119.70300","-0.68083","0.07577"
"119.80300","-0.71050","0.05851"
"119.90300","-0.74047","0.07518"
"120.00300","-0.77029","0.08472"
"120.10300","-0.80049","0.07120"
"120.20300","-0.83056","0.06843"
"120.30300","-0.86070","0.08597"
"120.40300","-0.89066","0.07520"
"120.50300","-0.92062","0.07434"
"120.60300","-0.95062","0.08824"
"120.70300","-0.98064","0.08425"
"120.80300","-1.01075","0.07850"
"120.90300","-1.04076","0.09903"
"121.00300","-1.07073","0.10722"
"121.10300","-1.10049","0.07780"
"121.20300","-1.13052","0.09331"
"121.30300","-1.16040","0.07911"
"121.40300","-1.19065","0.09396"
"121.50300","-1.22056","0.06648"
"121.60300","-1.25054","0.07547"
"121.70300","-1.28046","0.07962"
"121.80300","-1.31068","0.07488"
"121.90300","-1.34064","0.07461"
"122.00300","-1.37083","0.07062"
"122.10300","-1.40075","0.08718"
"122.20300","-1.43060","0.07712"
"122.30300","-1.46048","0.09831"
"122.40300","-1.49055","0.08875"
"122.50300","-1.52051","0.10785"
"122.60300","-1.55061","0.08675"
"122.70300","-1.58055","0.09469"
"122.80300","-1.61052","0.10717"
"122.90300","-1.64044","0.08893"
"123.00300","-1.67061","0.08950"
"123.10300","-1.70072","0.08691"
"123.20300","-1.73069","0.10362"
"123.30300","-1.76074","0.09456"
"123.40300","-1.79075","0.10720"
"123.50300","-1.82070","0.10506"
"123.60300","-1.85056","0.10535"
"123.70300","-1.88072","0.10270"
"123.80300","-1.91043","0.12181"
"123.90300","-1.94050","0.10422"
"124.00300","-1.97034","0.10428"
"124.10300","-2.00060","0.10457"
"124.20300","-2.03052","0.10608"
"124.30300","-2.06062","0.09727"
"124.40300","-2.09068","0.10545"
"124.50300","-2.12067","0.11341"
"124.60300","-2.15057","0.09232"
"124.70300","-2.18068","0.10435"
"124.80300","-2.21065","0.09459"
"124.90300","-2.24071","0.10487"
"125.00300","-2.27045","0.08474"
"125.10300","-2.30041","0.07963"
"125.20300","-2.33041","0.08846"
"125.30300","-2.36053","0.08094"
"125.40300","-2.39067","0.07646"
"125.50300","-2.42060","0.08080"
"125.60300","-2.45054","0.08806"
"125.70300","-2.48063","0.08051"
"125.76800","-2.50002","0.08528"
"125.77000","-2.50064","0.08468"
"125.87000","-2.50260","0.07545"
"125.97000","-2.47028","0.07342"
"126.07000","-2.43990","0.08569"
"126.17000","-2.40949","0.07359"
"126.27000","-2.37960","0.09230"
"126.37000","-2.34930","0.08205"
"126.47000","-2.31960","0.09157"
"126.57000","-2.28942","0.08775"
"126.67000","-2.25966","0.09176"
"126.77000","-2.22956","0.10186"
"126.87000","-2.19960","0.08573"
"126.97000","-2.16964","0.10035"
"127.07000","-2.13979","0.09460"
"127.17000","-2.10965","0.09324"
"127.27000","-2.07968","0.06878"
"127.37000","-2.04952","0.08018"
"127.47000","-2.01941","0.07540"
"127.57000","-1.98947","0.09056"
"127.67000","-1.95938","0.07650"
"127.77000","-1.92956","0.10119"
"127.87000","-1.89951","0.10217"
"127.97000","-1.86964","0.09804"
"128.07000","-1.83959","0.11063"
"128.17000","-1.80982","0.10860"
"128.27000","-1.77971","0.10189"
"128.37000","-1.74984","0.10467"
"128.47000","-1.71957","0.09428"
"128.57000","-1.68962","0.06890"
"128.67000","-1.65938","0.06512"
"128.77000","-1.62964","0.07052"
"128.87000","-1.59940","0.08182"
"128.97000","-1.56964","0.06901"
"129.07000","-1.53948","0.07524"
"129.17000","-1.50944","0.07102"
"129.27000","-1.47941","0.06759"
"129.37000","-1.44964","0.06658"
"129.47000","-1.41964","0.07633"
"129.57000","-1.38984","0.08150"
"129.67000","-1.35965","0.06092"
"129.77000","-1.32965","0.07883"
"129.87000","-1.29955","0.06921"
"129.97000","-1.26950","0.08814"
"130.07000","-1.23954","0.06130"
"130.17000","-1.20944","0.07683"
"130.27000","-1.17942","0.07740"
"130.37000","-1.14924","0.06797"
"130.47000","-1.11952","0.06638"
"130.57000","-1.08959","0.08023"
"130.67000","-1.05985","0.06786"
"130.77000","-1.02967","0.05057"
"130.87000","-0.99974","0.06405"
"130.97000","-0.96955","0.06807"
"131.07000","-0.93972","0.07394"
"131.17000","-0.90955","0.05627"
"131.27000","-0.87969","0.08460"
"131.37000","-0.84945","0.06893"
"131.47000","-0.81947","0.07171"
"131.57000","-0.78932","0.06625"
"131.67000","-0.75949","0.07058"
"131.77000","-0.72951","0.06191"
"131.87000","-0.69961","0.04279"
"131.97000","-0.66959","0.05326"
"132.07000","-0.63970","0.04250"
"132.17000","-0.60970","0.03967"
"132.27000","-0.57976","0.04867"
"132.37000","-0.54966","0.06080"
"132.47000","-0.51953","0.03857"
"132.57000","-0.48943","0.04323"
"132.67000","-0.45930","0.04363"
"132.77000","-0.42940","0.05006"
"132.87000","-0.39943","0.03962"
"132.97000","-0.36961","0.04709"
"133.07000","-0.33953","0.05124"
"133.17000","-0.30959","0.04353"
"133.27000","-0.27955","0.04187"
"133.37000","-0.24980","0.05520"
"133.47000","-0.21960","0.05515"
"133.57000","-0.18980","0.04326"
"133.67000","-0.15943","0.06056"
"133.77000","-0.12963","0.05805"
"133.87000","-0.09946","0.05177"
"133.97000","-0.06958","0.03118"
"134.07000","-0.03951","0.05544"
"134.17000","-0.00956","0.04636"
"134.20300","0.00011","0.02129"