File: SupLinearAndTan/Tan_Fan_Chart/Specimen_RawData_3.csv
Time,Extension,Load
(s),(mm),(N)
"0.00000","0.00000","0.08250"
"0.10000","0.00880","0.05169"
"0.20000","0.04160","0.02960"
"0.30000","0.07206","-0.00821"
"0.40000","0.10225","-0.05098"
"0.50000","0.13219","-0.06470"
"0.60000","0.16246","-0.08562"
"0.70000","0.19241","-0.13424"
"0.80000","0.22260","-0.17778"
"0.90000","0.25241","-0.18063"
"1.00000","0.28247","-0.21712"
"1.10000","0.31219","-0.24664"
"1.20000","0.34235","-0.26073"
"1.30000","0.37225","-0.27000"
"1.40000","0.40234","-0.31501"
"1.50000","0.43211","-0.28648"
"1.60000","0.46228","-0.38477"
"1.70000","0.49211","-0.45025"
"1.80000","0.52240","-0.47810"
"1.90000","0.55232","-0.49531"
"2.00000","0.58244","-0.52719"
"2.10000","0.61235","-0.55736"
"2.20000","0.64238","-0.60296"
"2.30000","0.67241","-0.61886"
"2.40000","0.70245","-0.64425"
"2.50000","0.73240","-0.68240"
"2.60000","0.76225","-0.68266"
"2.70000","0.79217","-0.71775"
"2.80000","0.82201","-0.73781"
"2.90000","0.85224","-0.77783"
"3.00000","0.88225","-0.79911"
"3.10000","0.91244","-0.84991"
"3.20000","0.94235","-0.87023"
"3.30000","0.97242","-0.90370"
"3.40000","1.00229","-0.91782"
"3.50000","1.03249","-0.95287"
"3.60000","1.06236","-1.00339"
"3.70000","1.09242","-1.02734"
"3.80000","1.12219","-1.05752"
"3.90000","1.15230","-1.08166"
"4.00000","1.18210","-1.10504"
"4.10000","1.21235","-1.12018"
"4.20000","1.24212","-1.15740"
"4.30000","1.27220","-1.18572"
"4.40000","1.30219","-1.21547"
"4.50000","1.33229","-1.23183"
"4.60000","1.36236","-1.27355"
"4.70000","1.39256","-1.30155"
"4.80000","1.42247","-1.31457"
"4.90000","1.45248","-1.36783"
"5.00000","1.48232","-1.39211"
"5.10000","1.51226","-1.42113"
"5.20000","1.54221","-1.43480"
"5.30000","1.57213","-1.45685"
"5.40000","1.60220","-1.51643"
"5.50000","1.63212","-1.55361"
"5.60000","1.66227","-1.59808"
"5.70000","1.69223","-1.64826"
"5.80000","1.72245","-1.65105"
"5.90000","1.75241","-1.67783"
"6.00000","1.78244","-1.71340"
"6.10000","1.81221","-1.72902"
"6.20000","1.84238","-1.76245"
"6.30000","1.87225","-1.79886"
"6.40000","1.90243","-1.81722"
"6.50000","1.93220","-1.84981"
"6.60000","1.96226","-1.87291"
"6.70000","1.99209","-1.90606"
"6.80000","2.02210","-1.93700"
"6.90000","2.05222","-1.96244"
"7.00000","2.08238","-2.01305"
"7.10000","2.11233","-2.02665"
"7.20000","2.14234","-2.05303"
"7.30000","2.17236","-2.05911"
"7.40000","2.20238","-2.09936"
"7.50000","2.23246","-2.13878"
"7.60000","2.26240","-2.14059"
"7.70000","2.29241","-2.18409"
"7.80000","2.32214","-2.19371"
"7.90000","2.35216","-2.24253"
"8.00000","2.38209","-2.25248"
"8.10000","2.41234","-2.32675"
"8.20000","2.44229","-2.33979"
"8.30000","2.47237","-2.36288"
"8.39300","2.50016","-2.41070"
"8.39500","2.50076","-2.41309"
"8.49500","2.50160","-2.41291"
"8.59500","2.47019","-2.34801"
"8.69500","2.43947","-2.31649"
"8.79500","2.40949","-2.31532"
"8.89500","2.37924","-2.26913"
"8.99500","2.34954","-2.24307"
"9.09500","2.31950","-2.19844"
"9.19500","2.28958","-2.18404"
"9.29500","2.25940","-2.12690"
"9.39500","2.22940","-2.11875"
"9.49500","2.19920","-2.07241"
"9.59500","2.16937","-2.04878"
"9.69500","2.13927","-2.00477"
"9.79500","2.10927","-1.99851"
"9.89500","2.07920","-1.98490"
"9.99500","2.04910","-1.94099"
"10.09500","2.01924","-1.91284"
"10.19500","1.98942","-1.88233"
"10.29500","1.95958","-1.85543"
"10.39500","1.92944","-1.83060"
"10.49500","1.89940","-1.80020"
"10.59500","1.86927","-1.78473"
"10.69500","1.83935","-1.73578"
"10.79500","1.80933","-1.69950"
"10.89500","1.77948","-1.68807"
"10.99500","1.74927","-1.64602"
"11.09500","1.71924","-1.61813"
"11.19500","1.68908","-1.59375"
"11.29500","1.65935","-1.57660"
"11.39500","1.62929","-1.53034"
"11.49500","1.59952","-1.49087"
"11.59500","1.56947","-1.45954"
"11.69500","1.53945","-1.42596"
"11.79500","1.50938","-1.39083"
"11.89500","1.47949","-1.35509"
"11.99500","1.44934","-1.33286"
"12.09500","1.41937","-1.28076"
"12.19500","1.38917","-1.26710"
"12.29500","1.35916","-1.23250"
"12.39500","1.32911","-1.20089"
"12.49500","1.29935","-1.17478"
"12.59500","1.26933","-1.14460"
"12.69500","1.23935","-1.12442"
"12.79500","1.20940","-1.08242"
"12.89500","1.17932","-1.06219"
"12.99500","1.14940","-1.04169"
"13.09500","1.11943","-1.02129"
"13.19500","1.08949","-0.98623"
"13.29500","1.05938","-0.96008"
"13.39500","1.02927","-0.93494"
"13.49500","0.99920","-0.89422"
"13.59500","0.96939","-0.87480"
"13.69500","0.93919","-0.86093"
"13.79500","0.90938","-0.81573"
"13.89500","0.87919","-0.78228"
"13.99500","0.84924","-0.75793"
"14.09500","0.81927","-0.72113"
"14.19500","0.78959","-0.68998"
"14.29500","0.75949","-0.64908"
"14.39500","0.72944","-0.64621"
"14.49500","0.69929","-0.60225"
"14.59500","0.66933","-0.58609"
"14.69500","0.63922","-0.55369"
"14.79500","0.60942","-0.51306"
"14.89500","0.57923","-0.48459"
"14.99500","0.54929","-0.46641"
"15.09500","0.51919","-0.44914"
"15.19500","0.48923","-0.40255"
"15.29500","0.45936","-0.27261"
"15.39500","0.42949","-0.30939"
"15.49500","0.39951","-0.29693"
"15.59500","0.36938","-0.25063"
"15.69500","0.33936","-0.22836"
"15.79500","0.30936","-0.20643"
"15.89500","0.27953","-0.17036"
"15.99500","0.24931","-0.12593"
"16.09500","0.21943","-0.10375"
"16.19500","0.18918","-0.07044"
"16.29500","0.15913","-0.04867"
"16.39500","0.12915","-0.02399"
"16.49500","0.09944","-0.01023"
"16.59500","0.06935","0.02190"
"16.69500","0.03957","0.06273"
"16.79500","0.00929","0.06603"
"16.89500","-0.02041","0.12604"
"16.99500","-0.05057","0.14735"
"17.09500","-0.08044","0.18534"
"17.19500","-0.11074","0.20990"
"17.29500","-0.14072","0.24967"
"17.39500","-0.17087","0.29196"
"17.49500","-0.20078","0.31804"
"17.59500","-0.23075","0.35941"
"17.69500","-0.26064","0.38500"
"17.79500","-0.29067","0.41001"
"17.89500","-0.32065","0.41553"
"17.99500","-0.35065","0.45117"
"18.09500","-0.38067","0.49245"
"18.19500","-0.41041","0.50588"
"18.29500","-0.44056","0.52493"
"18.39500","-0.47051","0.57540"
"18.49500","-0.50078","0.61234"
"18.59500","-0.53074","0.63237"
"18.69500","-0.56075","0.66226"
"18.79500","-0.59065","0.69472"
"18.89500","-0.62081","0.71995"
"18.99500","-0.65062","0.76355"
"19.09500","-0.68092","0.82011"
"19.19500","-0.71056","0.84863"
"19.29500","-0.74052","0.86380"
"19.39500","-0.77034","0.91033"
"19.49500","-0.80052","0.93619"
"19.59500","-0.83062","0.95906"
"19.69500","-0.86076","0.99640"
"19.79500","-0.89076","1.02539"
"19.89500","-0.92066","1.06464"
"19.99500","-0.95067","1.08284"
"20.09500","-0.98071","1.11534"
"20.19500","-1.01081","1.13755"
"20.29500","-1.04085","1.17141"
"20.39500","-1.07074","1.21338"
"20.49500","-1.10055","1.24280"
"20.59500","-1.13058","1.28385"
"20.69500","-1.16047","1.29542"
"20.79500","-1.19072","1.35498"
"20.89500","-1.22062","1.35494"
"20.99500","-1.25060","1.39490"
"21.09500","-1.28044","1.42861"
"21.19500","-1.31081","1.47722"
"21.29500","-1.34071","1.49495"
"21.39500","-1.37088","1.51161"
"21.49500","-1.40084","1.55315"
"21.59500","-1.43068","1.57576"
"21.69500","-1.46054","1.60127"
"21.79500","-1.49063","1.61847"
"21.89500","-1.52054","1.66750"
"21.99500","-1.55069","1.68995"
"22.09500","-1.58061","1.74294"
"22.19500","-1.61057","1.76795"
"22.29500","-1.64059","1.80104"
"22.39500","-1.67060","1.81105"
"22.49500","-1.70074","1.85884"
"22.59500","-1.73083","1.94386"
"22.69500","-1.76080","1.95561"
"22.79500","-1.79079","1.97064"
"22.89500","-1.82073","2.00821"
"22.99500","-1.85064","2.03840"
"23.09500","-1.88082","2.04407"
"23.19500","-1.91050","2.08321"
"23.29500","-1.94056","2.11238"
"23.39500","-1.97040","2.14475"
"23.49500","-2.00063","2.16380"
"23.59500","-2.03056","2.20486"
"23.69500","-2.06075","2.21767"
"23.79500","-2.09070","2.25109"
"23.89500","-2.12069","2.27803"
"23.99500","-2.15055","2.32440"
"24.09500","-2.18074","2.35474"
"24.19500","-2.21066","2.37240"
"24.29500","-2.24075","2.41631"
"24.39500","-2.27057","2.42473"
"24.49500","-2.30049","2.46502"
"24.59500","-2.33051","2.47958"
"24.69500","-2.36056","2.52920"
"24.79500","-2.39072","2.53693"
"24.89500","-2.42061","2.57626"
"24.99500","-2.45061","2.59638"
"25.09500","-2.48072","2.62877"
"25.16000","-2.50014","2.64380"
"25.16200","-2.50076","2.64324"
"25.26200","-2.50262","2.63587"
"25.36200","-2.47033","2.59809"
"25.46200","-2.43995","2.58284"
"25.56200","-2.40955","2.55367"
"25.66200","-2.37965","2.52589"
"25.76200","-2.34933","2.48154"
"25.86200","-2.31966","2.48059"
"25.96200","-2.28948","2.43942"
"26.06200","-2.25973","2.40747"
"26.16200","-2.22963","2.38850"
"26.26200","-2.19962","2.35377"
"26.36200","-2.16969","2.32459"
"26.46200","-2.13984","2.30303"
"26.56200","-2.10970","2.28213"
"26.66200","-2.07978","2.22580"
"26.76200","-2.04954","2.20367"
"26.86200","-2.01950","2.17872"
"26.96200","-1.98954","2.16132"
"27.06200","-1.95942","2.10553"
"27.16200","-1.92963","2.08911"
"27.26200","-1.89958","2.05037"
"27.36200","-1.86976","2.01735"
"27.46200","-1.83964","2.00651"
"27.56200","-1.80985","1.97686"
"27.66200","-1.77976","1.94462"
"27.76200","-1.74989","1.92924"
"27.86200","-1.71964","1.85265"
"27.96200","-1.68969","1.80579"
"28.06200","-1.65941","1.77613"
"28.16200","-1.62971","1.74333"
"28.26200","-1.59946","1.73745"
"28.36200","-1.56977","1.68630"
"28.46200","-1.53954","1.65947"
"28.56200","-1.50948","1.62655"
"28.66200","-1.47948","1.60430"
"28.76200","-1.44971","1.56181"
"28.86200","-1.41972","1.53394"
"28.96200","-1.38996","1.52103"
"29.06200","-1.35965","1.48845"
"29.16200","-1.32971","1.45486"
"29.26200","-1.29961","1.41467"
"29.36200","-1.26956","1.39375"
"29.46200","-1.23957","1.33713"
"29.56200","-1.20949","1.31847"
"29.66200","-1.17947","1.28741"
"29.76200","-1.14934","1.26025"
"29.86200","-1.11957","1.20473"
"29.96200","-1.08963","1.19391"
"30.06200","-1.05991","1.16359"
"30.16200","-1.02977","1.11955"
"30.26200","-0.99978","1.09524"
"30.36200","-0.96969","1.06804"
"30.46200","-0.93986","1.05170"
"30.56200","-0.90953","1.00178"
"30.66200","-0.87968","0.98897"
"30.76200","-0.84955","0.94135"
"30.86200","-0.81956","0.90051"
"30.96200","-0.78939","0.87525"
"31.06200","-0.75956","0.84994"
"31.16200","-0.72961","0.82276"
"31.26200","-0.69966","0.74622"
"31.36200","-0.66965","0.72785"
"31.46200","-0.63970","0.69200"
"31.56200","-0.60978","0.67135"
"31.66200","-0.57980","0.62973"
"31.76200","-0.54972","0.61383"
"31.86200","-0.51964","0.57531"
"31.96200","-0.48956","0.54924"
"32.06200","-0.45926","0.52240"
"32.16200","-0.42937","0.49950"
"32.26200","-0.39949","0.45509"
"32.36200","-0.36971","0.41799"
"32.46200","-0.33955","0.40897"
"32.56200","-0.30967","0.37819"
"32.66200","-0.27962","0.34559"
"32.76200","-0.24983","0.31592"
"32.86200","-0.21969","0.28542"
"32.96200","-0.18986","0.23897"
"33.06200","-0.15952","0.21414"
"33.16200","-0.12970","0.18803"
"33.26200","-0.09949","0.16657"
"33.36200","-0.06963","0.11658"
"33.46200","-0.03957","0.10830"
"33.56200","-0.00960","0.05858"
"33.66200","0.02060","0.02958"
"33.76200","0.05050","-0.00241"
"33.86200","0.08043","-0.01964"
"33.96200","0.11020","-0.04613"
"34.06200","0.14014","-0.08472"
"34.16200","0.17020","-0.08273"
"34.26200","0.20032","-0.12935"
"34.36200","0.23044","-0.16227"
"34.46200","0.26042","-0.20844"
"34.56200","0.29046","-0.21898"
"34.66200","0.32039","-0.24570"
"34.76200","0.35055","-0.27259"
"34.86200","0.38049","-0.28767"
"34.96200","0.41053","-0.33388"
"35.06200","0.44034","-0.28593"
"35.16200","0.47037","-0.43792"
"35.26200","0.50016","-0.44804"
"35.36200","0.53041","-0.47958"
"35.46200","0.56018","-0.49867"
"35.56200","0.59031","-0.52236"
"35.66200","0.62021","-0.54599"
"35.76200","0.65033","-0.60450"
"35.86200","0.68031","-0.61266"
"35.96200","0.71063","-0.64590"
"36.06200","0.74042","-0.67121"
"36.16200","0.77057","-0.71713"
"36.26200","0.80033","-0.72813"
"36.36200","0.83040","-0.75911"
"36.46200","0.86028","-0.81876"
"36.56200","0.89026","-0.81622"
"36.66200","0.92023","-0.84620"
"36.76200","0.95021","-0.87919"
"36.86200","0.98028","-0.91431"
"36.96200","1.01033","-0.92791"
"37.06200","1.04050","-0.96747"
"37.16200","1.07055","-1.00866"
"37.26200","1.10044","-1.02147"
"37.36200","1.13034","-1.03645"
"37.46200","1.16046","-1.08496"
"37.56200","1.19024","-1.10799"
"37.66200","1.22055","-1.13985"
"37.76200","1.25022","-1.16424"
"37.86200","1.28027","-1.19587"
"37.96200","1.31012","-1.22899"
"38.06200","1.34031","-1.24050"
"38.16200","1.37017","-1.29942"
"38.26200","1.40046","-1.32346"
"38.36200","1.43034","-1.34315"
"38.46200","1.46053","-1.36038"
"38.56200","1.49035","-1.41569"
"38.66200","1.52056","-1.43025"
"38.76200","1.55046","-1.42572"
"38.86200","1.58062","-1.45401"
"38.96200","1.61038","-1.52313"
"39.06200","1.64024","-1.54646"
"39.16200","1.67017","-1.59513"
"39.26200","1.70014","-1.62733"
"39.36200","1.73037","-1.63785"
"39.46200","1.76041","-1.66562"
"39.56200","1.79039","-1.72161"
"39.66200","1.82029","-1.74091"
"39.76200","1.85046","-1.75137"
"39.86200","1.88032","-1.79913"
"39.96200","1.91057","-1.83844"
"40.06200","1.94046","-1.86166"
"40.16200","1.97056","-1.87477"
"40.26200","2.00021","-1.91286"
"40.36200","2.03036","-1.93037"
"40.46200","2.06016","-1.96181"
"40.56200","2.09032","-1.99326"
"40.66200","2.12007","-2.00917"
"40.76200","2.15033","-2.04502"
"40.86200","2.18018","-2.06723"
"40.96200","2.21054","-2.11739"
"41.06200","2.24045","-2.14750"
"41.16200","2.27076","-2.15861"
"41.26200","2.30054","-2.18230"
"41.36200","2.33054","-2.23257"
"41.46200","2.36029","-2.26411"
"41.56200","2.39033","-2.28704"
"41.66200","2.42035","-2.32679"
"41.76200","2.45028","-2.32224"
"41.86200","2.48026","-2.35912"
"41.92800","2.50011","-2.39755"
"41.93000","2.50071","-2.39800"
"42.03000","2.50188","-2.39308"
"42.13000","2.47018","-2.36611"
"42.23000","2.43946","-2.32696"
"42.33000","2.40948","-2.29784"
"42.43000","2.37926","-2.26980"
"42.53000","2.34955","-2.24454"
"42.63000","2.31952","-2.19226"
"42.73000","2.28957","-2.15322"
"42.83000","2.25937","-2.14848"
"42.93000","2.22939","-2.11685"
"43.03000","2.19919","-2.06823"
"43.13000","2.16934","-2.03556"
"43.23000","2.13926","-2.02452"
"43.33000","2.10928","-1.98075"
"43.43000","2.07918","-1.98266"
"43.53000","2.04909","-1.94275"
"43.63000","2.01924","-1.90941"
"43.73000","1.98940","-1.87061"
"43.83000","1.95957","-1.84931"
"43.93000","1.92941","-1.83393"
"44.03000","1.89941","-1.79218"
"44.13000","1.86927","-1.76015"
"44.23000","1.83933","-1.72340"
"44.33000","1.80932","-1.69691"
"44.43000","1.77947","-1.65612"
"44.53000","1.74929","-1.63299"
"44.63000","1.71925","-1.61172"
"44.73000","1.68906","-1.58036"
"44.83000","1.65935","-1.53706"
"44.93000","1.62928","-1.51368"
"45.03000","1.59955","-1.46490"
"45.13000","1.56943","-1.43601"
"45.23000","1.53943","-1.40767"
"45.33000","1.50937","-1.39643"
"45.43000","1.47951","-1.35624"
"45.53000","1.44934","-1.30997"
"45.63000","1.41937","-1.28920"
"45.73000","1.38919","-1.28094"
"45.83000","1.35914","-1.23345"
"45.93000","1.32911","-1.19442"
"46.03000","1.29935","-1.17789"
"46.13000","1.26933","-1.13483"
"46.23000","1.23935","-1.10655"
"46.33000","1.20940","-1.08407"
"46.43000","1.17931","-1.05141"
"46.53000","1.14940","-1.02547"
"46.63000","1.11943","-0.99223"
"46.73000","1.08949","-0.99103"
"46.83000","1.05937","-0.93425"
"46.93000","1.02928","-0.91327"
"47.03000","0.99920","-0.89005"
"47.13000","0.96938","-0.87271"
"47.23000","0.93917","-0.82282"
"47.33000","0.90937","-0.79724"
"47.43000","0.87920","-0.77265"
"47.53000","0.84924","-0.73649"
"47.63000","0.81925","-0.70586"
"47.73000","0.78959","-0.67507"
"47.83000","0.75947","-0.65043"
"47.93000","0.72947","-0.61813"
"48.03000","0.69927","-0.59509"
"48.13000","0.66932","-0.56751"
"48.23000","0.63921","-0.52768"
"48.33000","0.60944","-0.47577"
"48.43000","0.57920","-0.48364"
"48.53000","0.54927","-0.45543"
"48.63000","0.51919","-0.43540"
"48.73000","0.48924","-0.37881"
"48.83000","0.45934","-0.28000"
"48.93000","0.42951","-0.30404"
"49.03000","0.39951","-0.29284"
"49.13000","0.36939","-0.26284"
"49.23000","0.33936","-0.22747"
"49.33000","0.30933","-0.19936"
"49.43000","0.27953","-0.17394"
"49.53000","0.24932","-0.14950"
"49.63000","0.21942","-0.09518"
"49.73000","0.18918","-0.06158"
"49.83000","0.15912","-0.04419"
"49.93000","0.12915","-0.02284"
"50.03000","0.09944","0.00324"
"50.13000","0.06935","0.02281"
"50.23000","0.03955","0.05571"
"50.33000","0.00929","0.08561"
"50.43000","-0.02042","0.12393"
"50.53000","-0.05058","0.14529"
"50.63000","-0.08046","0.16655"
"50.73000","-0.11073","0.20846"
"50.83000","-0.14074","0.22370"
"50.93000","-0.17086","0.26885"
"51.03000","-0.20079","0.29578"
"51.13000","-0.23076","0.34868"
"51.23000","-0.26065","0.36282"
"51.33000","-0.29066","0.39937"
"51.43000","-0.32069","0.43294"
"51.53000","-0.35069","0.46165"
"51.63000","-0.38063","0.48159"
"51.73000","-0.41042","0.51137"
"51.83000","-0.44055","0.55080"
"51.93000","-0.47051","0.56760"
"52.03000","-0.50077","0.60492"
"52.13000","-0.53075","0.64165"
"52.23000","-0.56075","0.65454"
"52.33000","-0.59065","0.66432"
"52.43000","-0.62079","0.72162"
"52.53000","-0.65064","0.75008"
"52.63000","-0.68090","0.77592"
"52.73000","-0.71058","0.82947"
"52.83000","-0.74054","0.86401"
"52.93000","-0.77032","0.89279"
"53.03000","-0.80054","0.91839"
"53.13000","-0.83063","0.97534"
"53.23000","-0.86080","0.99727"
"53.33000","-0.89075","1.02955"
"53.43000","-0.92067","1.07176"
"53.53000","-0.95066","1.09470"
"53.63000","-0.98068","1.11676"
"53.73000","-1.01083","1.13165"
"53.83000","-1.04086","1.17965"
"53.93000","-1.07085","1.21315"
"54.03000","-1.10060","1.23632"
"54.13000","-1.13059","1.26378"
"54.23000","-1.16049","1.28342"
"54.33000","-1.19071","1.31413"
"54.43000","-1.22064","1.34388"
"54.53000","-1.25061","1.37465"
"54.63000","-1.28050","1.42643"
"54.73000","-1.31078","1.44469"
"54.83000","-1.34073","1.49237"
"54.93000","-1.37091","1.53283"
"55.03000","-1.40082","1.55523"
"55.13000","-1.43068","1.57649"
"55.23000","-1.46055","1.61568"
"55.33000","-1.49062","1.64256"
"55.43000","-1.52055","1.66317"
"55.53000","-1.55066","1.69701"
"55.63000","-1.58062","1.74112"
"55.73000","-1.61060","1.75495"
"55.83000","-1.64060","1.76738"
"55.93000","-1.67061","1.81224"
"56.03000","-1.70079","1.83836"
"56.13000","-1.73071","1.90795"
"56.23000","-1.76086","1.95160"
"56.33000","-1.79080","1.97716"
"56.43000","-1.82075","1.99803"
"56.53000","-1.85058","2.03041"
"56.63000","-1.88083","2.06424"
"56.73000","-1.91050","2.08128"
"56.83000","-1.94054","2.10712"
"56.93000","-1.97039","2.14892"
"57.03000","-2.00065","2.18078"
"57.13000","-2.03059","2.19589"
"57.23000","-2.06077","2.21596"
"57.33000","-2.09070","2.25334"
"57.43000","-2.12069","2.28703"
"57.53000","-2.15051","2.30856"
"57.63000","-2.18081","2.34430"
"57.73000","-2.21066","2.37496"
"57.83000","-2.24074","2.39700"
"57.93000","-2.27057","2.40796"
"58.03000","-2.30052","2.44761"
"58.13000","-2.33049","2.48794"
"58.23000","-2.36059","2.50311"
"58.33000","-2.39072","2.54422"
"58.43000","-2.42066","2.57552"
"58.53000","-2.45063","2.58904"
"58.63000","-2.48070","2.61492"
"58.69500","-2.50014","2.60977"
"58.69700","-2.50076","2.61166"
"58.79700","-2.50264","2.62734"
"58.89700","-2.47034","2.60500"
"58.99700","-2.43996","2.56776"
"59.09700","-2.40953","2.54368"
"59.19700","-2.37966","2.52823"
"59.29700","-2.34935","2.48772"
"59.39700","-2.31963","2.45442"
"59.49700","-2.28950","2.43969"
"59.59700","-2.25971","2.40388"
"59.69700","-2.22963","2.38531"
"59.79700","-2.19967","2.33174"
"59.89700","-2.16969","2.31070"
"59.99700","-2.13983","2.29112"
"60.09700","-2.10969","2.25166"
"60.19700","-2.07980","2.20330"
"60.29700","-2.04953","2.18992"
"60.39700","-2.01947","2.16823"
"60.49700","-1.98955","2.14213"
"60.59700","-1.95940","2.11295"
"60.69700","-1.92962","2.08089"
"60.79700","-1.89957","2.04114"
"60.89700","-1.86972","2.01704"
"60.99700","-1.83965","2.02847"
"61.09700","-1.80988","1.96656"
"61.19700","-1.77978","1.94220"
"61.29700","-1.74988","1.92615"
"61.39700","-1.71963","1.85021"
"61.49700","-1.68966","1.79734"
"61.59700","-1.65942","1.76585"
"61.69700","-1.62970","1.74662"
"61.79700","-1.59944","1.71247"
"61.89700","-1.56975","1.67082"
"61.99700","-1.53952","1.65003"
"62.09700","-1.50949","1.61756"
"62.19700","-1.47949","1.56696"
"62.29700","-1.44971","1.55135"
"62.39700","-1.41978","1.53265"
"62.49700","-1.38989","1.51248"
"62.59700","-1.35963","1.47433"
"62.69700","-1.32972","1.45149"
"62.79700","-1.29964","1.41008"
"62.89700","-1.26958","1.37084"
"62.99700","-1.23956","1.34655"
"63.09700","-1.20949","1.32693"
"63.19700","-1.17948","1.29339"
"63.29700","-1.14933","1.24371"
"63.39700","-1.11957","1.22285"
"63.49700","-1.08963","1.19321"
"63.59700","-1.05989","1.14212"
"63.69700","-1.02978","1.10048"
"63.79700","-0.99979","1.09183"
"63.89700","-0.96969","1.05121"
"63.99700","-0.93984","1.02400"
"64.09700","-0.90947","0.98260"
"64.19700","-0.87973","0.97212"
"64.29700","-0.84947","0.92790"
"64.39700","-0.81956","0.89986"
"64.49700","-0.78940","0.87449"
"64.59700","-0.75954","0.83290"
"64.69700","-0.72957","0.81599"
"64.79700","-0.69967","0.75644"
"64.89700","-0.66963","0.73884"
"64.99700","-0.63972","0.68080"
"65.09700","-0.60977","0.66643"
"65.19700","-0.57980","0.64376"
"65.29700","-0.54974","0.59551"
"65.39700","-0.51960","0.55742"
"65.49700","-0.48947","0.53277"
"65.59700","-0.45935","0.50981"
"65.69700","-0.42945","0.47208"
"65.79700","-0.39949","0.43851"
"65.89700","-0.36968","0.41019"
"65.99700","-0.33957","0.40002"
"66.09700","-0.30965","0.36572"
"66.19700","-0.27962","0.35533"
"66.29700","-0.24982","0.31743"
"66.39700","-0.21969","0.27969"
"66.49700","-0.18989","0.24713"
"66.59700","-0.15950","0.21500"
"66.69700","-0.12968","0.18385"
"66.79700","-0.09950","0.14828"
"66.89700","-0.06965","0.11541"
"66.99700","-0.03953","0.09140"
"67.09700","-0.00960","0.04162"
"67.19700","0.02061","0.00534"
"67.29700","0.05047","-0.01063"
"67.39700","0.08044","-0.04420"
"67.49700","0.11019","-0.06837"
"67.59700","0.14014","-0.08753"
"67.69700","0.17021","-0.10547"
"67.79700","0.20031","-0.15186"
"67.89700","0.23044","-0.16866"
"67.99700","0.26043","-0.19781"
"68.09700","0.29047","-0.23761"
"68.19700","0.32041","-0.25128"
"68.29700","0.35053","-0.27494"
"68.39700","0.38052","-0.29387"
"68.49700","0.41053","-0.33514"
"68.59700","0.44033","-0.28471"
"68.69700","0.47035","-0.43445"
"68.79700","0.50017","-0.47011"
"68.89700","0.53044","-0.49750"
"68.99700","0.56020","-0.52078"
"69.09700","0.59029","-0.54331"
"69.19700","0.62023","-0.58103"
"69.29700","0.65034","-0.61466"
"69.39700","0.68031","-0.63887"
"69.49700","0.71064","-0.67855"
"69.59700","0.74039","-0.70342"
"69.69700","0.77059","-0.72405"
"69.79700","0.80032","-0.73580"
"69.89700","0.83042","-0.77011"
"69.99700","0.86027","-0.81328"
"70.09700","0.89029","-0.82068"
"70.19700","0.92021","-0.86210"
"70.29700","0.95022","-0.88797"
"70.39700","0.98029","-0.91116"
"70.49700","1.01032","-0.95096"
"70.59700","1.04051","-0.99087"
"70.69700","1.07054","-1.03168"
"70.79700","1.10046","-1.03978"
"70.89700","1.13036","-1.07974"
"70.99700","1.16044","-1.10869"
"71.09700","1.19025","-1.12423"
"71.19700","1.22056","-1.15007"
"71.29700","1.25025","-1.18019"
"71.39700","1.28033","-1.19407"
"71.49700","1.31010","-1.21687"
"71.59700","1.34034","-1.26024"
"71.69700","1.37019","-1.28879"
"71.79700","1.40046","-1.30717"
"71.89700","1.43033","-1.34099"
"71.99700","1.46053","-1.39100"
"72.09700","1.49036","-1.40584"
"72.19700","1.52057","-1.43987"
"72.29700","1.55047","-1.46587"
"72.39700","1.58061","-1.51050"
"72.49700","1.61039","-1.54944"
"72.59700","1.64026","-1.58823"
"72.69700","1.67018","-1.61685"
"72.79700","1.70016","-1.64283"
"72.89700","1.73036","-1.66379"
"72.99700","1.76043","-1.68301"
"73.09700","1.79035","-1.73719"
"73.19700","1.82034","-1.74352"
"73.29700","1.85040","-1.78360"
"73.39700","1.88031","-1.80520"
"73.49700","1.91056","-1.84214"
"73.59700","1.94044","-1.85915"
"73.69700","1.97057","-1.89655"
"73.79700","2.00022","-1.93423"
"73.89700","2.03036","-1.94299"
"73.99700","2.06015","-1.96825"
"74.09700","2.09032","-2.00131"
"74.19700","2.12009","-2.02277"
"74.29700","2.15033","-2.04107"
"74.39700","2.18019","-2.08143"
"74.49700","2.21060","-2.12647"
"74.59700","2.24050","-2.14489"
"74.69700","2.27076","-2.15811"
"74.79700","2.30054","-2.19524"
"74.89700","2.33053","-2.21310"
"74.99700","2.36032","-2.25421"
"75.09700","2.39032","-2.28745"
"75.19700","2.42036","-2.32118"
"75.29700","2.45030","-2.32104"
"75.39700","2.48026","-2.35362"
"75.46300","2.50014","-2.37693"
"75.46500","2.50073","-2.37592"
"75.56500","2.50184","-2.38897"
"75.66500","2.47015","-2.33511"
"75.76500","2.43944","-2.30619"
"75.86500","2.40945","-2.26875"
"75.96500","2.37921","-2.27713"
"76.06500","2.34953","-2.23006"
"76.16500","2.31948","-2.20332"
"76.26500","2.28953","-2.18185"
"76.36500","2.25936","-2.15324"
"76.46500","2.22939","-2.11749"
"76.56500","2.19915","-2.09060"
"76.66500","2.16933","-2.06692"
"76.76500","2.13926","-2.01238"
"76.86500","2.10927","-1.99181"
"76.96500","2.07914","-1.98249"
"77.06500","2.04906","-1.93371"
"77.16500","2.01923","-1.89342"
"77.26500","1.98937","-1.87475"
"77.36500","1.95956","-1.84830"
"77.46500","1.92937","-1.82692"
"77.56500","1.89941","-1.77914"
"77.66500","1.86926","-1.77403"
"77.76500","1.83931","-1.71932"
"77.86500","1.80927","-1.71711"
"77.96500","1.77947","-1.68032"
"78.06500","1.74924","-1.64974"
"78.16500","1.71921","-1.62075"
"78.26500","1.68904","-1.58044"
"78.36500","1.65932","-1.57590"
"78.46500","1.62925","-1.52838"
"78.56500","1.59953","-1.47210"
"78.66500","1.56942","-1.42804"
"78.76500","1.53941","-1.41916"
"78.86500","1.50934","-1.37668"
"78.96500","1.47948","-1.33805"
"79.06500","1.44930","-1.31494"
"79.16500","1.41935","-1.29138"
"79.26500","1.38914","-1.24918"
"79.36500","1.35914","-1.22977"
"79.46500","1.32909","-1.20961"
"79.56500","1.29931","-1.18167"
"79.66500","1.26930","-1.13691"
"79.76500","1.23934","-1.13063"
"79.86500","1.20937","-1.11527"
"79.96500","1.17931","-1.06049"
"80.06500","1.14937","-1.04287"
"80.16500","1.11941","-1.02042"
"80.26500","1.08949","-0.98096"
"80.36500","1.05934","-0.93199"
"80.46500","1.02925","-0.92495"
"80.56500","0.99916","-0.88796"
"80.66500","0.96938","-0.85828"
"80.76500","0.93913","-0.83726"
"80.86500","0.90936","-0.81172"
"80.96500","0.87917","-0.77840"
"81.06500","0.84919","-0.74400"
"81.16500","0.81922","-0.72485"
"81.26500","0.78955","-0.69950"
"81.36500","0.75946","-0.66159"
"81.46500","0.72943","-0.65305"
"81.56500","0.69925","-0.62343"
"81.66500","0.66931","-0.58826"
"81.76500","0.63919","-0.54921"
"81.86500","0.60942","-0.51668"
"81.96500","0.57917","-0.50186"
"82.06500","0.54928","-0.46432"
"82.16500","0.51918","-0.44486"
"82.26500","0.48922","-0.41204"
"82.36500","0.45935","-0.27489"
"82.46500","0.42946","-0.29718"
"82.56500","0.39948","-0.29187"
"82.66500","0.36937","-0.27390"
"82.76500","0.33932","-0.22853"
"82.86500","0.30932","-0.21846"
"82.96500","0.27949","-0.19135"
"83.06500","0.24933","-0.16266"
"83.16500","0.21937","-0.12263"
"83.26500","0.18912","-0.09389"
"83.36500","0.15910","-0.07415"
"83.46500","0.12912","-0.02684"
"83.56500","0.09942","-0.02061"
"83.66500","0.06937","0.00593"
"83.76500","0.03946","0.05348"
"83.86500","0.00925","0.08839"
"83.96500","-0.02048","0.10947"
"84.06500","-0.05060","0.14356"
"84.16500","-0.08047","0.18190"
"84.26500","-0.11078","0.20955"
"84.36500","-0.14075","0.22501"
"84.46500","-0.17090","0.26972"
"84.56500","-0.20075","0.29128"
"84.66500","-0.23079","0.33274"
"84.76500","-0.26069","0.35375"
"84.86500","-0.29068","0.38611"
"84.96500","-0.32072","0.41384"
"85.06500","-0.35072","0.42343"
"85.16500","-0.38060","0.47295"
"85.26500","-0.41046","0.49814"
"85.36500","-0.44058","0.53968"
"85.46500","-0.47053","0.56764"
"85.56500","-0.50080","0.60815"
"85.66500","-0.53078","0.64182"
"85.76500","-0.56077","0.65256"
"85.86500","-0.59068","0.68182"
"85.96500","-0.62080","0.71440"
"86.06500","-0.65067","0.73248"
"86.16500","-0.68093","0.76906"
"86.26500","-0.71061","0.83330"
"86.36500","-0.74055","0.84057"
"86.46500","-0.77036","0.87375"
"86.56500","-0.80059","0.90572"
"86.66500","-0.83058","0.94524"
"86.76500","-0.86081","0.95372"
"86.86500","-0.89077","1.01160"
"86.96500","-0.92067","1.05308"
"87.06500","-0.95070","1.07336"
"87.16500","-0.98075","1.09986"
"87.26500","-1.01086","1.13697"
"87.36500","-1.04085","1.17646"
"87.46500","-1.07077","1.20986"
"87.56500","-1.10061","1.22899"
"87.66500","-1.13062","1.26552"
"87.76500","-1.16050","1.27945"
"87.86500","-1.19074","1.31402"
"87.96500","-1.22066","1.34729"
"88.06500","-1.25062","1.36564"
"88.16500","-1.28060","1.41000"
"88.26500","-1.31074","1.42759"
"88.36500","-1.34079","1.48412"
"88.46500","-1.37095","1.51327"
"88.56500","-1.40085","1.52623"
"88.66500","-1.43069","1.57298"
"88.76500","-1.46056","1.59790"
"88.86500","-1.49066","1.62230"
"88.96500","-1.52057","1.65465"
"89.06500","-1.55068","1.70534"
"89.16500","-1.58064","1.73534"
"89.26500","-1.61062","1.75652"
"89.36500","-1.64064","1.78380"
"89.46500","-1.67063","1.81376"
"89.56500","-1.70081","1.83056"
"89.66500","-1.73068","1.89000"
"89.76500","-1.76091","1.95171"
"89.86500","-1.79081","1.95616"
"89.96500","-1.82076","1.97461"
"90.06500","-1.85068","2.02227"
"90.16500","-1.88086","2.05299"
"90.26500","-1.91054","2.06371"
"90.36500","-1.94060","2.09560"
"90.46500","-1.97038","2.14268"
"90.56500","-2.00068","2.17393"
"90.66500","-2.03061","2.18280"
"90.76500","-2.06081","2.22338"
"90.86500","-2.09074","2.24833"
"90.96500","-2.12072","2.27200"
"91.06500","-2.15062","2.30224"
"91.16500","-2.18071","2.33976"
"91.26500","-2.21076","2.36493"
"91.36500","-2.24077","2.38405"
"91.46500","-2.27055","2.40636"
"91.56500","-2.30059","2.44297"
"91.66500","-2.33048","2.45923"
"91.76500","-2.36061","2.48760"
"91.86500","-2.39075","2.53053"
"91.96500","-2.42069","2.55581"
"92.06500","-2.45065","2.57970"
"92.16500","-2.48074","2.61455"
"92.23000","-2.50017","2.60871"
"92.23200","-2.50079","2.61162"
"92.33200","-2.50270","2.62704"
"92.43200","-2.47040","2.58527"
"92.53200","-2.43998","2.55675"
"92.63200","-2.40958","2.53181"
"92.73200","-2.37970","2.52484"
"92.83200","-2.34939","2.47778"
"92.93200","-2.31966","2.44226"
"93.03200","-2.28954","2.44131"
"93.13200","-2.25974","2.38945"
"93.23200","-2.22966","2.37383"
"93.33200","-2.19965","2.33408"
"93.43200","-2.16974","2.31942"
"93.53200","-2.13988","2.27044"
"93.63200","-2.10972","2.25406"
"93.73200","-2.07980","2.21932"
"93.83200","-2.04958","2.18231"
"93.93200","-2.01948","2.14602"
"94.03200","-1.98959","2.14860"
"94.13200","-1.95943","2.09598"
"94.23200","-1.92967","2.05341"
"94.33200","-1.89965","2.05121"
"94.43200","-1.86973","2.02001"
"94.53200","-1.83971","2.00362"
"94.63200","-1.80989","1.96180"
"94.73200","-1.77983","1.95451"
"94.83200","-1.74994","1.92978"
"94.93200","-1.71967","1.83349"
"95.03200","-1.68967","1.79576"
"95.13200","-1.65945","1.76731"
"95.23200","-1.62974","1.73810"
"95.33200","-1.59950","1.71244"
"95.43200","-1.56977","1.68156"
"95.53200","-1.53955","1.65645"
"95.63200","-1.50950","1.61746"
"95.73200","-1.47952","1.58378"
"95.83200","-1.44973","1.56303"
"95.93200","-1.41979","1.51590"
"96.03200","-1.38992","1.50774"
"96.13200","-1.35966","1.47722"
"96.23200","-1.32972","1.46464"
"96.33200","-1.29970","1.39220"
"96.43200","-1.26961","1.37263"
"96.53200","-1.23960","1.34112"
"96.63200","-1.20952","1.31305"
"96.73200","-1.17951","1.26657"
"96.83200","-1.14935","1.24886"
"96.93200","-1.11960","1.21688"
"97.03200","-1.08970","1.17243"
"97.13200","-1.05995","1.15388"
"97.23200","-1.02981","1.11576"
"97.33200","-0.99983","1.08451"
"97.43200","-0.96972","1.05120"
"97.53200","-0.93980","1.04926"
"97.63200","-0.90959","0.98948"
"97.73200","-0.87962","0.97186"
"97.83200","-0.84958","0.93187"
"97.93200","-0.81958","0.90173"
"98.03200","-0.78942","0.86507"
"98.13200","-0.75957","0.82767"
"98.23200","-0.72962","0.81789"
"98.33200","-0.69969","0.74851"
"98.43200","-0.66966","0.72045"
"98.53200","-0.63980","0.68053"
"98.63200","-0.60979","0.66368"
"98.73200","-0.57985","0.63118"
"98.83200","-0.54976","0.59933"
"98.93200","-0.51963","0.56863"
"99.03200","-0.48951","0.54780"
"99.13200","-0.45938","0.49084"
"99.23200","-0.42948","0.47015"
"99.33200","-0.39955","0.45834"
"99.43200","-0.36972","0.41522"
"99.53200","-0.33961","0.39629"
"99.63200","-0.30968","0.36590"
"99.73200","-0.27965","0.34052"
"99.83200","-0.24987","0.29552"
"99.93200","-0.21973","0.27006"
"100.03200","-0.18988","0.23581"
"100.13200","-0.15952","0.19695"
"100.23200","-0.12973","0.16083"
"100.33200","-0.09954","0.14852"
"100.43200","-0.06966","0.10261"
"100.53200","-0.03958","0.07838"
"100.63200","-0.00962","0.03977"
"100.73200","0.02058","0.02700"
"100.83200","0.05044","-0.02045"
"100.93200","0.08041","-0.04822"
"101.03200","0.11015","-0.05263"
"101.13200","0.14010","-0.08706"
"101.23200","0.17017","-0.10600"
"101.33200","0.20026","-0.16156"
"101.43200","0.23042","-0.15957"
"101.53200","0.26040","-0.21761"
"101.63200","0.29043","-0.24399"
"101.73200","0.32038","-0.27176"
"101.83200","0.35051","-0.29307"
"101.93200","0.38045","-0.32458"
"102.03200","0.41049","-0.32723"
"102.13200","0.44031","-0.31192"
"102.23200","0.47032","-0.43793"
"102.33200","0.50013","-0.47175"
"102.43200","0.53040","-0.47927"
"102.53200","0.56017","-0.51447"
"102.63200","0.59025","-0.55370"
"102.73200","0.62020","-0.56808"
"102.83200","0.65031","-0.60575"
"102.93200","0.68028","-0.63602"
"103.03200","0.71059","-0.68834"
"103.13200","0.74036","-0.69208"
"103.23200","0.77055","-0.71571"
"103.33200","0.80035","-0.75267"
"103.43200","0.83034","-0.78805"
"103.53200","0.86023","-0.81958"
"103.63200","0.89024","-0.84278"
"103.73200","0.92018","-0.88278"
"103.83200","0.95017","-0.88244"
"103.93200","0.98028","-0.92055"
"104.03200","1.01027","-0.94380"
"104.13200","1.04049","-0.98800"
"104.23200","1.07050","-1.00933"
"104.33200","1.10042","-1.03605"
"104.43200","1.13036","-1.06567"
"104.53200","1.16041","-1.09086"
"104.63200","1.19020","-1.10493"
"104.73200","1.22057","-1.17027"
"104.83200","1.25021","-1.17798"
"104.93200","1.28031","-1.20321"
"105.03200","1.31011","-1.22687"
"105.13200","1.34020","-1.27218"
"105.23200","1.37016","-1.30344"
"105.33200","1.40040","-1.31057"
"105.43200","1.43028","-1.36584"
"105.53200","1.46048","-1.38145"
"105.63200","1.49034","-1.41753"
"105.73200","1.52052","-1.44186"
"105.83200","1.55044","-1.47461"
"105.93200","1.58060","-1.49611"
"106.03200","1.61034","-1.55526"
"106.13200","1.64020","-1.58815"
"106.23200","1.67015","-1.61364"
"106.33200","1.70012","-1.63599"
"106.43200","1.73034","-1.65977"
"106.53200","1.76039","-1.70866"
"106.63200","1.79029","-1.72520"
"106.73200","1.82041","-1.75834"
"106.83200","1.85034","-1.79073"
"106.93200","1.88027","-1.82831"
"107.03200","1.91052","-1.83512"
"107.13200","1.94044","-1.87448"
"107.23200","1.97054","-1.90585"
"107.33200","2.00017","-1.93062"
"107.43200","2.03033","-1.93630"
"107.53200","2.06013","-1.99702"
"107.63200","2.09024","-2.00481"
"107.73200","2.12000","-2.01767"
"107.83200","2.15033","-2.06825"
"107.93200","2.18021","-2.09994"
"108.03200","2.21049","-2.13458"
"108.13200","2.24050","-2.14656"
"108.23200","2.27070","-2.19126"
"108.33200","2.30051","-2.19529"
"108.43200","2.33048","-2.23481"
"108.53200","2.36029","-2.27112"
"108.63200","2.39023","-2.30543"
"108.73200","2.42035","-2.32990"
"108.83200","2.45027","-2.34543"
"108.93200","2.48023","-2.39243"
"108.99800","2.50010","-2.40366"
"109.00000","2.50070","-2.40585"
"109.10000","2.50163","-2.41080"
"109.20000","2.47018","-2.37634"
"109.30000","2.43943","-2.33568"
"109.40000","2.40950","-2.32249"
"109.50000","2.37922","-2.29508"
"109.60000","2.34954","-2.25521"
"109.70000","2.31948","-2.21042"
"109.80000","2.28955","-2.19175"
"109.90000","2.25938","-2.15064"
"110.00000","2.22941","-2.12873"
"110.10000","2.19918","-2.10595"
"110.20000","2.16936","-2.06983"
"110.30000","2.13924","-2.02058"
"110.40000","2.10928","-1.99601"
"110.50000","2.07915","-1.99439"
"110.60000","2.04908","-1.93217"
"110.70000","2.01924","-1.90942"
"110.80000","1.98940","-1.87948"
"110.90000","1.95958","-1.86706"
"111.00000","1.92944","-1.82875"
"111.10000","1.89938","-1.80297"
"111.20000","1.86925","-1.78738"
"111.30000","1.83932","-1.73454"
"111.40000","1.80934","-1.70801"
"111.50000","1.77949","-1.68136"
"111.60000","1.74928","-1.65521"
"111.70000","1.71924","-1.62681"
"111.80000","1.68907","-1.60192"
"111.90000","1.65933","-1.57345"
"112.00000","1.62927","-1.53322"
"112.10000","1.59953","-1.48302"
"112.20000","1.56947","-1.45259"
"112.30000","1.53944","-1.42442"
"112.40000","1.50935","-1.40205"
"112.50000","1.47951","-1.36194"
"112.60000","1.44932","-1.34639"
"112.70000","1.41936","-1.29934"
"112.80000","1.38917","-1.26749"
"112.90000","1.35915","-1.24983"
"113.00000","1.32909","-1.21510"
"113.10000","1.29933","-1.17760"
"113.20000","1.26934","-1.15073"
"113.30000","1.23932","-1.13948"
"113.40000","1.20938","-1.08248"
"113.50000","1.17938","-1.06228"
"113.60000","1.14933","-1.05147"
"113.70000","1.11942","-1.02686"
"113.80000","1.08948","-0.98792"
"113.90000","1.05935","-0.94790"
"114.00000","1.02927","-0.93296"
"114.10000","0.99918","-0.89445"
"114.20000","0.96938","-0.86710"
"114.30000","0.93917","-0.85054"
"114.40000","0.90935","-0.82393"
"114.50000","0.87922","-0.78080"
"114.60000","0.84922","-0.75665"
"114.70000","0.81927","-0.73145"
"114.80000","0.78957","-0.70629"
"114.90000","0.75944","-0.65848"
"115.00000","0.72947","-0.65217"
"115.10000","0.69928","-0.61548"
"115.20000","0.66932","-0.58006"
"115.30000","0.63920","-0.54691"
"115.40000","0.60943","-0.52817"
"115.50000","0.57920","-0.49199"
"115.60000","0.54926","-0.47090"
"115.70000","0.51918","-0.45863"
"115.80000","0.48925","-0.42455"
"115.90000","0.45937","-0.28924"
"116.00000","0.42947","-0.30536"
"116.10000","0.39951","-0.31059"
"116.20000","0.36936","-0.27118"
"116.30000","0.33936","-0.23961"
"116.40000","0.30934","-0.22239"
"116.50000","0.27952","-0.18359"
"116.60000","0.24928","-0.14374"
"116.70000","0.21945","-0.13895"
"116.80000","0.18913","-0.09178"
"116.90000","0.15915","-0.06119"
"117.00000","0.12915","-0.03321"
"117.10000","0.09944","-0.02302"
"117.20000","0.06935","0.00496"
"117.30000","0.03955","0.05972"
"117.40000","0.00930","0.07267"
"117.50000","-0.02043","0.10965"
"117.60000","-0.05057","0.13936"
"117.70000","-0.08045","0.17797"
"117.80000","-0.11077","0.19688"
"117.90000","-0.14072","0.22719"
"118.00000","-0.17088","0.27616"
"118.10000","-0.20080","0.29836"
"118.20000","-0.23076","0.33240"
"118.30000","-0.26067","0.37292"
"118.40000","-0.29066","0.39820"
"118.50000","-0.32070","0.41884"
"118.60000","-0.35071","0.45210"
"118.70000","-0.38063","0.48096"
"118.80000","-0.41044","0.49324"
"118.90000","-0.44055","0.51585"
"119.00000","-0.47052","0.56816"
"119.10000","-0.50081","0.60754"
"119.20000","-0.53073","0.62108"
"119.30000","-0.56074","0.64528"
"119.40000","-0.59066","0.68101"
"119.50000","-0.62079","0.70017"
"119.60000","-0.65064","0.74491"
"119.70000","-0.68092","0.78127"
"119.80000","-0.71058","0.83994"
"119.90000","-0.74054","0.85351"
"120.00000","-0.77036","0.88545"
"120.10000","-0.80053","0.92846"
"120.20000","-0.83062","0.95591"
"120.30000","-0.86083","0.98610"
"120.40000","-0.89075","1.01769"
"120.50000","-0.92067","1.06572"
"120.60000","-0.95067","1.06882"
"120.70000","-0.98074","1.10842"
"120.80000","-1.01083","1.12990"
"120.90000","-1.04084","1.15669"
"121.00000","-1.07073","1.20153"
"121.10000","-1.10060","1.23387"
"121.20000","-1.13061","1.26125"
"121.30000","-1.16050","1.26947"
"121.40000","-1.19070","1.32332"
"121.50000","-1.22062","1.35185"
"121.60000","-1.25062","1.38378"
"121.70000","-1.28053","1.40908"
"121.80000","-1.31066","1.45671"
"121.90000","-1.34075","1.48310"
"122.00000","-1.37097","1.50570"
"122.10000","-1.40084","1.54285"
"122.20000","-1.43069","1.56896"
"122.30000","-1.46054","1.59078"
"122.40000","-1.49064","1.60845"
"122.50000","-1.52055","1.64506"
"122.60000","-1.55065","1.67858"
"122.70000","-1.58064","1.71545"
"122.80000","-1.61058","1.73764"
"122.90000","-1.64063","1.78195"
"123.00000","-1.67061","1.79007"
"123.10000","-1.70078","1.82683"
"123.20000","-1.73078","1.89319"
"123.30000","-1.76081","1.95572"
"123.40000","-1.79083","1.95648"
"123.50000","-1.82076","1.99702"
"123.60000","-1.85064","2.03209"
"123.70000","-1.88084","2.03403"
"123.80000","-1.91048","2.06377"
"123.90000","-1.94060","2.09178"
"124.00000","-1.97037","2.12302"
"124.10000","-2.00064","2.14500"
"124.20000","-2.03062","2.18460"
"124.30000","-2.06078","2.19919"
"124.40000","-2.09072","2.22394"
"124.50000","-2.12070","2.25589"
"124.60000","-2.15065","2.30398"
"124.70000","-2.18057","2.33008"
"124.80000","-2.21075","2.35243"
"124.90000","-2.24078","2.40238"
"125.00000","-2.27052","2.40147"
"125.10000","-2.30053","2.43780"
"125.20000","-2.33048","2.45442"
"125.30000","-2.36059","2.50491"
"125.40000","-2.39075","2.52076"
"125.50000","-2.42063","2.54825"
"125.60000","-2.45063","2.56978"
"125.70000","-2.48072","2.60979"
"125.76500","-2.50016","2.63952"
"125.76700","-2.50078","2.63946"
"125.86700","-2.50266","2.61671"
"125.96700","-2.47037","2.57744"
"126.06700","-2.43999","2.56634"
"126.16700","-2.40957","2.53481"
"126.26700","-2.37970","2.49781"
"126.36700","-2.34938","2.45319"
"126.46700","-2.31969","2.44186"
"126.56700","-2.28953","2.40965"
"126.66700","-2.25977","2.38404"
"126.76700","-2.22966","2.35885"
"126.86700","-2.19968","2.33143"
"126.96700","-2.16974","2.29680"
"127.06700","-2.13988","2.28316"
"127.16700","-2.10973","2.26661"
"127.26700","-2.07979","2.21005"
"127.36700","-2.04959","2.19003"
"127.46700","-2.01950","2.16860"
"127.56700","-1.98956","2.14233"
"127.66700","-1.95946","2.07943"
"127.76700","-1.92967","2.07024"
"127.86700","-1.89959","2.03485"
"127.96700","-1.86975","2.00182"
"128.06700","-1.83973","1.97485"
"128.16700","-1.80984","1.95600"
"128.26700","-1.77984","1.92492"
"128.36700","-1.74994","1.89716"
"128.46700","-1.71968","1.82623"
"128.56700","-1.68968","1.79070"
"128.66700","-1.65944","1.76097"
"128.76700","-1.62974","1.72737"
"128.86700","-1.59948","1.72297"
"128.96700","-1.56979","1.68533"
"129.06700","-1.53956","1.65458"
"129.16700","-1.50952","1.60320"
"129.26700","-1.47954","1.58234"
"129.36700","-1.44974","1.54169"
"129.46700","-1.41981","1.52431"
"129.56700","-1.38988","1.50501"
"129.66700","-1.35970","1.47121"
"129.76700","-1.32973","1.41699"
"129.86700","-1.29968","1.38053"
"129.96700","-1.26961","1.37045"
"130.06700","-1.23960","1.31817"
"130.16700","-1.20953","1.29912"
"130.26700","-1.17949","1.27575"
"130.36700","-1.14936","1.25864"
"130.46700","-1.11959","1.20947"
"130.56700","-1.08971","1.19226"
"130.66700","-1.05993","1.16249"
"130.76700","-1.02981","1.12534"
"130.86700","-0.99982","1.08492"
"130.96700","-0.96974","1.07445"
"131.06700","-0.93979","1.03391"
"131.16700","-0.90955","0.98536"
"131.26700","-0.87972","0.97172"
"131.36700","-0.84958","0.91069"
"131.46700","-0.81960","0.88129"
"131.56700","-0.78944","0.84719"
"131.66700","-0.75960","0.83097"
"131.76700","-0.72961","0.80531"
"131.86700","-0.69969","0.74982"
"131.96700","-0.66966","0.71531"
"132.06700","-0.63981","0.69671"
"132.16700","-0.60980","0.67814"
"132.26700","-0.57985","0.64600"
"132.36700","-0.54976","0.61230"
"132.46700","-0.51964","0.58355"
"132.56700","-0.48953","0.53518"
"132.66700","-0.45939","0.50762"
"132.76700","-0.42948","0.48955"
"132.86700","-0.39954","0.44034"
"132.96700","-0.36971","0.40712"
"133.06700","-0.33964","0.38746"
"133.16700","-0.30968","0.36348"
"133.26700","-0.27965","0.30867"
"133.36700","-0.24989","0.31653"
"133.46700","-0.21973","0.25416"
"133.56700","-0.18989","0.23615"
"133.66700","-0.15953","0.22076"
"133.76700","-0.12973","0.18573"
"133.86700","-0.09955","0.15822"
"133.96700","-0.06969","0.12066"
"134.06700","-0.03958","0.10325"
"134.16700","-0.00964","0.06062"
"134.20000","0.00002","0.02547"