File: SupLinearAndTan/Tan_Fan_Chart/Specimen_RawData_2.csv
Time,Extension,Load
(s),(mm),(N)
"0.00000","0.00000","0.06029"
"0.10000","0.00838","0.08382"
"0.20000","0.04162","0.10016"
"0.30000","0.07205","0.13778"
"0.40000","0.10223","0.15641"
"0.50000","0.13214","0.20879"
"0.60000","0.16239","0.22395"
"0.70000","0.19235","0.25906"
"0.80000","0.22255","0.28656"
"0.90000","0.25235","0.33354"
"1.00000","0.28243","0.35159"
"1.10000","0.31213","0.37220"
"1.20000","0.34229","0.43018"
"1.30000","0.37216","0.44832"
"1.40000","0.40228","0.47738"
"1.50000","0.43205","0.50532"
"1.60000","0.46222","0.53744"
"1.70000","0.49209","0.55092"
"1.80000","0.52232","0.57030"
"1.90000","0.55226","0.61216"
"2.00000","0.58236","0.63228"
"2.10000","0.61229","0.67096"
"2.20000","0.64232","0.70314"
"2.30000","0.67235","0.74758"
"2.40000","0.70240","0.76642"
"2.50000","0.73235","0.80142"
"2.60000","0.76217","0.84444"
"2.70000","0.79213","0.88203"
"2.80000","0.82196","0.90932"
"2.90000","0.85212","0.92866"
"3.00000","0.88226","0.97149"
"3.10000","0.91238","0.99083"
"3.20000","0.94228","1.01239"
"3.30000","0.97240","1.04192"
"3.40000","1.00222","1.07727"
"3.50000","1.03243","1.08118"
"3.60000","1.06230","1.13208"
"3.70000","1.09235","1.15588"
"3.80000","1.12217","1.19124"
"3.90000","1.15228","1.20780"
"4.00000","1.18203","1.25893"
"4.10000","1.21232","1.29583"
"4.20000","1.24211","1.31180"
"4.30000","1.27216","1.34488"
"4.40000","1.30215","1.37736"
"4.50000","1.33220","1.40362"
"4.60000","1.36240","1.41901"
"4.70000","1.39250","1.46343"
"4.80000","1.42239","1.49086"
"4.90000","1.45244","1.51797"
"5.00000","1.48226","1.54951"
"5.10000","1.51217","1.59500"
"5.20000","1.54215","1.60586"
"5.30000","1.57210","1.63910"
"5.40000","1.60214","1.68530"
"5.50000","1.63208","1.69831"
"5.60000","1.66223","1.72553"
"5.70000","1.69215","1.76305"
"5.80000","1.72239","1.80657"
"5.90000","1.75228","1.81882"
"6.00000","1.78245","1.86573"
"6.10000","1.81226","1.89322"
"6.20000","1.84227","1.93056"
"6.30000","1.87206","1.93543"
"6.40000","1.90250","1.98622"
"6.50000","1.93218","2.01300"
"6.60000","1.96221","2.03050"
"6.70000","1.99203","2.05385"
"6.80000","2.02207","2.09276"
"6.90000","2.05217","2.12012"
"7.00000","2.08235","2.12834"
"7.10000","2.11228","2.17710"
"7.20000","2.14238","2.20590"
"7.30000","2.17216","2.23737"
"7.40000","2.20240","2.25899"
"7.50000","2.23228","2.30765"
"7.60000","2.26242","2.33723"
"7.70000","2.29231","2.36797"
"7.80000","2.32206","2.41290"
"7.90000","2.35217","2.44407"
"8.00000","2.38205","2.46356"
"8.10000","2.41232","2.48961"
"8.20000","2.44224","2.52672"
"8.30000","2.47231","2.55326"
"8.39300","2.50011","2.57083"
"8.39500","2.50070","2.57018"
"8.49500","2.50146","2.57333"
"8.59500","2.47007","2.57000"
"8.69500","2.43938","2.51236"
"8.79500","2.40941","2.48319"
"8.89500","2.37911","2.45419"
"8.99500","2.34945","2.43042"
"9.09500","2.31938","2.38369"
"9.19500","2.28947","2.36957"
"9.29500","2.25931","2.33544"
"9.39500","2.22930","2.30148"
"9.49500","2.19910","2.27865"
"9.59500","2.16926","2.25802"
"9.69500","2.13918","2.22710"
"9.79500","2.10915","2.18582"
"9.89500","2.07908","2.16269"
"9.99500","2.04899","2.13283"
"10.09500","2.01914","2.09227"
"10.19500","1.98930","2.05752"
"10.29500","1.95945","2.03071"
"10.39500","1.92932","2.00326"
"10.49500","1.89932","1.96964"
"10.59500","1.86921","1.94621"
"10.69500","1.83918","1.92122"
"10.79500","1.80921","1.88124"
"10.89500","1.77938","1.85233"
"10.99500","1.74918","1.83560"
"11.09500","1.71913","1.80650"
"11.19500","1.68898","1.76920"
"11.29500","1.65925","1.73367"
"11.39500","1.62917","1.71773"
"11.49500","1.59941","1.67898"
"11.59500","1.56936","1.64518"
"11.69500","1.53934","1.61376"
"11.79500","1.50926","1.57575"
"11.89500","1.47942","1.53784"
"11.99500","1.44923","1.52193"
"12.09500","1.41926","1.48951"
"12.19500","1.38910","1.44693"
"12.29500","1.35908","1.42005"
"12.39500","1.32899","1.40557"
"12.49500","1.29922","1.37478"
"12.59500","1.26922","1.32971"
"12.69500","1.23923","1.30813"
"12.79500","1.20931","1.27688"
"12.89500","1.17920","1.24730"
"12.99500","1.14934","1.21229"
"13.09500","1.11933","1.19549"
"13.19500","1.08936","1.16534"
"13.29500","1.05925","1.13287"
"13.39500","1.02918","1.10194"
"13.49500","0.99909","1.07237"
"13.59500","0.96930","1.03945"
"13.69500","0.93909","1.00269"
"13.79500","0.90923","0.99530"
"13.89500","0.87910","0.95174"
"13.99500","0.84912","0.91062"
"14.09500","0.81915","0.87646"
"14.19500","0.78946","0.86333"
"14.29500","0.75937","0.81344"
"14.39500","0.72941","0.78996"
"14.49500","0.69917","0.76907"
"14.59500","0.66923","0.74163"
"14.69500","0.63910","0.70540"
"14.79500","0.60935","0.68652"
"14.89500","0.57911","0.66779"
"14.99500","0.54924","0.60848"
"15.09500","0.51905","0.59067"
"15.19500","0.48912","0.56074"
"15.29500","0.45924","0.54078"
"15.39500","0.42938","0.48606"
"15.49500","0.39940","0.45733"
"15.59500","0.36925","0.42829"
"15.69500","0.33925","0.39288"
"15.79500","0.30925","0.35924"
"15.89500","0.27948","0.34143"
"15.99500","0.24919","0.31015"
"16.09500","0.21929","0.27335"
"16.19500","0.18908","0.26814"
"16.29500","0.15905","0.23183"
"16.39500","0.12904","0.20915"
"16.49500","0.09932","0.17348"
"16.59500","0.06924","0.15658"
"16.69500","0.03943","0.11368"
"16.79500","0.00917","0.08353"
"16.89500","-0.02050","0.05241"
"16.99500","-0.05066","0.03739"
"17.09500","-0.08053","-0.00841"
"17.19500","-0.11083","-0.04527"
"17.29500","-0.14080","-0.06880"
"17.39500","-0.17097","-0.09735"
"17.49500","-0.20086","-0.13547"
"17.59500","-0.23088","-0.15363"
"17.69500","-0.26075","-0.16861"
"17.79500","-0.29078","-0.21950"
"17.89500","-0.32078","-0.23034"
"17.99500","-0.35082","-0.27139"
"18.09500","-0.38071","-0.30250"
"18.19500","-0.41053","-0.33561"
"18.29500","-0.44067","-0.34972"
"18.39500","-0.47060","-0.39455"
"18.49500","-0.50088","-0.42956"
"18.59500","-0.53085","-0.45986"
"18.69500","-0.56084","-0.48935"
"18.79500","-0.59074","-0.51264"
"18.89500","-0.62087","-0.55712"
"18.99500","-0.65079","-0.58558"
"19.09500","-0.68102","-0.61649"
"19.19500","-0.71068","-0.64140"
"19.29500","-0.74063","-0.68716"
"19.39500","-0.77042","-0.68743"
"19.49500","-0.80067","-0.73324"
"19.59500","-0.83069","-0.75672"
"19.69500","-0.86088","-0.78191"
"19.79500","-0.89085","-0.79932"
"19.89500","-0.92079","-0.84015"
"19.99500","-0.95073","-0.87570"
"20.09500","-0.98084","-0.88436"
"20.19500","-1.01093","-0.93241"
"20.29500","-1.04094","-0.95870"
"20.39500","-1.07087","-0.98147"
"20.49500","-1.10070","-1.01366"
"20.59500","-1.13068","-1.07195"
"20.69500","-1.16057","-1.08196"
"20.79500","-1.19083","-1.10583"
"20.89500","-1.22073","-1.13881"
"20.99500","-1.25071","-1.17495"
"21.09500","-1.28064","-1.19719"
"21.19500","-1.31086","-1.21508"
"21.29500","-1.34079","-1.25864"
"21.39500","-1.37103","-1.27742"
"21.49500","-1.40093","-1.30497"
"21.59500","-1.43078","-1.33446"
"21.69500","-1.46065","-1.37556"
"21.79500","-1.49073","-1.39799"
"21.89500","-1.52067","-1.44321"
"21.99500","-1.55078","-1.46564"
"22.09500","-1.58072","-1.50509"
"22.19500","-1.61070","-1.53322"
"22.29500","-1.64066","-1.56691"
"22.39500","-1.67076","-1.60929"
"22.49500","-1.70091","-1.62916"
"22.59500","-1.73087","-1.64602"
"22.69500","-1.76089","-1.67953"
"22.79500","-1.79092","-1.71265"
"22.89500","-1.82088","-1.72722"
"22.99500","-1.85073","-1.75936"
"23.09500","-1.88092","-1.80569"
"23.19500","-1.91063","-1.82869"
"23.29500","-1.94064","-1.84338"
"23.39500","-1.97052","-1.90057"
"23.49500","-2.00072","-1.91900"
"23.59500","-2.03067","-1.93536"
"23.69500","-2.06089","-1.96948"
"23.79500","-2.09069","-2.00442"
"23.89500","-2.12088","-2.03704"
"23.99500","-2.15074","-2.06119"
"24.09500","-2.18081","-2.10347"
"24.19500","-2.21084","-2.11467"
"24.29500","-2.24089","-2.14915"
"24.39500","-2.27061","-2.19025"
"24.49500","-2.30056","-2.21474"
"24.59500","-2.33059","-2.23435"
"24.69500","-2.36068","-2.26948"
"24.79500","-2.39084","-2.30422"
"24.89500","-2.42076","-2.33364"
"24.99500","-2.45070","-2.35761"
"25.09500","-2.48077","-2.38284"
"25.16000","-2.50026","-2.40206"
"25.16200","-2.50088","-2.40149"
"25.26200","-2.50272","-2.42480"
"25.36200","-2.47039","-2.39090"
"25.46200","-2.44004","-2.34560"
"25.56200","-2.40966","-2.32179"
"25.66200","-2.37974","-2.29166"
"25.76200","-2.34941","-2.26207"
"25.86200","-2.31970","-2.22650"
"25.96200","-2.28954","-2.20900"
"26.06200","-2.25979","-2.17645"
"26.16200","-2.22970","-2.14107"
"26.26200","-2.19969","-2.11403"
"26.36200","-2.16975","-2.08779"
"26.46200","-2.13991","-2.04458"
"26.56200","-2.10975","-2.01924"
"26.66200","-2.07984","-1.99914"
"26.76200","-2.04964","-1.96445"
"26.86200","-2.01959","-1.91581"
"26.96200","-1.98956","-1.90451"
"27.06200","-1.95951","-1.88066"
"27.16200","-1.92969","-1.84099"
"27.26200","-1.89966","-1.79976"
"27.36200","-1.86979","-1.78593"
"27.46200","-1.83971","-1.74847"
"27.56200","-1.80994","-1.70914"
"27.66200","-1.77987","-1.69455"
"27.76200","-1.74995","-1.66534"
"27.86200","-1.71970","-1.64032"
"27.96200","-1.68975","-1.61212"
"28.06200","-1.65952","-1.59653"
"28.16200","-1.62976","-1.55044"
"28.26200","-1.59955","-1.51434"
"28.36200","-1.56980","-1.48747"
"28.46200","-1.53961","-1.46325"
"28.56200","-1.50957","-1.42256"
"28.66200","-1.47957","-1.38534"
"28.76200","-1.44978","-1.36036"
"28.86200","-1.41978","-1.32735"
"28.96200","-1.38998","-1.29043"
"29.06200","-1.35983","-1.26834"
"29.16200","-1.32977","-1.25320"
"29.26200","-1.29965","-1.21296"
"29.36200","-1.26964","-1.19179"
"29.46200","-1.23964","-1.15183"
"29.56200","-1.20955","-1.13834"
"29.66200","-1.17954","-1.08832"
"29.76200","-1.14940","-1.07140"
"29.86200","-1.11965","-1.04250"
"29.96200","-1.08973","-0.99897"
"30.06200","-1.05996","-0.96188"
"30.16200","-1.02983","-0.94024"
"30.26200","-0.99985","-0.90652"
"30.36200","-0.96968","-0.87757"
"30.46200","-0.93983","-0.85499"
"30.56200","-0.90968","-0.82848"
"30.66200","-0.87979","-0.79883"
"30.76200","-0.84956","-0.76991"
"30.86200","-0.81964","-0.75747"
"30.96200","-0.78945","-0.71897"
"31.06200","-0.75963","-0.68349"
"31.16200","-0.72967","-0.65598"
"31.26200","-0.69976","-0.64005"
"31.36200","-0.66972","-0.58908"
"31.46200","-0.63983","-0.54942"
"31.56200","-0.60981","-0.52435"
"31.66200","-0.57986","-0.48825"
"31.76200","-0.54979","-0.46878"
"31.86200","-0.51964","-0.44686"
"31.96200","-0.48957","-0.41763"
"32.06200","-0.45943","-0.36355"
"32.16200","-0.42952","-0.35087"
"32.26200","-0.39956","-0.32736"
"32.36200","-0.36976","-0.29632"
"32.46200","-0.33964","-0.26311"
"32.56200","-0.30972","-0.23390"
"32.66200","-0.27968","-0.19798"
"32.76200","-0.24991","-0.16045"
"32.86200","-0.21976","-0.14133"
"32.96200","-0.18993","-0.11765"
"33.06200","-0.15956","-0.08342"
"33.16200","-0.12976","-0.03290"
"33.26200","-0.09957","-0.02720"
"33.36200","-0.06971","0.01344"
"33.46200","-0.03963","0.04634"
"33.56200","-0.00967","0.06887"
"33.66200","0.02049","0.08602"
"33.76200","0.05037","0.12283"
"33.86200","0.08035","0.15818"
"33.96200","0.11011","0.18386"
"34.06200","0.14006","0.20462"
"34.16200","0.17013","0.24888"
"34.26200","0.20024","0.27578"
"34.36200","0.23035","0.29549"
"34.46200","0.26038","0.32839"
"34.56200","0.29037","0.35988"
"34.66200","0.32033","0.39669"
"34.76200","0.35045","0.42332"
"34.86200","0.38042","0.46555"
"34.96200","0.41040","0.48452"
"35.06200","0.44030","0.52809"
"35.16200","0.47032","0.54425"
"35.26200","0.50008","0.57989"
"35.36200","0.53032","0.60361"
"35.46200","0.56013","0.62939"
"35.56200","0.59021","0.67213"
"35.66200","0.62014","0.68878"
"35.76200","0.65028","0.71009"
"35.86200","0.68026","0.74167"
"35.96200","0.71055","0.77415"
"36.06200","0.74033","0.80054"
"36.16200","0.77052","0.83285"
"36.26200","0.80028","0.87289"
"36.36200","0.83025","0.90998"
"36.46200","0.86017","0.94034"
"36.56200","0.89023","0.98308"
"36.66200","0.92013","1.01331"
"36.76200","0.95013","1.02143"
"36.86200","0.98021","1.06347"
"36.96200","1.01023","1.08184"
"37.06200","1.04045","1.11343"
"37.16200","1.07044","1.12993"
"37.26200","1.10038","1.18071"
"37.36200","1.13033","1.20084"
"37.46200","1.16039","1.21738"
"37.56200","1.19017","1.24818"
"37.66200","1.22056","1.29136"
"37.76200","1.25012","1.32444"
"37.86200","1.28021","1.34865"
"37.96200","1.31000","1.39026"
"38.06200","1.34016","1.40967"
"38.16200","1.37019","1.44492"
"38.26200","1.40040","1.47340"
"38.36200","1.43025","1.52133"
"38.46200","1.46048","1.53834"
"38.56200","1.49029","1.56084"
"38.66200","1.52052","1.60023"
"38.76200","1.55039","1.62487"
"38.86200","1.58054","1.64762"
"38.96200","1.61031","1.67805"
"39.06200","1.64018","1.71033"
"39.16200","1.67012","1.72985"
"39.26200","1.70007","1.77028"
"39.36200","1.73030","1.80505"
"39.46200","1.76038","1.84232"
"39.56200","1.79031","1.84648"
"39.66200","1.82030","1.89540"
"39.76200","1.85024","1.93927"
"39.86200","1.88023","1.96495"
"39.96200","1.91054","1.99619"
"40.06200","1.94040","2.02150"
"40.16200","1.97050","2.04756"
"40.26200","2.00014","2.08058"
"40.36200","2.03027","2.11055"
"40.46200","2.06009","2.14300"
"40.56200","2.09027","2.16828"
"40.66200","2.12003","2.18191"
"40.76200","2.15023","2.22200"
"40.86200","2.18009","2.24518"
"40.96200","2.21039","2.27385"
"41.06200","2.24042","2.30134"
"41.16200","2.27075","2.34157"
"41.26200","2.30041","2.36349"
"41.36200","2.33052","2.40168"
"41.46200","2.36027","2.44496"
"41.56200","2.39025","2.48347"
"41.66200","2.42029","2.50130"
"41.76200","2.45021","2.53911"
"41.86200","2.48020","2.58863"
"41.92800","2.50004","2.58488"
"41.93000","2.50064","2.58817"
"42.03000","2.50147","2.59047"
"42.13000","2.47008","2.56095"
"42.23000","2.43936","2.53674"
"42.33000","2.40938","2.51877"
"42.43000","2.37913","2.45475"
"42.53000","2.34944","2.43006"
"42.63000","2.31935","2.39722"
"42.73000","2.28945","2.36456"
"42.83000","2.25929","2.32552"
"42.93000","2.22930","2.29850"
"43.03000","2.19907","2.26943"
"43.13000","2.16927","2.22285"
"43.23000","2.13914","2.21474"
"43.33000","2.10917","2.18737"
"43.43000","2.07907","2.15022"
"43.53000","2.04897","2.13110"
"43.63000","2.01911","2.11139"
"43.73000","1.98929","2.08378"
"43.83000","1.95945","2.04028"
"43.93000","1.92930","2.01405"
"44.03000","1.89930","1.99563"
"44.13000","1.86916","1.95120"
"44.23000","1.83926","1.92406"
"44.33000","1.80920","1.89641"
"44.43000","1.77936","1.85930"
"44.53000","1.74915","1.82403"
"44.63000","1.71912","1.78070"
"44.73000","1.68895","1.76932"
"44.83000","1.65924","1.72351"
"44.93000","1.62916","1.70060"
"45.03000","1.59940","1.67378"
"45.13000","1.56934","1.63971"
"45.23000","1.53932","1.60323"
"45.33000","1.50926","1.58921"
"45.43000","1.47943","1.56606"
"45.53000","1.44922","1.52480"
"45.63000","1.41925","1.48965"
"45.73000","1.38908","1.47429"
"45.83000","1.35907","1.44123"
"45.93000","1.32900","1.40107"
"46.03000","1.29919","1.38032"
"46.13000","1.26920","1.34623"
"46.23000","1.23921","1.30863"
"46.33000","1.20929","1.26898"
"46.43000","1.17920","1.25165"
"46.53000","1.14932","1.21292"
"46.63000","1.11932","1.17603"
"46.73000","1.08936","1.15467"
"46.83000","1.05922","1.12630"
"46.93000","1.02917","1.11058"
"47.03000","0.99907","1.07060"
"47.13000","0.96927","1.05105"
"47.23000","0.93909","1.02302"
"47.33000","0.90925","0.98836"
"47.43000","0.87905","0.96435"
"47.53000","0.84911","0.93786"
"47.63000","0.81911","0.88429"
"47.73000","0.78947","0.85251"
"47.83000","0.75937","0.82744"
"47.93000","0.72934","0.80609"
"48.03000","0.69923","0.75256"
"48.13000","0.66920","0.72464"
"48.23000","0.63909","0.71455"
"48.33000","0.60931","0.67056"
"48.43000","0.57911","0.63906"
"48.53000","0.54916","0.61480"
"48.63000","0.51912","0.58892"
"48.73000","0.48907","0.55621"
"48.83000","0.45924","0.55212"
"48.93000","0.42937","0.50360"
"49.03000","0.39939","0.46783"
"49.13000","0.36925","0.43089"
"49.23000","0.33924","0.41192"
"49.33000","0.30923","0.38002"
"49.43000","0.27943","0.34629"
"49.53000","0.24923","0.32113"
"49.63000","0.21930","0.28294"
"49.73000","0.18907","0.26026"
"49.83000","0.15902","0.21347"
"49.93000","0.12902","0.20438"
"50.03000","0.09933","0.16123"
"50.13000","0.06922","0.12395"
"50.23000","0.03941","0.09444"
"50.33000","0.00918","0.08440"
"50.43000","-0.02054","0.04595"
"50.53000","-0.05069","0.01472"
"50.63000","-0.08055","0.00439"
"50.73000","-0.11084","-0.03175"
"50.83000","-0.14085","-0.05579"
"50.93000","-0.17097","-0.08210"
"51.03000","-0.20089","-0.10389"
"51.13000","-0.23089","-0.14437"
"51.23000","-0.26075","-0.18003"
"51.33000","-0.29077","-0.20397"
"51.43000","-0.32076","-0.23794"
"51.53000","-0.35083","-0.27929"
"51.63000","-0.38075","-0.30726"
"51.73000","-0.41054","-0.33931"
"51.83000","-0.44067","-0.37804"
"51.93000","-0.47064","-0.40446"
"52.03000","-0.50091","-0.42369"
"52.13000","-0.53084","-0.44650"
"52.23000","-0.56084","-0.50534"
"52.33000","-0.59074","-0.50951"
"52.43000","-0.62089","-0.53735"
"52.53000","-0.65080","-0.56989"
"52.63000","-0.68102","-0.60069"
"52.73000","-0.71071","-0.61908"
"52.83000","-0.74064","-0.66132"
"52.93000","-0.77045","-0.69618"
"53.03000","-0.80071","-0.71969"
"53.13000","-0.83073","-0.75158"
"53.23000","-0.86087","-0.78191"
"53.33000","-0.89086","-0.82027"
"53.43000","-0.92078","-0.83211"
"53.53000","-0.95078","-0.87905"
"53.63000","-0.98083","-0.89624"
"53.73000","-1.01094","-0.93774"
"53.83000","-1.04095","-0.94773"
"53.93000","-1.07086","-0.99262"
"54.03000","-1.10071","-1.02303"
"54.13000","-1.13069","-1.03690"
"54.23000","-1.16060","-1.07669"
"54.33000","-1.19083","-1.10531"
"54.43000","-1.22075","-1.13611"
"54.53000","-1.25069","-1.13635"
"54.63000","-1.28065","-1.19923"
"54.73000","-1.31087","-1.21543"
"54.83000","-1.34085","-1.24238"
"54.93000","-1.37102","-1.27585"
"55.03000","-1.40094","-1.32415"
"55.13000","-1.43080","-1.33423"
"55.23000","-1.46066","-1.37925"
"55.33000","-1.49075","-1.41848"
"55.43000","-1.52068","-1.45238"
"55.53000","-1.55079","-1.46728"
"55.63000","-1.58072","-1.50600"
"55.73000","-1.61070","-1.53746"
"55.83000","-1.64069","-1.54419"
"55.93000","-1.67075","-1.59322"
"56.03000","-1.70091","-1.61952"
"56.13000","-1.73084","-1.63839"
"56.23000","-1.76088","-1.65360"
"56.33000","-1.79095","-1.69787"
"56.43000","-1.82088","-1.72417"
"56.53000","-1.85073","-1.75142"
"56.63000","-1.88092","-1.77510"
"56.73000","-1.91063","-1.82197"
"56.83000","-1.94067","-1.85819"
"56.93000","-1.97052","-1.88047"
"57.03000","-2.00077","-1.92310"
"57.13000","-2.03071","-1.94487"
"57.23000","-2.06089","-1.98024"
"57.33000","-2.09079","-1.99669"
"57.43000","-2.12081","-2.05035"
"57.53000","-2.15076","-2.05948"
"57.63000","-2.18084","-2.07801"
"57.73000","-2.21083","-2.11005"
"57.83000","-2.24090","-2.15418"
"57.93000","-2.27061","-2.17536"
"58.03000","-2.30058","-2.19549"
"58.13000","-2.33060","-2.23584"
"58.23000","-2.36072","-2.26358"
"58.33000","-2.39083","-2.28320"
"58.43000","-2.42076","-2.33192"
"58.53000","-2.45073","-2.36626"
"58.63000","-2.48079","-2.37676"
"58.69500","-2.50028","-2.40028"
"58.69700","-2.50090","-2.39902"
"58.79700","-2.50266","-2.40469"
"58.89700","-2.47039","-2.38065"
"58.99700","-2.44005","-2.36196"
"59.09700","-2.40962","-2.31163"
"59.19700","-2.37975","-2.28914"
"59.29700","-2.34943","-2.27002"
"59.39700","-2.31969","-2.23808"
"59.49700","-2.28957","-2.20926"
"59.59700","-2.25978","-2.17359"
"59.69700","-2.22970","-2.15262"
"59.79700","-2.19974","-2.10736"
"59.89700","-2.16974","-2.08170"
"59.99700","-2.13991","-2.05188"
"60.09700","-2.10977","-2.01827"
"60.19700","-2.07984","-1.98323"
"60.29700","-2.04962","-1.96110"
"60.39700","-2.01957","-1.92865"
"60.49700","-1.98954","-1.88821"
"60.59700","-1.95948","-1.85929"
"60.69700","-1.92970","-1.84618"
"60.79700","-1.89966","-1.81288"
"60.89700","-1.86979","-1.76835"
"60.99700","-1.83974","-1.74239"
"61.09700","-1.80993","-1.72651"
"61.19700","-1.77987","-1.69064"
"61.29700","-1.74996","-1.65340"
"61.39700","-1.71971","-1.65047"
"61.49700","-1.68975","-1.61774"
"61.59700","-1.65952","-1.57936"
"61.69700","-1.62976","-1.55471"
"61.79700","-1.59954","-1.52654"
"61.89700","-1.56982","-1.48348"
"61.99700","-1.53959","-1.44399"
"62.09700","-1.50957","-1.42474"
"62.19700","-1.47958","-1.38028"
"62.29700","-1.44976","-1.35336"
"62.39700","-1.41980","-1.32478"
"62.49700","-1.38998","-1.29698"
"62.59700","-1.35983","-1.24964"
"62.69700","-1.32979","-1.22874"
"62.79700","-1.29967","-1.21068"
"62.89700","-1.26963","-1.17765"
"62.99700","-1.23964","-1.14999"
"63.09700","-1.20957","-1.12480"
"63.19700","-1.17955","-1.10178"
"63.29700","-1.14939","-1.06933"
"63.39700","-1.11963","-1.04480"
"63.49700","-1.08973","-1.00471"
"63.59700","-1.05995","-0.97897"
"63.69700","-1.02983","-0.93580"
"63.79700","-0.99985","-0.91638"
"63.89700","-0.96967","-0.87648"
"63.99700","-0.93989","-0.84794"
"64.09700","-0.90964","-0.81739"
"64.19700","-0.87980","-0.79415"
"64.29700","-0.84960","-0.75855"
"64.39700","-0.81957","-0.72835"
"64.49700","-0.78946","-0.71647"
"64.59700","-0.75962","-0.68857"
"64.69700","-0.72968","-0.64667"
"64.79700","-0.69975","-0.61894"
"64.89700","-0.66970","-0.61178"
"64.99700","-0.63981","-0.57042"
"65.09700","-0.60984","-0.53027"
"65.19700","-0.57990","-0.50030"
"65.29700","-0.54976","-0.48861"
"65.39700","-0.51967","-0.43512"
"65.49700","-0.48956","-0.42359"
"65.59700","-0.45940","-0.37799"
"65.69700","-0.42952","-0.33733"
"65.79700","-0.39957","-0.30394"
"65.89700","-0.36975","-0.28466"
"65.99700","-0.33968","-0.24784"
"66.09700","-0.30972","-0.21020"
"66.19700","-0.27969","-0.19355"
"66.29700","-0.24990","-0.15266"
"66.39700","-0.21975","-0.13477"
"66.49700","-0.18993","-0.09891"
"66.59700","-0.15958","-0.09528"
"66.69700","-0.12976","-0.05147"
"66.79700","-0.09957","-0.03124"
"66.89700","-0.06970","0.00058"
"66.99700","-0.03965","0.03035"
"67.09700","-0.00966","0.05673"
"67.19700","0.02049","0.09775"
"67.29700","0.05039","0.11863"
"67.39700","0.08035","0.15493"
"67.49700","0.11014","0.18558"
"67.59700","0.14006","0.23191"
"67.69700","0.17012","0.24924"
"67.79700","0.20024","0.29001"
"67.89700","0.23036","0.31738"
"67.99700","0.26039","0.33618"
"68.09700","0.29037","0.35656"
"68.19700","0.32031","0.39089"
"68.29700","0.35044","0.42496"
"68.39700","0.38041","0.43953"
"68.49700","0.41042","0.47940"
"68.59700","0.44030","0.52783"
"68.69700","0.47033","0.52510"
"68.79700","0.50008","0.55732"
"68.89700","0.53033","0.61813"
"68.99700","0.56013","0.62340"
"69.09700","0.59020","0.64962"
"69.19700","0.62014","0.69677"
"69.29700","0.65029","0.73258"
"69.39700","0.68025","0.75582"
"69.49700","0.71055","0.77779"
"69.59700","0.74033","0.83027"
"69.69700","0.77054","0.83821"
"69.79700","0.80029","0.87377"
"69.89700","0.83023","0.91164"
"69.99700","0.86025","0.94353"
"70.09700","0.89021","0.95846"
"70.19700","0.92014","0.99871"
"70.29700","0.95014","1.03044"
"70.39700","0.98019","1.05387"
"70.49700","1.01024","1.07094"
"70.59700","1.04045","1.11038"
"70.69700","1.07045","1.14187"
"70.79700","1.10038","1.16123"
"70.89700","1.13030","1.20952"
"70.99700","1.16038","1.23851"
"71.09700","1.19020","1.27552"
"71.19700","1.22054","1.28062"
"71.29700","1.25011","1.33514"
"71.39700","1.28023","1.36762"
"71.49700","1.31000","1.39185"
"71.59700","1.34018","1.41337"
"71.69700","1.37019","1.44939"
"71.79700","1.40040","1.47359"
"71.89700","1.43024","1.49460"
"71.99700","1.46047","1.52880"
"72.09700","1.49027","1.56982"
"72.19700","1.52051","1.58655"
"72.29700","1.55038","1.61090"
"72.39700","1.58053","1.67242"
"72.49700","1.61030","1.68108"
"72.59700","1.64020","1.70831"
"72.69700","1.67011","1.74886"
"72.79700","1.70008","1.78889"
"72.89700","1.73028","1.80308"
"72.99700","1.76038","1.85417"
"73.09700","1.79032","1.88323"
"73.19700","1.82028","1.89521"
"73.29700","1.85022","1.92647"
"73.39700","1.88031","1.96028"
"73.49700","1.91052","2.00003"
"73.59700","1.94040","2.01069"
"73.69700","1.97048","2.04702"
"73.79700","2.00015","2.06829"
"73.89700","2.03028","2.10422"
"73.99700","2.06008","2.12794"
"74.09700","2.09026","2.16603"
"74.19700","2.12002","2.19674"
"74.29700","2.15022","2.21623"
"74.39700","2.18014","2.24840"
"74.49700","2.21043","2.28320"
"74.59700","2.24037","2.31337"
"74.69700","2.27074","2.32410"
"74.79700","2.30044","2.37412"
"74.89700","2.33051","2.41175"
"74.99700","2.36025","2.43204"
"75.09700","2.39025","2.46477"
"75.19700","2.42030","2.51056"
"75.29700","2.45021","2.53324"
"75.39700","2.48020","2.56504"
"75.46300","2.50003","2.58566"
"75.46500","2.50063","2.58661"
"75.56500","2.50173","2.57472"
"75.66500","2.47005","2.56523"
"75.76500","2.43935","2.52808"
"75.86500","2.40940","2.48446"
"75.96500","2.37915","2.46251"
"76.06500","2.34945","2.43574"
"76.16500","2.31938","2.38667"
"76.26500","2.28945","2.35403"
"76.36500","2.25926","2.34257"
"76.46500","2.22929","2.29395"
"76.56500","2.19908","2.27299"
"76.66500","2.16928","2.23695"
"76.76500","2.13916","2.22102"
"76.86500","2.10916","2.18257"
"76.96500","2.07909","2.16252"
"77.06500","2.04897","2.13922"
"77.16500","2.01912","2.09977"
"77.26500","1.98929","2.07025"
"77.36500","1.95943","2.03547"
"77.46500","1.92933","2.01609"
"77.56500","1.89930","1.97479"
"77.66500","1.86917","1.95401"
"77.76500","1.83925","1.91521"
"77.86500","1.80923","1.89210"
"77.96500","1.77935","1.84379"
"78.06500","1.74917","1.82662"
"78.16500","1.71912","1.79552"
"78.26500","1.68897","1.76599"
"78.36500","1.65924","1.73531"
"78.46500","1.62919","1.70382"
"78.56500","1.59940","1.68670"
"78.66500","1.56934","1.63373"
"78.76500","1.53933","1.61965"
"78.86500","1.50925","1.59305"
"78.96500","1.47941","1.55522"
"79.06500","1.44925","1.52045"
"79.16500","1.41925","1.51569"
"79.26500","1.38907","1.46402"
"79.36500","1.35906","1.43261"
"79.46500","1.32901","1.41067"
"79.56500","1.29921","1.38528"
"79.66500","1.26921","1.33945"
"79.76500","1.23927","1.30460"
"79.86500","1.20924","1.28438"
"79.96500","1.17922","1.24241"
"80.06500","1.14931","1.21955"
"80.16500","1.11934","1.18898"
"80.26500","1.08937","1.16526"
"80.36500","1.05924","1.11472"
"80.46500","1.02916","1.10893"
"80.56500","0.99909","1.07962"
"80.66500","0.96929","1.04151"
"80.76500","0.93912","1.01077"
"80.86500","0.90927","0.99512"
"80.96500","0.87906","0.96876"
"81.06500","0.84913","0.92516"
"81.16500","0.81917","0.90113"
"81.26500","0.78947","0.85902"
"81.36500","0.75937","0.83832"
"81.46500","0.72934","0.79065"
"81.56500","0.69919","0.77539"
"81.66500","0.66924","0.73173"
"81.76500","0.63911","0.70072"
"81.86500","0.60932","0.67019"
"81.96500","0.57910","0.66072"
"82.06500","0.54917","0.61897"
"82.16500","0.51909","0.57675"
"82.26500","0.48914","0.56451"
"82.36500","0.45927","0.55561"
"82.46500","0.42938","0.49720"
"82.56500","0.39940","0.45999"
"82.66500","0.36923","0.44597"
"82.76500","0.33923","0.40225"
"82.86500","0.30923","0.38782"
"82.96500","0.27943","0.35692"
"83.06500","0.24921","0.32737"
"83.16500","0.21932","0.27530"
"83.26500","0.18906","0.26365"
"83.36500","0.15905","0.23665"
"83.46500","0.12904","0.19977"
"83.56500","0.09937","0.15756"
"83.66500","0.06922","0.14179"
"83.76500","0.03942","0.10939"
"83.86500","0.00918","0.06738"
"83.96500","-0.02052","0.05372"
"84.06500","-0.05069","0.02032"
"84.16500","-0.08054","0.00156"
"84.26500","-0.11083","-0.03342"
"84.36500","-0.14081","-0.05132"
"84.46500","-0.17098","-0.08376"
"84.56500","-0.20088","-0.11896"
"84.66500","-0.23087","-0.13593"
"84.76500","-0.26076","-0.16677"
"84.86500","-0.29077","-0.20865"
"84.96500","-0.32082","-0.24291"
"85.06500","-0.35080","-0.26980"
"85.16500","-0.38073","-0.30032"
"85.26500","-0.41052","-0.33785"
"85.36500","-0.44067","-0.37121"
"85.46500","-0.47061","-0.38952"
"85.56500","-0.50090","-0.43518"
"85.66500","-0.53082","-0.45683"
"85.76500","-0.56087","-0.47609"
"85.86500","-0.59076","-0.50635"
"85.96500","-0.62087","-0.54969"
"86.06500","-0.65076","-0.57170"
"86.16500","-0.68104","-0.59033"
"86.26500","-0.71070","-0.62988"
"86.36500","-0.74063","-0.67042"
"86.46500","-0.77047","-0.69198"
"86.56500","-0.80064","-0.71625"
"86.66500","-0.83073","-0.76383"
"86.76500","-0.86087","-0.77853"
"86.86500","-0.89085","-0.81404"
"86.96500","-0.92079","-0.84780"
"87.06500","-0.95074","-0.88350"
"87.16500","-0.98083","-0.88888"
"87.26500","-1.01093","-0.93047"
"87.36500","-1.04094","-0.96187"
"87.46500","-1.07086","-0.98090"
"87.56500","-1.10069","-1.01160"
"87.66500","-1.13068","-1.04810"
"87.76500","-1.16060","-1.08065"
"87.86500","-1.19082","-1.08841"
"87.96500","-1.22073","-1.13278"
"88.06500","-1.25072","-1.15862"
"88.16500","-1.28063","-1.18900"
"88.26500","-1.31085","-1.21373"
"88.36500","-1.34083","-1.25540"
"88.46500","-1.37103","-1.28834"
"88.56500","-1.40092","-1.31397"
"88.66500","-1.43078","-1.34623"
"88.76500","-1.46065","-1.38495"
"88.86500","-1.49074","-1.40935"
"88.96500","-1.52068","-1.44103"
"89.06500","-1.55077","-1.48460"
"89.16500","-1.58074","-1.49710"
"89.26500","-1.61068","-1.52379"
"89.36500","-1.64070","-1.54660"
"89.46500","-1.67072","-1.59861"
"89.56500","-1.70090","-1.61509"
"89.66500","-1.73087","-1.64221"
"89.76500","-1.76087","-1.66643"
"89.86500","-1.79091","-1.70556"
"89.96500","-1.82088","-1.71679"
"90.06500","-1.85076","-1.76553"
"90.16500","-1.88091","-1.80406"
"90.26500","-1.91061","-1.82436"
"90.36500","-1.94067","-1.85827"
"90.46500","-1.97051","-1.88942"
"90.56500","-2.00077","-1.92232"
"90.66500","-2.03068","-1.93677"
"90.76500","-2.06088","-1.97247"
"90.86500","-2.09081","-2.00193"
"90.96500","-2.12069","-2.04154"
"91.06500","-2.15084","-2.04997"
"91.16500","-2.18085","-2.08914"
"91.26500","-2.21082","-2.11329"
"91.36500","-2.24089","-2.13853"
"91.46500","-2.27062","-2.17412"
"91.56500","-2.30061","-2.20828"
"91.66500","-2.33057","-2.24473"
"91.76500","-2.36072","-2.25445"
"91.86500","-2.39082","-2.31152"
"91.96500","-2.42078","-2.33188"
"92.06500","-2.45072","-2.36105"
"92.16500","-2.48079","-2.39276"
"92.23000","-2.50025","-2.39751"
"92.23200","-2.50087","-2.39861"
"92.33200","-2.50272","-2.42502"
"92.43200","-2.47043","-2.40226"
"92.53200","-2.44006","-2.35217"
"92.63200","-2.40965","-2.32542"
"92.73200","-2.37975","-2.30327"
"92.83200","-2.34946","-2.27242"
"92.93200","-2.31971","-2.23056"
"93.03200","-2.28959","-2.21951"
"93.13200","-2.25981","-2.17413"
"93.23200","-2.22971","-2.14055"
"93.33200","-2.19975","-2.10631"
"93.43200","-2.16980","-2.08363"
"93.53200","-2.13995","-2.04250"
"93.63200","-2.10978","-2.00698"
"93.73200","-2.07985","-1.98777"
"93.83200","-2.04965","-1.96123"
"93.93200","-2.01954","-1.93067"
"94.03200","-1.98966","-1.89425"
"94.13200","-1.95951","-1.88192"
"94.23200","-1.92972","-1.84986"
"94.33200","-1.89966","-1.81453"
"94.43200","-1.86983","-1.78420"
"94.53200","-1.83977","-1.76270"
"94.63200","-1.80994","-1.71917"
"94.73200","-1.77990","-1.68719"
"94.83200","-1.74998","-1.66227"
"94.93200","-1.71975","-1.65032"
"95.03200","-1.68975","-1.59461"
"95.13200","-1.65952","-1.58337"
"95.23200","-1.62980","-1.54863"
"95.33200","-1.59954","-1.51246"
"95.43200","-1.56985","-1.48351"
"95.53200","-1.53965","-1.45542"
"95.63200","-1.50958","-1.41942"
"95.73200","-1.47960","-1.38951"
"95.83200","-1.44979","-1.37278"
"95.93200","-1.41983","-1.33127"
"96.03200","-1.39001","-1.30217"
"96.13200","-1.35982","-1.26388"
"96.23200","-1.32975","-1.26016"
"96.33200","-1.29973","-1.21406"
"96.43200","-1.26965","-1.18096"
"96.53200","-1.23967","-1.15192"
"96.63200","-1.20958","-1.13064"
"96.73200","-1.17957","-1.09208"
"96.83200","-1.14944","-1.05255"
"96.93200","-1.11965","-1.03420"
"97.03200","-1.08974","-0.99865"
"97.13200","-1.05998","-0.96403"
"97.23200","-1.02986","-0.93050"
"97.33200","-0.99986","-0.91421"
"97.43200","-0.96970","-0.87586"
"97.53200","-0.93997","-0.85852"
"97.63200","-0.90963","-0.83822"
"97.73200","-0.87982","-0.80641"
"97.83200","-0.84959","-0.76365"
"97.93200","-0.81965","-0.75076"
"98.03200","-0.78948","-0.72705"
"98.13200","-0.75964","-0.68417"
"98.23200","-0.72967","-0.64732"
"98.33200","-0.69978","-0.62988"
"98.43200","-0.66976","-0.59842"
"98.53200","-0.63980","-0.55130"
"98.63200","-0.60986","-0.53245"
"98.73200","-0.57990","-0.49364"
"98.83200","-0.54983","-0.46237"
"98.93200","-0.51968","-0.43468"
"99.03200","-0.48958","-0.41912"
"99.13200","-0.45942","-0.38218"
"99.23200","-0.42955","-0.35039"
"99.33200","-0.39959","-0.33285"
"99.43200","-0.36978","-0.29597"
"99.53200","-0.33969","-0.25985"
"99.63200","-0.30976","-0.22630"
"99.73200","-0.27973","-0.20730"
"99.83200","-0.24995","-0.15505"
"99.93200","-0.21977","-0.13150"
"100.03200","-0.18996","-0.10159"
"100.13200","-0.15961","-0.09039"
"100.23200","-0.12977","-0.03962"
"100.33200","-0.09962","-0.02070"
"100.43200","-0.06972","0.00251"
"100.53200","-0.03964","0.04507"
"100.63200","-0.00968","0.06830"
"100.73200","0.02052","0.09459"
"100.83200","0.05037","0.10774"
"100.93200","0.08034","0.15447"
"101.03200","0.11011","0.18798"
"101.13200","0.14004","0.21302"
"101.23200","0.17012","0.23552"
"101.33200","0.20021","0.28059"
"101.43200","0.23034","0.29560"
"101.53200","0.26035","0.32049"
"101.63200","0.29038","0.37047"
"101.73200","0.32030","0.39718"
"101.83200","0.35043","0.40492"
"101.93200","0.38040","0.46346"
"102.03200","0.41043","0.49879"
"102.13200","0.44023","0.52110"
"102.23200","0.47027","0.54193"
"102.33200","0.50004","0.57618"
"102.43200","0.53031","0.60767"
"102.53200","0.56009","0.62270"
"102.63200","0.59022","0.66468"
"102.73200","0.62011","0.68346"
"102.83200","0.65027","0.71254"
"102.93200","0.68022","0.74341"
"103.03200","0.71052","0.77467"
"103.13200","0.74033","0.80246"
"103.23200","0.77051","0.83362"
"103.33200","0.80027","0.87275"
"103.43200","0.83027","0.91132"
"103.53200","0.86019","0.94191"
"103.63200","0.89018","0.96752"
"103.73200","0.92013","1.01283"
"103.83200","0.95010","1.03942"
"103.93200","0.98019","1.05983"
"104.03200","1.01025","1.08234"
"104.13200","1.04041","1.11892"
"104.23200","1.07045","1.13459"
"104.33200","1.10034","1.16266"
"104.43200","1.13027","1.20855"
"104.53200","1.16035","1.22585"
"104.63200","1.19018","1.24665"
"104.73200","1.22051","1.28209"
"104.83200","1.25011","1.33277"
"104.93200","1.28022","1.34594"
"105.03200","1.30997","1.38688"
"105.13200","1.34017","1.42086"
"105.23200","1.37013","1.45056"
"105.33200","1.40036","1.46468"
"105.43200","1.43023","1.51649"
"105.53200","1.46047","1.54306"
"105.63200","1.49024","1.56370"
"105.73200","1.52049","1.58781"
"105.83200","1.55036","1.62083"
"105.93200","1.58051","1.65271"
"106.03200","1.61028","1.67334"
"106.13200","1.64015","1.71532"
"106.23200","1.67008","1.73673"
"106.33200","1.70007","1.77060"
"106.43200","1.73027","1.79819"
"106.53200","1.76035","1.84842"
"106.63200","1.79027","1.86198"
"106.73200","1.82022","1.88271"
"106.83200","1.85025","1.93383"
"106.93200","1.88027","1.97081"
"107.03200","1.91049","1.99979"
"107.13200","1.94035","2.01696"
"107.23200","1.97046","2.05557"
"107.33200","2.00012","2.06944"
"107.43200","2.03025","2.10521"
"107.53200","2.06008","2.13126"
"107.63200","2.09022","2.17611"
"107.73200","2.12001","2.17415"
"107.83200","2.15013","2.21088"
"107.93200","2.18020","2.25132"
"108.03200","2.21039","2.27413"
"108.13200","2.24039","2.29607"
"108.23200","2.27061","2.34188"
"108.33200","2.30051","2.37591"
"108.43200","2.33043","2.40187"
"108.53200","2.36022","2.44929"
"108.63200","2.39022","2.48119"
"108.73200","2.42027","2.51573"
"108.83200","2.45017","2.53003"
"108.93200","2.48014","2.58156"
"108.99800","2.50004","2.58345"
"109.00000","2.50064","2.58619"
"109.10000","2.50150","2.59447"
"109.20000","2.47009","2.56466"
"109.30000","2.43937","2.52520"
"109.40000","2.40941","2.50030"
"109.50000","2.37911","2.46869"
"109.60000","2.34944","2.42465"
"109.70000","2.31939","2.39097"
"109.80000","2.28947","2.36514"
"109.90000","2.25931","2.33500"
"110.00000","2.22929","2.29132"
"110.10000","2.19910","2.27702"
"110.20000","2.16927","2.22817"
"110.30000","2.13915","2.21566"
"110.40000","2.10919","2.18919"
"110.50000","2.07909","2.16892"
"110.60000","2.04899","2.13118"
"110.70000","2.01914","2.09764"
"110.80000","1.98929","2.08243"
"110.90000","1.95945","2.04816"
"111.00000","1.92934","2.00746"
"111.10000","1.89933","1.98277"
"111.20000","1.86918","1.96029"
"111.30000","1.83922","1.91917"
"111.40000","1.80921","1.88927"
"111.50000","1.77937","1.85705"
"111.60000","1.74919","1.82275"
"111.70000","1.71914","1.78705"
"111.80000","1.68897","1.76596"
"111.90000","1.65923","1.73339"
"112.00000","1.62919","1.71034"
"112.10000","1.59943","1.67402"
"112.20000","1.56936","1.64456"
"112.30000","1.53935","1.62514"
"112.40000","1.50926","1.57960"
"112.50000","1.47941","1.56537"
"112.60000","1.44925","1.53915"
"112.70000","1.41925","1.49573"
"112.80000","1.38909","1.46629"
"112.90000","1.35905","1.43619"
"113.00000","1.32903","1.41008"
"113.10000","1.29921","1.36859"
"113.20000","1.26923","1.33614"
"113.30000","1.23923","1.32450"
"113.40000","1.20928","1.27705"
"113.50000","1.17924","1.24005"
"113.60000","1.14931","1.23154"
"113.70000","1.11935","1.18989"
"113.80000","1.08937","1.16064"
"113.90000","1.05926","1.14152"
"114.00000","1.02917","1.11955"
"114.10000","0.99909","1.08073"
"114.20000","0.96928","1.04066"
"114.30000","0.93909","1.02925"
"114.40000","0.90928","0.99881"
"114.50000","0.87907","0.95617"
"114.60000","0.84914","0.93183"
"114.70000","0.81918","0.89602"
"114.80000","0.78947","0.85239"
"114.90000","0.75937","0.83110"
"115.00000","0.72936","0.79448"
"115.10000","0.69919","0.76772"
"115.20000","0.66925","0.72199"
"115.30000","0.63912","0.71103"
"115.40000","0.60931","0.68104"
"115.50000","0.57912","0.65739"
"115.60000","0.54916","0.61893"
"115.70000","0.51909","0.59603"
"115.80000","0.48915","0.56340"
"115.90000","0.45928","0.54471"
"116.00000","0.42938","0.50439"
"116.10000","0.39941","0.47630"
"116.20000","0.36927","0.43567"
"116.30000","0.33925","0.39441"
"116.40000","0.30924","0.38104"
"116.50000","0.27942","0.34889"
"116.60000","0.24926","0.30821"
"116.70000","0.21928","0.28373"
"116.80000","0.18906","0.27102"
"116.90000","0.15904","0.22397"
"117.00000","0.12907","0.19814"
"117.10000","0.09934","0.17930"
"117.20000","0.06925","0.14923"
"117.30000","0.03942","0.10199"
"117.40000","0.00919","0.09089"
"117.50000","-0.02052","0.07932"
"117.60000","-0.05068","0.01773"
"117.70000","-0.08054","0.00221"
"117.80000","-0.11085","-0.02531"
"117.90000","-0.14081","-0.05660"
"118.00000","-0.17097","-0.09209"
"118.10000","-0.20088","-0.10971"
"118.20000","-0.23086","-0.14719"
"118.30000","-0.26074","-0.18209"
"118.40000","-0.29077","-0.21816"
"118.50000","-0.32080","-0.23780"
"118.60000","-0.35080","-0.27597"
"118.70000","-0.38070","-0.29784"
"118.80000","-0.41054","-0.32499"
"118.90000","-0.44066","-0.36192"
"119.00000","-0.47061","-0.38472"
"119.10000","-0.50090","-0.42753"
"119.20000","-0.53083","-0.43801"
"119.30000","-0.56084","-0.48494"
"119.40000","-0.59075","-0.51210"
"119.50000","-0.62089","-0.54007"
"119.60000","-0.65075","-0.56650"
"119.70000","-0.68104","-0.61140"
"119.80000","-0.71066","-0.64726"
"119.90000","-0.74062","-0.66979"
"120.00000","-0.77042","-0.70597"
"120.10000","-0.80067","-0.73188"
"120.20000","-0.83075","-0.75509"
"120.30000","-0.86086","-0.77306"
"120.40000","-0.89085","-0.81794"
"120.50000","-0.92077","-0.83238"
"120.60000","-0.95078","-0.86215"
"120.70000","-0.98079","-0.88016"
"120.80000","-1.01092","-0.93091"
"120.90000","-1.04097","-0.93984"
"121.00000","-1.07084","-0.97669"
"121.10000","-1.10070","-1.01905"
"121.20000","-1.13069","-1.04248"
"121.30000","-1.16057","-1.07151"
"121.40000","-1.19081","-1.10856"
"121.50000","-1.22072","-1.14977"
"121.60000","-1.25072","-1.15214"
"121.70000","-1.28062","-1.19087"
"121.80000","-1.31089","-1.22755"
"121.90000","-1.34081","-1.26050"
"122.00000","-1.37102","-1.27024"
"122.10000","-1.40095","-1.31747"
"122.20000","-1.43078","-1.33563"
"122.30000","-1.46062","-1.36463"
"122.40000","-1.49073","-1.40253"
"122.50000","-1.52065","-1.43789"
"122.60000","-1.55077","-1.46897"
"122.70000","-1.58070","-1.48222"
"122.80000","-1.61070","-1.53775"
"122.90000","-1.64071","-1.56182"
"123.00000","-1.67071","-1.59287"
"123.10000","-1.70090","-1.61651"
"123.20000","-1.73086","-1.65239"
"123.30000","-1.76089","-1.67527"
"123.40000","-1.79090","-1.69549"
"123.50000","-1.82084","-1.73012"
"123.60000","-1.85074","-1.77463"
"123.70000","-1.88091","-1.79208"
"123.80000","-1.91062","-1.81580"
"123.90000","-1.94064","-1.86147"
"124.00000","-1.97051","-1.88816"
"124.10000","-2.00076","-1.90834"
"124.20000","-2.03068","-1.93594"
"124.30000","-2.06088","-1.98465"
"124.40000","-2.09080","-1.99786"
"124.50000","-2.12082","-2.03994"
"124.60000","-2.15070","-2.06620"
"124.70000","-2.18082","-2.09409"
"124.80000","-2.21083","-2.10790"
"124.90000","-2.24089","-2.14640"
"125.00000","-2.27062","-2.20230"
"125.10000","-2.30058","-2.20148"
"125.20000","-2.33059","-2.23857"
"125.30000","-2.36068","-2.27812"
"125.40000","-2.39082","-2.30253"
"125.50000","-2.42073","-2.32099"
"125.60000","-2.45073","-2.36585"
"125.70000","-2.48080","-2.39271"
"125.76500","-2.50023","-2.41999"
"125.76700","-2.50085","-2.42039"
"125.86700","-2.50272","-2.43120"
"125.96700","-2.47044","-2.38186"
"126.06700","-2.44006","-2.35847"
"126.16700","-2.40966","-2.33151"
"126.26700","-2.37977","-2.28654"
"126.36700","-2.34945","-2.26623"
"126.46700","-2.31975","-2.23981"
"126.56700","-2.28960","-2.20738"
"126.66700","-2.25983","-2.16670"
"126.76700","-2.22973","-2.15006"
"126.86700","-2.19974","-2.11549"
"126.96700","-2.16979","-2.07427"
"127.06700","-2.13995","-2.04216"
"127.16700","-2.10982","-2.02085"
"127.26700","-2.07987","-1.98878"
"127.36700","-2.04965","-1.95588"
"127.46700","-2.01960","-1.94305"
"127.56700","-1.98966","-1.90725"
"127.66700","-1.95952","-1.87181"
"127.76700","-1.92971","-1.83326"
"127.86700","-1.89967","-1.81166"
"127.96700","-1.86983","-1.78667"
"128.06700","-1.83978","-1.75158"
"128.16700","-1.80993","-1.71916"
"128.26700","-1.77990","-1.70065"
"128.36700","-1.75000","-1.65127"
"128.46700","-1.71975","-1.64699"
"128.56700","-1.68977","-1.62107"
"128.66700","-1.65952","-1.58442"
"128.76700","-1.62982","-1.53573"
"128.86700","-1.59956","-1.51592"
"128.96700","-1.56987","-1.50193"
"129.06700","-1.53963","-1.44859"
"129.16700","-1.50958","-1.41975"
"129.26700","-1.47961","-1.39891"
"129.36700","-1.44981","-1.36129"
"129.46700","-1.41983","-1.32545"
"129.56700","-1.39006","-1.30311"
"129.66700","-1.35980","-1.27283"
"129.76700","-1.32978","-1.23518"
"129.86700","-1.29976","-1.20964"
"129.96700","-1.26967","-1.19489"
"130.06700","-1.23969","-1.15125"
"130.16700","-1.20961","-1.11252"
"130.26700","-1.17958","-1.10187"
"130.36700","-1.14945","-1.07532"
"130.46700","-1.11968","-1.02207"
"130.56700","-1.08976","-0.99559"
"130.66700","-1.05999","-0.98477"
"130.76700","-1.02988","-0.92596"
"130.86700","-0.99988","-0.90900"
"130.96700","-0.96973","-0.88524"
"131.06700","-0.93999","-0.85201"
"131.16700","-0.90961","-0.82331"
"131.26700","-0.87974","-0.80309"
"131.36700","-0.84964","-0.78656"
"131.46700","-0.81969","-0.73036"
"131.56700","-0.78950","-0.71397"
"131.66700","-0.75967","-0.69459"
"131.76700","-0.72969","-0.65659"
"131.86700","-0.69978","-0.62547"
"131.96700","-0.66976","-0.60591"
"132.06700","-0.63981","-0.55559"
"132.16700","-0.60988","-0.53229"
"132.26700","-0.57992","-0.47395"
"132.36700","-0.54983","-0.47371"
"132.46700","-0.51970","-0.44883"
"132.56700","-0.48962","-0.38995"
"132.66700","-0.45941","-0.37241"
"132.76700","-0.42957","-0.36892"
"132.86700","-0.39961","-0.32486"
"132.96700","-0.36978","-0.27209"
"133.06700","-0.33968","-0.26434"
"133.16700","-0.30978","-0.23035"
"133.26700","-0.27973","-0.19699"
"133.36700","-0.24997","-0.16011"
"133.46700","-0.21978","-0.14770"
"133.56700","-0.18997","-0.09862"
"133.66700","-0.15961","-0.07864"
"133.76700","-0.12978","-0.05784"
"133.86700","-0.09963","-0.02089"
"133.96700","-0.06974","0.02373"
"134.06700","-0.03967","0.04086"
"134.16700","-0.00970","0.05288"
"134.20100","0.00024","0.06207"