File: SupLinearAndTan/Tan_Fan_Chart/Specimen_RawData_4.csv
Time,Extension,Load
(s),(mm),(N)
"0.00000","0.00000","0.07393"
"0.10000","0.00863","0.10054"
"0.20000","0.04152","0.02366"
"0.30000","0.07197","0.04594"
"0.40000","0.10214","-0.00191"
"0.50000","0.13211","0.00523"
"0.60000","0.16233","-0.03594"
"0.70000","0.19232","-0.02783"
"0.80000","0.22252","-0.05606"
"0.90000","0.25229","-0.06610"
"1.00000","0.28239","-0.08467"
"1.10000","0.31208","-0.08200"
"1.20000","0.34223","-0.09596"
"1.30000","0.37215","-0.11794"
"1.40000","0.40225","-0.09108"
"1.50000","0.43200","-0.09051"
"1.60000","0.46215","-0.13506"
"1.70000","0.49202","-0.18237"
"1.80000","0.52231","-0.19795"
"1.90000","0.55221","-0.23144"
"2.00000","0.58233","-0.24673"
"2.10000","0.61224","-0.25989"
"2.20000","0.64226","-0.28442"
"2.30000","0.67232","-0.29638"
"2.40000","0.70235","-0.30072"
"2.50000","0.73229","-0.31697"
"2.60000","0.76210","-0.34980"
"2.70000","0.79204","-0.34890"
"2.80000","0.82198","-0.35681"
"2.90000","0.85212","-0.38928"
"3.00000","0.88215","-0.40404"
"3.10000","0.91233","-0.40547"
"3.20000","0.94226","-0.44928"
"3.30000","0.97237","-0.45282"
"3.40000","1.00214","-0.47293"
"3.50000","1.03240","-0.49788"
"3.60000","1.06225","-0.52953"
"3.70000","1.09233","-0.56236"
"3.80000","1.12210","-0.56149"
"3.90000","1.15218","-0.59730"
"4.00000","1.18196","-0.59469"
"4.10000","1.21220","-0.62869"
"4.20000","1.24203","-0.62494"
"4.30000","1.27217","-0.66175"
"4.40000","1.30214","-0.68299"
"4.50000","1.33222","-0.69712"
"4.60000","1.36223","-0.72380"
"4.70000","1.39243","-0.74992"
"4.80000","1.42235","-0.76174"
"4.90000","1.45238","-0.78150"
"5.00000","1.48223","-0.83056"
"5.10000","1.51210","-0.86771"
"5.20000","1.54210","-0.88338"
"5.30000","1.57203","-0.88102"
"5.40000","1.60210","-0.97866"
"5.50000","1.63201","-1.01858"
"5.60000","1.66215","-1.04382"
"5.70000","1.69214","-1.08647"
"5.80000","1.72237","-1.12272"
"5.90000","1.75230","-1.13509"
"6.00000","1.78229","-1.17629"
"6.10000","1.81222","-1.22118"
"6.20000","1.84231","-1.25987"
"6.30000","1.87207","-1.29592"
"6.40000","1.90234","-1.33427"
"6.50000","1.93211","-1.40111"
"6.60000","1.96215","-1.40305"
"6.70000","1.99203","-1.47412"
"6.80000","2.02201","-1.52356"
"6.90000","2.05211","-1.59182"
"7.00000","2.08227","-1.64270"
"7.10000","2.11218","-1.72677"
"7.20000","2.14239","-1.79627"
"7.30000","2.17230","-1.83990"
"7.40000","2.20223","-1.91855"
"7.50000","2.23238","-2.01114"
"7.60000","2.26233","-2.08178"
"7.70000","2.29224","-2.14325"
"7.80000","2.32200","-2.25869"
"7.90000","2.35205","-2.37078"
"8.00000","2.38196","-2.45614"
"8.10000","2.41228","-2.57138"
"8.20000","2.44220","-2.72166"
"8.30000","2.47226","-2.82818"
"8.39300","2.50006","-3.01130"
"8.39500","2.50066","-3.01274"
"8.49500","2.50153","-3.02282"
"8.59500","2.47010","-2.84507"
"8.69500","2.43936","-2.68860"
"8.79500","2.40942","-2.53196"
"8.89500","2.37915","-2.43874"
"8.99500","2.34949","-2.38702"
"9.09500","2.31940","-2.22876"
"9.19500","2.28950","-2.12389"
"9.29500","2.25929","-2.04740"
"9.39500","2.22931","-1.96940"
"9.49500","2.19911","-1.87228"
"9.59500","2.16931","-1.79717"
"9.69500","2.13917","-1.72273"
"9.79500","2.10920","-1.65196"
"9.89500","2.07909","-1.61399"
"9.99500","2.04901","-1.55639"
"10.09500","2.01917","-1.50425"
"10.19500","1.98932","-1.43478"
"10.29500","1.95949","-1.41526"
"10.39500","1.92936","-1.37331"
"10.49500","1.89926","-1.30256"
"10.59500","1.86916","-1.27962"
"10.69500","1.83930","-1.22736"
"10.79500","1.80924","-1.18275"
"10.89500","1.77939","-1.15424"
"10.99500","1.74920","-1.11129"
"11.09500","1.71916","-1.07260"
"11.19500","1.68899","-1.03497"
"11.29500","1.65925","-1.00017"
"11.39500","1.62920","-0.96813"
"11.49500","1.59946","-0.89731"
"11.59500","1.56939","-0.88327"
"11.69500","1.53936","-0.85320"
"11.79500","1.50928","-0.81944"
"11.89500","1.47943","-0.78395"
"11.99500","1.44925","-0.76026"
"12.09500","1.41928","-0.75219"
"12.19500","1.38910","-0.71925"
"12.29500","1.35909","-0.69589"
"12.39500","1.32902","-0.67436"
"12.49500","1.29926","-0.65809"
"12.59500","1.26923","-0.61640"
"12.69500","1.23928","-0.60858"
"12.79500","1.20933","-0.58687"
"12.89500","1.17920","-0.56770"
"12.99500","1.14931","-0.53539"
"13.09500","1.11934","-0.53039"
"13.19500","1.08941","-0.52599"
"13.29500","1.05926","-0.47835"
"13.39500","1.02919","-0.47302"
"13.49500","0.99910","-0.44939"
"13.59500","0.96932","-0.42708"
"13.69500","0.93909","-0.41210"
"13.79500","0.90926","-0.40455"
"13.89500","0.87916","-0.38939"
"13.99500","0.84914","-0.36153"
"14.09500","0.81918","-0.34841"
"14.19500","0.78950","-0.33048"
"14.29500","0.75939","-0.30491"
"14.39500","0.72939","-0.27239"
"14.49500","0.69919","-0.28857"
"14.59500","0.66924","-0.25102"
"14.69500","0.63912","-0.23549"
"14.79500","0.60935","-0.22101"
"14.89500","0.57912","-0.21926"
"14.99500","0.54918","-0.18827"
"15.09500","0.51916","-0.17340"
"15.19500","0.48913","-0.16563"
"15.29500","0.45928","-0.08451"
"15.39500","0.42941","-0.11388"
"15.49500","0.39943","-0.10702"
"15.59500","0.36928","-0.12250"
"15.69500","0.33929","-0.07487"
"15.79500","0.30926","-0.07994"
"15.89500","0.27943","-0.05699"
"15.99500","0.24921","-0.03034"
"16.09500","0.21933","-0.01330"
"16.19500","0.18911","-0.00600"
"16.29500","0.15908","-0.00382"
"16.39500","0.12906","0.02422"
"16.49500","0.09936","0.04080"
"16.59500","0.06927","0.04402"
"16.69500","0.03946","0.06413"
"16.79500","0.00924","0.08470"
"16.89500","-0.02047","0.10115"
"16.99500","-0.05065","0.11076"
"17.09500","-0.08052","0.14319"
"17.19500","-0.11084","0.14566"
"17.29500","-0.14080","0.14927"
"17.39500","-0.17096","0.19304"
"17.49500","-0.20086","0.19507"
"17.59500","-0.23083","0.21993"
"17.69500","-0.26074","0.21990"
"17.79500","-0.29073","0.24821"
"17.89500","-0.32078","0.27409"
"17.99500","-0.35079","0.27192"
"18.09500","-0.38068","0.28902"
"18.19500","-0.41051","0.29656"
"18.29500","-0.44064","0.30415"
"18.39500","-0.47059","0.31261"
"18.49500","-0.50089","0.34623"
"18.59500","-0.53081","0.36485"
"18.69500","-0.56085","0.37921"
"18.79500","-0.59073","0.39603"
"18.89500","-0.62084","0.42080"
"18.99500","-0.65071","0.43581"
"19.09500","-0.68101","0.44044"
"19.19500","-0.71067","0.48033"
"19.29500","-0.74062","0.50562"
"19.39500","-0.77039","0.50803"
"19.49500","-0.80066","0.53704"
"19.59500","-0.83070","0.58707"
"19.69500","-0.86085","0.58907"
"19.79500","-0.89081","0.58604"
"19.89500","-0.92074","0.62661"
"19.99500","-0.95073","0.64249"
"20.09500","-0.98083","0.63851"
"20.19500","-1.01091","0.65390"
"20.29500","-1.04091","0.69391"
"20.39500","-1.07085","0.72280"
"20.49500","-1.10066","0.72579"
"20.59500","-1.13065","0.76271"
"20.69500","-1.16058","0.76221"
"20.79500","-1.19077","0.78191"
"20.89500","-1.22073","0.81999"
"20.99500","-1.25071","0.85037"
"21.09500","-1.28064","0.88411"
"21.19500","-1.31078","0.89857"
"21.29500","-1.34074","0.94112"
"21.39500","-1.37103","0.96889"
"21.49500","-1.40090","0.98689"
"21.59500","-1.43079","0.99951"
"21.69500","-1.46062","1.03512"
"21.79500","-1.49072","1.04882"
"21.89500","-1.52064","1.06732"
"21.99500","-1.55072","1.11946"
"22.09500","-1.58072","1.16784"
"22.19500","-1.61070","1.18646"
"22.29500","-1.64065","1.20227"
"22.39500","-1.67069","1.25512"
"22.49500","-1.70087","1.27439"
"22.59500","-1.73085","1.33070"
"22.69500","-1.76080","1.41868"
"22.79500","-1.79094","1.43698"
"22.89500","-1.82081","1.47140"
"22.99500","-1.85072","1.53567"
"23.09500","-1.88093","1.56535"
"23.19500","-1.91060","1.60468"
"23.29500","-1.94061","1.64100"
"23.39500","-1.97046","1.70454"
"23.49500","-2.00070","1.75716"
"23.59500","-2.03068","1.80728"
"23.69500","-2.06085","1.85434"
"23.79500","-2.09081","1.91959"
"23.89500","-2.12077","1.98449"
"23.99500","-2.15071","2.05183"
"24.09500","-2.18073","2.13698"
"24.19500","-2.21073","2.20282"
"24.29500","-2.24087","2.31689"
"24.39500","-2.27057","2.37780"
"24.49500","-2.30055","2.48505"
"24.59500","-2.33061","2.56689"
"24.69500","-2.36067","2.68315"
"24.79500","-2.39081","2.79530"
"24.89500","-2.42074","2.90439"
"24.99500","-2.45071","3.03590"
"25.09500","-2.48080","3.20615"
"25.16000","-2.50021","3.31513"
"25.16200","-2.50083","3.31731"
"25.26200","-2.50277","3.35287"
"25.36200","-2.47045","3.14880"
"25.46200","-2.44006","3.01060"
"25.56200","-2.40963","2.84445"
"25.66200","-2.37976","2.73253"
"25.76200","-2.34945","2.60689"
"25.86200","-2.31973","2.50292"
"25.96200","-2.28959","2.40612"
"26.06200","-2.25979","2.33265"
"26.16200","-2.22971","2.25308"
"26.26200","-2.19974","2.15039"
"26.36200","-2.16978","2.09702"
"26.46200","-2.13992","2.02322"
"26.56200","-2.10978","1.96977"
"26.66200","-2.07989","1.88722"
"26.76200","-2.04963","1.84172"
"26.86200","-2.01955","1.74922"
"26.96200","-1.98966","1.73306"
"27.06200","-1.95948","1.67100"
"27.16200","-1.92974","1.61175"
"27.26200","-1.89962","1.54741"
"27.36200","-1.86981","1.52143"
"27.46200","-1.83974","1.47768"
"27.56200","-1.80992","1.41439"
"27.66200","-1.77988","1.39485"
"27.76200","-1.75000","1.36525"
"27.86200","-1.71975","1.27987"
"27.96200","-1.68973","1.22955"
"28.06200","-1.65949","1.22180"
"28.16200","-1.62977","1.18610"
"28.26200","-1.59956","1.16307"
"28.36200","-1.56982","1.10593"
"28.46200","-1.53963","1.08624"
"28.56200","-1.50960","1.04690"
"28.66200","-1.47959","1.02419"
"28.76200","-1.44979","0.99540"
"28.86200","-1.41981","0.96902"
"28.96200","-1.39000","0.93488"
"29.06200","-1.35975","0.91609"
"29.16200","-1.32979","0.89078"
"29.26200","-1.29972","0.84134"
"29.36200","-1.26966","0.82500"
"29.46200","-1.23964","0.80045"
"29.56200","-1.20960","0.78968"
"29.66200","-1.17955","0.74849"
"29.76200","-1.14942","0.74249"
"29.86200","-1.11965","0.73871"
"29.96200","-1.08976","0.69420"
"30.06200","-1.06002","0.63315"
"30.16200","-1.02983","0.71231"
"30.26200","-0.99985","0.66333"
"30.36200","-0.96975","0.58902"
"30.46200","-0.93987","0.57202"
"30.56200","-0.90963","0.56108"
"30.66200","-0.87971","0.57670"
"30.76200","-0.84965","0.51672"
"30.86200","-0.81964","0.51726"
"30.96200","-0.78951","0.47591"
"31.06200","-0.75960","0.47511"
"31.16200","-0.72968","0.45767"
"31.26200","-0.69974","0.42145"
"31.36200","-0.66974","0.39915"
"31.46200","-0.63983","0.39706"
"31.56200","-0.60988","0.39503"
"31.66200","-0.57988","0.36771"
"31.76200","-0.54980","0.33815"
"31.86200","-0.51968","0.31581"
"31.96200","-0.48957","0.31755"
"32.06200","-0.45943","0.26434"
"32.16200","-0.42953","0.25853"
"32.26200","-0.39961","0.26930"
"32.36200","-0.36978","0.24314"
"32.46200","-0.33968","0.20637"
"32.56200","-0.30976","0.20773"
"32.66200","-0.27969","0.20320"
"32.76200","-0.24993","0.18788"
"32.86200","-0.21975","0.16568"
"32.96200","-0.18993","0.14944"
"33.06200","-0.15959","0.12336"
"33.16200","-0.12978","0.12167"
"33.26200","-0.09962","0.11902"
"33.36200","-0.06967","0.09611"
"33.46200","-0.03966","0.06811"
"33.56200","-0.00970","0.04485"
"33.66200","0.02049","0.05776"
"33.76200","0.05039","-0.00069"
"33.86200","0.08034","0.00251"
"33.96200","0.11012","-0.00716"
"34.06200","0.14005","-0.02298"
"34.16200","0.17010","-0.03523"
"34.26200","0.20021","-0.05488"
"34.36200","0.23037","-0.05708"
"34.46200","0.26035","-0.07407"
"34.56200","0.29038","-0.09910"
"34.66200","0.32030","-0.10729"
"34.76200","0.35043","-0.11181"
"34.86200","0.38042","-0.13433"
"34.96200","0.41042","-0.12069"
"35.06200","0.44023","-0.09950"
"35.16200","0.47029","-0.19427"
"35.26200","0.50009","-0.22053"
"35.36200","0.53036","-0.21588"
"35.46200","0.56010","-0.23646"
"35.56200","0.59018","-0.26289"
"35.66200","0.62014","-0.27733"
"35.76200","0.65025","-0.28934"
"35.86200","0.68024","-0.30561"
"35.96200","0.71052","-0.33474"
"36.06200","0.74034","-0.32670"
"36.16200","0.77046","-0.35045"
"36.26200","0.80032","-0.36871"
"36.36200","0.83028","-0.38750"
"36.46200","0.86018","-0.38932"
"36.56200","0.89020","-0.40920"
"36.66200","0.92012","-0.43383"
"36.76200","0.95013","-0.43148"
"36.86200","0.98019","-0.44596"
"36.96200","1.01023","-0.49364"
"37.06200","1.04042","-0.51009"
"37.16200","1.07043","-0.54087"
"37.26200","1.10037","-0.56268"
"37.36200","1.13028","-0.58499"
"37.46200","1.16035","-0.59996"
"37.56200","1.19011","-0.61023"
"37.66200","1.22051","-0.65000"
"37.76200","1.25017","-0.65889"
"37.86200","1.28023","-0.66389"
"37.96200","1.31007","-0.68794"
"38.06200","1.34013","-0.71425"
"38.16200","1.37010","-0.74363"
"38.26200","1.40037","-0.74265"
"38.36200","1.43020","-0.77740"
"38.46200","1.46046","-0.80508"
"38.56200","1.49028","-0.83111"
"38.66200","1.52048","-0.86912"
"38.76200","1.55039","-0.91816"
"38.86200","1.58052","-0.92664"
"38.96200","1.61028","-0.98666"
"39.06200","1.64015","-1.03672"
"39.16200","1.67007","-1.06629"
"39.26200","1.70007","-1.08197"
"39.36200","1.73028","-1.11895"
"39.46200","1.76029","-1.15663"
"39.56200","1.79034","-1.20019"
"39.66200","1.82030","-1.21078"
"39.76200","1.85030","-1.28155"
"39.86200","1.88019","-1.31706"
"39.96200","1.91048","-1.34580"
"40.06200","1.94035","-1.41141"
"40.16200","1.97048","-1.45883"
"40.26200","2.00015","-1.50164"
"40.36200","2.03027","-1.54371"
"40.46200","2.06002","-1.61734"
"40.56200","2.09025","-1.66136"
"40.66200","2.11999","-1.71398"
"40.76200","2.15033","-1.80345"
"40.86200","2.18011","-1.87844"
"40.96200","2.21041","-1.95938"
"41.06200","2.24039","-2.01738"
"41.16200","2.27064","-2.10475"
"41.26200","2.30043","-2.17371"
"41.36200","2.33042","-2.29366"
"41.46200","2.36019","-2.40350"
"41.56200","2.39017","-2.49785"
"41.66200","2.42037","-2.63623"
"41.76200","2.45021","-2.73947"
"41.86200","2.48017","-2.87227"
"41.92800","2.50003","-3.00365"
"41.93000","2.50063","-3.00580"
"42.03000","2.50154","-3.03166"
"42.13000","2.47010","-2.82162"
"42.23000","2.43936","-2.67753"
"42.33000","2.40940","-2.55607"
"42.43000","2.37913","-2.44136"
"42.53000","2.34943","-2.32516"
"42.63000","2.31938","-2.22660"
"42.73000","2.28946","-2.15173"
"42.83000","2.25929","-2.04398"
"42.93000","2.22930","-1.96198"
"43.03000","2.19909","-1.88676"
"43.13000","2.16926","-1.82324"
"43.23000","2.13915","-1.69538"
"43.33000","2.10918","-1.65886"
"43.43000","2.07907","-1.61871"
"43.53000","2.04898","-1.52495"
"43.63000","2.01915","-1.50002"
"43.73000","1.98929","-1.43885"
"43.83000","1.95945","-1.39254"
"43.93000","1.92934","-1.34332"
"44.03000","1.89928","-1.31953"
"44.13000","1.86918","-1.26969"
"44.23000","1.83924","-1.21391"
"44.33000","1.80921","-1.16733"
"44.43000","1.77937","-1.14825"
"44.53000","1.74922","-1.10599"
"44.63000","1.71913","-1.07121"
"44.73000","1.68895","-1.02867"
"44.83000","1.65921","-1.02021"
"44.93000","1.62918","-0.96836"
"45.03000","1.59944","-0.90891"
"45.13000","1.56935","-0.88800"
"45.23000","1.53933","-0.85094"
"45.33000","1.50926","-0.81522"
"45.43000","1.47941","-0.77618"
"45.53000","1.44924","-0.77411"
"45.63000","1.41926","-0.73265"
"45.73000","1.38910","-0.71643"
"45.83000","1.35906","-0.69603"
"45.93000","1.32898","-0.66171"
"46.03000","1.29924","-0.63371"
"46.13000","1.26920","-0.61995"
"46.23000","1.23926","-0.62310"
"46.33000","1.20928","-0.58238"
"46.43000","1.17922","-0.57068"
"46.53000","1.14930","-0.55804"
"46.63000","1.11932","-0.53375"
"46.73000","1.08938","-0.49588"
"46.83000","1.05928","-0.48655"
"46.93000","1.02917","-0.44840"
"47.03000","0.99909","-0.43161"
"47.13000","0.96930","-0.40575"
"47.23000","0.93909","-0.41095"
"47.33000","0.90925","-0.38864"
"47.43000","0.87913","-0.37087"
"47.53000","0.84914","-0.35927"
"47.63000","0.81916","-0.34280"
"47.73000","0.78946","-0.32573"
"47.83000","0.75937","-0.30744"
"47.93000","0.72936","-0.29377"
"48.03000","0.69917","-0.27365"
"48.13000","0.66923","-0.25598"
"48.23000","0.63909","-0.23858"
"48.33000","0.60933","-0.23362"
"48.43000","0.57907","-0.20026"
"48.53000","0.54918","-0.18497"
"48.63000","0.51913","-0.18014"
"48.73000","0.48913","-0.16422"
"48.83000","0.45928","-0.05607"
"48.93000","0.42938","-0.09875"
"49.03000","0.39939","-0.10963"
"49.13000","0.36926","-0.08668"
"49.23000","0.33926","-0.06912"
"49.33000","0.30922","-0.06651"
"49.43000","0.27943","-0.06009"
"49.53000","0.24920","-0.02251"
"49.63000","0.21931","-0.02668"
"49.73000","0.18908","0.00389"
"49.83000","0.15903","0.01173"
"49.93000","0.12904","0.02524"
"50.03000","0.09934","0.03002"
"50.13000","0.06927","0.04290"
"50.23000","0.03942","0.07633"
"50.33000","0.00916","0.08656"
"50.43000","-0.02050","0.10775"
"50.53000","-0.05068","0.11511"
"50.63000","-0.08052","0.14625"
"50.73000","-0.11086","0.14165"
"50.83000","-0.14083","0.16011"
"50.93000","-0.17096","0.18642"
"51.03000","-0.20079","0.17672"
"51.13000","-0.23088","0.20391"
"51.23000","-0.26079","0.22862"
"51.33000","-0.29077","0.23839"
"51.43000","-0.32084","0.25790"
"51.53000","-0.35078","0.26973"
"51.63000","-0.38072","0.29424"
"51.73000","-0.41055","0.29522"
"51.83000","-0.44065","0.30515"
"51.93000","-0.47060","0.33868"
"52.03000","-0.50089","0.35285"
"52.13000","-0.53085","0.38287"
"52.23000","-0.56086","0.39143"
"52.33000","-0.59076","0.42002"
"52.43000","-0.62089","0.41203"
"52.53000","-0.65070","0.44468"
"52.63000","-0.68091","0.45039"
"52.73000","-0.71076","0.47720"
"52.83000","-0.74066","0.48158"
"52.93000","-0.77045","0.50951"
"53.03000","-0.80069","0.53858"
"53.13000","-0.83064","0.56302"
"53.23000","-0.86093","0.58192"
"53.33000","-0.89084","0.60017"
"53.43000","-0.92077","0.62746"
"53.53000","-0.95076","0.62957"
"53.63000","-0.98085","0.66504"
"53.73000","-1.01092","0.68069"
"53.83000","-1.04097","0.70388"
"53.93000","-1.07088","0.72237"
"54.03000","-1.10067","0.76264"
"54.13000","-1.13068","0.77154"
"54.23000","-1.16060","0.77307"
"54.33000","-1.19079","0.80009"
"54.43000","-1.22074","0.81675"
"54.53000","-1.25070","0.84990"
"54.63000","-1.28066","0.86655"
"54.73000","-1.31084","0.90836"
"54.83000","-1.34069","0.93140"
"54.93000","-1.37107","0.96053"
"55.03000","-1.40094","0.98966"
"55.13000","-1.43081","1.01642"
"55.23000","-1.46064","1.03918"
"55.33000","-1.49076","1.06469"
"55.43000","-1.52067","1.10513"
"55.53000","-1.55075","1.12964"
"55.63000","-1.58071","1.15686"
"55.73000","-1.61069","1.19436"
"55.83000","-1.64068","1.22197"
"55.93000","-1.67072","1.25432"
"56.03000","-1.70089","1.28316"
"56.13000","-1.73088","1.33858"
"56.23000","-1.76085","1.41442"
"56.33000","-1.79092","1.44313"
"56.43000","-1.82087","1.47413"
"56.53000","-1.85074","1.52746"
"56.63000","-1.88096","1.56119"
"56.73000","-1.91063","1.61247"
"56.83000","-1.94066","1.67633"
"56.93000","-1.97049","1.72702"
"57.03000","-2.00074","1.75660"
"57.13000","-2.03070","1.81735"
"57.23000","-2.06088","1.86808"
"57.33000","-2.09082","1.94593"
"57.43000","-2.12079","2.00994"
"57.53000","-2.15073","2.07650"
"57.63000","-2.18085","2.14879"
"57.73000","-2.21066","2.20996"
"57.83000","-2.24096","2.28825"
"57.93000","-2.27059","2.37327"
"58.03000","-2.30058","2.46365"
"58.13000","-2.33061","2.57157"
"58.23000","-2.36072","2.69820"
"58.33000","-2.39080","2.80247"
"58.43000","-2.42076","2.92266"
"58.53000","-2.45072","3.06649"
"58.63000","-2.48079","3.25050"
"58.69500","-2.50027","3.31120"
"58.69700","-2.50089","3.31654"
"58.79700","-2.50276","3.32827"
"58.89700","-2.47045","3.15955"
"58.99700","-2.44006","3.00950"
"59.09700","-2.40967","2.86795"
"59.19700","-2.37978","2.74024"
"59.29700","-2.34947","2.63958"
"59.39700","-2.31976","2.52160"
"59.49700","-2.28963","2.42468"
"59.59700","-2.25983","2.32073"
"59.69700","-2.22976","2.26666"
"59.79700","-2.19977","2.15253"
"59.89700","-2.16981","2.07699"
"59.99700","-2.13996","2.01610"
"60.09700","-2.10978","1.96192"
"60.19700","-2.07991","1.89087"
"60.29700","-2.04967","1.79530"
"60.39700","-2.01956","1.76718"
"60.49700","-1.98965","1.73559"
"60.59700","-1.95955","1.66312"
"60.69700","-1.92975","1.61266"
"60.79700","-1.89968","1.58285"
"60.89700","-1.86984","1.51850"
"60.99700","-1.83978","1.46901"
"61.09700","-1.80995","1.45159"
"61.19700","-1.77991","1.42292"
"61.29700","-1.75002","1.36123"
"61.39700","-1.71976","1.26058"
"61.49700","-1.68978","1.23070"
"61.59700","-1.65950","1.20117"
"61.69700","-1.62983","1.16692"
"61.79700","-1.59958","1.14489"
"61.89700","-1.56984","1.11533"
"61.99700","-1.53967","1.07662"
"62.09700","-1.50962","1.05395"
"62.19700","-1.47960","1.02205"
"62.29700","-1.44982","0.99772"
"62.39700","-1.41986","0.97693"
"62.49700","-1.38999","0.95345"
"62.59700","-1.35979","0.93188"
"62.69700","-1.32982","0.89073"
"62.79700","-1.29975","0.86737"
"62.89700","-1.26968","0.83505"
"62.99700","-1.23967","0.80429"
"63.09700","-1.20961","0.77364"
"63.19700","-1.17959","0.76441"
"63.29700","-1.14943","0.74027"
"63.39700","-1.11969","0.72136"
"63.49700","-1.08977","0.69816"
"63.59700","-1.06004","0.68185"
"63.69700","-1.02990","0.64767"
"63.79700","-0.99994","0.61172"
"63.89700","-0.96974","0.62141"
"63.99700","-0.93986","0.60690"
"64.09700","-0.90956","0.57108"
"64.19700","-0.87985","0.56307"
"64.29700","-0.84969","0.55741"
"64.39700","-0.81966","0.51817"
"64.49700","-0.78952","0.48655"
"64.59700","-0.75968","0.47584"
"64.69700","-0.72970","0.46134"
"64.79700","-0.69977","0.39623"
"64.89700","-0.66980","0.40192"
"64.99700","-0.63987","0.38879"
"65.09700","-0.60983","0.37186"
"65.19700","-0.57994","0.35658"
"65.29700","-0.54982","0.34680"
"65.39700","-0.51972","0.31869"
"65.49700","-0.48956","0.28584"
"65.59700","-0.45946","0.28946"
"65.69700","-0.42955","0.28002"
"65.79700","-0.39961","0.27009"
"65.89700","-0.36981","0.24914"
"65.99700","-0.33968","0.24426"
"66.09700","-0.30980","0.22153"
"66.19700","-0.27973","0.20533"
"66.29700","-0.24998","0.17970"
"66.39700","-0.21976","0.15575"
"66.49700","-0.18995","0.13837"
"66.59700","-0.15961","0.11592"
"66.69700","-0.12981","0.12783"
"66.79700","-0.09964","0.10490"
"66.89700","-0.06974","0.08787"
"66.99700","-0.03969","0.05958"
"67.09700","-0.00970","0.06753"
"67.19700","0.02045","0.03728"
"67.29700","0.05037","0.02487"
"67.39700","0.08033","0.01352"
"67.49700","0.11007","0.00786"
"67.59700","0.14001","-0.01145"
"67.69700","0.17009","-0.00860"
"67.79700","0.20018","-0.03105"
"67.89700","0.23033","-0.06020"
"67.99700","0.26030","-0.07992"
"68.09700","0.29035","-0.08839"
"68.19700","0.32026","-0.10533"
"68.29700","0.35040","-0.15491"
"68.39700","0.38038","-0.13365"
"68.49700","0.41040","-0.13275"
"68.59700","0.44019","-0.11418"
"68.69700","0.47024","-0.20328"
"68.79700","0.50005","-0.21077"
"68.89700","0.53032","-0.22738"
"68.99700","0.56008","-0.24584"
"69.09700","0.59014","-0.24596"
"69.19700","0.62009","-0.27314"
"69.29700","0.65027","-0.27985"
"69.39700","0.68022","-0.30102"
"69.49700","0.71051","-0.31979"
"69.59700","0.74030","-0.34487"
"69.69700","0.77043","-0.36457"
"69.79700","0.80029","-0.37954"
"69.89700","0.83024","-0.39740"
"69.99700","0.86015","-0.42388"
"70.09700","0.89016","-0.42732"
"70.19700","0.92009","-0.43355"
"70.29700","0.95012","-0.45390"
"70.39700","0.98016","-0.46782"
"70.49700","1.01021","-0.49989"
"70.59700","1.04041","-0.48971"
"70.69700","1.07039","-0.54035"
"70.79700","1.10034","-0.55216"
"70.89700","1.13022","-0.55215"
"70.99700","1.16033","-0.58658"
"71.09700","1.19009","-0.60762"
"71.19700","1.22047","-0.63124"
"71.29700","1.25013","-0.63439"
"71.39700","1.28020","-0.66842"
"71.49700","1.31011","-0.70624"
"71.59700","1.34007","-0.71374"
"71.69700","1.37008","-0.75050"
"71.79700","1.40035","-0.77318"
"71.89700","1.43016","-0.78858"
"71.99700","1.46040","-0.82084"
"72.09700","1.49022","-0.84636"
"72.19700","1.52047","-0.89120"
"72.29700","1.55036","-0.88348"
"72.39700","1.58048","-0.92423"
"72.49700","1.61024","-0.98308"
"72.59700","1.64011","-1.00659"
"72.69700","1.67006","-1.02499"
"72.79700","1.70003","-1.07850"
"72.89700","1.73025","-1.11882"
"72.99700","1.76029","-1.13531"
"73.09700","1.79029","-1.18366"
"73.19700","1.82026","-1.22700"
"73.29700","1.85028","-1.27442"
"73.39700","1.88014","-1.31688"
"73.49700","1.91042","-1.37172"
"73.59700","1.94034","-1.41016"
"73.69700","1.97048","-1.45420"
"73.79700","2.00012","-1.52521"
"73.89700","2.03022","-1.55327"
"73.99700","2.06000","-1.59716"
"74.09700","2.09017","-1.64469"
"74.19700","2.12004","-1.72506"
"74.29700","2.15026","-1.79682"
"74.39700","2.18008","-1.84814"
"74.49700","2.21043","-1.93777"
"74.59700","2.24036","-2.01887"
"74.69700","2.27061","-2.08866"
"74.79700","2.30040","-2.18701"
"74.89700","2.33039","-2.31025"
"74.99700","2.36016","-2.40859"
"75.09700","2.39019","-2.48580"
"75.19700","2.42031","-2.65605"
"75.29700","2.45019","-2.78648"
"75.39700","2.48016","-2.92060"
"75.46300","2.50000","-3.01672"
"75.46500","2.50060","-3.01668"
"75.56500","2.50152","-3.03622"
"75.66500","2.47005","-2.84824"
"75.76500","2.43934","-2.71760"
"75.86500","2.40935","-2.55535"
"75.96500","2.37909","-2.45295"
"76.06500","2.34939","-2.35497"
"76.16500","2.31935","-2.22368"
"76.26500","2.28942","-2.13982"
"76.36500","2.25927","-2.04626"
"76.46500","2.22926","-1.96511"
"76.56500","2.19907","-1.87863"
"76.66500","2.16920","-1.80251"
"76.76500","2.13914","-1.72985"
"76.86500","2.10916","-1.66094"
"76.96500","2.07903","-1.59740"
"77.06500","2.04895","-1.55928"
"77.16500","2.01911","-1.51293"
"77.26500","1.98929","-1.45304"
"77.36500","1.95942","-1.39233"
"77.46500","1.92928","-1.37322"
"77.56500","1.89926","-1.31617"
"77.66500","1.86911","-1.27472"
"77.76500","1.83922","-1.21679"
"77.86500","1.80916","-1.19458"
"77.96500","1.77933","-1.13152"
"78.06500","1.74916","-1.10275"
"78.16500","1.71910","-1.07141"
"78.26500","1.68892","-1.01903"
"78.36500","1.65919","-1.00571"
"78.46500","1.62913","-0.95849"
"78.56500","1.59939","-0.91037"
"78.66500","1.56932","-0.86115"
"78.76500","1.53931","-0.85614"
"78.86500","1.50923","-0.83213"
"78.96500","1.47938","-0.78160"
"79.06500","1.44918","-0.77001"
"79.16500","1.41924","-0.74198"
"79.26500","1.38904","-0.72783"
"79.36500","1.35902","-0.68724"
"79.46500","1.32895","-0.66694"
"79.56500","1.29919","-0.64784"
"79.66500","1.26917","-0.62740"
"79.76500","1.23922","-0.59838"
"79.86500","1.20925","-0.58571"
"79.96500","1.17920","-0.57381"
"80.06500","1.14925","-0.54194"
"80.16500","1.11929","-0.52364"
"80.26500","1.08934","-0.51908"
"80.36500","1.05921","-0.48132"
"80.46500","1.02913","-0.46883"
"80.56500","0.99906","-0.43979"
"80.66500","0.96928","-0.42733"
"80.76500","0.93905","-0.40856"
"80.86500","0.90921","-0.39779"
"80.96500","0.87905","-0.40247"
"81.06500","0.84913","-0.34947"
"81.16500","0.81910","-0.35269"
"81.26500","0.78941","-0.33750"
"81.36500","0.75935","-0.31274"
"81.46500","0.72933","-0.28731"
"81.56500","0.69913","-0.26731"
"81.66500","0.66918","-0.26236"
"81.76500","0.63906","-0.23845"
"81.86500","0.60930","-0.20725"
"81.96500","0.57902","-0.19878"
"82.06500","0.54916","-0.19978"
"82.16500","0.51907","-0.16439"
"82.26500","0.48909","-0.15854"
"82.36500","0.45921","-0.07229"
"82.46500","0.42936","-0.11410"
"82.56500","0.39937","-0.09955"
"82.66500","0.36922","-0.11423"
"82.76500","0.33922","-0.08475"
"82.86500","0.30918","-0.07089"
"82.96500","0.27939","-0.05104"
"83.06500","0.24917","-0.03869"
"83.16500","0.21925","-0.01374"
"83.26500","0.18906","0.00467"
"83.36500","0.15897","0.01395"
"83.46500","0.12902","0.02791"
"83.56500","0.09928","0.03496"
"83.66500","0.06924","0.05560"
"83.76500","0.03939","0.06732"
"83.86500","0.00913","0.08912"
"83.96500","-0.02055","0.09041"
"84.06500","-0.05071","0.11624"
"84.16500","-0.08057","0.12100"
"84.26500","-0.11089","0.15960"
"84.36500","-0.14087","0.16047"
"84.46500","-0.17099","0.15616"
"84.56500","-0.20093","0.17588"
"84.66500","-0.23081","0.19559"
"84.76500","-0.26081","0.21594"
"84.86500","-0.29081","0.23027"
"84.96500","-0.32089","0.26988"
"85.06500","-0.35082","0.26391"
"85.16500","-0.38073","0.28347"
"85.26500","-0.41053","0.29580"
"85.36500","-0.44074","0.31909"
"85.46500","-0.47067","0.31592"
"85.56500","-0.50092","0.34849"
"85.66500","-0.53086","0.37138"
"85.76500","-0.56090","0.37584"
"85.86500","-0.59079","0.38800"
"85.96500","-0.62091","0.39978"
"86.06500","-0.65082","0.42397"
"86.16500","-0.68097","0.43047"
"86.26500","-0.71063","0.46501"
"86.36500","-0.74077","0.48158"
"86.46500","-0.77050","0.50958"
"86.56500","-0.80071","0.52589"
"86.66500","-0.83077","0.56041"
"86.76500","-0.86090","0.58039"
"86.86500","-0.89086","0.59382"
"86.96500","-0.92080","0.61830"
"87.06500","-0.95079","0.62729"
"87.16500","-0.98090","0.65506"
"87.26500","-1.01099","0.66218"
"87.36500","-1.04099","0.70097"
"87.46500","-1.07089","0.71341"
"87.56500","-1.10073","0.73309"
"87.66500","-1.13072","0.75169"
"87.76500","-1.16063","0.77055"
"87.86500","-1.19085","0.78473"
"87.96500","-1.22074","0.80223"
"88.06500","-1.25075","0.83999"
"88.16500","-1.28070","0.87234"
"88.26500","-1.31088","0.88021"
"88.36500","-1.34086","0.92757"
"88.46500","-1.37103","0.95725"
"88.56500","-1.40097","0.98372"
"88.66500","-1.43083","0.98372"
"88.76500","-1.46071","1.02104"
"88.86500","-1.49077","1.06216"
"88.96500","-1.52070","1.06799"
"89.06500","-1.55078","1.12584"
"89.16500","-1.58076","1.15688"
"89.26500","-1.61077","1.19081"
"89.36500","-1.64072","1.20803"
"89.46500","-1.67076","1.25037"
"89.56500","-1.70093","1.27080"
"89.66500","-1.73090","1.32478"
"89.76500","-1.76093","1.42082"
"89.86500","-1.79089","1.44031"
"89.96500","-1.82092","1.46434"
"90.06500","-1.85079","1.50414"
"90.16500","-1.88099","1.55558"
"90.26500","-1.91065","1.60203"
"90.36500","-1.94068","1.65792"
"90.46500","-1.97051","1.70211"
"90.56500","-2.00078","1.76218"
"90.66500","-2.03074","1.80777"
"90.76500","-2.06093","1.87055"
"90.86500","-2.09087","1.92321"
"90.96500","-2.12079","2.00614"
"91.06500","-2.15080","2.06119"
"91.16500","-2.18087","2.13290"
"91.26500","-2.21083","2.22770"
"91.36500","-2.24085","2.29635"
"91.46500","-2.27068","2.35552"
"91.56500","-2.30063","2.47613"
"91.66500","-2.33061","2.55589"
"91.76500","-2.36073","2.66537"
"91.86500","-2.39085","2.78028"
"91.96500","-2.42079","2.91887"
"92.06500","-2.45074","3.04413"
"92.16500","-2.48085","3.20562"
"92.23000","-2.50028","3.31691"
"92.23200","-2.50090","3.31943"
"92.33200","-2.50251","3.33453"
"92.43200","-2.47054","3.17354"
"92.53200","-2.44011","3.00129"
"92.63200","-2.40971","2.85369"
"92.73200","-2.37985","2.77035"
"92.83200","-2.34951","2.62232"
"92.93200","-2.31980","2.50560"
"93.03200","-2.28966","2.41342"
"93.13200","-2.25986","2.32032"
"93.23200","-2.22978","2.23257"
"93.33200","-2.19984","2.14853"
"93.43200","-2.16984","2.09355"
"93.53200","-2.14001","2.00782"
"93.63200","-2.10984","1.95629"
"93.73200","-2.07995","1.88073"
"93.83200","-2.04971","1.82412"
"93.93200","-2.01961","1.75185"
"94.03200","-1.98970","1.72051"
"94.13200","-1.95961","1.65773"
"94.23200","-1.92976","1.61256"
"94.33200","-1.89975","1.55566"
"94.43200","-1.86989","1.50488"
"94.53200","-1.83979","1.48515"
"94.63200","-1.81003","1.42522"
"94.73200","-1.77997","1.38830"
"94.83200","-1.75006","1.37294"
"94.93200","-1.71979","1.27723"
"95.03200","-1.68981","1.23284"
"95.13200","-1.65958","1.20172"
"95.23200","-1.62985","1.18539"
"95.33200","-1.59962","1.14232"
"95.43200","-1.56989","1.09869"
"95.53200","-1.53972","1.08185"
"95.63200","-1.50968","1.04919"
"95.73200","-1.47965","1.00402"
"95.83200","-1.44989","0.99547"
"95.93200","-1.41990","0.96336"
"96.03200","-1.39001","0.94467"
"96.13200","-1.35985","0.91886"
"96.23200","-1.32988","0.89922"
"96.33200","-1.29980","0.86390"
"96.43200","-1.26974","0.84585"
"96.53200","-1.23971","0.81030"
"96.63200","-1.20965","0.80230"
"96.73200","-1.17964","0.77239"
"96.83200","-1.14948","0.74928"
"96.93200","-1.11974","0.73510"
"97.03200","-1.08982","0.70400"
"97.13200","-1.06005","0.67675"
"97.23200","-1.02993","0.64490"
"97.33200","-1.00002","0.62922"
"97.43200","-0.96981","0.60375"
"97.53200","-0.93994","0.58883"
"97.63200","-0.90957","0.57019"
"97.73200","-0.87988","0.56599"
"97.83200","-0.84971","0.52924"
"97.93200","-0.81972","0.51863"
"98.03200","-0.78956","0.51286"
"98.13200","-0.75973","0.47983"
"98.23200","-0.72975","0.45787"
"98.33200","-0.69982","0.42231"
"98.43200","-0.66982","0.41665"
"98.53200","-0.63994","0.38103"
"98.63200","-0.60987","0.38390"
"98.73200","-0.57996","0.36308"
"98.83200","-0.54988","0.34055"
"98.93200","-0.51983","0.30128"
"99.03200","-0.48955","0.29476"
"99.13200","-0.45948","0.27599"
"99.23200","-0.42965","0.26340"
"99.33200","-0.39967","0.25584"
"99.43200","-0.36983","0.23179"
"99.53200","-0.33973","0.23816"
"99.63200","-0.30984","0.20510"
"99.73200","-0.27977","0.21604"
"99.83200","-0.25000","0.17602"
"99.93200","-0.21983","0.15434"
"100.03200","-0.19002","0.15000"
"100.13200","-0.15967","0.15114"
"100.23200","-0.12986","0.12473"
"100.33200","-0.09972","0.09833"
"100.43200","-0.06976","0.09584"
"100.53200","-0.03974","0.06740"
"100.63200","-0.00977","0.04408"
"100.73200","0.02043","0.03753"
"100.83200","0.05035","0.01725"
"100.93200","0.08027","-0.01461"
"101.03200","0.11003","-0.01116"
"101.13200","0.13996","-0.00813"
"101.23200","0.17004","-0.01547"
"101.33200","0.20016","-0.04285"
"101.43200","0.23030","-0.05601"
"101.53200","0.26028","-0.07288"
"101.63200","0.29030","-0.08924"
"101.73200","0.32022","-0.10621"
"101.83200","0.35037","-0.12106"
"101.93200","0.38033","-0.13347"
"102.03200","0.41037","-0.14166"
"102.13200","0.44015","-0.09795"
"102.23200","0.47019","-0.19492"
"102.33200","0.50001","-0.22538"
"102.43200","0.53026","-0.24410"
"102.53200","0.56006","-0.23617"
"102.63200","0.59014","-0.26244"
"102.73200","0.62003","-0.28986"
"102.83200","0.65022","-0.28875"
"102.93200","0.68017","-0.28885"
"103.03200","0.71046","-0.31223"
"103.13200","0.74023","-0.32064"
"103.23200","0.77042","-0.33988"
"103.33200","0.80022","-0.37721"
"103.43200","0.83018","-0.37553"
"103.53200","0.86011","-0.40448"
"103.63200","0.89013","-0.40601"
"103.73200","0.92007","-0.44975"
"103.83200","0.95005","-0.43347"
"103.93200","0.98011","-0.46521"
"104.03200","1.01016","-0.51065"
"104.13200","1.04033","-0.52549"
"104.23200","1.07036","-0.54182"
"104.33200","1.10028","-0.55465"
"104.43200","1.13019","-0.58314"
"104.53200","1.16029","-0.59687"
"104.63200","1.19004","-0.60229"
"104.73200","1.22046","-0.62899"
"104.83200","1.25012","-0.64448"
"104.93200","1.28021","-0.66118"
"105.03200","1.30999","-0.68650"
"105.13200","1.34006","-0.71096"
"105.23200","1.37003","-0.74182"
"105.33200","1.40031","-0.75482"
"105.43200","1.43015","-0.78059"
"105.53200","1.46038","-0.81973"
"105.63200","1.49018","-0.83499"
"105.73200","1.52044","-0.88803"
"105.83200","1.55029","-0.90653"
"105.93200","1.58043","-0.92471"
"106.03200","1.61019","-0.96255"
"106.13200","1.64007","-1.01599"
"106.23200","1.67000","-1.04242"
"106.33200","1.69998","-1.07306"
"106.43200","1.73020","-1.09559"
"106.53200","1.76029","-1.15956"
"106.63200","1.79022","-1.18691"
"106.73200","1.82022","-1.21424"
"106.83200","1.85021","-1.27385"
"106.93200","1.88010","-1.31744"
"107.03200","1.91039","-1.35451"
"107.13200","1.94027","-1.39081"
"107.23200","1.97044","-1.47094"
"107.33200","2.00008","-1.50848"
"107.43200","2.03017","-1.56142"
"107.53200","2.05995","-1.60940"
"107.63200","2.09005","-1.66817"
"107.73200","2.12004","-1.72481"
"107.83200","2.15012","-1.80706"
"107.93200","2.18012","-1.86104"
"108.03200","2.21037","-1.93887"
"108.13200","2.24032","-2.00950"
"108.23200","2.27056","-2.09698"
"108.33200","2.30037","-2.18879"
"108.43200","2.33032","-2.28204"
"108.53200","2.36010","-2.40618"
"108.63200","2.39018","-2.49471"
"108.73200","2.42023","-2.66010"
"108.83200","2.45014","-2.73530"
"108.93200","2.48011","-2.90556"
"108.99900","2.50023","-3.05988"
"109.00100","2.50082","-3.06289"
"109.10100","2.50186","-3.04884"
"109.20100","2.47037","-2.84736"
"109.30100","2.43963","-2.69565"
"109.40100","2.40968","-2.56453"
"109.50100","2.37936","-2.45515"
"109.60100","2.34971","-2.36235"
"109.70100","2.31964","-2.24149"
"109.80100","2.28978","-2.16057"
"109.90100","2.25956","-2.05559"
"110.00100","2.22958","-1.95170"
"110.10100","2.19938","-1.87823"
"110.20100","2.16951","-1.80208"
"110.30100","2.13942","-1.73163"
"110.40100","2.10944","-1.65385"
"110.50100","2.07934","-1.61832"
"110.60100","2.04927","-1.54313"
"110.70100","2.01943","-1.49238"
"110.80100","1.98960","-1.45344"
"110.90100","1.95974","-1.40316"
"111.00100","1.92958","-1.36265"
"111.10100","1.89960","-1.30737"
"111.20100","1.86940","-1.28159"
"111.30100","1.83952","-1.22152"
"111.40100","1.80949","-1.17922"
"111.50100","1.77966","-1.14756"
"111.60100","1.74943","-1.11862"
"111.70100","1.71941","-1.07907"
"111.80100","1.68923","-1.03135"
"111.90100","1.65952","-1.01514"
"112.00100","1.62946","-0.97736"
"112.10100","1.59970","-0.91907"
"112.20100","1.56964","-0.88423"
"112.30100","1.53961","-0.86333"
"112.40100","1.50954","-0.82429"
"112.50100","1.47966","-0.80320"
"112.60100","1.44950","-0.77490"
"112.70100","1.41956","-0.75559"
"112.80100","1.38936","-0.70318"
"112.90100","1.35934","-0.71296"
"113.00100","1.32927","-0.68563"
"113.10100","1.29950","-0.65318"
"113.20100","1.26950","-0.62812"
"113.30100","1.23953","-0.62681"
"113.40100","1.20957","-0.58782"
"113.50100","1.17949","-0.56479"
"113.60100","1.14957","-0.55208"
"113.70100","1.11959","-0.53451"
"113.80100","1.08965","-0.51347"
"113.90100","1.05952","-0.48221"
"114.00100","1.02948","-0.48135"
"114.10100","0.99936","-0.42160"
"114.20100","0.96954","-0.41877"
"114.30100","0.93936","-0.41359"
"114.40100","0.90951","-0.39298"
"114.50100","0.87939","-0.38151"
"114.60100","0.84946","-0.36967"
"114.70100","0.81943","-0.35723"
"114.80100","0.78974","-0.33716"
"114.90100","0.75965","-0.30551"
"115.00100","0.72963","-0.30509"
"115.10100","0.69946","-0.28732"
"115.20100","0.66951","-0.25701"
"115.30100","0.63936","-0.25617"
"115.40100","0.60961","-0.22521"
"115.50100","0.57934","-0.21384"
"115.60100","0.54945","-0.19102"
"115.70100","0.51937","-0.18635"
"115.80100","0.48941","-0.16127"
"115.90100","0.45953","-0.06819"
"116.00100","0.42969","-0.10764"
"116.10100","0.39968","-0.10945"
"116.20100","0.36956","-0.10311"
"116.30100","0.33952","-0.08363"
"116.40100","0.30951","-0.07550"
"116.50100","0.27971","-0.04785"
"116.60100","0.24949","-0.03140"
"116.70100","0.21955","-0.02596"
"116.80100","0.18933","-0.01970"
"116.90100","0.15934","0.00512"
"117.00100","0.12932","0.02497"
"117.10100","0.09962","0.02584"
"117.20100","0.06956","0.02787"
"117.30100","0.03971","0.07077"
"117.40100","0.00944","0.06715"
"117.50100","-0.02026","0.07930"
"117.60100","-0.05040","0.10682"
"117.70100","-0.08027","0.11877"
"117.80100","-0.11056","0.13207"
"117.90100","-0.14057","0.13775"
"118.00100","-0.17067","0.18002"
"118.10100","-0.20061","0.17048"
"118.20100","-0.23060","0.20560"
"118.30100","-0.26040","0.21829"
"118.40100","-0.29050","0.24779"
"118.50100","-0.32057","0.24942"
"118.60100","-0.35052","0.26913"
"118.70100","-0.38044","0.28006"
"118.80100","-0.41024","0.28406"
"118.90100","-0.44041","0.30561"
"119.00100","-0.47032","0.32480"
"119.10100","-0.50059","0.33230"
"119.20100","-0.53058","0.34411"
"119.30100","-0.56060","0.36959"
"119.40100","-0.59048","0.38536"
"119.50100","-0.62059","0.40248"
"119.60100","-0.65050","0.40648"
"119.70100","-0.68075","0.44778"
"119.80100","-0.71029","0.46352"
"119.90100","-0.74030","0.47669"
"120.00100","-0.77029","0.50601"
"120.10100","-0.80040","0.54305"
"120.20100","-0.83041","0.54729"
"120.30100","-0.86063","0.57299"
"120.40100","-0.89059","0.59751"
"120.50100","-0.92049","0.61534"
"120.60100","-0.95043","0.61526"
"120.70100","-0.98057","0.63325"
"120.80100","-1.01069","0.67555"
"120.90100","-1.04066","0.68256"
"121.00100","-1.07058","0.71543"
"121.10100","-1.10042","0.73979"
"121.20100","-1.13040","0.76123"
"121.30100","-1.16030","0.75278"
"121.40100","-1.19054","0.79877"
"121.50100","-1.22047","0.81930"
"121.60100","-1.25044","0.83735"
"121.70100","-1.28037","0.87545"
"121.80100","-1.31059","0.89609"
"121.90100","-1.34055","0.94252"
"122.00100","-1.37072","0.95037"
"122.10100","-1.40066","0.98199"
"122.20100","-1.43052","1.01252"
"122.30100","-1.46037","1.01045"
"122.40100","-1.49045","1.06086"
"122.50100","-1.52038","1.09101"
"122.60100","-1.55049","1.10995"
"122.70100","-1.58043","1.14879"
"122.80100","-1.61043","1.17074"
"122.90100","-1.64042","1.21819"
"123.00100","-1.67044","1.23791"
"123.10100","-1.70064","1.27992"
"123.20100","-1.73057","1.33167"
"123.30100","-1.76064","1.42874"
"123.40100","-1.79062","1.44052"
"123.50100","-1.82057","1.45438"
"123.60100","-1.85047","1.53329"
"123.70100","-1.88067","1.54641"
"123.80100","-1.91034","1.58908"
"123.90100","-1.94037","1.63423"
"124.00100","-1.97022","1.69858"
"124.10100","-2.00050","1.73074"
"124.20100","-2.03042","1.77848"
"124.30100","-2.06061","1.86462"
"124.40100","-2.09052","1.91489"
"124.50100","-2.12052","1.98416"
"124.60100","-2.15046","2.05009"
"124.70100","-2.18057","2.13877"
"124.80100","-2.21056","2.17441"
"124.90100","-2.24042","2.30611"
"125.00100","-2.27044","2.36322"
"125.10100","-2.30031","2.45587"
"125.20100","-2.33031","2.54265"
"125.30100","-2.36042","2.66575"
"125.40100","-2.39055","2.76588"
"125.50100","-2.42047","2.89044"
"125.60100","-2.45042","3.02655"
"125.70100","-2.48056","3.19719"
"125.76700","-2.50027","3.31047"
"125.76900","-2.50089","3.31522"
"125.86900","-2.50283","3.31761"
"125.96900","-2.47050","3.12666"
"126.06900","-2.44011","2.98929"
"126.16900","-2.40969","2.83232"
"126.26900","-2.37983","2.72294"
"126.36900","-2.34950","2.58386"
"126.46900","-2.31978","2.50211"
"126.56900","-2.28964","2.39590"
"126.66900","-2.25988","2.31203"
"126.76900","-2.22977","2.21045"
"126.86900","-2.19982","2.14362"
"126.96900","-2.16983","2.06433"
"127.06900","-2.13998","2.01306"
"127.16900","-2.10983","1.96226"
"127.26900","-2.07992","1.88068"
"127.36900","-2.04971","1.82823"
"127.46900","-2.01962","1.76397"
"127.56900","-1.98972","1.73007"
"127.66900","-1.95959","1.64819"
"127.76900","-1.92975","1.59768"
"127.86900","-1.89974","1.55167"
"127.96900","-1.86987","1.50525"
"128.06900","-1.83980","1.45140"
"128.16900","-1.81000","1.42401"
"128.26900","-1.77997","1.38978"
"128.36900","-1.75005","1.32870"
"128.46900","-1.71977","1.26164"
"128.56900","-1.68981","1.22351"
"128.66900","-1.65958","1.20270"
"128.76900","-1.62984","1.15530"
"128.86900","-1.59961","1.15372"
"128.96900","-1.56990","1.10518"
"129.06900","-1.53969","1.07295"
"129.16900","-1.50967","1.03363"
"129.26900","-1.47963","1.01948"
"129.36900","-1.44989","0.97882"
"129.46900","-1.41991","0.94180"
"129.56900","-1.39000","0.94677"
"129.66900","-1.35982","0.90065"
"129.76900","-1.32986","0.87245"
"129.86900","-1.29979","0.82640"
"129.96900","-1.26971","0.81842"
"130.06900","-1.23970","0.78333"
"130.16900","-1.20968","0.76330"
"130.26900","-1.17963","0.74809"
"130.36900","-1.14947","0.74295"
"130.46900","-1.11975","0.71578"
"130.56900","-1.08980","0.69565"
"130.66900","-1.06006","0.68285"
"130.76900","-1.02992","0.65746"
"130.86900","-1.00004","0.61486"
"130.96900","-0.96972","0.60597"
"131.06900","-0.93991","0.59785"
"131.16900","-0.90970","0.55045"
"131.26900","-0.87982","0.54604"
"131.36900","-0.84970","0.53416"
"131.46900","-0.81972","0.50442"
"131.56900","-0.78954","0.46452"
"131.66900","-0.75971","0.46071"
"131.76900","-0.72972","0.44831"
"131.86900","-0.69984","0.40504"
"131.96900","-0.66978","0.39510"
"132.06900","-0.63997","0.39009"
"132.16900","-0.60991","0.38005"
"132.26900","-0.57992","0.34179"
"132.36900","-0.54986","0.34841"
"132.46900","-0.51972","0.31230"
"132.56900","-0.48962","0.28293"
"132.66900","-0.45948","0.26733"
"132.76900","-0.42964","0.26410"
"132.86900","-0.39964","0.24179"
"132.96900","-0.36984","0.22607"
"133.06900","-0.33974","0.22046"
"133.16900","-0.30982","0.19550"
"133.26900","-0.27976","0.18394"
"133.36900","-0.25002","0.17874"
"133.46900","-0.21981","0.16330"
"133.56900","-0.19000","0.13456"
"133.66900","-0.15966","0.12551"
"133.76900","-0.12985","0.11805"
"133.86900","-0.09968","0.11957"
"133.96900","-0.06976","0.08503"
"134.06900","-0.03972","0.06605"
"134.16900","-0.00978","0.04716"
"134.20300","0.00016","0.00776"