File: SupHysteresis/Specimen_RawData_1.csv
Time,Extension,Load
(s),(mm),(N)
"0.00000","0.00000","-0.02600"
"0.10000","0.01147","0.06108"
"0.20000","0.04568","0.06278"
"0.30000","0.07605","0.16329"
"0.40000","0.10593","0.17191"
"0.50000","0.13609","0.25590"
"0.60000","0.16605","0.27565"
"0.70000","0.19610","0.35350"
"0.80000","0.22603","0.39790"
"0.90000","0.25597","0.44892"
"1.00000","0.28602","0.51736"
"1.10000","0.31601","0.54804"
"1.20000","0.34636","0.62842"
"1.30000","0.37625","0.66970"
"1.40000","0.40618","0.73568"
"1.50000","0.43611","0.78001"
"1.60000","0.46628","0.81456"
"1.70000","0.49605","0.88089"
"1.80000","0.52639","0.91903"
"1.90000","0.55605","0.98441"
"2.00000","0.58613","1.02678"
"2.10000","0.61580","1.09460"
"2.20000","0.64601","1.12581"
"2.30000","0.67596","1.19247"
"2.40000","0.70612","1.24924"
"2.50000","0.73603","1.29636"
"2.60000","0.76638","1.35145"
"2.70000","0.79617","1.39221"
"2.80000","0.82627","1.45005"
"2.90000","0.85612","1.49770"
"3.00000","0.88634","1.57571"
"3.10000","0.91612","1.60397"
"3.20000","0.94605","1.67180"
"3.30000","0.97596","1.71438"
"3.40000","1.00590","1.77758"
"3.50000","1.03617","1.83129"
"3.60000","1.06619","1.88851"
"3.70000","1.09614","1.93798"
"3.80000","1.12608","1.99226"
"3.90000","1.15604","2.04079"
"4.00000","1.18589","2.10184"
"4.10000","1.21636","2.14988"
"4.20000","1.24623","2.22063"
"4.30000","1.27662","2.25545"
"4.40000","1.30591","2.32203"
"4.50000","1.33622","2.36240"
"4.60000","1.36596","2.42760"
"4.70000","1.39611","2.48294"
"4.80000","1.42584","2.54344"
"4.90000","1.45608","2.58232"
"5.00000","1.48589","2.63987"
"5.10000","1.51630","2.68806"
"5.20000","1.54625","2.74547"
"5.30000","1.57647","2.79082"
"5.40000","1.60623","2.85214"
"5.50000","1.63631","2.88814"
"5.60000","1.66608","2.95168"
"5.70000","1.69606","3.00338"
"5.80000","1.72619","3.06816"
"5.90000","1.75610","3.12213"
"6.00000","1.78605","3.18452"
"6.10000","1.81598","3.22217"
"6.20000","1.84607","3.28721"
"6.30000","1.87615","3.33512"
"6.40000","1.90621","3.39583"
"6.50000","1.93620","3.44408"
"6.60000","1.96633","3.50788"
"6.70000","1.99609","3.54657"
"6.80000","2.02630","3.60402"
"6.90000","2.05603","3.66293"
"7.00000","2.08644","3.73169"
"7.10000","2.11596","3.77492"
"7.20000","2.14604","3.84462"
"7.30000","2.17582","3.88191"
"7.40000","2.20609","3.95778"
"7.50000","2.23607","3.99900"
"7.60000","2.26629","4.06583"
"7.70000","2.29620","4.10378"
"7.80000","2.32611","4.16411"
"7.90000","2.35589","4.22076"
"8.00000","2.38633","4.27635"
"8.10000","2.41642","4.33227"
"8.20000","2.44632","4.39171"
"8.30000","2.47613","4.42631"
"8.38100","2.50026","4.49382"
"8.38300","2.50087","4.49484"
"8.48300","2.50232","4.49015"
"8.58300","2.47109","4.43558"
"8.68300","2.44030","4.37738"
"8.78300","2.41023","4.32417"
"8.88300","2.37991","4.26510"
"8.98300","2.35004","4.20088"
"9.08300","2.32004","4.14706"
"9.18300","2.29004","4.10554"
"9.28300","2.25990","4.03771"
"9.38300","2.22984","3.99826"
"9.48300","2.19980","3.91934"
"9.58300","2.17006","3.86415"
"9.68300","2.14018","3.81158"
"9.78300","2.11002","3.75267"
"9.88300","2.08027","3.69925"
"9.98300","2.05008","3.63925"
"10.08300","2.02008","3.57566"
"10.18300","1.99003","3.53379"
"10.28300","1.96024","3.47451"
"10.38300","1.92990","3.43195"
"10.48300","1.90004","3.37234"
"10.58300","1.86981","3.32777"
"10.68300","1.83999","3.26420"
"10.78300","1.80994","3.21879"
"10.88300","1.78020","3.16091"
"10.98300","1.75009","3.10271"
"11.08300","1.72025","3.04737"
"11.18300","1.68990","2.99558"
"11.28300","1.66019","2.92471"
"11.38300","1.63020","2.88955"
"11.48300","1.60006","2.82187"
"11.58300","1.56997","2.77666"
"11.68300","1.53999","2.71839"
"11.78300","1.50977","2.66578"
"11.88300","1.47990","2.60052"
"11.98300","1.44998","2.56236"
"12.08300","1.41994","2.50133"
"12.18300","1.39004","2.44625"
"12.28300","1.35995","2.38396"
"12.38300","1.33017","2.33127"
"12.48300","1.30014","2.26582"
"12.58300","1.27034","2.23196"
"12.68300","1.24001","2.16868"
"12.78300","1.21008","2.12855"
"12.88300","1.17986","2.06189"
"12.98300","1.14998","2.01450"
"13.08300","1.11991","1.95936"
"13.18300","1.09011","1.91025"
"13.28300","1.05991","1.85391"
"13.38300","1.02999","1.79756"
"13.48300","0.99977","1.73862"
"13.58300","0.97013","1.69666"
"13.68300","0.94015","1.63952"
"13.78300","0.91026","1.60524"
"13.88300","0.88017","1.52333"
"13.98300","0.85009","1.49196"
"14.08300","0.81996","1.42571"
"14.18300","0.79006","1.38877"
"14.28300","0.76004","1.33127"
"14.38300","0.72989","1.27415"
"14.48300","0.69988","1.21270"
"14.58300","0.66983","1.16140"
"14.68300","0.63990","1.10258"
"14.78300","0.61008","1.05736"
"14.88300","0.58024","0.99086"
"14.98300","0.55013","0.94888"
"15.08300","0.52017","0.86813"
"15.18300","0.48994","0.84439"
"15.28300","0.46004","0.77477"
"15.38300","0.42996","0.73478"
"15.48300","0.40011","0.67461"
"15.58300","0.36997","0.62374"
"15.68300","0.34000","0.56334"
"15.78300","0.30976","0.52618"
"15.88300","0.28002","0.47205"
"15.98300","0.24988","0.42759"
"16.08300","0.22015","0.36198"
"16.18300","0.19004","0.31063"
"16.28300","0.16010","0.24737"
"16.38300","0.13002","0.20597"
"16.48300","0.10024","0.15631"
"16.58300","0.07012","0.10621"
"16.68300","0.04002","0.04524"
"16.78300","0.00991","0.00911"
"16.88300","-0.02010","-0.05734"
"16.98300","-0.05016","-0.09494"
"17.08300","-0.07997","-0.15576"
"17.18300","-0.11002","-0.20670"
"17.28300","-0.14002","-0.26689"
"17.38300","-0.16991","-0.32986"
"17.48300","-0.19994","-0.37357"
"17.58300","-0.22979","-0.42801"
"17.68300","-0.25987","-0.48623"
"17.78300","-0.28980","-0.54037"
"17.88300","-0.31997","-0.59799"
"17.98300","-0.34994","-0.64728"
"18.08300","-0.38009","-0.70222"
"18.18300","-0.40984","-0.74808"
"18.28300","-0.44011","-0.81110"
"18.38300","-0.46994","-0.85788"
"18.48300","-0.50017","-0.91852"
"18.58300","-0.53008","-0.95893"
"18.68300","-0.56004","-1.01943"
"18.78300","-0.58975","-1.06956"
"18.88300","-0.61982","-1.12757"
"18.98300","-0.64981","-1.17774"
"19.08300","-0.67999","-1.22746"
"19.18300","-0.70998","-1.27051"
"19.28300","-0.74005","-1.32900"
"19.38300","-0.76988","-1.38906"
"19.48300","-0.80009","-1.43224"
"19.58300","-0.83009","-1.48976"
"19.68300","-0.86010","-1.54319"
"19.78300","-0.89002","-1.58359"
"19.88300","-0.91990","-1.64830"
"19.98300","-0.94994","-1.70841"
"20.08300","-0.97974","-1.75342"
"20.18300","-1.00995","-1.81924"
"20.28300","-1.03986","-1.87720"
"20.38300","-1.06995","-1.91328"
"20.48300","-1.09976","-1.97837"
"20.58300","-1.12994","-2.03946"
"20.68300","-1.15988","-2.08994"
"20.78300","-1.19014","-2.14800"
"20.88300","-1.22017","-2.19357"
"20.98300","-1.25015","-2.24256"
"21.08300","-1.27993","-2.31031"
"21.18300","-1.30997","-2.36998"
"21.28300","-1.33982","-2.41633"
"21.38300","-1.37003","-2.47913"
"21.48300","-1.39986","-2.51308"
"21.58300","-1.42982","-2.57691"
"21.68300","-1.45976","-2.63433"
"21.78300","-1.48997","-2.68868"
"21.88300","-1.52002","-2.73093"
"21.98300","-1.55008","-2.77408"
"22.08300","-1.58020","-2.83711"
"22.18300","-1.61006","-2.89246"
"22.28300","-1.64003","-2.94473"
"22.38300","-1.66997","-3.00340"
"22.48300","-1.70006","-3.05630"
"22.58300","-1.72999","-3.11143"
"22.68300","-1.75989","-3.16560"
"22.78300","-1.78978","-3.23854"
"22.88300","-1.81986","-3.28310"
"22.98300","-1.84980","-3.34707"
"23.08300","-1.88003","-3.38523"
"23.18300","-1.91010","-3.44660"
"23.28300","-1.94003","-3.49931"
"23.38300","-1.96980","-3.56535"
"23.48300","-2.00023","-3.60234"
"23.58300","-2.03004","-3.67449"
"23.68300","-2.06017","-3.71955"
"23.78300","-2.09002","-3.78456"
"23.88300","-2.11981","-3.84246"
"23.98300","-2.14970","-3.90283"
"24.08300","-2.17984","-3.94671"
"24.18300","-2.20997","-4.00154"
"24.28300","-2.24010","-4.05321"
"24.38300","-2.27005","-4.11078"
"24.48300","-2.29996","-4.15876"
"24.58300","-2.33003","-4.22309"
"24.68300","-2.35996","-4.26088"
"24.78300","-2.39009","-4.32648"
"24.88300","-2.42014","-4.37795"
"24.98300","-2.45011","-4.44056"
"25.08300","-2.47992","-4.49253"
"25.15000","-2.50005","-4.53562"
"25.15200","-2.50064","-4.53728"
"25.25200","-2.50231","-4.54788"
"25.35200","-2.47049","-4.48927"
"25.45200","-2.43987","-4.42540"
"25.55200","-2.40965","-4.35252"
"25.65200","-2.37954","-4.31219"
"25.75200","-2.34933","-4.24215"
"25.85200","-2.31953","-4.19625"
"25.95200","-2.28924","-4.14014"
"26.05200","-2.25954","-4.07963"
"26.15200","-2.22928","-4.01770"
"26.25200","-2.19931","-3.97599"
"26.35200","-2.16915","-3.91188"
"26.45200","-2.13944","-3.86651"
"26.55200","-2.10932","-3.79987"
"26.65200","-2.07946","-3.74775"
"26.75200","-2.04940","-3.68646"
"26.85200","-2.01954","-3.64482"
"26.95200","-1.98954","-3.58295"
"27.05200","-1.95950","-3.54244"
"27.15200","-1.92942","-3.47408"
"27.25200","-1.89933","-3.42546"
"27.35200","-1.86915","-3.36291"
"27.45200","-1.83905","-3.31728"
"27.55200","-1.80924","-3.25627"
"27.65200","-1.77929","-3.21079"
"27.75200","-1.74947","-3.13801"
"27.85200","-1.71941","-3.08789"
"27.95200","-1.68944","-3.03107"
"28.05200","-1.65934","-2.97224"
"28.15200","-1.62957","-2.91603"
"28.25200","-1.59944","-2.85810"
"28.35200","-1.56955","-2.80200"
"28.45200","-1.53925","-2.75939"
"28.55200","-1.50941","-2.70070"
"28.65200","-1.47930","-2.64770"
"28.75200","-1.44931","-2.57881"
"28.85200","-1.41928","-2.53175"
"28.95200","-1.38936","-2.47227"
"29.05200","-1.35919","-2.42917"
"29.15200","-1.32936","-2.37639"
"29.25200","-1.29936","-2.31435"
"29.35200","-1.26960","-2.25203"
"29.45200","-1.23962","-2.20758"
"29.55200","-1.20953","-2.16107"
"29.65200","-1.17933","-2.10737"
"29.75200","-1.14925","-2.06061"
"29.85200","-1.11924","-2.00458"
"29.95200","-1.08931","-1.93702"
"30.05200","-1.05934","-1.89297"
"30.15200","-1.02925","-1.84030"
"30.25200","-0.99927","-1.78882"
"30.35200","-0.96923","-1.73149"
"30.45200","-0.93945","-1.67288"
"30.55200","-0.90939","-1.60790"
"30.65200","-0.87964","-1.56002"
"30.75200","-0.84930","-1.50451"
"30.85200","-0.81952","-1.44451"
"30.95200","-0.78944","-1.39390"
"31.05200","-0.75951","-1.33143"
"31.15200","-0.72936","-1.28597"
"31.25200","-0.69939","-1.23382"
"31.35200","-0.66906","-1.18165"
"31.45200","-0.63925","-1.13383"
"31.55200","-0.60918","-1.07476"
"31.65200","-0.57943","-1.01751"
"31.75200","-0.54944","-0.96714"
"31.85200","-0.51955","-0.91648"
"31.95200","-0.48948","-0.86159"
"32.05200","-0.45951","-0.80765"
"32.15200","-0.42944","-0.75912"
"32.25200","-0.39944","-0.69545"
"32.35200","-0.36934","-0.67120"
"32.45200","-0.33919","-0.60837"
"32.55200","-0.30922","-0.55964"
"32.65200","-0.27931","-0.50109"
"32.75200","-0.24934","-0.45091"
"32.85200","-0.21933","-0.39608"
"32.95200","-0.18950","-0.34754"
"33.05200","-0.15917","-0.29057"
"33.15200","-0.12946","-0.23224"
"33.25200","-0.09945","-0.17172"
"33.35200","-0.06964","-0.12033"
"33.45200","-0.03951","-0.06893"
"33.55200","-0.00955","-0.02278"
"33.65200","0.02073","0.03991"
"33.75200","0.05053","0.09013"
"33.85200","0.08082","0.15281"
"33.95200","0.11061","0.20381"
"34.05200","0.14077","0.25711"
"34.15200","0.17070","0.29490"
"34.25200","0.20076","0.37101"
"34.35200","0.23056","0.41359"
"34.45200","0.26038","0.47059"
"34.55200","0.29039","0.51205"
"34.65200","0.32041","0.56860"
"34.75200","0.35066","0.61353"
"34.85200","0.38082","0.67356"
"34.95200","0.41072","0.72149"
"35.05200","0.44065","0.77526"
"35.15200","0.47068","0.81810"
"35.25200","0.50058","0.88182"
"35.35200","0.53086","0.91454"
"35.45200","0.56065","0.99421"
"35.55200","0.59076","1.03025"
"35.65200","0.62039","1.09456"
"35.75200","0.65054","1.13661"
"35.85200","0.68040","1.19946"
"35.95200","0.71057","1.24722"
"36.05200","0.74026","1.30960"
"36.15200","0.77077","1.35620"
"36.25200","0.80054","1.41240"
"36.35200","0.83074","1.45251"
"36.45200","0.86064","1.52117"
"36.55200","0.89097","1.56615"
"36.65200","0.92064","1.63766"
"36.75200","0.95069","1.67530"
"36.85200","0.98048","1.73491"
"36.95200","1.01051","1.78297"
"37.05200","1.04061","1.84513"
"37.15200","1.07065","1.90012"
"37.25200","1.10044","1.94778"
"37.35200","1.13053","1.99173"
"37.45200","1.16037","2.04450"
"37.55200","1.19062","2.09600"
"37.65200","1.22075","2.15524"
"37.75200","1.25073","2.20527"
"37.85200","1.28102","2.26784"
"37.95200","1.31057","2.29553"
"38.05200","1.34078","2.37361"
"38.15200","1.37063","2.41690"
"38.25200","1.40074","2.48157"
"38.35200","1.43038","2.53289"
"38.45200","1.46047","2.59201"
"38.55200","1.49029","2.62936"
"38.65200","1.52059","2.69690"
"38.75200","1.55066","2.74320"
"38.85200","1.58087","2.79624"
"38.95200","1.61063","2.85295"
"39.05200","1.64088","2.90012"
"39.15200","1.67062","2.95829"
"39.25200","1.70070","3.01894"
"39.35200","1.73068","3.07595"
"39.45200","1.76069","3.13153"
"39.55200","1.79055","3.18289"
"39.65200","1.82049","3.23894"
"39.75200","1.85047","3.29678"
"39.85200","1.88061","3.34758"
"39.95200","1.91068","3.40177"
"40.05200","1.94057","3.44783"
"40.15200","1.97063","3.50785"
"40.25200","2.00064","3.54838"
"40.35200","2.03060","3.61405"
"40.45200","2.06093","3.66554"
"40.55200","2.09087","3.71828"
"40.65200","2.12064","3.77911"
"40.75200","2.15065","3.82406"
"40.85200","2.18036","3.88715"
"40.95200","2.21053","3.94302"
"41.05200","2.24039","4.01041"
"41.15200","2.27062","4.05601"
"41.25200","2.30051","4.10529"
"41.35200","2.33070","4.15704"
"41.45200","2.36053","4.20951"
"41.55200","2.39072","4.28078"
"41.65200","2.42084","4.33618"
"41.75200","2.45070","4.38418"
"41.85200","2.48061","4.43668"
"41.91700","2.50008","4.47440"
"41.91900","2.50068","4.47315"
"42.01900","2.50210","4.47526"
"42.11900","2.47083","4.41777"
"42.21900","2.44001","4.36291"
"42.31900","2.40996","4.31534"
"42.41900","2.37963","4.25578"
"42.51900","2.34977","4.19528"
"42.61900","2.31974","4.13509"
"42.71900","2.28977","4.08487"
"42.81900","2.25963","4.03263"
"42.91900","2.22957","3.97930"
"43.01900","2.19950","3.93075"
"43.11900","2.16967","3.86653"
"43.21900","2.13992","3.81376"
"43.31900","2.10988","3.75719"
"43.41900","2.07981","3.70664"
"43.51900","2.04982","3.64443"
"43.61900","2.01985","3.59137"
"43.71900","1.98975","3.53821"
"43.81900","1.95996","3.48234"
"43.91900","1.92960","3.43213"
"44.01900","1.89974","3.37637"
"44.11900","1.86957","3.31183"
"44.21900","1.83970","3.25307"
"44.31900","1.80968","3.19091"
"44.41900","1.77991","3.14909"
"44.51900","1.74984","3.08291"
"44.61900","1.71992","3.03460"
"44.71900","1.68972","2.96644"
"44.81900","1.65989","2.92062"
"44.91900","1.62984","2.86228"
"45.01900","1.59985","2.81597"
"45.11900","1.56970","2.76148"
"45.21900","1.53972","2.70988"
"45.31900","1.50948","2.65843"
"45.41900","1.47960","2.60892"
"45.51900","1.44967","2.54935"
"45.61900","1.41967","2.50452"
"45.71900","1.38974","2.44058"
"45.81900","1.35968","2.39812"
"45.91900","1.32987","2.32590"
"46.01900","1.29988","2.28417"
"46.11900","1.27003","2.22789"
"46.21900","1.23975","2.17790"
"46.31900","1.20980","2.11770"
"46.41900","1.17961","2.06330"
"46.51900","1.14971","2.00283"
"46.61900","1.11963","1.96511"
"46.71900","1.08984","1.91068"
"46.81900","1.05965","1.85266"
"46.91900","1.02973","1.79166"
"47.01900","0.99948","1.74758"
"47.11900","0.96981","1.67415"
"47.21900","0.93984","1.63437"
"47.31900","0.90999","1.57519"
"47.41900","0.87985","1.53135"
"47.51900","0.84983","1.45763"
"47.61900","0.81969","1.42084"
"47.71900","0.78979","1.35698"
"47.81900","0.75971","1.31364"
"47.91900","0.72966","1.26463"
"48.01900","0.69959","1.20438"
"48.11900","0.66955","1.15358"
"48.21900","0.63961","1.10999"
"48.31900","0.60977","1.05189"
"48.41900","0.57994","1.00981"
"48.51900","0.54987","0.94390"
"48.61900","0.51992","0.90274"
"48.71900","0.48970","0.82960"
"48.81900","0.45976","0.79841"
"48.91900","0.42969","0.72923"
"49.01900","0.39986","0.69986"
"49.11900","0.36967","0.63472"
"49.21900","0.33971","0.57021"
"49.31900","0.30947","0.52026"
"49.41900","0.27975","0.47111"
"49.51900","0.24962","0.41426"
"49.61900","0.21987","0.36751"
"49.71900","0.18975","0.29536"
"49.81900","0.15982","0.24660"
"49.91900","0.12974","0.18610"
"50.01900","0.09994","0.15704"
"50.11900","0.06985","0.08472"
"50.21900","0.03976","0.05135"
"50.31900","0.00961","-0.01612"
"50.41900","-0.02041","-0.06839"
"50.51900","-0.05048","-0.11942"
"50.61900","-0.08026","-0.16035"
"50.71900","-0.11030","-0.22461"
"50.81900","-0.14028","-0.27437"
"50.91900","-0.17021","-0.33487"
"51.01900","-0.20027","-0.38396"
"51.11900","-0.23009","-0.42962"
"51.21900","-0.26012","-0.47503"
"51.31900","-0.29007","-0.54264"
"51.41900","-0.32026","-0.58047"
"51.51900","-0.35018","-0.64644"
"51.61900","-0.38037","-0.68420"
"51.71900","-0.41013","-0.74377"
"51.81900","-0.44040","-0.79223"
"51.91900","-0.47023","-0.86102"
"52.01900","-0.50043","-0.89883"
"52.11900","-0.53033","-0.96576"
"52.21900","-0.56032","-1.01601"
"52.31900","-0.59001","-1.07050"
"52.41900","-0.62010","-1.12462"
"52.51900","-0.65009","-1.18735"
"52.61900","-0.68025","-1.23118"
"52.71900","-0.71023","-1.29671"
"52.81900","-0.74032","-1.33692"
"52.91900","-0.77016","-1.39637"
"53.01900","-0.80037","-1.43188"
"53.11900","-0.83035","-1.51653"
"53.21900","-0.86035","-1.54934"
"53.31900","-0.89042","-1.60445"
"53.41900","-0.92021","-1.65122"
"53.51900","-0.95016","-1.70567"
"53.61900","-0.98004","-1.76951"
"53.71900","-1.01022","-1.81838"
"53.81900","-1.04014","-1.86971"
"53.91900","-1.07024","-1.91828"
"54.01900","-1.09997","-1.97047"
"54.11900","-1.13025","-2.02855"
"54.21900","-1.16014","-2.08130"
"54.31900","-1.19042","-2.14287"
"54.41900","-1.22044","-2.18500"
"54.51900","-1.25044","-2.24595"
"54.61900","-1.28020","-2.29689"
"54.71900","-1.31020","-2.35534"
"54.81900","-1.34013","-2.41436"
"54.91900","-1.37032","-2.47348"
"55.01900","-1.40016","-2.51718"
"55.11900","-1.43009","-2.57851"
"55.21900","-1.46004","-2.62787"
"55.31900","-1.49024","-2.68648"
"55.41900","-1.52034","-2.74035"
"55.51900","-1.55031","-2.79077"
"55.61900","-1.58048","-2.84276"
"55.71900","-1.61033","-2.91070"
"55.81900","-1.64033","-2.95840"
"55.91900","-1.67024","-3.02702"
"56.01900","-1.70035","-3.06111"
"56.11900","-1.73026","-3.12107"
"56.21900","-1.76015","-3.17293"
"56.31900","-1.79005","-3.23184"
"56.41900","-1.82015","-3.28834"
"56.51900","-1.85007","-3.32646"
"56.61900","-1.88032","-3.39953"
"56.71900","-1.91038","-3.42722"
"56.81900","-1.94030","-3.49598"
"56.91900","-1.97015","-3.56352"
"57.01900","-2.00043","-3.60476"
"57.11900","-2.03037","-3.66772"
"57.21900","-2.06044","-3.71428"
"57.31900","-2.09032","-3.77743"
"57.41900","-2.12009","-3.83473"
"57.51900","-2.14999","-3.90600"
"57.61900","-2.18017","-3.95296"
"57.71900","-2.21020","-4.00513"
"57.81900","-2.24038","-4.05703"
"57.91900","-2.27035","-4.11312"
"58.01900","-2.30025","-4.17435"
"58.11900","-2.33029","-4.23049"
"58.21900","-2.36022","-4.27620"
"58.31900","-2.39041","-4.33617"
"58.41900","-2.42040","-4.37958"
"58.51900","-2.45044","-4.44698"
"58.61900","-2.48022","-4.50405"
"58.68500","-2.50001","-4.53453"
"58.68700","-2.50060","-4.53687"
"58.78700","-2.50229","-4.54942"
"58.88700","-2.47048","-4.48922"
"58.98700","-2.43983","-4.42577"
"59.08700","-2.40965","-4.36546"
"59.18700","-2.37952","-4.30948"
"59.28700","-2.34930","-4.26039"
"59.38700","-2.31950","-4.20863"
"59.48700","-2.28925","-4.15947"
"59.58700","-2.25951","-4.09056"
"59.68700","-2.22927","-4.03552"
"59.78700","-2.19930","-3.98431"
"59.88700","-2.16913","-3.92676"
"59.98700","-2.13941","-3.87607"
"60.08700","-2.10923","-3.81061"
"60.18700","-2.07953","-3.75457"
"60.28700","-2.04938","-3.68739"
"60.38700","-2.01952","-3.63594"
"60.48700","-1.98949","-3.58482"
"60.58700","-1.95946","-3.51601"
"60.68700","-1.92945","-3.47349"
"60.78700","-1.89928","-3.41682"
"60.88700","-1.86912","-3.35341"
"60.98700","-1.83903","-3.30635"
"61.08700","-1.80921","-3.26179"
"61.18700","-1.77928","-3.20490"
"61.28700","-1.74941","-3.13430"
"61.38700","-1.71937","-3.09275"
"61.48700","-1.68941","-3.02723"
"61.58700","-1.65934","-2.98599"
"61.68700","-1.62955","-2.92637"
"61.78700","-1.59942","-2.87297"
"61.88700","-1.56953","-2.81583"
"61.98700","-1.53924","-2.76023"
"62.08700","-1.50938","-2.71289"
"62.18700","-1.47927","-2.65975"
"62.28700","-1.44930","-2.60047"
"62.38700","-1.41923","-2.53681"
"62.48700","-1.38933","-2.49013"
"62.58700","-1.35917","-2.43737"
"62.68700","-1.32932","-2.38397"
"62.78700","-1.29936","-2.32723"
"62.88700","-1.26959","-2.26278"
"62.98700","-1.23960","-2.19841"
"63.08700","-1.20950","-2.15866"
"63.18700","-1.17930","-2.10710"
"63.28700","-1.14923","-2.04929"
"63.38700","-1.11922","-1.99414"
"63.48700","-1.08927","-1.93985"
"63.58700","-1.05935","-1.87020"
"63.68700","-1.02920","-1.83623"
"63.78700","-0.99924","-1.77568"
"63.88700","-0.96925","-1.71548"
"63.98700","-0.93943","-1.67046"
"64.08700","-0.90937","-1.60913"
"64.18700","-0.87962","-1.55750"
"64.28700","-0.84928","-1.50846"
"64.38700","-0.81951","-1.45909"
"64.48700","-0.78942","-1.40417"
"64.58700","-0.75946","-1.35443"
"64.68700","-0.72931","-1.30798"
"64.78700","-0.69936","-1.24862"
"64.88700","-0.66903","-1.20746"
"64.98700","-0.63925","-1.14536"
"65.08700","-0.60911","-1.08888"
"65.18700","-0.57945","-1.02751"
"65.28700","-0.54941","-0.97730"
"65.38700","-0.51951","-0.92035"
"65.48700","-0.48945","-0.87078"
"65.58700","-0.45954","-0.80709"
"65.68700","-0.42935","-0.75579"
"65.78700","-0.39939","-0.70452"
"65.88700","-0.36931","-0.66051"
"65.98700","-0.33918","-0.59567"
"66.08700","-0.30921","-0.55974"
"66.18700","-0.27927","-0.49238"
"66.28700","-0.24930","-0.44522"
"66.38700","-0.21931","-0.38586"
"66.48700","-0.18944","-0.34094"
"66.58700","-0.15918","-0.28708"
"66.68700","-0.12941","-0.23151"
"66.78700","-0.09943","-0.17041"
"66.88700","-0.06964","-0.11983"
"66.98700","-0.03949","-0.06953"
"67.08700","-0.00953","-0.02555"
"67.18700","0.02077","0.03146"
"67.28700","0.05054","0.08489"
"67.38700","0.08083","0.14430"
"67.48700","0.11062","0.18141"
"67.58700","0.14079","0.23874"
"67.68700","0.17072","0.28622"
"67.78700","0.20081","0.34721"
"67.88700","0.23057","0.38921"
"67.98700","0.26050","0.45696"
"68.08700","0.29035","0.49987"
"68.18700","0.32055","0.55461"
"68.28700","0.35070","0.61271"
"68.38700","0.38071","0.66891"
"68.48700","0.41069","0.71762"
"68.58700","0.44067","0.78504"
"68.68700","0.47069","0.83087"
"68.78700","0.50061","0.87844"
"68.88700","0.53089","0.92536"
"68.98700","0.56069","0.99748"
"69.08700","0.59078","1.03127"
"69.18700","0.62042","1.10499"
"69.28700","0.65056","1.13710"
"69.38700","0.68036","1.19921"
"69.48700","0.71042","1.25208"
"69.58700","0.74055","1.30806"
"69.68700","0.77074","1.35500"
"69.78700","0.80054","1.40188"
"69.88700","0.83076","1.45064"
"69.98700","0.86069","1.50456"
"70.08700","0.89098","1.55871"
"70.18700","0.92066","1.62180"
"70.28700","0.95072","1.66456"
"70.38700","0.98053","1.72839"
"70.48700","1.01051","1.76799"
"70.58700","1.04064","1.82992"
"70.68700","1.07063","1.88822"
"70.78700","1.10049","1.94428"
"70.88700","1.13044","1.98510"
"70.98700","1.16045","2.04390"
"71.08700","1.19079","2.08837"
"71.18700","1.22071","2.15468"
"71.28700","1.25075","2.20589"
"71.38700","1.28096","2.26102"
"71.48700","1.31064","2.29551"
"71.58700","1.34080","2.37161"
"71.68700","1.37067","2.41898"
"71.78700","1.40073","2.48312"
"71.88700","1.43037","2.53542"
"71.98700","1.46048","2.59555"
"72.08700","1.49033","2.63245"
"72.18700","1.52055","2.70448"
"72.28700","1.55069","2.74003"
"72.38700","1.58079","2.80015"
"72.48700","1.61085","2.84973"
"72.58700","1.64085","2.89743"
"72.68700","1.67063","2.94747"
"72.78700","1.70069","3.00930"
"72.88700","1.73078","3.06493"
"72.98700","1.76072","3.11413"
"73.08700","1.79058","3.15995"
"73.18700","1.82055","3.23458"
"73.28700","1.85051","3.27411"
"73.38700","1.88064","3.34789"
"73.48700","1.91068","3.39229"
"73.58700","1.94054","3.45173"
"73.68700","1.97078","3.50132"
"73.78700","2.00060","3.56379"
"73.88700","2.03069","3.60638"
"73.98700","2.06096","3.66645"
"74.08700","2.09086","3.72353"
"74.18700","2.12060","3.77784"
"74.28700","2.15074","3.82601"
"74.38700","2.18038","3.89497"
"74.48700","2.21055","3.94095"
"74.58700","2.24041","4.01885"
"74.68700","2.27063","4.05211"
"74.78700","2.30053","4.11199"
"74.88700","2.33070","4.15342"
"74.98700","2.36058","4.21934"
"75.08700","2.39077","4.27204"
"75.18700","2.42087","4.33946"
"75.28700","2.45058","4.38155"
"75.38700","2.48077","4.43695"
"75.45200","2.50004","4.48274"
"75.45400","2.50064","4.48448"
"75.55400","2.50223","4.48283"
"75.65400","2.47087","4.42668"
"75.75400","2.44008","4.36690"
"75.85400","2.41001","4.31795"
"75.95400","2.37969","4.25946"
"76.05400","2.34982","4.21321"
"76.15400","2.31980","4.13099"
"76.25400","2.28982","4.09524"
"76.35400","2.25967","4.02594"
"76.45400","2.22960","3.98107"
"76.55400","2.19960","3.91111"
"76.65400","2.16976","3.85654"
"76.75400","2.13993","3.79053"
"76.85400","2.11004","3.74020"
"76.95400","2.07985","3.68637"
"77.05400","2.04984","3.63745"
"77.15400","2.01992","3.57682"
"77.25400","1.98982","3.52592"
"77.35400","1.96000","3.46806"
"77.45400","1.92968","3.43064"
"77.55400","1.89980","3.36506"
"77.65400","1.86964","3.32516"
"77.75400","1.83975","3.25295"
"77.85400","1.80974","3.20688"
"77.95400","1.77998","3.14675"
"78.05400","1.74987","3.10404"
"78.15400","1.71997","3.03702"
"78.25400","1.68979","2.99336"
"78.35400","1.65998","2.92619"
"78.45400","1.62988","2.86865"
"78.55400","1.59992","2.81801"
"78.65400","1.56976","2.77620"
"78.75400","1.53977","2.70523"
"78.85400","1.50952","2.66782"
"78.95400","1.47969","2.59921"
"79.05400","1.44972","2.55638"
"79.15400","1.41973","2.49899"
"79.25400","1.38978","2.44731"
"79.35400","1.35974","2.38009"
"79.45400","1.32991","2.32641"
"79.55400","1.29994","2.25853"
"79.65400","1.27011","2.21740"
"79.75400","1.23980","2.16149"
"79.85400","1.20983","2.10925"
"79.95400","1.17963","2.04706"
"80.05400","1.14975","2.00361"
"80.15400","1.11969","1.94383"
"80.25400","1.08989","1.90433"
"80.35400","1.05970","1.84385"
"80.45400","1.02978","1.80617"
"80.55400","0.99955","1.73765"
"80.65400","0.96989","1.69569"
"80.75400","0.93992","1.61902"
"80.85400","0.91004","1.59770"
"80.95400","0.87992","1.52854"
"81.05400","0.84988","1.48303"
"81.15400","0.81975","1.42646"
"81.25400","0.78984","1.36986"
"81.35400","0.75979","1.31149"
"81.45400","0.72974","1.27144"
"81.55400","0.69961","1.21278"
"81.65400","0.66961","1.15261"
"81.75400","0.63968","1.09504"
"81.85400","0.60984","1.05012"
"81.95400","0.58003","0.98211"
"82.05400","0.54992","0.93916"
"82.15400","0.51995","0.88321"
"82.25400","0.48975","0.82289"
"82.35400","0.45981","0.77672"
"82.45400","0.42975","0.73317"
"82.55400","0.39996","0.67533"
"82.65400","0.36974","0.63024"
"82.75400","0.33975","0.56398"
"82.85400","0.30952","0.52020"
"82.95400","0.27983","0.45308"
"83.05400","0.24967","0.42182"
"83.15400","0.21991","0.36114"
"83.25400","0.18982","0.30844"
"83.35400","0.15988","0.24703"
"83.45400","0.12980","0.19466"
"83.55400","0.10000","0.14417"
"83.65400","0.06988","0.10454"
"83.75400","0.03982","0.04634"
"83.85400","0.00967","0.00238"
"83.95400","-0.02036","-0.06867"
"84.05400","-0.05040","-0.10433"
"84.15400","-0.08021","-0.16202"
"84.25400","-0.11024","-0.20864"
"84.35400","-0.14024","-0.27482"
"84.45400","-0.17015","-0.33136"
"84.55400","-0.20020","-0.39323"
"84.65400","-0.22998","-0.43667"
"84.75400","-0.26007","-0.49883"
"84.85400","-0.29003","-0.54031"
"84.95400","-0.32020","-0.60419"
"85.05400","-0.35015","-0.64958"
"85.15400","-0.38030","-0.71851"
"85.25400","-0.41006","-0.74144"
"85.35400","-0.44036","-0.80763"
"85.45400","-0.47011","-0.86289"
"85.55400","-0.50038","-0.91246"
"85.65400","-0.53030","-0.96761"
"85.75400","-0.56028","-1.02767"
"85.85400","-0.58998","-1.06054"
"85.95400","-0.62003","-1.13126"
"86.05400","-0.65000","-1.17310"
"86.15400","-0.68020","-1.23849"
"86.25400","-0.71020","-1.27626"
"86.35400","-0.74027","-1.34356"
"86.45400","-0.77010","-1.37719"
"86.55400","-0.80033","-1.43481"
"86.65400","-0.83031","-1.49147"
"86.75400","-0.86032","-1.54853"
"86.85400","-0.89030","-1.59913"
"86.95400","-0.92011","-1.65954"
"87.05400","-0.95017","-1.70013"
"87.15400","-0.97998","-1.76864"
"87.25400","-1.01014","-1.81957"
"87.35400","-1.04008","-1.88029"
"87.45400","-1.07018","-1.92338"
"87.55400","-1.09992","-1.98443"
"87.65400","-1.13018","-2.02699"
"87.75400","-1.16011","-2.09610"
"87.85400","-1.19037","-2.14194"
"87.95400","-1.22038","-2.20537"
"88.05400","-1.25039","-2.24626"
"88.15400","-1.28016","-2.31254"
"88.25400","-1.31021","-2.35117"
"88.35400","-1.34003","-2.42176"
"88.45400","-1.37023","-2.47306"
"88.55400","-1.40006","-2.53662"
"88.65400","-1.43006","-2.57051"
"88.75400","-1.45996","-2.63756"
"88.85400","-1.49020","-2.67459"
"88.95400","-1.52025","-2.74679"
"89.05400","-1.55013","-2.78296"
"89.15400","-1.58047","-2.84689"
"89.25400","-1.61030","-2.88629"
"89.35400","-1.64026","-2.94890"
"89.45400","-1.67018","-3.00718"
"89.55400","-1.70028","-3.06165"
"89.65400","-1.73020","-3.12621"
"89.75400","-1.76011","-3.17837"
"89.85400","-1.78997","-3.22204"
"89.95400","-1.82012","-3.28833"
"90.05400","-1.85000","-3.33794"
"90.15400","-1.88027","-3.40735"
"90.25400","-1.91031","-3.44197"
"90.35400","-1.94024","-3.51055"
"90.45400","-1.97010","-3.55573"
"90.55400","-2.00030","-3.62899"
"90.65400","-2.03035","-3.67504"
"90.75400","-2.06040","-3.73417"
"90.85400","-2.09027","-3.78020"
"90.95400","-2.12004","-3.84288"
"91.05400","-2.14994","-3.89676"
"91.15400","-2.18010","-3.96277"
"91.25400","-2.21015","-4.00261"
"91.35400","-2.24032","-4.06235"
"91.45400","-2.27028","-4.10879"
"91.55400","-2.30017","-4.17813"
"91.65400","-2.33022","-4.22408"
"91.75400","-2.36020","-4.28300"
"91.85400","-2.39035","-4.33126"
"91.95400","-2.42025","-4.38232"
"92.05400","-2.45040","-4.42877"
"92.15400","-2.48017","-4.51064"
"92.22100","-2.50024","-4.54897"
"92.22300","-2.50083","-4.55117"
"92.32300","-2.50238","-4.54473"
"92.42300","-2.47077","-4.50309"
"92.52300","-2.44014","-4.42102"
"92.62300","-2.40993","-4.36815"
"92.72300","-2.37980","-4.29800"
"92.82300","-2.34963","-4.25243"
"92.92300","-2.31977","-4.18453"
"93.02300","-2.28953","-4.15622"
"93.12300","-2.25981","-4.07169"
"93.22300","-2.22956","-4.02916"
"93.32300","-2.19961","-3.97142"
"93.42300","-2.16940","-3.92376"
"93.52300","-2.13959","-3.86727"
"93.62300","-2.10965","-3.82833"
"93.72300","-2.07984","-3.75000"
"93.82300","-2.04969","-3.69875"
"93.92300","-2.01982","-3.64090"
"94.02300","-1.98979","-3.58776"
"94.12300","-1.95980","-3.52803"
"94.22300","-1.92966","-3.49051"
"94.32300","-1.89955","-3.42248"
"94.42300","-1.86941","-3.37571"
"94.52300","-1.83935","-3.31337"
"94.62300","-1.80951","-3.27103"
"94.72300","-1.77956","-3.20622"
"94.82300","-1.74973","-3.15927"
"94.92300","-1.71977","-3.08612"
"95.02300","-1.68957","-3.04234"
"95.12300","-1.65968","-2.97347"
"95.22300","-1.62984","-2.92846"
"95.32300","-1.59970","-2.86972"
"95.42300","-1.56981","-2.81061"
"95.52300","-1.53954","-2.74594"
"95.62300","-1.50967","-2.71126"
"95.72300","-1.47957","-2.64016"
"95.82300","-1.44954","-2.60012"
"95.92300","-1.41956","-2.53727"
"96.02300","-1.38963","-2.48224"
"96.12300","-1.35946","-2.41587"
"96.22300","-1.32962","-2.38896"
"96.32300","-1.29966","-2.31593"
"96.42300","-1.26993","-2.27153"
"96.52300","-1.23984","-2.21080"
"96.62300","-1.20980","-2.15422"
"96.72300","-1.17959","-2.10176"
"96.82300","-1.14952","-2.06159"
"96.92300","-1.11950","-2.01206"
"97.02300","-1.08957","-1.95513"
"97.12300","-1.05962","-1.88645"
"97.22300","-1.02956","-1.83572"
"97.32300","-0.99951","-1.76816"
"97.42300","-0.96955","-1.74068"
"97.52300","-0.93974","-1.66860"
"97.62300","-0.90965","-1.62235"
"97.72300","-0.87992","-1.54795"
"97.82300","-0.84955","-1.51109"
"97.92300","-0.81981","-1.45011"
"98.02300","-0.78971","-1.41378"
"98.12300","-0.75975","-1.34705"
"98.22300","-0.72962","-1.29777"
"98.32300","-0.69966","-1.23287"
"98.42300","-0.66932","-1.19542"
"98.52300","-0.63954","-1.13247"
"98.62300","-0.60944","-1.08983"
"98.72300","-0.57969","-1.01763"
"98.82300","-0.54972","-0.97630"
"98.92300","-0.51984","-0.91405"
"99.02300","-0.48976","-0.87189"
"99.12300","-0.45981","-0.80712"
"99.22300","-0.42968","-0.76383"
"99.32300","-0.39966","-0.70217"
"99.42300","-0.36962","-0.66381"
"99.52300","-0.33946","-0.61436"
"99.62300","-0.30949","-0.56069"
"99.72300","-0.27956","-0.50676"
"99.82300","-0.24962","-0.46310"
"99.92300","-0.21959","-0.39915"
"100.02300","-0.18977","-0.35905"
"100.12300","-0.15948","-0.29486"
"100.22300","-0.12970","-0.24715"
"100.32300","-0.09975","-0.17450"
"100.42300","-0.06991","-0.13646"
"100.52300","-0.03976","-0.06205"
"100.62300","-0.00979","-0.02941"
"100.72300","0.02046","0.03443"
"100.82300","0.05027","0.08588"
"100.92300","0.08054","0.13928"
"101.02300","0.11034","0.18635"
"101.12300","0.14048","0.24900"
"101.22300","0.17043","0.28845"
"101.32300","0.20049","0.35799"
"101.42300","0.23025","0.40089"
"101.52300","0.26004","0.46453"
"101.62300","0.29020","0.50984"
"101.72300","0.32018","0.57343"
"101.82300","0.35035","0.60803"
"101.92300","0.38058","0.66335"
"102.02300","0.41043","0.70649"
"102.12300","0.44040","0.77202"
"102.22300","0.47042","0.82128"
"102.32300","0.50028","0.86762"
"102.42300","0.53058","0.91170"
"102.52300","0.56038","0.97639"
"102.62300","0.59050","1.02891"
"102.72300","0.62013","1.08977"
"102.82300","0.65025","1.13374"
"102.92300","0.68009","1.18591"
"103.02300","0.71026","1.23237"
"103.12300","0.74020","1.30579"
"103.22300","0.77043","1.34558"
"103.32300","0.80028","1.41161"
"103.42300","0.83049","1.44546"
"103.52300","0.86037","1.51599"
"103.62300","0.89070","1.54947"
"103.72300","0.92039","1.62185"
"103.82300","0.95040","1.67880"
"103.92300","0.98023","1.73184"
"104.02300","1.01021","1.77483"
"104.12300","1.04033","1.83617"
"104.22300","1.07032","1.88355"
"104.32300","1.10021","1.95368"
"104.42300","1.13016","1.99487"
"104.52300","1.16033","2.04622"
"104.62300","1.19028","2.08029"
"104.72300","1.22043","2.15462"
"104.82300","1.25056","2.19184"
"104.92300","1.28072","2.25607"
"105.02300","1.31031","2.30876"
"105.12300","1.34048","2.36100"
"105.22300","1.37035","2.40808"
"105.32300","1.40044","2.46480"
"105.42300","1.43007","2.52247"
"105.52300","1.46019","2.58156"
"105.62300","1.49005","2.62637"
"105.72300","1.52035","2.68351"
"105.82300","1.55029","2.72243"
"105.92300","1.58060","2.79604"
"106.02300","1.61050","2.84413"
"106.12300","1.64054","2.90481"
"106.22300","1.67030","2.95042"
"106.32300","1.70042","3.00786"
"106.42300","1.73036","3.06422"
"106.52300","1.76044","3.13005"
"106.62300","1.79036","3.17367"
"106.72300","1.82027","3.23886"
"106.82300","1.85021","3.28420"
"106.92300","1.88034","3.33623"
"107.02300","1.91040","3.38757"
"107.12300","1.94023","3.45421"
"107.22300","1.97056","3.49645"
"107.32300","2.00017","3.55444"
"107.42300","2.03053","3.60025"
"107.52300","2.06063","3.66269"
"107.62300","2.09059","3.71421"
"107.72300","2.12035","3.77675"
"107.82300","2.15041","3.81908"
"107.92300","2.18003","3.88054"
"108.02300","2.21024","3.93729"
"108.12300","2.24013","3.99553"
"108.22300","2.27032","4.05694"
"108.32300","2.30025","4.10825"
"108.42300","2.33041","4.15018"
"108.52300","2.36028","4.21354"
"108.62300","2.39050","4.26186"
"108.72300","2.42054","4.32472"
"108.82300","2.45040","4.37913"
"108.92300","2.48044","4.44566"
"108.98900","2.50002","4.47669"
"108.99100","2.50062","4.47708"
"109.09100","2.50195","4.47589"
"109.19100","2.47089","4.41164"
"109.29100","2.44006","4.35811"
"109.39100","2.40999","4.29941"
"109.49100","2.37968","4.24813"
"109.59100","2.34982","4.19730"
"109.69100","2.31977","4.13840"
"109.79100","2.28978","4.08042"
"109.89100","2.25963","4.02968"
"109.99100","2.22959","3.98038"
"110.09100","2.19958","3.91721"
"110.19100","2.16971","3.87150"
"110.29100","2.13984","3.80910"
"110.39100","2.11001","3.75314"
"110.49100","2.07994","3.69208"
"110.59100","2.04978","3.64964"
"110.69100","2.01993","3.58581"
"110.79100","1.98972","3.52355"
"110.89100","1.95997","3.47596"
"110.99100","1.92965","3.41556"
"111.09100","1.89979","3.36759"
"111.19100","1.86959","3.31648"
"111.29100","1.83974","3.25029"
"111.39100","1.80970","3.18682"
"111.49100","1.77993","3.13797"
"111.59100","1.74985","3.08015"
"111.69100","1.71994","3.03140"
"111.79100","1.68974","2.97934"
"111.89100","1.66002","2.91626"
"111.99100","1.62980","2.85685"
"112.09100","1.59989","2.80951"
"112.19100","1.56972","2.75682"
"112.29100","1.53972","2.71048"
"112.39100","1.50951","2.65364"
"112.49100","1.47968","2.60405"
"112.59100","1.44970","2.54202"
"112.69100","1.41971","2.50152"
"112.79100","1.38977","2.44714"
"112.89100","1.35969","2.38695"
"112.99100","1.32987","2.32987"
"113.09100","1.29992","2.26880"
"113.19100","1.27009","2.22283"
"113.29100","1.23977","2.16132"
"113.39100","1.20982","2.12127"
"113.49100","1.17961","2.06216"
"113.59100","1.14977","1.99792"
"113.69100","1.11968","1.95774"
"113.79100","1.08986","1.88977"
"113.89100","1.05967","1.84690"
"113.99100","1.02975","1.79098"
"114.09100","0.99952","1.74048"
"114.19100","0.96986","1.66966"
"114.29100","0.93986","1.61990"
"114.39100","0.91002","1.56991"
"114.49100","0.87991","1.51251"
"114.59100","0.84985","1.46891"
"114.69100","0.81975","1.40934"
"114.79100","0.78983","1.35424"
"114.89100","0.75975","1.31053"
"114.99100","0.72969","1.25530"
"115.09100","0.69959","1.21282"
"115.19100","0.66958","1.16106"
"115.29100","0.63965","1.10650"
"115.39100","0.60981","1.04489"
"115.49100","0.58002","1.00028"
"115.59100","0.54988","0.94711"
"115.69100","0.51993","0.89378"
"115.79100","0.48970","0.84183"
"115.89100","0.45977","0.78306"
"115.99100","0.42975","0.72319"
"116.09100","0.39987","0.67951"
"116.19100","0.36973","0.62733"
"116.29100","0.33974","0.56439"
"116.39100","0.30952","0.50962"
"116.49100","0.27980","0.46510"
"116.59100","0.24963","0.40402"
"116.69100","0.21989","0.36279"
"116.79100","0.18980","0.29772"
"116.89100","0.15986","0.24964"
"116.99100","0.12976","0.18485"
"117.09100","0.09998","0.14011"
"117.19100","0.06985","0.08903"
"117.29100","0.03982","0.03936"
"117.39100","0.00966","-0.01564"
"117.49100","-0.02038","-0.06637"
"117.59100","-0.05041","-0.12348"
"117.69100","-0.08026","-0.16445"
"117.79100","-0.11029","-0.22461"
"117.89100","-0.14026","-0.26821"
"117.99100","-0.17019","-0.33583"
"118.09100","-0.20023","-0.38261"
"118.19100","-0.23004","-0.44230"
"118.29100","-0.26012","-0.48129"
"118.39100","-0.29005","-0.53811"
"118.49100","-0.32021","-0.59105"
"118.59100","-0.35017","-0.65177"
"118.69100","-0.38032","-0.69631"
"118.79100","-0.41007","-0.75342"
"118.89100","-0.44038","-0.79950"
"118.99100","-0.47021","-0.85914"
"119.09100","-0.50042","-0.90891"
"119.19100","-0.53030","-0.97721"
"119.29100","-0.56032","-1.01857"
"119.39100","-0.59001","-1.09147"
"119.49100","-0.62006","-1.12747"
"119.59100","-0.65004","-1.18730"
"119.69100","-0.68018","-1.24242"
"119.79100","-0.71023","-1.29744"
"119.89100","-0.74029","-1.33779"
"119.99100","-0.77015","-1.38998"
"120.09100","-0.80034","-1.43698"
"120.19100","-0.83032","-1.49474"
"120.29100","-0.86035","-1.54741"
"120.39100","-0.89037","-1.61481"
"120.49100","-0.92016","-1.64542"
"120.59100","-0.95014","-1.71473"
"120.69100","-0.98000","-1.76434"
"120.79100","-1.01018","-1.82051"
"120.89100","-1.04012","-1.87643"
"120.99100","-1.07022","-1.93803"
"121.09100","-1.09999","-1.97260"
"121.19100","-1.13018","-2.03599"
"121.29100","-1.16012","-2.08932"
"121.39100","-1.19037","-2.14091"
"121.49100","-1.22044","-2.19027"
"121.59100","-1.25042","-2.25281"
"121.69100","-1.28019","-2.29701"
"121.79100","-1.31025","-2.36310"
"121.89100","-1.34005","-2.42032"
"121.99100","-1.37026","-2.48358"
"122.09100","-1.40009","-2.52493"
"122.19100","-1.43007","-2.59073"
"122.29100","-1.45999","-2.63165"
"122.39100","-1.49024","-2.69092"
"122.49100","-1.52029","-2.74505"
"122.59100","-1.55017","-2.80114"
"122.69100","-1.58045","-2.84809"
"122.79100","-1.61034","-2.90090"
"122.89100","-1.64029","-2.95555"
"122.99100","-1.67021","-3.00940"
"123.09100","-1.70032","-3.06509"
"123.19100","-1.73022","-3.13788"
"123.29100","-1.76020","-3.16499"
"123.39100","-1.78996","-3.23512"
"123.49100","-1.82014","-3.27950"
"123.59100","-1.85004","-3.34569"
"123.69100","-1.88029","-3.38789"
"123.79100","-1.91034","-3.45290"
"123.89100","-1.94026","-3.50032"
"123.99100","-1.97016","-3.55755"
"124.09100","-2.00021","-3.61031"
"124.19100","-2.03046","-3.68064"
"124.29100","-2.06045","-3.72468"
"124.39100","-2.09028","-3.79630"
"124.49100","-2.12010","-3.83488"
"124.59100","-2.14996","-3.90248"
"124.69100","-2.18015","-3.95626"
"124.79100","-2.21016","-4.02045"
"124.89100","-2.24031","-4.06113"
"124.99100","-2.27033","-4.11806"
"125.09100","-2.30018","-4.16462"
"125.19100","-2.33025","-4.23088"
"125.29100","-2.36019","-4.28688"
"125.39100","-2.39038","-4.34749"
"125.49100","-2.42027","-4.38548"
"125.59100","-2.45040","-4.44546"
"125.69100","-2.48021","-4.50381"
"125.75800","-2.50028","-4.54881"
"125.76000","-2.50088","-4.55024"
"125.86000","-2.50256","-4.54886"
"125.96000","-2.47087","-4.49856"
"126.06000","-2.44023","-4.43204"
"126.16000","-2.41000","-4.36663"
"126.26000","-2.37991","-4.31364"
"126.36000","-2.34967","-4.24863"
"126.46000","-2.31989","-4.21022"
"126.56000","-2.28962","-4.14620"
"126.66000","-2.25989","-4.09489"
"126.76000","-2.22964","-4.02677"
"126.86000","-2.19969","-3.98302"
"126.96000","-2.16951","-3.92240"
"127.06000","-2.13970","-3.86655"
"127.16000","-2.10974","-3.81994"
"127.26000","-2.07992","-3.75018"
"127.36000","-2.04978","-3.69409"
"127.46000","-2.01992","-3.63549"
"127.56000","-1.98987","-3.58217"
"127.66000","-1.95992","-3.53719"
"127.76000","-1.92974","-3.48040"
"127.86000","-1.89965","-3.43475"
"127.96000","-1.86952","-3.36303"
"128.06000","-1.83945","-3.32579"
"128.16000","-1.80959","-3.26428"
"128.26000","-1.77968","-3.21570"
"128.36000","-1.74982","-3.15320"
"128.46000","-1.71985","-3.09603"
"128.56000","-1.68965","-3.03922"
"128.66000","-1.65977","-2.97586"
"128.76000","-1.62993","-2.92331"
"128.86000","-1.59978","-2.86878"
"128.96000","-1.56990","-2.81178"
"129.06000","-1.53960","-2.75942"
"129.16000","-1.50980","-2.70111"
"129.26000","-1.47966","-2.65479"
"129.36000","-1.44963","-2.59817"
"129.46000","-1.41966","-2.55129"
"129.56000","-1.38972","-2.48800"
"129.66000","-1.35954","-2.43001"
"129.76000","-1.32972","-2.38012"
"129.86000","-1.29977","-2.32522"
"129.96000","-1.27002","-2.26815"
"130.06000","-1.23993","-2.20952"
"130.16000","-1.20990","-2.15820"
"130.26000","-1.17967","-2.09834"
"130.36000","-1.14962","-2.05289"
"130.46000","-1.11961","-2.01239"
"130.56000","-1.08966","-1.95291"
"130.66000","-1.05974","-1.89352"
"130.76000","-1.02961","-1.83541"
"130.86000","-0.99962","-1.78291"
"130.96000","-0.96962","-1.73380"
"131.06000","-0.93985","-1.67929"
"131.16000","-0.90974","-1.62511"
"131.26000","-0.87999","-1.56854"
"131.36000","-0.84966","-1.50562"
"131.46000","-0.81990","-1.46082"
"131.56000","-0.78979","-1.40959"
"131.66000","-0.75984","-1.35153"
"131.76000","-0.72970","-1.29937"
"131.86000","-0.69976","-1.24294"
"131.96000","-0.66940","-1.18730"
"132.06000","-0.63962","-1.14068"
"132.16000","-0.60955","-1.08926"
"132.26000","-0.57974","-1.03197"
"132.36000","-0.54981","-0.96806"
"132.46000","-0.51993","-0.92267"
"132.56000","-0.48983","-0.86316"
"132.66000","-0.45983","-0.81279"
"132.76000","-0.42978","-0.77136"
"132.86000","-0.39974","-0.70623"
"132.96000","-0.36971","-0.65981"
"133.06000","-0.33957","-0.60664"
"133.16000","-0.30958","-0.56629"
"133.26000","-0.27968","-0.50880"
"133.36000","-0.24972","-0.46116"
"133.46000","-0.21969","-0.40059"
"133.56000","-0.18992","-0.34250"
"133.66000","-0.15954","-0.29580"
"133.76000","-0.12981","-0.24112"
"133.86000","-0.09982","-0.18669"
"133.96000","-0.07001","-0.13347"
"134.06000","-0.03987","-0.07166"
"134.16000","-0.00991","-0.01874"
"134.19400","0.00019","-0.02736"