File: BeamForceDisplacement/Specimen_RawData_1.csv
Time,Extension,Load
(s),(mm),(N)
"0.00000","0.00000","-0.03700"
"0.10000","0.00864","-0.01406"
"0.20000","0.04228","-0.01447"
"0.30000","0.07263","-0.01774"
"0.40000","0.10277","-0.02029"
"0.50000","0.13275","-0.02447"
"0.60000","0.16282","-0.01335"
"0.70000","0.19278","-0.00899"
"0.80000","0.22265","0.02497"
"0.90000","0.25254","-0.01171"
"1.00000","0.28240","0.01011"
"1.10000","0.31262","0.02085"
"1.20000","0.34245","0.04019"
"1.30000","0.37296","0.00236"
"1.40000","0.40274","0.00607"
"1.50000","0.43286","0.00638"
"1.60000","0.46267","0.02127"
"1.70000","0.49288","0.00749"
"1.80000","0.52270","0.01754"
"1.90000","0.55283","0.02362"
"2.00000","0.58261","0.02748"
"2.10000","0.61266","0.06796"
"2.20000","0.64247","0.06429"
"2.30000","0.67274","0.02175"
"2.40000","0.70254","0.02852"
"2.50000","0.73263","0.03628"
"2.60000","0.76246","0.04567"
"2.70000","0.79270","0.02714"
"2.80000","0.82275","0.02708"
"2.90000","0.85297","0.04560"
"3.00000","0.88282","0.04057"
"3.10000","0.91291","0.03902"
"3.20000","0.94270","0.05699"
"3.30000","0.97259","0.06384"
"3.40000","1.00261","0.06490"
"3.50000","1.03251","0.05838"
"3.60000","1.06257","0.05110"
"3.70000","1.09249","0.06184"
"3.80000","1.12267","0.08371"
"3.90000","1.15261","0.05326"
"4.00000","1.18286","0.07235"
"4.10000","1.21264","0.05614"
"4.20000","1.24295","0.08947"
"4.30000","1.27265","0.08258"
"4.40000","1.30277","0.08689"
"4.50000","1.33253","0.08489"
"4.60000","1.36286","0.08896"
"4.70000","1.39258","0.08476"
"4.80000","1.42269","0.09348"
"4.90000","1.45246","0.09835"
"5.00000","1.48250","0.09654"
"5.10000","1.51257","0.11126"
"5.20000","1.54276","0.11328"
"5.30000","1.57269","0.10535"
"5.40000","1.60287","0.07522"
"5.50000","1.63259","0.09440"
"5.60000","1.66284","0.09113"
"5.70000","1.69281","0.10656"
"5.80000","1.72283","0.08911"
"5.90000","1.75271","0.10896"
"6.00000","1.78254","0.12086"
"6.10000","1.81250","0.12756"
"6.20000","1.84243","0.10947"
"6.30000","1.87274","0.11685"
"6.40000","1.90268","0.11463"
"6.50000","1.93276","0.12584"
"6.60000","1.96265","0.11358"
"6.70000","1.99273","0.11452"
"6.80000","2.02260","0.13349"
"6.90000","2.05292","0.13401"
"7.00000","2.08264","0.13618"
"7.10000","2.11289","0.11774"
"7.20000","2.14254","0.13372"
"7.30000","2.17262","0.13329"
"7.40000","2.20245","0.14499"
"7.50000","2.23259","0.13506"
"7.60000","2.26247","0.13642"
"7.70000","2.29257","0.13070"
"7.80000","2.32265","0.15322"
"7.90000","2.35293","0.14586"
"8.00000","2.38290","0.13384"
"8.10000","2.41300","0.14302"
"8.20000","2.44281","0.16524"
"8.30000","2.47279","0.16781"
"8.40000","2.50262","0.14468"
"8.50000","2.53253","0.13031"
"8.60000","2.56276","0.12218"
"8.70000","2.59257","0.14762"
"8.80000","2.62260","0.13268"
"8.90000","2.65252","0.12761"
"9.00000","2.68266","0.13218"
"9.10000","2.71259","0.15212"
"9.20000","2.74273","0.13858"
"9.30000","2.77267","0.13965"
"9.39100","2.80026","0.13640"
"9.39300","2.80086","0.13634"
"9.49300","2.80197","0.15153"
"9.59300","2.77040","0.14678"
"9.69300","2.73980","0.16092"
"9.79300","2.70953","0.11555"
"9.89300","2.67970","0.13304"
"9.99300","2.64956","0.14008"
"10.09300","2.61981","0.17139"
"10.19300","2.58969","0.10762"
"10.29300","2.55979","0.13968"
"10.39300","2.52950","0.12750"
"10.49300","2.49976","0.15003"
"10.59300","2.46967","0.17199"
"10.69300","2.43982","0.13819"
"10.79300","2.40963","0.13588"
"10.89300","2.37954","0.16138"
"10.99300","2.34931","0.17020"
"11.09300","2.31953","0.11940"
"11.19300","2.28950","0.15617"
"11.29300","2.25969","0.13079"
"11.39300","2.22959","0.14674"
"11.49300","2.19965","0.13060"
"11.59300","2.16978","0.13617"
"11.69300","2.13976","0.12797"
"11.79300","2.10989","0.15040"
"11.89300","2.07962","0.14423"
"11.99300","2.04961","0.13450"
"12.09300","2.01949","0.13718"
"12.19300","1.98963","0.12542"
"12.29300","1.95950","0.13932"
"12.39300","1.92972","0.12237"
"12.49300","1.89951","0.11102"
"12.59300","1.86966","0.10794"
"12.69300","1.83947","0.13229"
"12.79300","1.80980","0.12812"
"12.89300","1.77977","0.12073"
"12.99300","1.74992","0.11047"
"13.09300","1.71955","0.11261"
"13.19300","1.68966","0.10726"
"13.29300","1.65943","0.09322"
"13.39300","1.62966","0.09263"
"13.49300","1.59954","0.09002"
"13.59300","1.56954","0.11408"
"13.69300","1.53947","0.11416"
"13.79300","1.50944","0.10417"
"13.89300","1.47955","0.10537"
"13.99300","1.44971","0.11322"
"14.09300","1.41982","0.10293"
"14.19300","1.38975","0.09545"
"14.29300","1.35961","0.08379"
"14.39300","1.32953","0.07838"
"14.49300","1.29964","0.09642"
"14.59300","1.26960","0.08187"
"14.69300","1.23978","0.08356"
"14.79300","1.20955","0.07814"
"14.89300","1.17960","0.10099"
"14.99300","1.14931","0.08449"
"15.09300","1.11965","0.09348"
"15.19300","1.08955","0.05491"
"15.29300","1.05981","0.05605"
"15.39300","1.02969","0.06532"
"15.49300","0.99978","0.07499"
"15.59300","0.96964","0.05150"
"15.69300","0.93982","0.04624"
"15.79300","0.90968","0.05966"
"15.89300","0.87961","0.07326"
"15.99300","0.84946","0.04125"
"16.09300","0.81941","0.02795"
"16.19300","0.78940","0.06281"
"16.29300","0.75962","0.04951"
"16.39300","0.72963","0.03336"
"16.49300","0.69961","0.03678"
"16.59300","0.66973","0.03555"
"16.69300","0.63962","0.07696"
"16.79300","0.60969","0.06508"
"16.89300","0.57969","0.03211"
"16.99300","0.54976","0.02956"
"17.09300","0.51958","0.02848"
"17.19300","0.48961","0.06272"
"17.29300","0.45943","-0.01847"
"17.39300","0.42968","0.02308"
"17.49300","0.39945","0.02747"
"17.59300","0.36963","0.04250"
"17.69300","0.33947","0.01626"
"17.79300","0.30957","0.00549"
"17.89300","0.27957","0.00563"
"17.99300","0.24983","0.01096"
"18.09300","0.21977","-0.01160"
"18.19300","0.18976","-0.02297"
"18.29300","0.15955","-0.00794"
"18.39300","0.12956","-0.01686"
"18.49300","0.09952","-0.00042"
"18.59300","0.06971","0.00121"
"18.69300","0.03955","-0.01431"
"18.79300","0.00959","-0.01066"
"18.89300","-0.02038","0.00916"
"18.99300","-0.05048","-0.00403"
"19.09300","-0.08029","-0.04451"
"19.19300","-0.11022","-0.01555"
"19.29300","-0.14018","-0.00137"
"19.39300","-0.17037","-0.01909"
"19.49300","-0.20032","0.01508"
"19.59300","-0.23033","-0.03650"
"19.69300","-0.26018","-0.04033"
"19.79300","-0.29035","-0.01904"
"19.89300","-0.32034","-0.00961"
"19.99300","-0.35054","0.00692"
"20.09300","-0.38053","-0.01195"
"20.19300","-0.41056","0.00822"
"20.29300","-0.44030","-0.02516"
"20.39300","-0.47035","0.02831"
"20.49300","-0.50018","-0.02829"
"20.59300","-0.53039","-0.03756"
"20.69300","-0.56020","-0.01437"
"20.79300","-0.59031","-0.01163"
"20.89300","-0.62017","-0.00863"
"20.99300","-0.65045","-0.01871"
"21.09300","-0.68039","-0.02636"
"21.19300","-0.71060","-0.01575"
"21.29300","-0.74050","-0.01626"
"21.39300","-0.77046","-0.05597"
"21.49300","-0.80036","-0.01328"
"21.59300","-0.83038","-0.05242"
"21.69300","-0.86045","-0.02070"
"21.79300","-0.89037","-0.04156"
"21.89300","-0.92037","-0.01974"
"21.99300","-0.95013","-0.03664"
"22.09300","-0.98027","-0.01467"
"22.19300","-1.01025","-0.03923"
"22.29300","-1.04048","-0.05665"
"22.39300","-1.07048","-0.07048"
"22.49300","-1.10040","0.00797"
"22.59300","-1.13040","-0.05581"
"22.69300","-1.16049","-0.05271"
"22.79300","-1.19031","-0.06132"
"22.89300","-1.22057","-0.02380"
"22.99300","-1.25031","-0.01399"
"23.09300","-1.28022","-0.05637"
"23.19300","-1.31006","-0.04986"
"23.29300","-1.34031","-0.04464"
"23.39300","-1.37034","-0.02293"
"23.49300","-1.40047","-0.02743"
"23.59300","-1.43044","-0.04932"
"23.69300","-1.46037","-0.04517"
"23.79300","-1.49036","-0.02032"
"23.89300","-1.52045","-0.02340"
"23.99300","-1.55049","-0.02246"
"24.09300","-1.58061","-0.06706"
"24.19300","-1.61052","-0.01295"
"24.29300","-1.64019","-0.03757"
"24.39300","-1.67035","-0.06083"
"24.49300","-1.70021","-0.03800"
"24.59300","-1.73042","-0.03083"
"24.69300","-1.76035","-0.04364"
"24.79300","-1.79030","-0.01444"
"24.89300","-1.82024","-0.02040"
"24.99300","-1.85048","-0.02949"
"25.09300","-1.88042","-0.01415"
"25.19300","-1.91063","-0.00560"
"25.29300","-1.94051","-0.03855"
"25.39300","-1.97040","-0.00697"
"25.49300","-2.00022","-0.03340"
"25.59300","-2.03035","-0.02811"
"25.69300","-2.06024","-0.02245"
"25.79300","-2.09044","-0.01351"
"25.89300","-2.12037","-0.00709"
"25.99300","-2.15031","-0.02563"
"26.09300","-2.18029","-0.03729"
"26.19300","-2.21036","0.02307"
"26.29300","-2.24045","0.00102"
"26.39300","-2.27049","-0.00891"
"26.49300","-2.30049","0.02065"
"26.59300","-2.33048","-0.00137"
"26.69300","-2.36048","0.05040"
"26.79300","-2.39038","0.03944"
"26.89300","-2.42048","0.02785"
"26.99300","-2.45022","0.05495"
"27.09300","-2.48023","0.01404"
"27.19300","-2.51003","0.05296"
"27.29300","-2.54042","0.06934"
"27.39300","-2.57031","0.04484"
"27.49300","-2.60051","0.05906"
"27.59300","-2.63040","0.05870"
"27.69300","-2.66040","0.09245"
"27.79300","-2.69036","0.08616"
"27.89300","-2.72048","0.07240"
"27.99300","-2.75036","0.08114"
"28.09300","-2.78048","0.09223"
"28.15900","-2.80023","0.09988"
"28.16100","-2.80081","0.09819"
"28.26100","-2.80199","0.08559"
"28.36100","-2.77046","0.10646"
"28.46100","-2.73961","0.09581"
"28.56100","-2.70957","0.10644"
"28.66100","-2.67963","0.05251"
"28.76100","-2.64946","0.02505"
"28.86100","-2.61953","0.12325"
"28.96100","-2.58939","0.05011"
"29.06100","-2.55927","0.02328"
"29.16100","-2.52937","0.04198"
"29.26100","-2.49921","0.05798"
"29.36100","-2.46940","0.03179"
"29.46100","-2.43942","0.03085"
"29.56100","-2.40953","0.02363"
"29.66100","-2.37944","0.02999"
"29.76100","-2.34965","0.02863"
"29.86100","-2.31956","0.02085"
"29.96100","-2.28973","0.00017"
"30.06100","-2.25946","-0.00971"
"30.16100","-2.22955","-0.00419"
"30.26100","-2.19911","-0.01058"
"30.36100","-2.16949","-0.01134"
"30.46100","-2.13929","-0.02509"
"30.56100","-2.10951","-0.02769"
"30.66100","-2.07934","-0.02828"
"30.76100","-2.04930","-0.04131"
"30.86100","-2.01931","-0.04530"
"30.96100","-1.98952","-0.02900"
"31.06100","-1.95953","-0.04028"
"31.16100","-1.92968","-0.02361"
"31.26100","-1.89952","-0.04233"
"31.36100","-1.86950","-0.02155"
"31.46100","-1.83949","-0.02571"
"31.56100","-1.80937","-0.03177"
"31.66100","-1.77941","-0.04186"
"31.76100","-1.74928","-0.05737"
"31.86100","-1.71928","-0.04202"
"31.96100","-1.68913","-0.04849"
"32.06100","-1.65941","-0.05484"
"32.16100","-1.62944","-0.05959"
"32.26100","-1.59970","-0.03088"
"32.36100","-1.56958","-0.03208"
"32.46100","-1.53954","-0.01748"
"32.56100","-1.50940","-0.04651"
"32.66100","-1.47957","-0.02438"
"32.76100","-1.44934","-0.04420"
"32.86100","-1.41958","-0.03772"
"32.96100","-1.38928","-0.05647"
"33.06100","-1.35936","-0.04129"
"33.16100","-1.32917","-0.05193"
"33.26100","-1.29932","-0.03523"
"33.36100","-1.26939","-0.01772"
"33.46100","-1.23953","-0.07450"
"33.56100","-1.20947","-0.05961"
"33.66100","-1.17954","-0.05066"
"33.76100","-1.14951","-0.04768"
"33.86100","-1.11963","-0.06928"
"33.96100","-1.08953","-0.05852"
"34.06100","-1.05937","-0.05743"
"34.16100","-1.02926","-0.03923"
"34.26100","-0.99916","-0.04912"
"34.36100","-0.96940","-0.05257"
"34.46100","-0.93925","-0.05654"
"34.56100","-0.90948","-0.04280"
"34.66100","-0.87936","-0.03479"
"34.76100","-0.84946","-0.04407"
"34.86100","-0.81940","-0.05487"
"34.96100","-0.78966","-0.03853"
"35.06100","-0.75946","-0.02964"
"35.16100","-0.72969","-0.05237"
"35.26100","-0.69929","-0.04197"
"35.36100","-0.66951","-0.03270"
"35.46100","-0.63933","-0.02456"
"35.56100","-0.60943","-0.03177"
"35.66100","-0.57935","-0.03890"
"35.76100","-0.54943","-0.04789"
"35.86100","-0.51909","-0.03661"
"35.96100","-0.48926","-0.01120"
"36.06100","-0.45935","-0.02303"
"36.16100","-0.42956","-0.01765"
"36.26100","-0.39968","-0.00937"
"36.36100","-0.36954","-0.00167"
"36.46100","-0.33950","-0.01766"
"36.56100","-0.30935","-0.02398"
"36.66100","-0.27936","-0.03542"
"36.76100","-0.24935","-0.04140"
"36.86100","-0.21947","-0.02676"
"36.96100","-0.18927","-0.03489"
"37.06100","-0.15935","-0.03907"
"37.16100","-0.12929","-0.01293"
"37.26100","-0.09950","-0.02112"
"37.36100","-0.06940","-0.01897"
"37.46100","-0.03962","-0.03565"
"37.56100","-0.00934","-0.01334"
"37.66100","0.02036","-0.00896"
"37.76100","0.05041","-0.01535"
"37.86100","0.08042","-0.02345"
"37.96100","0.11056","-0.03385"
"38.06100","0.14052","-0.00834"
"38.16100","0.17084","0.00207"
"38.26100","0.20062","-0.00850"
"38.36100","0.23082","-0.01883"
"38.46100","0.26055","0.00921"
"38.56100","0.29057","0.01354"
"38.66100","0.32032","0.02409"
"38.76100","0.35057","0.01191"
"38.86100","0.38048","0.01587"
"38.96100","0.41042","0.01478"
"39.06100","0.44049","0.02168"
"39.16100","0.47050","-0.00344"
"39.26100","0.50072","0.00734"
"39.36100","0.53070","0.02068"
"39.46100","0.56067","0.02079"
"39.56100","0.59059","0.03317"
"39.66100","0.62067","0.07765"
"39.76100","0.65045","0.02814"
"39.86100","0.68085","0.02733"
"39.96100","0.71046","0.04954"
"40.06100","0.74047","0.04503"
"40.16100","0.77029","0.04072"
"40.26100","0.80051","0.04254"
"40.36100","0.83039","0.05731"
"40.46100","0.86069","0.03591"
"40.56100","0.89049","0.03775"
"40.66100","0.92077","0.04060"
"40.76100","0.95054","0.05735"
"40.86100","0.98072","0.05237"
"40.96100","1.01064","0.04927"
"41.06100","1.04079","0.05582"
"41.16100","1.07057","0.05978"
"41.26100","1.10046","0.08955"
"41.36100","1.13038","0.05924"
"41.46100","1.16032","0.06833"
"41.56100","1.19046","0.07524"
"41.66100","1.22072","0.08206"
"41.76100","1.25061","0.08670"
"41.86100","1.28058","0.06579"
"41.96100","1.31055","0.06941"
"42.06100","1.34049","0.09390"
"42.16100","1.37075","0.06843"
"42.26100","1.40062","0.07900"
"42.36100","1.43077","0.07752"
"42.46100","1.46044","0.10739"
"42.56100","1.49053","0.09168"
"42.66100","1.52036","0.09867"
"42.76100","1.55055","0.10255"
"42.86100","1.58030","0.08028"
"42.96100","1.61047","0.08696"
"43.06100","1.64044","0.11700"
"43.16100","1.67074","0.07892"
"43.26100","1.70070","0.08024"
"43.36100","1.73090","0.09866"
"43.46100","1.76070","0.11263"
"43.56100","1.79069","0.10063"
"43.66100","1.82051","0.09398"
"43.76100","1.85048","0.11693"
"43.86100","1.88059","0.12105"
"43.96100","1.91051","0.12657"
"44.06100","1.94048","0.11069"
"44.16100","1.97047","0.11108"
"44.26100","2.00050","0.12877"
"44.36100","2.03056","0.12914"
"44.46100","2.06048","0.14184"
"44.56100","2.09069","0.12268"
"44.66100","2.12082","0.13601"
"44.76100","2.15050","0.13345"
"44.86100","2.18072","0.14468"
"44.96100","2.21063","0.13328"
"45.06100","2.24067","0.13427"
"45.16100","2.27038","0.14594"
"45.26100","2.30049","0.14626"
"45.36100","2.33023","0.12827"
"45.46100","2.36053","0.13275"
"45.56100","2.39055","0.13661"
"45.66100","2.42074","0.13338"
"45.76100","2.45069","0.14392"
"45.86100","2.48069","0.15585"
"45.96100","2.51053","0.12199"
"46.06100","2.54072","0.13683"
"46.16100","2.57074","0.13884"
"46.26100","2.60067","0.12869"
"46.36100","2.63058","0.13888"
"46.46100","2.66047","0.15036"
"46.56100","2.69047","0.16689"
"46.66100","2.72051","0.14737"
"46.76100","2.75056","0.15191"
"46.86100","2.78043","0.15196"
"46.92600","2.80029","0.11797"
"46.92800","2.80088","0.12370"
"47.02800","2.80203","0.15922"
"47.12800","2.77046","0.15437"
"47.22800","2.73985","0.15891"
"47.32800","2.70962","0.14712"
"47.42800","2.67974","0.13975"
"47.52800","2.64960","0.14663"
"47.62800","2.61986","0.15480"
"47.72800","2.58975","0.12367"
"47.82800","2.55985","0.12774"
"47.92800","2.52956","0.13258"
"48.02800","2.49982","0.14269"
"48.12800","2.46977","0.16123"
"48.22800","2.43986","0.14190"
"48.32800","2.40961","0.15181"
"48.42800","2.37966","0.14542"
"48.52800","2.34936","0.16785"
"48.62800","2.31958","0.13070"
"48.72800","2.28956","0.14633"
"48.82800","2.25974","0.15226"
"48.92800","2.22964","0.15194"
"49.02800","2.19974","0.13257"
"49.12800","2.16980","0.13735"
"49.22800","2.13980","0.13959"
"49.32800","2.10993","0.14600"
"49.42800","2.07969","0.15006"
"49.52800","2.04964","0.13563"
"49.62800","2.01951","0.14100"
"49.72800","1.98964","0.13118"
"49.82800","1.95961","0.13207"
"49.92800","1.92978","0.12124"
"50.02800","1.89959","0.12421"
"50.12800","1.86970","0.12729"
"50.22800","1.83951","0.13822"
"50.32800","1.80988","0.13526"
"50.42800","1.77982","0.13022"
"50.52800","1.74990","0.13025"
"50.62800","1.71980","0.12162"
"50.72800","1.68964","0.11699"
"50.82800","1.65946","0.11340"
"50.92800","1.62971","0.09361"
"51.02800","1.59962","0.09380"
"51.12800","1.56961","0.12555"
"51.22800","1.53954","0.12033"
"51.32800","1.50947","0.11241"
"51.42800","1.47960","0.11090"
"51.52800","1.44976","0.11799"
"51.62800","1.41998","0.09142"
"51.72800","1.38972","0.08962"
"51.82800","1.35971","0.09405"
"51.92800","1.32958","0.10347"
"52.02800","1.29968","0.09789"
"52.12800","1.26966","0.09224"
"52.22800","1.23982","0.09217"
"52.32800","1.20962","0.08806"
"52.42800","1.17964","0.10616"
"52.52800","1.14936","0.07939"
"52.62800","1.11969","0.09647"
"52.72800","1.08960","0.06320"
"52.82800","1.05986","0.08477"
"52.92800","1.02974","0.06606"
"53.02800","0.99983","0.08214"
"53.12800","0.96970","0.04525"
"53.22800","0.93990","0.05854"
"53.32800","0.90971","0.05929"
"53.42800","0.87967","0.05804"
"53.52800","0.84951","0.05231"
"53.62800","0.81950","0.04334"
"53.72800","0.78946","0.05808"
"53.82800","0.75969","0.06389"
"53.92800","0.72969","0.05459"
"54.02800","0.69967","0.04238"
"54.12800","0.66978","0.02928"
"54.22800","0.63965","0.10696"
"54.32800","0.60976","0.05465"
"54.42800","0.57977","0.04002"
"54.52800","0.54981","0.03817"
"54.62800","0.51963","0.03546"
"54.72800","0.48965","0.03750"
"54.82800","0.45952","0.02161"
"54.92800","0.42972","0.02386"
"55.02800","0.39952","0.02629"
"55.12800","0.36967","0.03608"
"55.22800","0.33952","0.03170"
"55.32800","0.30964","0.00954"
"55.42800","0.27963","0.01296"
"55.52800","0.24989","0.01866"
"55.62800","0.21984","0.01598"
"55.72800","0.18977","0.00353"
"55.82800","0.15960","-0.00233"
"55.92800","0.12965","0.00473"
"56.02800","0.09957","-0.00171"
"56.12800","0.06978","0.00161"
"56.22800","0.03959","-0.01054"
"56.32800","0.00962","0.01042"
"56.42800","-0.02038","-0.00882"
"56.52800","-0.05040","0.01239"
"56.62800","-0.08022","-0.01774"
"56.72800","-0.11015","-0.00958"
"56.82800","-0.14015","-0.02025"
"56.92800","-0.17029","0.00702"
"57.02800","-0.20028","-0.01138"
"57.12800","-0.23032","-0.01200"
"57.22800","-0.26008","-0.03153"
"57.32800","-0.29028","-0.00299"
"57.42800","-0.32030","-0.00163"
"57.52800","-0.35048","-0.00080"
"57.62800","-0.38047","-0.00013"
"57.72800","-0.41052","0.01435"
"57.82800","-0.44023","-0.00147"
"57.92800","-0.47029","-0.01507"
"58.02800","-0.50012","-0.02298"
"58.12800","-0.53032","-0.02747"
"58.22800","-0.56014","0.00052"
"58.32800","-0.59025","-0.02135"
"58.42800","-0.62010","-0.02085"
"58.52800","-0.65041","-0.01293"
"58.62800","-0.68038","-0.01286"
"58.72800","-0.71050","-0.01609"
"58.82800","-0.74047","-0.02641"
"58.92800","-0.77032","-0.02568"
"59.02800","-0.80027","-0.01794"
"59.12800","-0.83038","-0.01458"
"59.22800","-0.86038","-0.02782"
"59.32800","-0.89033","-0.03180"
"59.42800","-0.92029","-0.03393"
"59.52800","-0.95010","-0.01677"
"59.62800","-0.98018","-0.02436"
"59.72800","-1.01022","-0.03181"
"59.82800","-1.04043","-0.04509"
"59.92800","-1.07042","-0.01882"
"60.02800","-1.10040","-0.03641"
"60.12800","-1.13031","-0.03807"
"60.22800","-1.16042","-0.04292"
"60.32800","-1.19033","-0.03921"
"60.42800","-1.22046","-0.03410"
"60.52800","-1.25024","-0.00557"
"60.62800","-1.28019","-0.01985"
"60.72800","-1.31001","-0.06045"
"60.82800","-1.34025","-0.02707"
"60.92800","-1.37031","-0.02717"
"61.02800","-1.40042","-0.02264"
"61.12800","-1.43036","-0.04086"
"61.22800","-1.46031","-0.02068"
"61.32800","-1.49031","-0.02512"
"61.42800","-1.52042","-0.01064"
"61.52800","-1.55044","-0.04644"
"61.62800","-1.58053","-0.01430"
"61.72800","-1.61041","-0.04284"
"61.82800","-1.64020","-0.02985"
"61.92800","-1.67024","-0.05943"
"62.02800","-1.70017","-0.04710"
"62.12800","-1.73037","-0.04004"
"62.22800","-1.76029","-0.02402"
"62.32800","-1.79025","-0.01980"
"62.42800","-1.82020","-0.01972"
"62.52800","-1.85042","-0.03143"
"62.62800","-1.88038","-0.01470"
"62.72800","-1.91058","-0.01287"
"62.82800","-1.94047","-0.02227"
"62.92800","-1.97034","-0.02556"
"63.02800","-2.00013","-0.02421"
"63.12800","-2.03030","-0.01362"
"63.22800","-2.06017","-0.01978"
"63.32800","-2.09036","-0.01399"
"63.42800","-2.12032","-0.01635"
"63.52800","-2.15025","-0.01151"
"63.62800","-2.18026","0.00529"
"63.72800","-2.21028","-0.01203"
"63.82800","-2.24040","0.00721"
"63.92800","-2.27044","0.00797"
"64.02800","-2.30040","0.02383"
"64.12800","-2.33043","0.01031"
"64.22800","-2.36042","0.02775"
"64.32800","-2.39030","0.03313"
"64.42800","-2.42043","0.04620"
"64.52800","-2.45015","0.01947"
"64.62800","-2.48020","0.03804"
"64.72800","-2.50990","0.03391"
"64.82800","-2.54046","0.05995"
"64.92800","-2.57022","0.05401"
"65.02800","-2.60043","0.06249"
"65.12800","-2.63040","0.06586"
"65.22800","-2.66033","0.07306"
"65.32800","-2.69033","0.09018"
"65.42800","-2.72041","0.07639"
"65.52800","-2.75034","0.09332"
"65.62800","-2.78042","0.07912"
"65.69400","-2.80016","0.09181"
"65.69600","-2.80075","0.09132"
"65.79600","-2.80494","0.10057"
"65.89600","-2.78086","0.09721"
"65.99600","-2.75642","0.10856"
"66.09600","-2.73294","0.07555"
"66.19600","-2.70970","0.09484"
"66.29600","-2.68633","0.07712"
"66.39600","-2.66287","0.08535"
"66.49600","-2.63952","0.08298"
"66.59600","-2.61652","0.06382"
"66.69600","-2.59291","0.06918"
"66.79600","-2.56928","0.04750"
"66.89600","-2.54649","0.05956"
"66.99600","-2.52298","0.04581"
"67.09600","-2.49938","0.05623"
"67.19600","-2.47635","0.03392"
"67.29600","-2.45310","0.03019"
"67.39600","-2.42964","0.02904"
"67.49600","-2.40607","0.03026"
"67.59600","-2.38311","0.03396"
"67.69600","-2.35973","0.02895"
"67.79600","-2.33602","0.01722"
"67.89600","-2.31284","-0.00411"
"67.99600","-2.28989","0.01003"
"68.09600","-2.26616","0.00747"
"68.19600","-2.24289","-0.00273"
"68.29600","-2.21964","-0.00687"
"68.39600","-2.19614","-0.03806"
"68.49600","-2.17297","-0.01221"
"68.59600","-2.14940","-0.01794"
"68.69600","-2.12640","-0.01099"
"68.79600","-2.10306","-0.01605"
"68.89600","-2.07946","-0.03359"
"68.99600","-2.05618","0.00958"
"69.09600","-2.03301","-0.02996"
"69.19600","-2.00946","-0.02661"
"69.29600","-1.98612","-0.03426"
"69.39600","-1.96310","-0.02201"
"69.49600","-1.93966","-0.00881"
"69.59600","-1.91615","-0.04538"
"69.69600","-1.89286","-0.02968"
"69.79600","-1.86979","-0.02520"
"69.89600","-1.84627","-0.02134"
"69.99600","-1.82268","-0.03849"
"70.09600","-1.79996","-0.01852"
"70.19600","-1.77614","-0.03834"
"70.29600","-1.75272","-0.03008"
"70.39600","-1.72973","-0.03598"
"70.49600","-1.70633","-0.03358"
"70.59600","-1.68274","-0.05584"
"70.69600","-1.65943","-0.05032"
"70.79600","-1.63648","-0.03602"
"70.89600","-1.61303","-0.05216"
"70.99600","-1.58945","-0.04946"
"71.09600","-1.56630","-0.04579"
"71.19600","-1.54305","-0.01812"
"71.29600","-1.51938","-0.02448"
"71.39600","-1.49608","-0.04607"
"71.49600","-1.47307","-0.03729"
"71.59600","-1.44957","-0.03230"
"71.69600","-1.42636","-0.02898"
"71.79600","-1.40289","-0.03551"
"71.89600","-1.37959","-0.04648"
"71.99600","-1.35630","-0.03249"
"72.09600","-1.33259","-0.04220"
"72.19600","-1.30970","-0.01537"
"72.29600","-1.28640","-0.03794"
"72.39600","-1.26288","-0.01040"
"72.49600","-1.23951","-0.04284"
"72.59600","-1.21646","-0.04939"
"72.69600","-1.19286","-0.05441"
"72.79600","-1.16946","-0.06940"
"72.89600","-1.14627","-0.05025"
"72.99600","-1.12307","-0.04585"
"73.09600","-1.09957","-0.04035"
"73.19600","-1.07616","-0.05523"
"73.29600","-1.05323","-0.04414"
"73.39600","-1.02944","-0.04905"
"73.49600","-1.00599","-0.04982"
"73.59600","-0.98307","-0.04956"
"73.69600","-0.95960","-0.05226"
"73.79600","-0.93615","-0.04509"
"73.89600","-0.91295","-0.03911"
"73.99600","-0.88980","-0.02394"
"74.09600","-0.86618","-0.06278"
"74.19600","-0.84270","-0.04967"
"74.29600","-0.81959","-0.03130"
"74.39600","-0.79645","-0.02587"
"74.49600","-0.77283","-0.05172"
"74.59600","-0.74944","-0.07472"
"74.69600","-0.72652","-0.03779"
"74.79600","-0.70278","-0.03130"
"74.89600","-0.67950","-0.03919"
"74.99600","-0.65624","-0.02736"
"75.09600","-0.63309","-0.02652"
"75.19600","-0.60966","-0.00799"
"75.29600","-0.58613","-0.02885"
"75.39600","-0.56318","-0.01855"
"75.49600","-0.53966","-0.02522"
"75.59600","-0.51589","-0.03463"
"75.69600","-0.49278","-0.01817"
"75.79600","-0.46983","-0.02441"
"75.89600","-0.44614","-0.03191"
"75.99600","-0.42289","-0.01659"
"76.09600","-0.39984","-0.00587"
"76.19600","-0.37623","-0.01114"
"76.29600","-0.35280","-0.02290"
"76.39600","-0.32942","-0.02699"
"76.49600","-0.30644","-0.01726"
"76.59600","-0.28287","-0.02364"
"76.69600","-0.25938","-0.03426"
"76.79600","-0.23664","-0.03361"
"76.89600","-0.21292","-0.01728"
"76.99600","-0.18940","-0.02316"
"77.09600","-0.16619","-0.02206"
"77.19600","-0.14308","-0.02398"
"77.29600","-0.11963","-0.02365"
"77.39600","-0.09610","-0.00719"
"77.49600","-0.07294","-0.01381"
"77.59600","-0.04973","-0.00992"
"77.69600","-0.02623","-0.02024"
"77.79600","-0.00265","-0.01100"
"77.80800","0.00006","-0.02208"