File: BeamForceDisplacement/Specimen_RawData_4.csv
Time,Extension,Load
(s),(mm),(N)
"0.00000","0.00000","0.12535"
"0.10000","0.00864","0.06014"
"0.20000","0.04209","0.03466"
"0.30000","0.07257","0.00904"
"0.40000","0.10264","-0.04752"
"0.50000","0.13267","-0.04507"
"0.60000","0.16272","-0.07774"
"0.70000","0.19264","-0.10153"
"0.80000","0.22244","-0.13612"
"0.90000","0.25250","-0.15753"
"1.00000","0.28230","-0.17806"
"1.10000","0.31250","-0.22920"
"1.20000","0.34254","-0.24849"
"1.30000","0.37270","-0.27546"
"1.40000","0.40260","-0.27466"
"1.50000","0.43271","-0.31915"
"1.60000","0.46251","-0.35818"
"1.70000","0.49274","-0.37677"
"1.80000","0.52262","-0.39798"
"1.90000","0.55271","-0.41869"
"2.00000","0.58247","-0.45829"
"2.10000","0.61256","-0.47324"
"2.20000","0.64217","-0.42047"
"2.30000","0.67281","-0.53826"
"2.40000","0.70248","-0.58404"
"2.50000","0.73249","-0.59704"
"2.60000","0.76249","-0.62314"
"2.70000","0.79256","-0.66507"
"2.80000","0.82260","-0.67637"
"2.90000","0.85283","-0.73189"
"3.00000","0.88272","-0.73941"
"3.10000","0.91277","-0.78282"
"3.20000","0.94259","-0.79872"
"3.30000","0.97248","-0.83034"
"3.40000","1.00250","-0.84655"
"3.50000","1.03238","-0.86514"
"3.60000","1.06236","-0.88926"
"3.70000","1.09234","-0.93145"
"3.80000","1.12265","-0.95278"
"3.90000","1.15251","-1.00373"
"4.00000","1.18280","-0.99923"
"4.10000","1.21263","-1.04197"
"4.20000","1.24271","-1.06923"
"4.30000","1.27255","-1.11036"
"4.40000","1.30264","-1.11202"
"4.50000","1.33245","-1.13581"
"4.60000","1.36274","-1.17513"
"4.70000","1.39249","-1.21523"
"4.80000","1.42254","-1.23545"
"4.90000","1.45235","-1.23878"
"5.00000","1.48235","-1.26815"
"5.10000","1.51238","-1.30877"
"5.20000","1.54272","-1.33057"
"5.30000","1.57259","-1.36897"
"5.40000","1.60277","-1.41667"
"5.50000","1.63260","-1.44436"
"5.60000","1.66269","-1.48554"
"5.70000","1.69268","-1.48876"
"5.80000","1.72274","-1.52773"
"5.90000","1.75261","-1.54769"
"6.00000","1.78241","-1.58507"
"6.10000","1.81239","-1.60414"
"6.20000","1.84230","-1.62998"
"6.30000","1.87267","-1.63624"
"6.40000","1.90257","-1.69262"
"6.50000","1.93261","-1.69972"
"6.60000","1.96238","-1.73997"
"6.70000","1.99259","-1.73997"
"6.80000","2.02254","-1.78749"
"6.90000","2.05291","-1.81554"
"7.00000","2.08266","-1.83792"
"7.10000","2.11276","-1.86133"
"7.20000","2.14240","-1.88268"
"7.30000","2.17251","-1.92344"
"7.40000","2.20237","-1.95839"
"7.50000","2.23245","-1.97429"
"7.60000","2.26236","-1.98906"
"7.70000","2.29261","-2.03064"
"7.80000","2.32256","-2.07126"
"7.90000","2.35270","-2.09618"
"8.00000","2.38277","-2.10470"
"8.10000","2.41289","-2.15171"
"8.20000","2.44275","-2.17013"
"8.30000","2.47263","-2.15775"
"8.40000","2.50251","-2.25601"
"8.50000","2.53238","-2.29650"
"8.60000","2.56267","-2.31320"
"8.70000","2.59246","-2.34238"
"8.80000","2.62249","-2.35831"
"8.90000","2.65243","-2.39447"
"9.00000","2.68252","-2.41913"
"9.10000","2.71250","-2.45735"
"9.20000","2.74269","-2.47469"
"9.30000","2.77258","-2.50015"
"9.39100","2.80006","-2.52076"
"9.39300","2.80066","-2.52210"
"9.49300","2.80180","-2.52658"
"9.59300","2.77030","-2.51834"
"9.69300","2.73963","-2.46320"
"9.79300","2.70939","-2.44106"
"9.89300","2.67950","-2.41356"
"9.99300","2.64940","-2.41946"
"10.09300","2.61968","-2.36252"
"10.19300","2.58960","-2.34019"
"10.29300","2.55964","-2.29280"
"10.39300","2.52937","-2.28219"
"10.49300","2.49961","-2.24121"
"10.59300","2.46956","-2.17855"
"10.69300","2.43964","-2.14277"
"10.79300","2.40939","-2.11230"
"10.89300","2.37946","-2.11145"
"10.99300","2.34916","-2.07957"
"11.09300","2.31940","-2.04986"
"11.19300","2.28934","-2.01624"
"11.29300","2.25948","-1.99872"
"11.39300","2.22949","-1.98439"
"11.49300","2.19948","-1.95180"
"11.59300","2.16965","-1.91351"
"11.69300","2.13963","-1.90566"
"11.79300","2.10970","-1.85927"
"11.89300","2.07948","-1.83112"
"11.99300","2.04943","-1.77806"
"12.09300","2.01932","-1.75613"
"12.19300","1.98945","-1.74124"
"12.29300","1.95939","-1.72539"
"12.39300","1.92958","-1.65437"
"12.49300","1.89937","-1.65827"
"12.59300","1.86952","-1.63910"
"12.69300","1.83927","-1.62334"
"12.79300","1.80965","-1.58529"
"12.89300","1.77963","-1.56349"
"12.99300","1.74969","-1.53295"
"13.09300","1.71951","-1.51921"
"13.19300","1.68953","-1.47918"
"13.29300","1.65930","-1.44250"
"13.39300","1.62950","-1.41576"
"13.49300","1.59940","-1.39502"
"13.59300","1.56943","-1.33323"
"13.69300","1.53930","-1.30681"
"13.79300","1.50926","-1.27785"
"13.89300","1.47939","-1.24150"
"13.99300","1.44954","-1.24411"
"14.09300","1.41969","-1.20575"
"14.19300","1.38955","-1.19723"
"14.29300","1.35954","-1.13745"
"14.39300","1.32939","-1.14559"
"14.49300","1.29946","-1.10485"
"14.59300","1.26945","-1.07802"
"14.69300","1.23962","-1.02485"
"14.79300","1.20938","-1.01933"
"14.89300","1.17943","-0.99327"
"14.99300","1.14916","-0.95028"
"15.09300","1.11949","-0.92684"
"15.19300","1.08940","-0.91119"
"15.29300","1.05967","-0.88532"
"15.39300","1.02954","-0.86541"
"15.49300","0.99962","-0.81522"
"15.59300","0.96952","-0.79547"
"15.69300","0.93968","-0.79307"
"15.79300","0.90949","-0.76069"
"15.89300","0.87945","-0.71957"
"15.99300","0.84929","-0.68323"
"16.09300","0.81927","-0.66591"
"16.19300","0.78927","-0.64427"
"16.29300","0.75946","-0.62286"
"16.39300","0.72950","-0.58644"
"16.49300","0.69949","-0.57467"
"16.59300","0.66956","-0.53911"
"16.69300","0.63945","-0.44433"
"16.79300","0.60953","-0.45180"
"16.89300","0.57953","-0.42124"
"16.99300","0.54961","-0.40144"
"17.09300","0.51943","-0.37302"
"17.19300","0.48947","-0.37662"
"17.29300","0.45933","-0.32814"
"17.39300","0.42959","-0.29349"
"17.49300","0.39928","-0.28261"
"17.59300","0.36947","-0.25693"
"17.69300","0.33932","-0.22547"
"17.79300","0.30942","-0.18190"
"17.89300","0.27940","-0.17397"
"17.99300","0.24969","-0.16994"
"18.09300","0.21963","-0.12608"
"18.19300","0.18954","-0.08625"
"18.29300","0.15942","-0.05098"
"18.39300","0.12945","-0.03573"
"18.49300","0.09939","-0.01179"
"18.59300","0.06956","0.02977"
"18.69300","0.03934","0.06952"
"18.79300","0.00944","0.07778"
"18.89300","-0.02055","0.09626"
"18.99300","-0.05061","0.13365"
"19.09300","-0.08045","0.16534"
"19.19300","-0.11036","0.18595"
"19.29300","-0.14033","0.21479"
"19.39300","-0.17051","0.24802"
"19.49300","-0.20049","0.30341"
"19.59300","-0.23053","0.31382"
"19.69300","-0.26032","0.32430"
"19.79300","-0.29051","0.34231"
"19.89300","-0.32050","0.39619"
"19.99300","-0.35066","0.44407"
"20.09300","-0.38065","0.48798"
"20.19300","-0.41069","0.49370"
"20.29300","-0.44048","0.51135"
"20.39300","-0.47051","0.54038"
"20.49300","-0.50033","0.56481"
"20.59300","-0.53056","0.59523"
"20.69300","-0.56035","0.62931"
"20.79300","-0.59046","0.65642"
"20.89300","-0.62032","0.69705"
"20.99300","-0.65060","0.72422"
"21.09300","-0.68060","0.74863"
"21.19300","-0.71073","0.76561"
"21.29300","-0.74066","0.82668"
"21.39300","-0.77059","0.85197"
"21.49300","-0.80051","0.84672"
"21.59300","-0.83051","0.86620"
"21.69300","-0.86063","0.90322"
"21.79300","-0.89061","0.93342"
"21.89300","-0.92049","0.98385"
"21.99300","-0.95029","0.98718"
"22.09300","-0.98040","1.03568"
"22.19300","-1.01041","1.06028"
"22.29300","-1.04061","1.08907"
"22.39300","-1.07062","1.12021"
"22.49300","-1.10061","1.14452"
"22.59300","-1.13053","1.17821"
"22.69300","-1.16066","1.22196"
"22.79300","-1.19053","1.23155"
"22.89300","-1.22070","1.29443"
"22.99300","-1.25042","1.30609"
"23.09300","-1.28035","1.33855"
"23.19300","-1.31024","1.36925"
"23.29300","-1.34047","1.38213"
"23.39300","-1.37051","1.42118"
"23.49300","-1.40062","1.44340"
"23.59300","-1.43061","1.49849"
"23.69300","-1.46056","1.50600"
"23.79300","-1.49052","1.53655"
"23.89300","-1.52059","1.58377"
"23.99300","-1.55066","1.64153"
"24.09300","-1.58076","1.65078"
"24.19300","-1.61064","1.68868"
"24.29300","-1.64046","1.69436"
"24.39300","-1.67042","1.75820"
"24.49300","-1.70033","1.78651"
"24.59300","-1.73058","1.82760"
"24.69300","-1.76055","1.83466"
"24.79300","-1.79049","1.88192"
"24.89300","-1.82041","1.90461"
"24.99300","-1.85062","1.95454"
"25.09300","-1.88060","1.96407"
"25.19300","-1.91079","2.00907"
"25.29300","-1.94065","2.06474"
"25.39300","-1.97053","2.08140"
"25.49300","-2.00038","2.09033"
"25.59300","-2.03050","2.13804"
"25.69300","-2.06042","2.17293"
"25.79300","-2.09048","2.21950"
"25.89300","-2.12052","2.24989"
"25.99300","-2.15048","2.27488"
"26.09300","-2.18048","2.33020"
"26.19300","-2.21051","2.36871"
"26.29300","-2.24059","2.40838"
"26.39300","-2.27064","2.44284"
"26.49300","-2.30064","2.47495"
"26.59300","-2.33067","2.49828"
"26.69300","-2.36061","2.55803"
"26.79300","-2.39052","2.58248"
"26.89300","-2.42065","2.60940"
"26.99300","-2.45034","2.65015"
"27.09300","-2.48043","2.71620"
"27.19300","-2.51024","2.73301"
"27.29300","-2.54054","2.77604"
"27.39300","-2.57031","2.81216"
"27.49300","-2.60076","2.86936"
"27.59300","-2.63060","2.91141"
"27.69300","-2.66057","2.93272"
"27.79300","-2.69053","2.94688"
"27.89300","-2.72060","3.01085"
"27.99300","-2.75054","3.05995"
"28.09300","-2.78066","3.08525"
"28.15800","-2.80010","3.11515"
"28.16000","-2.80068","3.11724"
"28.26000","-2.80171","3.11676"
"28.36000","-2.77025","3.06895"
"28.46000","-2.73939","3.02535"
"28.56000","-2.70939","3.00368"
"28.66000","-2.67943","2.96233"
"28.76000","-2.64929","2.91076"
"28.86000","-2.61935","2.86070"
"28.96000","-2.58913","2.84076"
"29.06000","-2.55908","2.77213"
"29.16000","-2.52915","2.74108"
"29.26000","-2.49900","2.69632"
"29.36000","-2.46920","2.68429"
"29.46000","-2.43918","2.64469"
"29.56000","-2.40927","2.60542"
"29.66000","-2.37922","2.57729"
"29.76000","-2.34945","2.54473"
"29.86000","-2.31938","2.50210"
"29.96000","-2.28955","2.47313"
"30.06000","-2.25924","2.42673"
"30.16000","-2.22917","2.37690"
"30.26000","-2.19902","2.34238"
"30.36000","-2.16928","2.28950"
"30.46000","-2.13905","2.24100"
"30.56000","-2.10932","2.19989"
"30.66000","-2.07910","2.15364"
"30.76000","-2.04908","2.12940"
"30.86000","-2.01909","2.11277"
"30.96000","-1.98926","2.06251"
"31.06000","-1.95931","2.03687"
"31.16000","-1.92949","2.01820"
"31.26000","-1.89933","1.99630"
"31.36000","-1.86928","1.94421"
"31.46000","-1.83930","1.90201"
"31.56000","-1.80915","1.87581"
"31.66000","-1.77914","1.85381"
"31.76000","-1.74910","1.82942"
"31.86000","-1.71905","1.77938"
"31.96000","-1.68892","1.73528"
"32.06000","-1.65918","1.69981"
"32.16000","-1.62923","1.68390"
"32.26000","-1.59946","1.63885"
"32.36000","-1.56935","1.61506"
"32.46000","-1.53932","1.58016"
"32.56000","-1.50922","1.55683"
"32.66000","-1.47937","1.49802"
"32.76000","-1.44924","1.48469"
"32.86000","-1.41927","1.45245"
"32.96000","-1.38903","1.45274"
"33.06000","-1.35919","1.41138"
"33.16000","-1.32900","1.37371"
"33.26000","-1.29913","1.33008"
"33.36000","-1.26916","1.32699"
"33.46000","-1.23926","1.31176"
"33.56000","-1.20926","1.23277"
"33.66000","-1.17936","1.19639"
"33.76000","-1.14940","1.19105"
"33.86000","-1.11934","1.11545"
"33.96000","-1.08930","1.11921"
"34.06000","-1.05917","1.06273"
"34.16000","-1.02905","1.03482"
"34.26000","-0.99893","1.02354"
"34.36000","-0.96906","0.98044"
"34.46000","-0.93909","0.95875"
"34.56000","-0.90927","0.92667"
"34.66000","-0.87916","0.91436"
"34.76000","-0.84923","0.89943"
"34.86000","-0.81919","0.86705"
"34.96000","-0.78944","0.83116"
"35.06000","-0.75924","0.80383"
"35.16000","-0.72948","0.75680"
"35.26000","-0.69910","0.74187"
"35.36000","-0.66931","0.69472"
"35.46000","-0.63908","0.67850"
"35.56000","-0.60921","0.64416"
"35.66000","-0.57916","0.61601"
"35.76000","-0.54916","0.57217"
"35.86000","-0.51893","0.56065"
"35.96000","-0.48907","0.51228"
"36.06000","-0.45912","0.52209"
"36.16000","-0.42931","0.47574"
"36.26000","-0.39947","0.46677"
"36.36000","-0.36937","0.42061"
"36.46000","-0.33928","0.40708"
"36.56000","-0.30916","0.35713"
"36.66000","-0.27918","0.30699"
"36.76000","-0.24916","0.27574"
"36.86000","-0.21920","0.22624"
"36.96000","-0.18904","0.24584"
"37.06000","-0.15910","0.21078"
"37.16000","-0.12907","0.17452"
"37.26000","-0.09924","0.13354"
"37.36000","-0.06917","0.11231"
"37.46000","-0.03944","0.09388"
"37.56000","-0.00913","0.06202"
"37.66000","0.02056","0.01933"
"37.76000","0.05064","0.01180"
"37.86000","0.08065","-0.02142"
"37.96000","0.11076","-0.02993"
"38.06000","0.14075","-0.08514"
"38.16000","0.17102","-0.09826"
"38.26000","0.20077","-0.12590"
"38.36000","0.23107","-0.14653"
"38.46000","0.26079","-0.19088"
"38.56000","0.29076","-0.22298"
"38.66000","0.32073","-0.23841"
"38.76000","0.35071","-0.24816"
"38.86000","0.38065","-0.29283"
"38.96000","0.41062","-0.30984"
"39.06000","0.44069","-0.34554"
"39.16000","0.47074","-0.37185"
"39.26000","0.50096","-0.38560"
"39.36000","0.53090","-0.41879"
"39.46000","0.56089","-0.43315"
"39.56000","0.59078","-0.47841"
"39.66000","0.62077","-0.43421"
"39.76000","0.65078","-0.54531"
"39.86000","0.68112","-0.59021"
"39.96000","0.71072","-0.61107"
"40.06000","0.74076","-0.60801"
"40.16000","0.77051","-0.65520"
"40.26000","0.80062","-0.67898"
"40.36000","0.83059","-0.72412"
"40.46000","0.86087","-0.74090"
"40.56000","0.89069","-0.77345"
"40.66000","0.92095","-0.79893"
"40.76000","0.95077","-0.84140"
"40.86000","0.98095","-0.84780"
"40.96000","1.01086","-0.86649"
"41.06000","1.04095","-0.88966"
"41.16000","1.07079","-0.93130"
"41.26000","1.10074","-0.95795"
"41.36000","1.13060","-0.96826"
"41.46000","1.16058","-0.99374"
"41.56000","1.19079","-1.02027"
"41.66000","1.22082","-1.05978"
"41.76000","1.25078","-1.08876"
"41.86000","1.28080","-1.11780"
"41.96000","1.31079","-1.14546"
"42.06000","1.34073","-1.17477"
"42.16000","1.37093","-1.19858"
"42.26000","1.40086","-1.22180"
"42.36000","1.43099","-1.24611"
"42.46000","1.46064","-1.28849"
"42.56000","1.49064","-1.31403"
"42.66000","1.52071","-1.32195"
"42.76000","1.55075","-1.32859"
"42.86000","1.58054","-1.40438"
"42.96000","1.61077","-1.45360"
"43.06000","1.64066","-1.48067"
"43.16000","1.67093","-1.49754"
"43.26000","1.70091","-1.49793"
"43.36000","1.73113","-1.57569"
"43.46000","1.76089","-1.58072"
"43.56000","1.79088","-1.60723"
"43.66000","1.82070","-1.60569"
"43.76000","1.85072","-1.65785"
"43.86000","1.88086","-1.67252"
"43.96000","1.91068","-1.70266"
"44.06000","1.94057","-1.71621"
"44.16000","1.97068","-1.75256"
"44.26000","2.00066","-1.76843"
"44.36000","2.03088","-1.81018"
"44.46000","2.06095","-1.82564"
"44.56000","2.09084","-1.87315"
"44.66000","2.12099","-1.88697"
"44.76000","2.15074","-1.91002"
"44.86000","2.18096","-1.96031"
"44.96000","2.21084","-1.96814"
"45.06000","2.24086","-2.00203"
"45.16000","2.27060","-2.01236"
"45.26000","2.30076","-2.05485"
"45.36000","2.33049","-2.06792"
"45.46000","2.36067","-2.07067"
"45.56000","2.39080","-2.14027"
"45.66000","2.42094","-2.18133"
"45.76000","2.45086","-2.18556"
"45.86000","2.48095","-2.16943"
"45.96000","2.51077","-2.26764"
"46.06000","2.54093","-2.33752"
"46.16000","2.57095","-2.31589"
"46.26000","2.60088","-2.34941"
"46.36000","2.63078","-2.37721"
"46.46000","2.66061","-2.38976"
"46.56000","2.69060","-2.43488"
"46.66000","2.72090","-2.45808"
"46.76000","2.75080","-2.47645"
"46.86000","2.78064","-2.51772"
"46.92400","2.80018","-2.53657"
"46.92600","2.80078","-2.53775"
"47.02600","2.80198","-2.53606"
"47.12600","2.77046","-2.52361"
"47.22600","2.73980","-2.47303"
"47.32600","2.70957","-2.44455"
"47.42600","2.67967","-2.41718"
"47.52600","2.64956","-2.40637"
"47.62600","2.61984","-2.37100"
"47.72600","2.58976","-2.32876"
"47.82600","2.55983","-2.31786"
"47.92600","2.52954","-2.28509"
"48.02600","2.49979","-2.27861"
"48.12600","2.46973","-2.15033"
"48.22600","2.43978","-2.17461"
"48.32600","2.40956","-2.14930"
"48.42600","2.37964","-2.13958"
"48.52600","2.34933","-2.08384"
"48.62600","2.31957","-2.06764"
"48.72600","2.28950","-2.02748"
"48.82600","2.25967","-2.02445"
"48.92600","2.22967","-1.98197"
"49.02600","2.19968","-1.96514"
"49.12600","2.16980","-1.91889"
"49.22600","2.13982","-1.88390"
"49.32600","2.10985","-1.85463"
"49.42600","2.07963","-1.83630"
"49.52600","2.04962","-1.79191"
"49.62600","2.01950","-1.77805"
"49.72600","1.98960","-1.75550"
"49.82600","1.95956","-1.72968"
"49.92600","1.92976","-1.70490"
"50.02600","1.89954","-1.66559"
"50.12600","1.86969","-1.65469"
"50.22600","1.83945","-1.63442"
"50.32600","1.80979","-1.60642"
"50.42600","1.77978","-1.56373"
"50.52600","1.74985","-1.54318"
"50.62600","1.71967","-1.51925"
"50.72600","1.68971","-1.49453"
"50.82600","1.65947","-1.45121"
"50.92600","1.62973","-1.43633"
"51.02600","1.59956","-1.40366"
"51.12600","1.56956","-1.36071"
"51.22600","1.53945","-1.30432"
"51.32600","1.50943","-1.28848"
"51.42600","1.47954","-1.27739"
"51.52600","1.44972","-1.25289"
"51.62600","1.41987","-1.21617"
"51.72600","1.38972","-1.17367"
"51.82600","1.35971","-1.15341"
"51.92600","1.32957","-1.13323"
"52.02600","1.29964","-1.10960"
"52.12600","1.26964","-1.07376"
"52.22600","1.23977","-1.03499"
"52.32600","1.20956","-1.00372"
"52.42600","1.17959","-1.00012"
"52.52600","1.14934","-0.96262"
"52.62600","1.11966","-0.92270"
"52.72600","1.08957","-0.90599"
"52.82600","1.05984","-0.89167"
"52.92600","1.02973","-0.86660"
"53.02600","0.99980","-0.83608"
"53.12600","0.96967","-0.79797"
"53.22600","0.93985","-0.78597"
"53.32600","0.90965","-0.77262"
"53.42600","0.87963","-0.72314"
"53.52600","0.84946","-0.69551"
"53.62600","0.81945","-0.66507"
"53.72600","0.78944","-0.64973"
"53.82600","0.75963","-0.60301"
"53.92600","0.72966","-0.59743"
"54.02600","0.69967","-0.55167"
"54.12600","0.66972","-0.54656"
"54.22600","0.63963","-0.44104"
"54.32600","0.60971","-0.45655"
"54.42600","0.57969","-0.43053"
"54.52600","0.54980","-0.40728"
"54.62600","0.51961","-0.40449"
"54.72600","0.48963","-0.36725"
"54.82600","0.45949","-0.33474"
"54.92600","0.42973","-0.29360"
"55.02600","0.39946","-0.27931"
"55.12600","0.36963","-0.26416"
"55.22600","0.33945","-0.23007"
"55.32600","0.30960","-0.18686"
"55.42600","0.27955","-0.18575"
"55.52600","0.24986","-0.15825"
"55.62600","0.21978","-0.13703"
"55.72600","0.18972","-0.08671"
"55.82600","0.15959","-0.07420"
"55.92600","0.12961","-0.04691"
"56.02600","0.09955","-0.04242"
"56.12600","0.06971","0.01624"
"56.22600","0.03953","0.05151"
"56.32600","0.00958","0.08178"
"56.42600","-0.02040","0.08937"
"56.52600","-0.05044","0.14157"
"56.62600","-0.08027","0.16809"
"56.72600","-0.11019","0.18996"
"56.82600","-0.14014","0.21065"
"56.92600","-0.17032","0.25686"
"57.02600","-0.20032","0.28615"
"57.12600","-0.23035","0.28432"
"57.22600","-0.26015","0.30834"
"57.32600","-0.29033","0.33770"
"57.42600","-0.32033","0.40277"
"57.52600","-0.35050","0.42990"
"57.62600","-0.38048","0.46996"
"57.72600","-0.41051","0.47086"
"57.82600","-0.44029","0.52008"
"57.92600","-0.47032","0.54039"
"58.02600","-0.50016","0.58056"
"58.12600","-0.53040","0.59251"
"58.22600","-0.56019","0.62536"
"58.32600","-0.59029","0.65907"
"58.42600","-0.62016","0.68667"
"58.52600","-0.65042","0.70882"
"58.62600","-0.68043","0.73452"
"58.72600","-0.71056","0.77025"
"58.82600","-0.74049","0.80597"
"58.92600","-0.77042","0.83413"
"59.02600","-0.80035","0.85622"
"59.12600","-0.83034","0.88417"
"59.22600","-0.86040","0.92126"
"59.32600","-0.89044","0.94448"
"59.42600","-0.92032","0.97550"
"59.52600","-0.95013","0.99611"
"59.62600","-0.98022","1.04395"
"59.72600","-1.01020","1.06363"
"59.82600","-1.04047","1.08180"
"59.92600","-1.07046","1.11612"
"60.02600","-1.10046","1.14650"
"60.12600","-1.13035","1.18588"
"60.22600","-1.16049","1.21582"
"60.32600","-1.19037","1.23521"
"60.42600","-1.22053","1.30214"
"60.52600","-1.25027","1.32783"
"60.62600","-1.28013","1.34207"
"60.72600","-1.31007","1.37362"
"60.82600","-1.34029","1.39868"
"60.92600","-1.37034","1.42938"
"61.02600","-1.40046","1.47591"
"61.12600","-1.43042","1.48285"
"61.22600","-1.46040","1.51531"
"61.32600","-1.49035","1.53728"
"61.42600","-1.52043","1.59615"
"61.52600","-1.55049","1.62548"
"61.62600","-1.58059","1.64294"
"61.72600","-1.61044","1.68176"
"61.82600","-1.64024","1.71640"
"61.92600","-1.67021","1.74682"
"62.02600","-1.70023","1.77872"
"62.12600","-1.73037","1.80531"
"62.22600","-1.76037","1.83899"
"62.32600","-1.79033","1.88919"
"62.42600","-1.82023","1.91282"
"62.52600","-1.85044","1.93556"
"62.62600","-1.88045","1.96733"
"62.72600","-1.91058","2.01926"
"62.82600","-1.94049","2.05429"
"62.92600","-1.97038","2.07730"
"63.02600","-2.00019","2.10660"
"63.12600","-2.03035","2.13619"
"63.22600","-2.06023","2.16325"
"63.32600","-2.09036","2.21988"
"63.42600","-2.12032","2.24080"
"63.52600","-2.15027","2.28413"
"63.62600","-2.18032","2.32557"
"63.72600","-2.21035","2.36926"
"63.82600","-2.24045","2.40291"
"63.92600","-2.27047","2.43305"
"64.02600","-2.30048","2.48756"
"64.12600","-2.33051","2.51153"
"64.22600","-2.36043","2.55447"
"64.32600","-2.39034","2.57690"
"64.42600","-2.42045","2.62398"
"64.52600","-2.45019","2.65486"
"64.62600","-2.48023","2.70851"
"64.72600","-2.51006","2.71740"
"64.82600","-2.54037","2.77014"
"64.92600","-2.57012","2.78915"
"65.02600","-2.60062","2.86527"
"65.12600","-2.63044","2.89721"
"65.22600","-2.66039","2.92231"
"65.32600","-2.69037","2.96118"
"65.42600","-2.72042","3.01896"
"65.52600","-2.75036","3.03123"
"65.62600","-2.78046","3.06703"
"65.69200","-2.80022","3.11774"
"65.69400","-2.80080","3.11705"
"65.79400","-2.80495","3.10766"
"65.89400","-2.78086","3.08062"
"65.99400","-2.75645","3.05300"
"66.09400","-2.73294","3.00967"
"66.19400","-2.70976","2.98410"
"66.29400","-2.68635","2.94895"
"66.39400","-2.66290","2.93665"
"66.49400","-2.63959","2.91148"
"66.59400","-2.61656","2.87220"
"66.69400","-2.59287","2.79807"
"66.79400","-2.56930","2.78865"
"66.89400","-2.54651","2.78148"
"66.99400","-2.52299","2.75054"
"67.09400","-2.49943","2.71371"
"67.19400","-2.47634","2.68175"
"67.29400","-2.45314","2.62246"
"67.39400","-2.42965","2.65367"
"67.49400","-2.40606","2.57804"
"67.59400","-2.38314","2.56864"
"67.69400","-2.35975","2.53451"
"67.79400","-2.33606","2.50049"
"67.89400","-2.31294","2.48326"
"67.99400","-2.28990","2.45103"
"68.09400","-2.26615","2.42574"
"68.19400","-2.24277","2.38815"
"68.29400","-2.21968","2.36273"
"68.39400","-2.19625","2.32285"
"68.49400","-2.17300","2.27613"
"68.59400","-2.14943","2.25451"
"68.69400","-2.12640","2.21455"
"68.79400","-2.10309","2.19904"
"68.89400","-2.07954","2.15745"
"68.99400","-2.05621","2.12062"
"69.09400","-2.03303","2.12851"
"69.19400","-2.00946","2.08533"
"69.29400","-1.98614","2.05581"
"69.39400","-1.96309","2.02740"
"69.49400","-1.93969","2.02648"
"69.59400","-1.91615","1.97948"
"69.69400","-1.89290","1.95864"
"69.79400","-1.86979","1.93347"
"69.89400","-1.84634","1.90382"
"69.99400","-1.82268","1.87983"
"70.09400","-1.79996","1.86496"
"70.19400","-1.77624","1.83198"
"70.29400","-1.75275","1.80066"
"70.39400","-1.72975","1.79190"
"70.49400","-1.70635","1.76485"
"70.59400","-1.68276","1.74604"
"70.69400","-1.65944","1.68155"
"70.79400","-1.63651","1.69312"
"70.89400","-1.61307","1.66077"
"70.99400","-1.58946","1.64713"
"71.09400","-1.56635","1.61181"
"71.19400","-1.54305","1.58214"
"71.29400","-1.51941","1.55909"
"71.39400","-1.49613","1.52727"
"71.49400","-1.47316","1.50181"
"71.59400","-1.44968","1.46673"
"71.69400","-1.42632","1.45427"
"71.79400","-1.40275","1.44464"
"71.89400","-1.37959","1.40917"
"71.99400","-1.35639","1.38585"
"72.09400","-1.33268","1.37483"
"72.19400","-1.30971","1.36793"
"72.29400","-1.28641","1.32492"
"72.39400","-1.26292","1.30360"
"72.49400","-1.23958","1.27914"
"72.59400","-1.21647","1.22911"
"72.69400","-1.19290","1.22378"
"72.79400","-1.16952","1.18126"
"72.89400","-1.14634","1.16945"
"72.99400","-1.12307","1.12284"
"73.09400","-1.09956","1.12252"
"73.19400","-1.07615","1.07069"
"73.29400","-1.05327","1.07013"
"73.39400","-1.02947","1.03209"
"73.49400","-1.00587","1.01430"
"73.59400","-0.98311","1.00435"
"73.69400","-0.95967","0.96420"
"73.79400","-0.93620","0.96040"
"73.89400","-0.91299","0.93126"
"73.99400","-0.88983","0.91961"
"74.09400","-0.86625","0.87944"
"74.19400","-0.84273","0.85044"
"74.29400","-0.81963","0.84423"
"74.39400","-0.79645","0.82949"
"74.49400","-0.77285","0.80151"
"74.59400","-0.74946","0.78991"
"74.69400","-0.72654","0.74670"
"74.79400","-0.70282","0.73542"
"74.89400","-0.67949","0.71219"
"74.99400","-0.65625","0.69683"
"75.09400","-0.63311","0.66258"
"75.19400","-0.60969","0.63731"
"75.29400","-0.58618","0.62501"
"75.39400","-0.56311","0.61651"
"75.49400","-0.53975","0.58044"
"75.59400","-0.51594","0.55578"
"75.69400","-0.49278","0.53879"
"75.79400","-0.46985","0.52433"
"75.89400","-0.44619","0.47947"
"75.99400","-0.42290","0.43417"
"76.09400","-0.39987","0.46131"
"76.19400","-0.37625","0.41888"
"76.29400","-0.35281","0.42373"
"76.39400","-0.32944","0.34999"
"76.49400","-0.30648","0.34223"
"76.59400","-0.28290","0.30950"
"76.69400","-0.25943","0.28680"
"76.79400","-0.23662","0.27120"
"76.89400","-0.21294","0.24697"
"76.99400","-0.18940","0.22703"
"77.09400","-0.16621","0.20796"
"77.19400","-0.14304","0.18286"
"77.29400","-0.11966","0.15433"
"77.39400","-0.09616","0.12615"
"77.49400","-0.07300","0.11657"
"77.59400","-0.04978","0.08354"
"77.69400","-0.02623","0.04763"
"77.79400","-0.00269","0.03228"
"77.80600","0.00002","0.02385"