File: BeamForceDisplacement/Specimen_RawData_3.csv
Time,Extension,Load
(s),(mm),(N)
"0.00000","0.00000","0.14059"
"0.10000","0.00862","0.05078"
"0.20000","0.04207","0.07859"
"0.30000","0.07254","-0.00928"
"0.40000","0.10260","-0.05717"
"0.50000","0.13263","-0.09488"
"0.60000","0.16273","-0.15838"
"0.70000","0.19265","-0.14706"
"0.80000","0.22250","-0.24538"
"0.90000","0.25237","-0.24089"
"1.00000","0.28232","-0.32246"
"1.10000","0.31251","-0.33920"
"1.20000","0.34249","-0.38764"
"1.30000","0.37269","-0.42814"
"1.40000","0.40261","-0.48051"
"1.50000","0.43271","-0.50870"
"1.60000","0.46251","-0.55139"
"1.70000","0.49274","-0.58822"
"1.80000","0.52258","-0.62662"
"1.90000","0.55270","-0.66482"
"2.00000","0.58246","-0.73385"
"2.10000","0.61259","-0.73872"
"2.20000","0.64232","-0.72623"
"2.30000","0.67261","-0.87368"
"2.40000","0.70229","-0.91859"
"2.50000","0.73259","-0.95015"
"2.60000","0.76248","-0.99351"
"2.70000","0.79253","-1.04292"
"2.80000","0.82256","-1.08367"
"2.90000","0.85278","-1.10783"
"3.00000","0.88273","-1.15273"
"3.10000","0.91273","-1.21874"
"3.20000","0.94255","-1.24588"
"3.30000","0.97245","-1.28667"
"3.40000","1.00243","-1.30444"
"3.50000","1.03237","-1.36923"
"3.60000","1.06244","-1.39754"
"3.70000","1.09238","-1.45104"
"3.80000","1.12236","-1.47888"
"3.90000","1.15256","-1.54692"
"4.00000","1.18282","-1.58441"
"4.10000","1.21264","-1.62447"
"4.20000","1.24268","-1.66850"
"4.30000","1.27251","-1.70784"
"4.40000","1.30260","-1.73539"
"4.50000","1.33245","-1.78401"
"4.60000","1.36272","-1.84411"
"4.70000","1.39244","-1.84560"
"4.80000","1.42252","-1.91217"
"4.90000","1.45233","-1.96335"
"5.00000","1.48236","-1.99201"
"5.10000","1.51244","-2.02285"
"5.20000","1.54257","-2.08012"
"5.30000","1.57250","-2.16143"
"5.40000","1.60284","-2.22279"
"5.50000","1.63258","-2.23448"
"5.60000","1.66265","-2.27136"
"5.70000","1.69269","-2.31254"
"5.80000","1.72266","-2.37346"
"5.90000","1.75257","-2.39478"
"6.00000","1.78240","-2.41819"
"6.10000","1.81238","-2.47170"
"6.20000","1.84228","-2.51559"
"6.30000","1.87265","-2.56593"
"6.40000","1.90254","-2.61313"
"6.50000","1.93263","-2.63278"
"6.60000","1.96249","-2.70044"
"6.70000","1.99245","-2.74346"
"6.80000","2.02236","-2.78363"
"6.90000","2.05299","-2.81007"
"7.00000","2.08263","-2.87065"
"7.10000","2.11271","-2.90473"
"7.20000","2.14238","-2.92861"
"7.30000","2.17248","-2.98422"
"7.40000","2.20235","-2.99886"
"7.50000","2.23245","-3.05260"
"7.60000","2.26233","-3.09948"
"7.70000","2.29254","-3.15383"
"7.80000","2.32258","-3.18732"
"7.90000","2.35269","-3.21647"
"8.00000","2.38273","-3.27043"
"8.10000","2.41290","-3.31346"
"8.20000","2.44272","-3.34917"
"8.30000","2.47261","-3.33462"
"8.40000","2.50249","-3.44040"
"8.50000","2.53237","-3.37020"
"8.60000","2.56264","-3.28961"
"8.70000","2.59243","-3.20200"
"8.80000","2.62247","-3.15656"
"8.90000","2.65239","-3.08889"
"9.00000","2.68254","-3.01436"
"9.10000","2.71246","-2.93358"
"9.20000","2.74268","-2.86563"
"9.30000","2.77255","-2.80686"
"9.39100","2.80007","-2.75780"
"9.39300","2.80067","-2.75730"
"9.49300","2.80170","-2.74548"
"9.59300","2.77023","-2.79826"
"9.69300","2.73960","-2.87344"
"9.79300","2.70934","-2.96504"
"9.89300","2.67947","-3.02586"
"9.99300","2.64934","-3.08818"
"10.09300","2.61965","-3.15889"
"10.19300","2.58952","-3.23643"
"10.29300","2.55960","-3.31271"
"10.39300","2.52935","-3.37446"
"10.49300","2.49957","-3.43943"
"10.59300","2.46952","-3.30453"
"10.69300","2.43960","-3.32828"
"10.79300","2.40936","-3.26511"
"10.89300","2.37943","-3.22816"
"10.99300","2.34912","-3.17125"
"11.09300","2.31935","-3.18716"
"11.19300","2.28932","-3.12505"
"11.29300","2.25940","-3.08248"
"11.39300","2.22945","-3.04545"
"11.49300","2.19947","-3.01005"
"11.59300","2.16964","-2.98369"
"11.69300","2.13954","-2.93063"
"11.79300","2.10966","-2.86266"
"11.89300","2.07944","-2.82425"
"11.99300","2.04940","-2.78945"
"12.09300","2.01927","-2.77344"
"12.19300","1.98940","-2.72006"
"12.29300","1.95935","-2.65983"
"12.39300","1.92954","-2.59266"
"12.49300","1.89934","-2.57635"
"12.59300","1.86947","-2.54396"
"12.69300","1.83924","-2.50634"
"12.79300","1.80958","-2.44919"
"12.89300","1.77958","-2.41036"
"12.99300","1.74963","-2.37071"
"13.09300","1.71944","-2.31546"
"13.19300","1.68954","-2.28032"
"13.29300","1.65933","-2.26375"
"13.39300","1.62943","-2.20057"
"13.49300","1.59931","-2.16119"
"13.59300","1.56937","-2.08616"
"13.69300","1.53925","-2.04227"
"13.79300","1.50924","-2.01393"
"13.89300","1.47935","-1.97291"
"13.99300","1.44953","-1.92730"
"14.09300","1.41962","-1.90119"
"14.19300","1.38949","-1.86261"
"14.29300","1.35948","-1.79378"
"14.39300","1.32936","-1.75951"
"14.49300","1.29947","-1.72121"
"14.59300","1.26941","-1.67204"
"14.69300","1.23956","-1.62975"
"14.79300","1.20934","-1.57981"
"14.89300","1.17939","-1.51792"
"14.99300","1.14910","-1.49283"
"15.09300","1.11946","-1.46149"
"15.19300","1.08936","-1.41510"
"15.29300","1.05960","-1.37320"
"15.39300","1.02950","-1.34508"
"15.49300","0.99959","-1.28860"
"15.59300","0.96947","-1.26739"
"15.69300","0.93963","-1.21110"
"15.79300","0.90947","-1.17645"
"15.89300","0.87941","-1.12410"
"15.99300","0.84925","-1.09475"
"16.09300","0.81926","-1.04585"
"16.19300","0.78921","-1.01464"
"16.29300","0.75944","-0.95765"
"16.39300","0.72942","-0.92458"
"16.49300","0.69944","-0.87937"
"16.59300","0.66951","-0.82477"
"16.69300","0.63944","-0.70958"
"16.79300","0.60950","-0.72684"
"16.89300","0.57947","-0.69520"
"16.99300","0.54957","-0.63050"
"17.09300","0.51938","-0.60691"
"17.19300","0.48944","-0.55810"
"17.29300","0.45928","-0.53845"
"17.39300","0.42951","-0.47731"
"17.49300","0.39924","-0.44038"
"17.59300","0.36941","-0.38369"
"17.69300","0.33926","-0.37344"
"17.79300","0.30937","-0.33608"
"17.89300","0.27934","-0.29567"
"17.99300","0.24965","-0.22059"
"18.09300","0.21956","-0.19378"
"18.19300","0.18951","-0.14822"
"18.29300","0.15938","-0.12055"
"18.39300","0.12941","-0.07526"
"18.49300","0.09935","-0.02545"
"18.59300","0.06953","0.00996"
"18.69300","0.03931","0.04643"
"18.79300","0.00940","0.11285"
"18.89300","-0.02061","0.15965"
"18.99300","-0.05064","0.19181"
"19.09300","-0.08047","0.24282"
"19.19300","-0.11040","0.29143"
"19.29300","-0.14038","0.33419"
"19.39300","-0.17053","0.35080"
"19.49300","-0.20050","0.39328"
"19.59300","-0.23054","0.41611"
"19.69300","-0.26033","0.48447"
"19.79300","-0.29054","0.52367"
"19.89300","-0.32055","0.60164"
"19.99300","-0.35070","0.61996"
"20.09300","-0.38070","0.68384"
"20.19300","-0.41077","0.73790"
"20.29300","-0.44050","0.77408"
"20.39300","-0.47056","0.79889"
"20.49300","-0.50039","0.84084"
"20.59300","-0.53057","0.89299"
"20.69300","-0.56041","0.94532"
"20.79300","-0.59047","0.97924"
"20.89300","-0.62035","1.02374"
"20.99300","-0.65066","1.08349"
"21.09300","-0.68064","1.13628"
"21.19300","-0.71075","1.15493"
"21.29300","-0.74072","1.20624"
"21.39300","-0.77060","1.26583"
"21.49300","-0.80054","1.32033"
"21.59300","-0.83056","1.34402"
"21.69300","-0.86069","1.35004"
"21.79300","-0.89061","1.41770"
"21.89300","-0.92053","1.46104"
"21.99300","-0.95032","1.54047"
"22.09300","-0.98045","1.57562"
"22.19300","-1.01044","1.59398"
"22.29300","-1.04065","1.64295"
"22.39300","-1.07068","1.69297"
"22.49300","-1.10066","1.74220"
"22.59300","-1.13056","1.77298"
"22.69300","-1.16069","1.83015"
"22.79300","-1.19055","1.85254"
"22.89300","-1.22076","1.98555"
"22.99300","-1.25040","1.95220"
"23.09300","-1.28049","1.98811"
"23.19300","-1.31027","2.08473"
"23.29300","-1.34051","2.13338"
"23.39300","-1.37053","2.16849"
"23.49300","-1.40065","2.21369"
"23.59300","-1.43064","2.28734"
"23.69300","-1.46055","2.32403"
"23.79300","-1.49058","2.38170"
"23.89300","-1.52065","2.40213"
"23.99300","-1.55069","2.44749"
"24.09300","-1.58077","2.49977"
"24.19300","-1.61068","2.56523"
"24.29300","-1.64050","2.58760"
"24.39300","-1.67046","2.62684"
"24.49300","-1.70038","2.66645"
"24.59300","-1.73064","2.72013"
"24.69300","-1.76057","2.78566"
"24.79300","-1.79054","2.82037"
"24.89300","-1.82043","2.86691"
"24.99300","-1.85068","2.92937"
"25.09300","-1.88065","2.98189"
"25.19300","-1.91081","3.02762"
"25.29300","-1.94073","3.07594"
"25.39300","-1.97058","3.11923"
"25.49300","-2.00043","3.18527"
"25.59300","-2.03053","3.21483"
"25.69300","-2.06043","3.25569"
"25.79300","-2.09059","3.31177"
"25.89300","-2.12053","3.37671"
"25.99300","-2.15051","3.42732"
"26.09300","-2.18052","3.49722"
"26.19300","-2.21055","3.52404"
"26.29300","-2.24060","3.59445"
"26.39300","-2.27066","3.64249"
"26.49300","-2.30067","3.70767"
"26.59300","-2.33067","3.73978"
"26.69300","-2.36067","3.80267"
"26.79300","-2.39056","3.85732"
"26.89300","-2.42071","3.93038"
"26.99300","-2.45039","3.95366"
"27.09300","-2.48046","4.00618"
"27.19300","-2.51029","4.07391"
"27.29300","-2.54043","4.11660"
"27.39300","-2.57058","4.14127"
"27.49300","-2.60071","4.08681"
"27.59300","-2.63062","4.02616"
"27.69300","-2.66060","3.97109"
"27.79300","-2.69056","3.92102"
"27.89300","-2.72066","3.85158"
"27.99300","-2.75056","3.79198"
"28.09300","-2.78070","3.73551"
"28.15800","-2.80011","3.68074"
"28.16000","-2.80069","3.68013"
"28.26000","-2.80208","3.69986"
"28.36000","-2.77033","3.74412"
"28.46000","-2.73947","3.81938"
"28.56000","-2.70944","3.86880"
"28.66000","-2.67949","3.94260"
"28.76000","-2.64935","3.99556"
"28.86000","-2.61941","4.07122"
"28.96000","-2.58921","4.10434"
"29.06000","-2.55913","4.16219"
"29.16000","-2.52921","4.11670"
"29.26000","-2.49908","4.03140"
"29.36000","-2.46928","3.99433"
"29.46000","-2.43926","3.91810"
"29.56000","-2.40936","3.89303"
"29.66000","-2.37927","3.81477"
"29.76000","-2.34948","3.77466"
"29.86000","-2.31945","3.71700"
"29.96000","-2.28956","3.70837"
"30.06000","-2.25937","3.63765"
"30.16000","-2.22920","3.58103"
"30.26000","-2.19908","3.47908"
"30.36000","-2.16935","3.43119"
"30.46000","-2.13912","3.39469"
"30.56000","-2.10940","3.33134"
"30.66000","-2.07918","3.28093"
"30.76000","-2.04913","3.20987"
"30.86000","-2.01912","3.18164"
"30.96000","-1.98937","3.11980"
"31.06000","-1.95938","3.07480"
"31.16000","-1.92953","3.01387"
"31.26000","-1.89938","3.00855"
"31.36000","-1.86934","2.92731"
"31.46000","-1.83938","2.88120"
"31.56000","-1.80923","2.82135"
"31.66000","-1.77922","2.77395"
"31.76000","-1.74917","2.73536"
"31.86000","-1.71911","2.68002"
"31.96000","-1.68897","2.62531"
"32.06000","-1.65923","2.57395"
"32.16000","-1.62930","2.54250"
"32.26000","-1.59955","2.49586"
"32.36000","-1.56940","2.42667"
"32.46000","-1.53940","2.38870"
"32.56000","-1.50927","2.36667"
"32.66000","-1.47940","2.31072"
"32.76000","-1.44923","2.27085"
"32.86000","-1.41943","2.20350"
"32.96000","-1.38910","2.18131"
"33.06000","-1.35920","2.08274"
"33.16000","-1.32908","2.08617"
"33.26000","-1.29917","2.01747"
"33.36000","-1.26923","1.95880"
"33.46000","-1.23932","1.95215"
"33.56000","-1.20933","1.86326"
"33.66000","-1.17945","1.80519"
"33.76000","-1.14944","1.74605"
"33.86000","-1.11944","1.71218"
"33.96000","-1.08939","1.66186"
"34.06000","-1.05929","1.63787"
"34.16000","-1.02908","1.57706"
"34.26000","-0.99903","1.50812"
"34.36000","-0.96911","1.49055"
"34.46000","-0.93916","1.45413"
"34.56000","-0.90934","1.37455"
"34.66000","-0.87924","1.36320"
"34.76000","-0.84929","1.31073"
"34.86000","-0.81926","1.26437"
"34.96000","-0.78949","1.23050"
"35.06000","-0.75931","1.19563"
"35.16000","-0.72954","1.12654"
"35.26000","-0.69914","1.11501"
"35.36000","-0.66937","1.07754"
"35.46000","-0.63920","1.02282"
"35.56000","-0.60926","0.95171"
"35.66000","-0.57921","0.91910"
"35.76000","-0.54923","0.88674"
"35.86000","-0.51898","0.85060"
"35.96000","-0.48914","0.80310"
"36.06000","-0.45920","0.74543"
"36.16000","-0.42941","0.71499"
"36.26000","-0.39953","0.69528"
"36.36000","-0.36941","0.62483"
"36.46000","-0.33933","0.57474"
"36.56000","-0.30925","0.50939"
"36.66000","-0.27923","0.45805"
"36.76000","-0.24920","0.41520"
"36.86000","-0.21931","0.37866"
"36.96000","-0.18917","0.34139"
"37.06000","-0.15913","0.29683"
"37.16000","-0.12912","0.27482"
"37.26000","-0.09931","0.21383"
"37.36000","-0.06925","0.16721"
"37.46000","-0.03949","0.07125"
"37.56000","-0.00920","0.08193"
"37.66000","0.02051","0.03697"
"37.76000","0.05059","-0.00702"
"37.86000","0.08058","-0.05427"
"37.96000","0.11071","-0.09775"
"38.06000","0.14067","-0.12504"
"38.16000","0.17097","-0.16779"
"38.26000","0.20077","-0.21209"
"38.36000","0.23091","-0.27024"
"38.46000","0.26071","-0.28539"
"38.56000","0.29074","-0.33840"
"38.66000","0.32064","-0.38982"
"38.76000","0.35064","-0.41843"
"38.86000","0.38057","-0.44983"
"38.96000","0.41056","-0.48741"
"39.06000","0.44063","-0.54725"
"39.16000","0.47062","-0.59422"
"39.26000","0.50090","-0.62984"
"39.36000","0.53086","-0.64902"
"39.46000","0.56080","-0.70310"
"39.56000","0.59072","-0.74519"
"39.66000","0.62080","-0.72164"
"39.76000","0.65062","-0.83848"
"39.86000","0.68089","-0.90318"
"39.96000","0.71073","-0.92650"
"40.06000","0.74071","-0.99007"
"40.16000","0.77044","-1.00748"
"40.26000","0.80055","-1.05324"
"40.36000","0.83052","-1.09251"
"40.46000","0.86080","-1.13958"
"40.56000","0.89065","-1.18265"
"40.66000","0.92089","-1.22722"
"40.76000","0.95069","-1.26108"
"40.86000","0.98089","-1.30852"
"40.96000","1.01077","-1.35767"
"41.06000","1.04095","-1.38757"
"41.16000","1.07073","-1.42463"
"41.26000","1.10045","-1.46796"
"41.36000","1.13065","-1.52384"
"41.46000","1.16056","-1.55301"
"41.56000","1.19078","-1.59207"
"41.66000","1.22076","-1.63476"
"41.76000","1.25071","-1.69992"
"41.86000","1.28072","-1.72972"
"41.96000","1.31074","-1.76154"
"42.06000","1.34064","-1.79614"
"42.16000","1.37088","-1.86110"
"42.26000","1.40078","-1.90048"
"42.36000","1.43094","-1.94060"
"42.46000","1.46056","-1.95715"
"42.56000","1.49069","-2.02625"
"42.66000","1.52052","-2.05055"
"42.76000","1.55062","-2.08783"
"42.86000","1.58047","-2.16821"
"42.96000","1.61070","-2.20158"
"43.06000","1.64057","-2.24551"
"43.16000","1.67083","-2.33022"
"43.26000","1.70085","-2.33952"
"43.36000","1.73108","-2.36854"
"43.46000","1.76084","-2.42452"
"43.56000","1.79083","-2.46336"
"43.66000","1.82066","-2.49774"
"43.76000","1.85066","-2.52463"
"43.86000","1.88074","-2.53991"
"43.96000","1.91068","-2.59560"
"44.06000","1.94060","-2.66899"
"44.16000","1.97049","-2.68707"
"44.26000","2.00061","-2.71793"
"44.36000","2.03076","-2.78987"
"44.46000","2.06095","-2.83487"
"44.56000","2.09080","-2.86346"
"44.66000","2.12092","-2.91172"
"44.76000","2.15065","-2.95641"
"44.86000","2.18090","-3.00799"
"44.96000","2.21078","-3.04566"
"45.06000","2.24081","-3.08378"
"45.16000","2.27055","-3.11196"
"45.26000","2.30068","-3.15697"
"45.36000","2.33038","-3.20743"
"45.46000","2.36066","-3.21483"
"45.56000","2.39070","-3.25539"
"45.66000","2.42088","-3.30536"
"45.76000","2.45080","-3.35762"
"45.86000","2.48087","-3.37174"
"45.96000","2.51067","-3.40580"
"46.06000","2.54085","-3.33516"
"46.16000","2.57089","-3.27601"
"46.26000","2.60082","-3.21866"
"46.36000","2.63072","-3.12265"
"46.46000","2.66064","-3.05950"
"46.56000","2.69063","-2.99073"
"46.66000","2.72065","-2.93096"
"46.76000","2.75072","-2.84483"
"46.86000","2.78057","-2.77718"
"46.92400","2.80015","-2.74179"
"46.92600","2.80075","-2.74079"
"47.02600","2.80187","-2.71731"
"47.12600","2.77034","-2.78574"
"47.22600","2.73971","-2.86910"
"47.32600","2.70944","-2.95538"
"47.42600","2.67955","-3.00427"
"47.52600","2.64944","-3.07716"
"47.62600","2.61974","-3.15548"
"47.72600","2.58963","-3.24147"
"47.82600","2.55971","-3.30731"
"47.92600","2.52944","-3.36090"
"48.02600","2.49967","-3.42360"
"48.12600","2.46962","-3.32258"
"48.22600","2.43970","-3.34155"
"48.32600","2.40946","-3.29087"
"48.42600","2.37952","-3.24798"
"48.52600","2.34922","-3.19385"
"48.62600","2.31951","-3.16170"
"48.72600","2.28935","-3.12021"
"48.82600","2.25954","-3.08010"
"48.92600","2.22953","-3.03599"
"49.02600","2.19956","-3.02466"
"49.12600","2.16972","-2.97481"
"49.22600","2.13963","-2.94103"
"49.32600","2.10978","-2.87347"
"49.42600","2.07951","-2.85632"
"49.52600","2.04949","-2.79312"
"49.62600","2.01938","-2.76362"
"49.72600","1.98952","-2.70084"
"49.82600","1.95945","-2.66953"
"49.92600","1.92964","-2.60380"
"50.02600","1.89944","-2.57559"
"50.12600","1.86956","-2.55226"
"50.22600","1.83932","-2.48681"
"50.32600","1.80970","-2.45344"
"50.42600","1.77968","-2.41143"
"50.52600","1.74977","-2.34543"
"50.62600","1.71956","-2.34587"
"50.72600","1.68959","-2.29979"
"50.82600","1.65934","-2.25825"
"50.92600","1.62957","-2.22428"
"51.02600","1.59944","-2.16442"
"51.12600","1.56946","-2.11608"
"51.22600","1.53936","-2.05582"
"51.32600","1.50933","-2.00945"
"51.42600","1.47948","-1.96401"
"51.52600","1.44958","-1.92116"
"51.62600","1.41974","-1.86252"
"51.72600","1.38961","-1.83032"
"51.82600","1.35958","-1.80152"
"51.92600","1.32946","-1.76200"
"52.02600","1.29954","-1.72861"
"52.12600","1.26951","-1.70051"
"52.22600","1.23968","-1.65130"
"52.32600","1.20944","-1.57622"
"52.42600","1.17949","-1.55813"
"52.52600","1.14920","-1.50658"
"52.62600","1.11955","-1.47796"
"52.72600","1.08945","-1.40035"
"52.82600","1.05973","-1.37185"
"52.92600","1.02963","-1.34065"
"53.02600","0.99968","-1.30878"
"53.12600","0.96956","-1.26165"
"53.22600","0.93973","-1.21842"
"53.32600","0.90956","-1.17501"
"53.42600","0.87952","-1.13873"
"53.52600","0.84935","-1.10314"
"53.62600","0.81936","-1.05056"
"53.72600","0.78931","-1.01470"
"53.82600","0.75955","-0.94707"
"53.92600","0.72955","-0.96443"
"54.02600","0.69952","-0.89087"
"54.12600","0.66964","-0.84300"
"54.22600","0.63951","-0.70100"
"54.32600","0.60959","-0.74047"
"54.42600","0.57961","-0.70250"
"54.52600","0.54965","-0.64450"
"54.62600","0.51950","-0.60521"
"54.72600","0.48952","-0.56949"
"54.82600","0.45938","-0.54005"
"54.92600","0.42960","-0.47811"
"55.02600","0.39932","-0.44776"
"55.12600","0.36953","-0.40235"
"55.22600","0.33937","-0.36987"
"55.32600","0.30945","-0.31421"
"55.42600","0.27947","-0.30263"
"55.52600","0.24976","-0.24734"
"55.62600","0.21966","-0.22114"
"55.72600","0.18961","-0.15259"
"55.82600","0.15949","-0.12395"
"55.92600","0.12950","-0.05288"
"56.02600","0.09945","-0.03485"
"56.12600","0.06964","0.00859"
"56.22600","0.03940","0.04393"
"56.32600","0.00949","0.10324"
"56.42600","-0.02053","0.12539"
"56.52600","-0.05055","0.17826"
"56.62600","-0.08040","0.21390"
"56.72600","-0.11030","0.24447"
"56.82600","-0.14027","0.31532"
"56.92600","-0.17043","0.34022"
"57.02600","-0.20042","0.37813"
"57.12600","-0.23046","0.42424"
"57.22600","-0.26027","0.50013"
"57.32600","-0.29045","0.51577"
"57.42600","-0.32044","0.59035"
"57.52600","-0.35059","0.62114"
"57.62600","-0.38059","0.68683"
"57.72600","-0.41067","0.71793"
"57.82600","-0.44039","0.76889"
"57.92600","-0.47043","0.77149"
"58.02600","-0.50023","0.84844"
"58.12600","-0.53050","0.85344"
"58.22600","-0.56032","0.94025"
"58.32600","-0.59041","0.95893"
"58.42600","-0.62026","1.02584"
"58.52600","-0.65055","1.08768"
"58.62600","-0.68055","1.11695"
"58.72600","-0.71064","1.14369"
"58.82600","-0.74060","1.20040"
"58.92600","-0.77052","1.25538"
"59.02600","-0.80046","1.29879"
"59.12600","-0.83042","1.33020"
"59.22600","-0.86060","1.35199"
"59.32600","-0.89051","1.39846"
"59.42600","-0.92041","1.44953"
"59.52600","-0.95019","1.48293"
"59.62600","-0.98037","1.53307"
"59.72600","-1.01034","1.56233"
"59.82600","-1.04056","1.63151"
"59.92600","-1.07055","1.68291"
"60.02600","-1.10057","1.73152"
"60.12600","-1.13045","1.76365"
"60.22600","-1.16060","1.81273"
"60.32600","-1.19047","1.86622"
"60.42600","-1.22064","1.97832"
"60.52600","-1.25035","1.95855"
"60.62600","-1.28034","1.99778"
"60.72600","-1.31016","2.06127"
"60.82600","-1.34040","2.10379"
"60.92600","-1.37042","2.14602"
"61.02600","-1.40054","2.20035"
"61.12600","-1.43059","2.24099"
"61.22600","-1.46050","2.28713"
"61.32600","-1.49045","2.33885"
"61.42600","-1.52055","2.37725"
"61.52600","-1.55061","2.42212"
"61.62600","-1.58068","2.49404"
"61.72600","-1.61058","2.54576"
"61.82600","-1.64040","2.57178"
"61.92600","-1.67035","2.61988"
"62.02600","-1.70031","2.67375"
"62.12600","-1.73050","2.72520"
"62.22600","-1.76048","2.75378"
"62.32600","-1.79042","2.81327"
"62.42600","-1.82033","2.85524"
"62.52600","-1.85058","2.91672"
"62.62600","-1.88051","2.95831"
"62.72600","-1.91072","2.99869"
"62.82600","-1.94059","3.03144"
"62.92600","-1.97049","3.10562"
"63.02600","-2.00033","3.15070"
"63.12600","-2.03043","3.20386"
"63.22600","-2.06036","3.23563"
"63.32600","-2.09041","3.29472"
"63.42600","-2.12045","3.34795"
"63.52600","-2.15041","3.41381"
"63.62600","-2.18042","3.46636"
"63.72600","-2.21044","3.52715"
"63.82600","-2.24052","3.58879"
"63.92600","-2.27057","3.63759"
"64.02600","-2.30058","3.68118"
"64.12600","-2.33061","3.71890"
"64.22600","-2.36055","3.79195"
"64.32600","-2.39047","3.84906"
"64.42600","-2.42060","3.91339"
"64.52600","-2.45029","3.93433"
"64.62600","-2.48034","4.00404"
"64.72600","-2.51018","4.04524"
"64.82600","-2.54038","4.10895"
"64.92600","-2.57039","4.14360"
"65.02600","-2.60067","4.09239"
"65.12600","-2.63056","4.02651"
"65.22600","-2.66052","3.98151"
"65.32600","-2.69044","3.91151"
"65.42600","-2.72054","3.85734"
"65.52600","-2.75048","3.78803"
"65.62600","-2.78059","3.74607"
"65.69100","-2.80003","3.70213"
"65.69300","-2.80061","3.70098"
"65.79300","-2.80499","3.68799"
"65.89300","-2.78070","3.72615"
"65.99300","-2.75625","3.77454"
"66.09300","-2.73275","3.82381"
"66.19300","-2.70955","3.88438"
"66.29300","-2.68616","3.92678"
"66.39300","-2.66272","3.97233"
"66.49300","-2.63942","4.00745"
"66.59300","-2.61636","4.08129"
"66.69300","-2.59271","4.11216"
"66.79300","-2.56911","4.14850"
"66.89300","-2.54631","4.11866"
"66.99300","-2.52281","4.05944"
"67.09300","-2.49924","4.01334"
"67.19300","-2.47615","3.99177"
"67.29300","-2.45297","3.92259"
"67.39300","-2.42946","3.89048"
"67.49300","-2.40586","3.84143"
"67.59300","-2.38292","3.82536"
"67.69300","-2.35955","3.76476"
"67.79300","-2.33588","3.72138"
"67.89300","-2.31266","3.68655"
"67.99300","-2.28978","3.66579"
"68.09300","-2.26599","3.64317"
"68.19300","-2.24255","3.59096"
"68.29300","-2.21947","3.52693"
"68.39300","-2.19607","3.49828"
"68.49300","-2.17280","3.42033"
"68.59300","-2.14923","3.36337"
"68.69300","-2.12624","3.33675"
"68.79300","-2.10288","3.27861"
"68.89300","-2.07930","3.29081"
"68.99300","-2.05602","3.22670"
"69.09300","-2.03283","3.17289"
"69.19300","-2.00933","3.13690"
"69.29300","-1.98595","3.10767"
"69.39300","-1.96300","3.08089"
"69.49300","-1.93942","3.02332"
"69.59300","-1.91595","2.98772"
"69.69300","-1.89270","2.95751"
"69.79300","-1.86958","2.91602"
"69.89300","-1.84614","2.87568"
"69.99300","-1.82251","2.82740"
"70.09300","-1.79975","2.81131"
"70.19300","-1.77604","2.73011"
"70.29300","-1.75257","2.70510"
"70.39300","-1.72951","2.68622"
"70.49300","-1.70618","2.62812"
"70.59300","-1.68259","2.62534"
"70.69300","-1.65926","2.56996"
"70.79300","-1.63634","2.55624"
"70.89300","-1.61287","2.48587"
"70.99300","-1.58925","2.45627"
"71.09300","-1.56612","2.42745"
"71.19300","-1.54296","2.39206"
"71.29300","-1.51926","2.35768"
"71.39300","-1.49584","2.30095"
"71.49300","-1.47291","2.27814"
"71.59300","-1.44941","2.26000"
"71.69300","-1.42618","2.18845"
"71.79300","-1.40261","2.13347"
"71.89300","-1.37940","2.12725"
"71.99300","-1.35619","2.09380"
"72.09300","-1.33249","2.05712"
"72.19300","-1.30950","2.00549"
"72.29300","-1.28623","1.97100"
"72.39300","-1.26273","1.94938"
"72.49300","-1.23935","1.92932"
"72.59300","-1.21632","1.86089"
"72.69300","-1.19270","1.79747"
"72.79300","-1.16931","1.77180"
"72.89300","-1.14612","1.75776"
"72.99300","-1.12285","1.70572"
"73.09300","-1.09956","1.68883"
"73.19300","-1.07590","1.61994"
"73.29300","-1.05303","1.60943"
"73.39300","-1.02927","1.57340"
"73.49300","-1.00571","1.52798"
"73.59300","-0.98293","1.50992"
"73.69300","-0.95947","1.47572"
"73.79300","-0.93601","1.45361"
"73.89300","-0.91279","1.39670"
"73.99300","-0.88963","1.37172"
"74.09300","-0.86603","1.33048"
"74.19300","-0.84256","1.30414"
"74.29300","-0.81944","1.29341"
"74.39300","-0.79627","1.23581"
"74.49300","-0.77265","1.18820"
"74.59300","-0.74928","1.19648"
"74.69300","-0.72635","1.14233"
"74.79300","-0.70263","1.10231"
"74.89300","-0.67935","1.05043"
"74.99300","-0.65616","1.03542"
"75.09300","-0.63286","1.00880"
"75.19300","-0.60951","0.96535"
"75.29300","-0.58594","0.93684"
"75.39300","-0.56294","0.89715"
"75.49300","-0.53956","0.87198"
"75.59300","-0.51575","0.83721"
"75.69300","-0.49261","0.80171"
"75.79300","-0.46968","0.75371"
"75.89300","-0.44598","0.74428"
"75.99300","-0.42269","0.67294"
"76.09300","-0.39969","0.66334"
"76.19300","-0.37605","0.60149"
"76.29300","-0.35263","0.61052"
"76.39300","-0.32924","0.55774"
"76.49300","-0.30631","0.50353"
"76.59300","-0.28270","0.45166"
"76.69300","-0.25919","0.40901"
"76.79300","-0.23650","0.40874"
"76.89300","-0.21287","0.36828"
"76.99300","-0.18917","0.35006"
"77.09300","-0.16602","0.29590"
"77.19300","-0.14283","0.27598"
"77.29300","-0.11946","0.25062"
"77.39300","-0.09596","0.20473"
"77.49300","-0.07279","0.14057"
"77.59300","-0.04959","0.12553"
"77.69300","-0.02605","0.08414"
"77.79300","-0.00249","0.07444"
"77.80500","0.00021","0.05116"